<<< PROJECT PART I -- process set (n=20) with 12 CPU-bound processes >>>
I/O-bound process A: arrival time 45ms; 60 CPU bursts
I/O-bound process B: arrival time 76ms; 35 CPU bursts
I/O-bound process C: arrival time 114ms; 13 CPU bursts
I/O-bound process D: arrival time 227ms; 48 CPU bursts
I/O-bound process E: arrival time 39ms; 60 CPU bursts
I/O-bound process F: arrival time 18ms; 44 CPU bursts
I/O-bound process G: arrival time 274ms; 53 CPU bursts
I/O-bound process H: arrival time 30ms; 51 CPU bursts
CPU-bound process I: arrival time 23ms; 6 CPU bursts
CPU-bound process J: arrival time 18ms; 35 CPU bursts
CPU-bound process K: arrival time 414ms; 61 CPU bursts
CPU-bound process L: arrival time 3ms; 38 CPU bursts
CPU-bound process M: arrival time 160ms; 50 CPU bursts
CPU-bound process N: arrival time 115ms; 63 CPU bursts
CPU-bound process O: arrival time 9ms; 52 CPU bursts
CPU-bound process P: arrival time 212ms; 13 CPU bursts
CPU-bound process Q: arrival time 15ms; 51 CPU bursts
CPU-bound process R: arrival time 59ms; 63 CPU bursts
CPU-bound process S: arrival time 155ms; 53 CPU bursts
CPU-bound process T: arrival time 116ms; 17 CPU bursts

<<< PROJECT PART II -- t_cs=4ms; alpha=0.96; t_slice=64ms >>>
time 0ms: Simulator started for FCFS [Q <empty>]
time 3ms: Process L arrived; added to ready queue [Q L]
time 5ms: Process L started using the CPU for 500ms burst [Q <empty>]
time 9ms: Process O arrived; added to ready queue [Q O]
time 15ms: Process Q arrived; added to ready queue [Q O Q]
time 18ms: Process F arrived; added to ready queue [Q O Q F]
time 18ms: Process J arrived; added to ready queue [Q O Q F J]
time 23ms: Process I arrived; added to ready queue [Q O Q F J I]
time 30ms: Process H arrived; added to ready queue [Q O Q F J I H]
time 39ms: Process E arrived; added to ready queue [Q O Q F J I H E]
time 45ms: Process A arrived; added to ready queue [Q O Q F J I H E A]
time 59ms: Process R arrived; added to ready queue [Q O Q F J I H E A R]
time 76ms: Process B arrived; added to ready queue [Q O Q F J I H E A R B]
time 114ms: Process C arrived; added to ready queue [Q O Q F J I H E A R B C]
time 115ms: Process N arrived; added to ready queue [Q O Q F J I H E A R B C N]
time 116ms: Process T arrived; added to ready queue [Q O Q F J I H E A R B C N T]
time 155ms: Process S arrived; added to ready queue [Q O Q F J I H E A R B C N T S]
time 160ms: Process M arrived; added to ready queue [Q O Q F J I H E A R B C N T S M]
time 212ms: Process P arrived; added to ready queue [Q O Q F J I H E A R B C N T S M P]
time 227ms: Process D arrived; added to ready queue [Q O Q F J I H E A R B C N T S M P D]
time 274ms: Process G arrived; added to ready queue [Q O Q F J I H E A R B C N T S M P D G]
time 414ms: Process K arrived; added to ready queue [Q O Q F J I H E A R B C N T S M P D G K]
time 505ms: Process L completed a CPU burst; 37 bursts to go [Q O Q F J I H E A R B C N T S M P D G K]
time 505ms: Process L switching out of CPU; blocking on I/O until time 518ms [Q O Q F J I H E A R B C N T S M P D G K]
time 509ms: Process O started using the CPU for 152ms burst [Q Q F J I H E A R B C N T S M P D G K]
time 518ms: Process L completed I/O; added to ready queue [Q Q F J I H E A R B C N T S M P D G K L]
time 661ms: Process O completed a CPU burst; 51 bursts to go [Q Q F J I H E A R B C N T S M P D G K L]
time 661ms: Process O switching out of CPU; blocking on I/O until time 860ms [Q Q F J I H E A R B C N T S M P D G K L]
time 665ms: Process Q started using the CPU for 328ms burst [Q F J I H E A R B C N T S M P D G K L]
time 860ms: Process O completed I/O; added to ready queue [Q F J I H E A R B C N T S M P D G K L O]
time 993ms: Process Q completed a CPU burst; 50 bursts to go [Q F J I H E A R B C N T S M P D G K L O]
time 993ms: Process Q switching out of CPU; blocking on I/O until time 1282ms [Q F J I H E A R B C N T S M P D G K L O]
time 997ms: Process F started using the CPU for 28ms burst [Q J I H E A R B C N T S M P D G K L O]
time 1025ms: Process F completed a CPU burst; 43 bursts to go [Q J I H E A R B C N T S M P D G K L O]
time 1025ms: Process F switching out of CPU; blocking on I/O until time 2297ms [Q J I H E A R B C N T S M P D G K L O]
time 1029ms: Process J started using the CPU for 2048ms burst [Q I H E A R B C N T S M P D G K L O]
time 1282ms: Process Q completed I/O; added to ready queue [Q I H E A R B C N T S M P D G K L O Q]
time 2297ms: Process F completed I/O; added to ready queue [Q I H E A R B C N T S M P D G K L O Q F]
time 3077ms: Process J completed a CPU burst; 34 bursts to go [Q I H E A R B C N T S M P D G K L O Q F]
time 3077ms: Process J switching out of CPU; blocking on I/O until time 3131ms [Q I H E A R B C N T S M P D G K L O Q F]
time 3081ms: Process I started using the CPU for 192ms burst [Q H E A R B C N T S M P D G K L O Q F]
time 3131ms: Process J completed I/O; added to ready queue [Q H E A R B C N T S M P D G K L O Q F J]
time 3273ms: Process I completed a CPU burst; 5 bursts to go [Q H E A R B C N T S M P D G K L O Q F J]
time 3273ms: Process I switching out of CPU; blocking on I/O until time 3303ms [Q H E A R B C N T S M P D G K L O Q F J]
time 3277ms: Process H started using the CPU for 71ms burst [Q E A R B C N T S M P D G K L O Q F J]
time 3303ms: Process I completed I/O; added to ready queue [Q E A R B C N T S M P D G K L O Q F J I]
time 3348ms: Process H completed a CPU burst; 50 bursts to go [Q E A R B C N T S M P D G K L O Q F J I]
time 3348ms: Process H switching out of CPU; blocking on I/O until time 7160ms [Q E A R B C N T S M P D G K L O Q F J I]
time 3352ms: Process E started using the CPU for 28ms burst [Q A R B C N T S M P D G K L O Q F J I]
time 3380ms: Process E completed a CPU burst; 59 bursts to go [Q A R B C N T S M P D G K L O Q F J I]
time 3380ms: Process E switching out of CPU; blocking on I/O until time 4152ms [Q A R B C N T S M P D G K L O Q F J I]
time 3384ms: Process A started using the CPU for 49ms burst [Q R B C N T S M P D G K L O Q F J I]
time 3433ms: Process A completed a CPU burst; 59 bursts to go [Q R B C N T S M P D G K L O Q F J I]
time 3433ms: Process A switching out of CPU; blocking on I/O until time 4225ms [Q R B C N T S M P D G K L O Q F J I]
time 3437ms: Process R started using the CPU for 272ms burst [Q B C N T S M P D G K L O Q F J I]
time 3709ms: Process R completed a CPU burst; 62 bursts to go [Q B C N T S M P D G K L O Q F J I]
time 3709ms: Process R switching out of CPU; blocking on I/O until time 3798ms [Q B C N T S M P D G K L O Q F J I]
time 3713ms: Process B started using the CPU for 14ms burst [Q C N T S M P D G K L O Q F J I]
time 3727ms: Process B completed a CPU burst; 34 bursts to go [Q C N T S M P D G K L O Q F J I]
time 3727ms: Process B switching out of CPU; blocking on I/O until time 4169ms [Q C N T S M P D G K L O Q F J I]
time 3731ms: Process C started using the CPU for 204ms burst [Q N T S M P D G K L O Q F J I]
time 3798ms: Process R completed I/O; added to ready queue [Q N T S M P D G K L O Q F J I R]
time 3935ms: Process C completed a CPU burst; 12 bursts to go [Q N T S M P D G K L O Q F J I R]
time 3935ms: Process C switching out of CPU; blocking on I/O until time 4947ms [Q N T S M P D G K L O Q F J I R]
time 3939ms: Process N started using the CPU for 256ms burst [Q T S M P D G K L O Q F J I R]
time 4152ms: Process E completed I/O; added to ready queue [Q T S M P D G K L O Q F J I R E]
time 4169ms: Process B completed I/O; added to ready queue [Q T S M P D G K L O Q F J I R E B]
time 4195ms: Process N completed a CPU burst; 62 bursts to go [Q T S M P D G K L O Q F J I R E B]
time 4195ms: Process N switching out of CPU; blocking on I/O until time 4205ms [Q T S M P D G K L O Q F J I R E B]
time 4199ms: Process T started using the CPU for 20ms burst [Q S M P D G K L O Q F J I R E B]
time 4205ms: Process N completed I/O; added to ready queue [Q S M P D G K L O Q F J I R E B N]
time 4219ms: Process T completed a CPU burst; 16 bursts to go [Q S M P D G K L O Q F J I R E B N]
time 4219ms: Process T switching out of CPU; blocking on I/O until time 4552ms [Q S M P D G K L O Q F J I R E B N]
time 4223ms: Process S started using the CPU for 2432ms burst [Q M P D G K L O Q F J I R E B N]
time 4225ms: Process A completed I/O; added to ready queue [Q M P D G K L O Q F J I R E B N A]
time 4552ms: Process T completed I/O; added to ready queue [Q M P D G K L O Q F J I R E B N A T]
time 4947ms: Process C completed I/O; added to ready queue [Q M P D G K L O Q F J I R E B N A T C]
time 6655ms: Process S completed a CPU burst; 52 bursts to go [Q M P D G K L O Q F J I R E B N A T C]
time 6655ms: Process S switching out of CPU; blocking on I/O until time 6739ms [Q M P D G K L O Q F J I R E B N A T C]
time 6659ms: Process M started using the CPU for 396ms burst [Q P D G K L O Q F J I R E B N A T C]
time 6739ms: Process S completed I/O; added to ready queue [Q P D G K L O Q F J I R E B N A T C S]
time 7055ms: Process M completed a CPU burst; 49 bursts to go [Q P D G K L O Q F J I R E B N A T C S]
time 7055ms: Process M switching out of CPU; blocking on I/O until time 7217ms [Q P D G K L O Q F J I R E B N A T C S]
time 7059ms: Process P started using the CPU for 20ms burst [Q D G K L O Q F J I R E B N A T C S]
time 7079ms: Process P completed a CPU burst; 12 bursts to go [Q D G K L O Q F J I R E B N A T C S]
time 7079ms: Process P switching out of CPU; blocking on I/O until time 7194ms [Q D G K L O Q F J I R E B N A T C S]
time 7083ms: Process D started using the CPU for 59ms burst [Q G K L O Q F J I R E B N A T C S]
time 7142ms: Process D completed a CPU burst; 47 bursts to go [Q G K L O Q F J I R E B N A T C S]
time 7142ms: Process D switching out of CPU; blocking on I/O until time 7844ms [Q G K L O Q F J I R E B N A T C S]
time 7146ms: Process G started using the CPU for 3ms burst [Q K L O Q F J I R E B N A T C S]
time 7149ms: Process G completed a CPU burst; 52 bursts to go [Q K L O Q F J I R E B N A T C S]
time 7149ms: Process G switching out of CPU; blocking on I/O until time 7871ms [Q K L O Q F J I R E B N A T C S]
time 7153ms: Process K started using the CPU for 116ms burst [Q L O Q F J I R E B N A T C S]
time 7160ms: Process H completed I/O; added to ready queue [Q L O Q F J I R E B N A T C S H]
time 7194ms: Process P completed I/O; added to ready queue [Q L O Q F J I R E B N A T C S H P]
time 7217ms: Process M completed I/O; added to ready queue [Q L O Q F J I R E B N A T C S H P M]
time 7269ms: Process K completed a CPU burst; 60 bursts to go [Q L O Q F J I R E B N A T C S H P M]
time 7269ms: Process K switching out of CPU; blocking on I/O until time 7273ms [Q L O Q F J I R E B N A T C S H P M]
time 7273ms: Process L started using the CPU for 56ms burst [Q O Q F J I R E B N A T C S H P M]
time 7273ms: Process K completed I/O; added to ready queue [Q O Q F J I R E B N A T C S H P M K]
time 7329ms: Process L completed a CPU burst; 36 bursts to go [Q O Q F J I R E B N A T C S H P M K]
time 7329ms: Process L switching out of CPU; blocking on I/O until time 7366ms [Q O Q F J I R E B N A T C S H P M K]
time 7333ms: Process O started using the CPU for 180ms burst [Q Q F J I R E B N A T C S H P M K]
time 7366ms: Process L completed I/O; added to ready queue [Q Q F J I R E B N A T C S H P M K L]
time 7513ms: Process O completed a CPU burst; 50 bursts to go [Q Q F J I R E B N A T C S H P M K L]
time 7513ms: Process O switching out of CPU; blocking on I/O until time 7580ms [Q Q F J I R E B N A T C S H P M K L]
time 7517ms: Process Q started using the CPU for 56ms burst [Q F J I R E B N A T C S H P M K L]
time 7573ms: Process Q completed a CPU burst; 49 bursts to go [Q F J I R E B N A T C S H P M K L]
time 7573ms: Process Q switching out of CPU; blocking on I/O until time 7797ms [Q F J I R E B N A T C S H P M K L]
time 7577ms: Process F started using the CPU for 98ms burst [Q J I R E B N A T C S H P M K L]
time 7580ms: Process O completed I/O; added to ready queue [Q J I R E B N A T C S H P M K L O]
time 7675ms: Process F completed a CPU burst; 42 bursts to go [Q J I R E B N A T C S H P M K L O]
time 7675ms: Process F switching out of CPU; blocking on I/O until time 10087ms [Q J I R E B N A T C S H P M K L O]
time 7679ms: Process J started using the CPU for 100ms burst [Q I R E B N A T C S H P M K L O]
time 7779ms: Process J completed a CPU burst; 33 bursts to go [Q I R E B N A T C S H P M K L O]
time 7779ms: Process J switching out of CPU; blocking on I/O until time 7887ms [Q I R E B N A T C S H P M K L O]
time 7783ms: Process I started using the CPU for 64ms burst [Q R E B N A T C S H P M K L O]
time 7797ms: Process Q completed I/O; added to ready queue [Q R E B N A T C S H P M K L O Q]
time 7844ms: Process D completed I/O; added to ready queue [Q R E B N A T C S H P M K L O Q D]
time 7847ms: Process I completed a CPU burst; 4 bursts to go [Q R E B N A T C S H P M K L O Q D]
time 7847ms: Process I switching out of CPU; blocking on I/O until time 8034ms [Q R E B N A T C S H P M K L O Q D]
time 7851ms: Process R started using the CPU for 1088ms burst [Q E B N A T C S H P M K L O Q D]
time 7871ms: Process G completed I/O; added to ready queue [Q E B N A T C S H P M K L O Q D G]
time 7887ms: Process J completed I/O; added to ready queue [Q E B N A T C S H P M K L O Q D G J]
time 8034ms: Process I completed I/O; added to ready queue [Q E B N A T C S H P M K L O Q D G J I]
time 8939ms: Process R completed a CPU burst; 61 bursts to go [Q E B N A T C S H P M K L O Q D G J I]
time 8939ms: Process R switching out of CPU; blocking on I/O until time 9182ms [Q E B N A T C S H P M K L O Q D G J I]
time 8943ms: Process E started using the CPU for 33ms burst [Q B N A T C S H P M K L O Q D G J I]
time 8976ms: Process E completed a CPU burst; 58 bursts to go [Q B N A T C S H P M K L O Q D G J I]
time 8976ms: Process E switching out of CPU; blocking on I/O until time 9018ms [Q B N A T C S H P M K L O Q D G J I]
time 8980ms: Process B started using the CPU for 160ms burst [Q N A T C S H P M K L O Q D G J I]
time 9018ms: Process E completed I/O; added to ready queue [Q N A T C S H P M K L O Q D G J I E]
time 9140ms: Process B completed a CPU burst; 33 bursts to go [Q N A T C S H P M K L O Q D G J I E]
time 9140ms: Process B switching out of CPU; blocking on I/O until time 9412ms [Q N A T C S H P M K L O Q D G J I E]
time 9144ms: Process N started using the CPU for 380ms burst [Q A T C S H P M K L O Q D G J I E]
time 9182ms: Process R completed I/O; added to ready queue [Q A T C S H P M K L O Q D G J I E R]
time 9412ms: Process B completed I/O; added to ready queue [Q A T C S H P M K L O Q D G J I E R B]
time 9524ms: Process N completed a CPU burst; 61 bursts to go [Q A T C S H P M K L O Q D G J I E R B]
time 9524ms: Process N switching out of CPU; blocking on I/O until time 9634ms [Q A T C S H P M K L O Q D G J I E R B]
time 9528ms: Process A started using the CPU for 274ms burst [Q T C S H P M K L O Q D G J I E R B]
time 9634ms: Process N completed I/O; added to ready queue [Q T C S H P M K L O Q D G J I E R B N]
time 9802ms: Process A completed a CPU burst; 58 bursts to go [Q T C S H P M K L O Q D G J I E R B N]
time 9802ms: Process A switching out of CPU; blocking on I/O until time 10654ms [Q T C S H P M K L O Q D G J I E R B N]
time 9806ms: Process T started using the CPU for 436ms burst [Q C S H P M K L O Q D G J I E R B N]
time 41422ms: Process I terminated [Q D R C N G B E H T P S A M K F Q L O J]
time 75850ms: Process P terminated [Q T B M G K L E C O Q A F R J S]
time 82976ms: Process C terminated [Q O Q F A R E J S N T M D K L]
time 93650ms: Process T terminated [Q S A G F M K L D B O E H Q N R]
time 160787ms: Process J terminated [Q S H K F O A Q G M B E R N D L]
time 172349ms: Process L terminated [Q B D K O S Q H A E F M R N G]
time 184027ms: Process B terminated [Q E S H M Q K R O]
time 210877ms: Process M terminated [Q H R N D K G Q E F A O S]
time 212416ms: Process O terminated [Q S H R N Q K E]
time 214678ms: Process Q terminated [Q K E G S F H R N D A]
time 218391ms: Process S terminated [Q E H R N D K]
time 226586ms: Process F terminated [Q R N G A]
time 239183ms: Process H terminated [Q D N G R K E]
time 239277ms: Process D terminated [Q N G R K E]
time 240914ms: Process K terminated [Q E N R A]
time 241622ms: Process N terminated [Q R]
time 242006ms: Process R terminated [Q A]
time 246975ms: Process G terminated [Q <empty>]
time 255175ms: Process A terminated [Q E]
time 262654ms: Process E terminated [Q <empty>]
time 262656ms: Simulator ended for FCFS [Q <empty>]

time 0ms: Simulator started for SJF [Q <empty>]
time 3ms: Process L (tau 100ms) arrived; added to ready queue [Q L]
time 5ms: Process L (tau 100ms) started using the CPU for 500ms burst [Q <empty>]
time 9ms: Process O (tau 100ms) arrived; added to ready queue [Q O]
time 15ms: Process Q (tau 100ms) arrived; added to ready queue [Q O Q]
time 18ms: Process F (tau 100ms) arrived; added to ready queue [Q F O Q]
time 18ms: Process J (tau 100ms) arrived; added to ready queue [Q F J O Q]
time 23ms: Process I (tau 100ms) arrived; added to ready queue [Q F I J O Q]
time 30ms: Process H (tau 100ms) arrived; added to ready queue [Q F H I J O Q]
time 39ms: Process E (tau 100ms) arrived; added to ready queue [Q E F H I J O Q]
time 45ms: Process A (tau 100ms) arrived; added to ready queue [Q A E F H I J O Q]
time 59ms: Process R (tau 100ms) arrived; added to ready queue [Q A E F H I J O Q R]
time 76ms: Process B (tau 100ms) arrived; added to ready queue [Q A B E F H I J O Q R]
time 114ms: Process C (tau 100ms) arrived; added to ready queue [Q A B C E F H I J O Q R]
time 115ms: Process N (tau 100ms) arrived; added to ready queue [Q A B C E F H I J N O Q R]
time 116ms: Process T (tau 100ms) arrived; added to ready queue [Q A B C E F H I J N O Q R T]
time 155ms: Process S (tau 100ms) arrived; added to ready queue [Q A B C E F H I J N O Q R S T]
time 160ms: Process M (tau 100ms) arrived; added to ready queue [Q A B C E F H I J M N O Q R S T]
time 212ms: Process P (tau 100ms) arrived; added to ready queue [Q A B C E F H I J M N O P Q R S T]
time 227ms: Process D (tau 100ms) arrived; added to ready queue [Q A B C D E F H I J M N O P Q R S T]
time 274ms: Process G (tau 100ms) arrived; added to ready queue [Q A B C D E F G H I J M N O P Q R S T]
time 414ms: Process K (tau 100ms) arrived; added to ready queue [Q A B C D E F G H I J K M N O P Q R S T]
time 505ms: Process L (tau 100ms) completed a CPU burst; 37 bursts to go [Q A B C D E F G H I J K M N O P Q R S T]
time 505ms: Recalculating tau for process L: old tau 100ms ==> new tau 485ms [Q A B C D E F G H I J K M N O P Q R S T]
time 505ms: Process L switching out of CPU; blocking on I/O until time 518ms [Q A B C D E F G H I J K M N O P Q R S T]
time 509ms: Process A (tau 100ms) started using the CPU for 49ms burst [Q B C D E F G H I J K M N O P Q R S T]
time 518ms: Process L (tau 485ms) completed I/O; added to ready queue [Q B C D E F G H I J K M N O P Q R S T L]
time 558ms: Process A (tau 100ms) completed a CPU burst; 59 bursts to go [Q B C D E F G H I J K M N O P Q R S T L]
time 558ms: Recalculating tau for process A: old tau 100ms ==> new tau 52ms [Q B C D E F G H I J K M N O P Q R S T L]
time 558ms: Process A switching out of CPU; blocking on I/O until time 1350ms [Q B C D E F G H I J K M N O P Q R S T L]
time 562ms: Process B (tau 100ms) started using the CPU for 14ms burst [Q C D E F G H I J K M N O P Q R S T L]
time 576ms: Process B (tau 100ms) completed a CPU burst; 34 bursts to go [Q C D E F G H I J K M N O P Q R S T L]
time 576ms: Recalculating tau for process B: old tau 100ms ==> new tau 18ms [Q C D E F G H I J K M N O P Q R S T L]
time 576ms: Process B switching out of CPU; blocking on I/O until time 1018ms [Q C D E F G H I J K M N O P Q R S T L]
time 580ms: Process C (tau 100ms) started using the CPU for 204ms burst [Q D E F G H I J K M N O P Q R S T L]
time 784ms: Process C (tau 100ms) completed a CPU burst; 12 bursts to go [Q D E F G H I J K M N O P Q R S T L]
time 784ms: Recalculating tau for process C: old tau 100ms ==> new tau 200ms [Q D E F G H I J K M N O P Q R S T L]
time 784ms: Process C switching out of CPU; blocking on I/O until time 1796ms [Q D E F G H I J K M N O P Q R S T L]
time 788ms: Process D (tau 100ms) started using the CPU for 59ms burst [Q E F G H I J K M N O P Q R S T L]
time 847ms: Process D (tau 100ms) completed a CPU burst; 47 bursts to go [Q E F G H I J K M N O P Q R S T L]
time 847ms: Recalculating tau for process D: old tau 100ms ==> new tau 61ms [Q E F G H I J K M N O P Q R S T L]
time 847ms: Process D switching out of CPU; blocking on I/O until time 1549ms [Q E F G H I J K M N O P Q R S T L]
time 851ms: Process E (tau 100ms) started using the CPU for 28ms burst [Q F G H I J K M N O P Q R S T L]
time 879ms: Process E (tau 100ms) completed a CPU burst; 59 bursts to go [Q F G H I J K M N O P Q R S T L]
time 879ms: Recalculating tau for process E: old tau 100ms ==> new tau 31ms [Q F G H I J K M N O P Q R S T L]
time 879ms: Process E switching out of CPU; blocking on I/O until time 1651ms [Q F G H I J K M N O P Q R S T L]
time 883ms: Process F (tau 100ms) started using the CPU for 28ms burst [Q G H I J K M N O P Q R S T L]
time 911ms: Process F (tau 100ms) completed a CPU burst; 43 bursts to go [Q G H I J K M N O P Q R S T L]
time 911ms: Recalculating tau for process F: old tau 100ms ==> new tau 31ms [Q G H I J K M N O P Q R S T L]
time 911ms: Process F switching out of CPU; blocking on I/O until time 2183ms [Q G H I J K M N O P Q R S T L]
time 915ms: Process G (tau 100ms) started using the CPU for 3ms burst [Q H I J K M N O P Q R S T L]
time 918ms: Process G (tau 100ms) completed a CPU burst; 52 bursts to go [Q H I J K M N O P Q R S T L]
time 918ms: Recalculating tau for process G: old tau 100ms ==> new tau 7ms [Q H I J K M N O P Q R S T L]
time 918ms: Process G switching out of CPU; blocking on I/O until time 1640ms [Q H I J K M N O P Q R S T L]
time 922ms: Process H (tau 100ms) started using the CPU for 71ms burst [Q I J K M N O P Q R S T L]
time 993ms: Process H (tau 100ms) completed a CPU burst; 50 bursts to go [Q I J K M N O P Q R S T L]
time 993ms: Recalculating tau for process H: old tau 100ms ==> new tau 73ms [Q I J K M N O P Q R S T L]
time 993ms: Process H switching out of CPU; blocking on I/O until time 4805ms [Q I J K M N O P Q R S T L]
time 997ms: Process I (tau 100ms) started using the CPU for 192ms burst [Q J K M N O P Q R S T L]
time 1018ms: Process B (tau 18ms) completed I/O; added to ready queue [Q B J K M N O P Q R S T L]
time 1189ms: Process I (tau 100ms) completed a CPU burst; 5 bursts to go [Q B J K M N O P Q R S T L]
time 1189ms: Recalculating tau for process I: old tau 100ms ==> new tau 189ms [Q B J K M N O P Q R S T L]
time 1189ms: Process I switching out of CPU; blocking on I/O until time 1219ms [Q B J K M N O P Q R S T L]
time 1193ms: Process B (tau 18ms) started using the CPU for 160ms burst [Q J K M N O P Q R S T L]
time 1219ms: Process I (tau 189ms) completed I/O; added to ready queue [Q J K M N O P Q R S T I L]
time 1350ms: Process A (tau 52ms) completed I/O; added to ready queue [Q A J K M N O P Q R S T I L]
time 1353ms: Process B (tau 18ms) completed a CPU burst; 33 bursts to go [Q A J K M N O P Q R S T I L]
time 1353ms: Recalculating tau for process B: old tau 18ms ==> new tau 155ms [Q A J K M N O P Q R S T I L]
time 1353ms: Process B switching out of CPU; blocking on I/O until time 1625ms [Q A J K M N O P Q R S T I L]
time 1357ms: Process A (tau 52ms) started using the CPU for 274ms burst [Q J K M N O P Q R S T I L]
time 1549ms: Process D (tau 61ms) completed I/O; added to ready queue [Q D J K M N O P Q R S T I L]
time 1625ms: Process B (tau 155ms) completed I/O; added to ready queue [Q D J K M N O P Q R S T B I L]
time 1631ms: Process A (tau 52ms) completed a CPU burst; 58 bursts to go [Q D J K M N O P Q R S T B I L]
time 1631ms: Recalculating tau for process A: old tau 52ms ==> new tau 266ms [Q D J K M N O P Q R S T B I L]
time 1631ms: Process A switching out of CPU; blocking on I/O until time 2483ms [Q D J K M N O P Q R S T B I L]
time 1635ms: Process D (tau 61ms) started using the CPU for 72ms burst [Q J K M N O P Q R S T B I L]
time 1640ms: Process G (tau 7ms) completed I/O; added to ready queue [Q G J K M N O P Q R S T B I L]
time 1651ms: Process E (tau 31ms) completed I/O; added to ready queue [Q G E J K M N O P Q R S T B I L]
time 1707ms: Process D (tau 61ms) completed a CPU burst; 46 bursts to go [Q G E J K M N O P Q R S T B I L]
time 1707ms: Recalculating tau for process D: old tau 61ms ==> new tau 72ms [Q G E J K M N O P Q R S T B I L]
time 1707ms: Process D switching out of CPU; blocking on I/O until time 1959ms [Q G E J K M N O P Q R S T B I L]
time 1711ms: Process G (tau 7ms) started using the CPU for 8ms burst [Q E J K M N O P Q R S T B I L]
time 1719ms: Process G (tau 7ms) completed a CPU burst; 51 bursts to go [Q E J K M N O P Q R S T B I L]
time 1719ms: Recalculating tau for process G: old tau 7ms ==> new tau 8ms [Q E J K M N O P Q R S T B I L]
time 1719ms: Process G switching out of CPU; blocking on I/O until time 2931ms [Q E J K M N O P Q R S T B I L]
time 1723ms: Process E (tau 31ms) started using the CPU for 33ms burst [Q J K M N O P Q R S T B I L]
time 1756ms: Process E (tau 31ms) completed a CPU burst; 58 bursts to go [Q J K M N O P Q R S T B I L]
time 1756ms: Recalculating tau for process E: old tau 31ms ==> new tau 33ms [Q J K M N O P Q R S T B I L]
time 1756ms: Process E switching out of CPU; blocking on I/O until time 1798ms [Q J K M N O P Q R S T B I L]
time 1760ms: Process J (tau 100ms) started using the CPU for 2048ms burst [Q K M N O P Q R S T B I L]
time 1796ms: Process C (tau 200ms) completed I/O; added to ready queue [Q K M N O P Q R S T B I C L]
time 1798ms: Process E (tau 33ms) completed I/O; added to ready queue [Q E K M N O P Q R S T B I C L]
time 1959ms: Process D (tau 72ms) completed I/O; added to ready queue [Q E D K M N O P Q R S T B I C L]
time 2183ms: Process F (tau 31ms) completed I/O; added to ready queue [Q F E D K M N O P Q R S T B I C L]
time 2483ms: Process A (tau 266ms) completed I/O; added to ready queue [Q F E D K M N O P Q R S T B I C A L]
time 2931ms: Process G (tau 8ms) completed I/O; added to ready queue [Q G F E D K M N O P Q R S T B I C A L]
time 3808ms: Process J (tau 100ms) completed a CPU burst; 34 bursts to go [Q G F E D K M N O P Q R S T B I C A L]
time 3808ms: Recalculating tau for process J: old tau 100ms ==> new tau 1971ms [Q G F E D K M N O P Q R S T B I C A L]
time 3808ms: Process J switching out of CPU; blocking on I/O until time 3862ms [Q G F E D K M N O P Q R S T B I C A L]
time 3812ms: Process G (tau 8ms) started using the CPU for 3ms burst [Q F E D K M N O P Q R S T B I C A L]
time 3815ms: Process G (tau 8ms) completed a CPU burst; 50 bursts to go [Q F E D K M N O P Q R S T B I C A L]
time 3815ms: Recalculating tau for process G: old tau 8ms ==> new tau 4ms [Q F E D K M N O P Q R S T B I C A L]
time 3815ms: Process G switching out of CPU; blocking on I/O until time 5187ms [Q F E D K M N O P Q R S T B I C A L]
time 3819ms: Process F (tau 31ms) started using the CPU for 98ms burst [Q E D K M N O P Q R S T B I C A L]
time 3862ms: Process J (tau 1971ms) completed I/O; added to ready queue [Q E D K M N O P Q R S T B I C A L J]
time 3917ms: Process F (tau 31ms) completed a CPU burst; 42 bursts to go [Q E D K M N O P Q R S T B I C A L J]
time 3917ms: Recalculating tau for process F: old tau 31ms ==> new tau 96ms [Q E D K M N O P Q R S T B I C A L J]
time 3917ms: Process F switching out of CPU; blocking on I/O until time 6329ms [Q E D K M N O P Q R S T B I C A L J]
time 3921ms: Process E (tau 33ms) started using the CPU for 14ms burst [Q D K M N O P Q R S T B I C A L J]
time 3935ms: Process E (tau 33ms) completed a CPU burst; 57 bursts to go [Q D K M N O P Q R S T B I C A L J]
time 3935ms: Recalculating tau for process E: old tau 33ms ==> new tau 15ms [Q D K M N O P Q R S T B I C A L J]
time 3935ms: Process E switching out of CPU; blocking on I/O until time 5547ms [Q D K M N O P Q R S T B I C A L J]
time 3939ms: Process D (tau 72ms) started using the CPU for 15ms burst [Q K M N O P Q R S T B I C A L J]
time 3954ms: Process D (tau 72ms) completed a CPU burst; 45 bursts to go [Q K M N O P Q R S T B I C A L J]
time 3954ms: Recalculating tau for process D: old tau 72ms ==> new tau 18ms [Q K M N O P Q R S T B I C A L J]
time 3954ms: Process D switching out of CPU; blocking on I/O until time 4816ms [Q K M N O P Q R S T B I C A L J]
time 3958ms: Process K (tau 100ms) started using the CPU for 116ms burst [Q M N O P Q R S T B I C A L J]
time 4074ms: Process K (tau 100ms) completed a CPU burst; 60 bursts to go [Q M N O P Q R S T B I C A L J]
time 4074ms: Recalculating tau for process K: old tau 100ms ==> new tau 116ms [Q M N O P Q R S T B I C A L J]
time 4074ms: Process K switching out of CPU; blocking on I/O until time 4078ms [Q M N O P Q R S T B I C A L J]
time 4078ms: Process M (tau 100ms) started using the CPU for 396ms burst [Q N O P Q R S T B I C A L J]
time 4078ms: Process K (tau 116ms) completed I/O; added to ready queue [Q N O P Q R S T K B I C A L J]
time 4474ms: Process M (tau 100ms) completed a CPU burst; 49 bursts to go [Q N O P Q R S T K B I C A L J]
time 4474ms: Recalculating tau for process M: old tau 100ms ==> new tau 385ms [Q N O P Q R S T K B I C A L J]
time 4474ms: Process M switching out of CPU; blocking on I/O until time 4636ms [Q N O P Q R S T K B I C A L J]
time 4478ms: Process N (tau 100ms) started using the CPU for 256ms burst [Q O P Q R S T K B I C A L J]
time 4636ms: Process M (tau 385ms) completed I/O; added to ready queue [Q O P Q R S T K B I C A M L J]
time 4734ms: Process N (tau 100ms) completed a CPU burst; 62 bursts to go [Q O P Q R S T K B I C A M L J]
time 4734ms: Recalculating tau for process N: old tau 100ms ==> new tau 250ms [Q O P Q R S T K B I C A M L J]
time 4734ms: Process N switching out of CPU; blocking on I/O until time 4744ms [Q O P Q R S T K B I C A M L J]
time 4738ms: Process O (tau 100ms) started using the CPU for 152ms burst [Q P Q R S T K B I C A M L J]
time 4744ms: Process N (tau 250ms) completed I/O; added to ready queue [Q P Q R S T K B I C N A M L J]
time 4805ms: Process H (tau 73ms) completed I/O; added to ready queue [Q H P Q R S T K B I C N A M L J]
time 4816ms: Process D (tau 18ms) completed I/O; added to ready queue [Q D H P Q R S T K B I C N A M L J]
time 4890ms: Process O (tau 100ms) completed a CPU burst; 51 bursts to go [Q D H P Q R S T K B I C N A M L J]
time 4890ms: Recalculating tau for process O: old tau 100ms ==> new tau 150ms [Q D H P Q R S T K B I C N A M L J]
time 4890ms: Process O switching out of CPU; blocking on I/O until time 5089ms [Q D H P Q R S T K B I C N A M L J]
time 4894ms: Process D (tau 18ms) started using the CPU for 41ms burst [Q H P Q R S T K B I C N A M L J]
time 4935ms: Process D (tau 18ms) completed a CPU burst; 44 bursts to go [Q H P Q R S T K B I C N A M L J]
time 4935ms: Recalculating tau for process D: old tau 18ms ==> new tau 41ms [Q H P Q R S T K B I C N A M L J]
time 4935ms: Process D switching out of CPU; blocking on I/O until time 6827ms [Q H P Q R S T K B I C N A M L J]
time 4939ms: Process H (tau 73ms) started using the CPU for 20ms burst [Q P Q R S T K B I C N A M L J]
time 4959ms: Process H (tau 73ms) completed a CPU burst; 49 bursts to go [Q P Q R S T K B I C N A M L J]
time 4959ms: Recalculating tau for process H: old tau 73ms ==> new tau 23ms [Q P Q R S T K B I C N A M L J]
time 4959ms: Process H switching out of CPU; blocking on I/O until time 5011ms [Q P Q R S T K B I C N A M L J]
time 4963ms: Process P (tau 100ms) started using the CPU for 20ms burst [Q Q R S T K B I C N A M L J]
time 4983ms: Process P (tau 100ms) completed a CPU burst; 12 bursts to go [Q Q R S T K B I C N A M L J]
time 4983ms: Recalculating tau for process P: old tau 100ms ==> new tau 24ms [Q Q R S T K B I C N A M L J]
time 4983ms: Process P switching out of CPU; blocking on I/O until time 5098ms [Q Q R S T K B I C N A M L J]
time 4987ms: Process Q (tau 100ms) started using the CPU for 328ms burst [Q R S T K B I C N A M L J]
time 5011ms: Process H (tau 23ms) completed I/O; added to ready queue [Q H R S T K B I C N A M L J]
time 5089ms: Process O (tau 150ms) completed I/O; added to ready queue [Q H R S T K O B I C N A M L J]
time 5098ms: Process P (tau 24ms) completed I/O; added to ready queue [Q H P R S T K O B I C N A M L J]
time 5187ms: Process G (tau 4ms) completed I/O; added to ready queue [Q G H P R S T K O B I C N A M L J]
time 5315ms: Process Q (tau 100ms) completed a CPU burst; 50 bursts to go [Q G H P R S T K O B I C N A M L J]
time 5315ms: Recalculating tau for process Q: old tau 100ms ==> new tau 319ms [Q G H P R S T K O B I C N A M L J]
time 5315ms: Process Q switching out of CPU; blocking on I/O until time 5604ms [Q G H P R S T K O B I C N A M L J]
time 5319ms: Process G (tau 4ms) started using the CPU for 285ms burst [Q H P R S T K O B I C N A M L J]
time 5547ms: Process E (tau 15ms) completed I/O; added to ready queue [Q E H P R S T K O B I C N A M L J]
time 5604ms: Process G (tau 4ms) completed a CPU burst; 49 bursts to go [Q E H P R S T K O B I C N A M L J]
time 5604ms: Recalculating tau for process G: old tau 4ms ==> new tau 274ms [Q E H P R S T K O B I C N A M L J]
time 5604ms: Process G switching out of CPU; blocking on I/O until time 5886ms [Q E H P R S T K O B I C N A M L J]
time 5604ms: Process Q (tau 319ms) completed I/O; added to ready queue [Q E H P R S T K O B I C N A Q M L J]
time 5608ms: Process E (tau 15ms) started using the CPU for 51ms burst [Q H P R S T K O B I C N A Q M L J]
time 5659ms: Process E (tau 15ms) completed a CPU burst; 56 bursts to go [Q H P R S T K O B I C N A Q M L J]
time 5659ms: Recalculating tau for process E: old tau 15ms ==> new tau 50ms [Q H P R S T K O B I C N A Q M L J]
time 5659ms: Process E switching out of CPU; blocking on I/O until time 6421ms [Q H P R S T K O B I C N A Q M L J]
time 5663ms: Process H (tau 23ms) started using the CPU for 3ms burst [Q P R S T K O B I C N A Q M L J]
time 5666ms: Process H (tau 23ms) completed a CPU burst; 48 bursts to go [Q P R S T K O B I C N A Q M L J]
time 5666ms: Recalculating tau for process H: old tau 23ms ==> new tau 4ms [Q P R S T K O B I C N A Q M L J]
time 5666ms: Process H switching out of CPU; blocking on I/O until time 9368ms [Q P R S T K O B I C N A Q M L J]
time 5670ms: Process P (tau 24ms) started using the CPU for 52ms burst [Q R S T K O B I C N A Q M L J]
time 5722ms: Process P (tau 24ms) completed a CPU burst; 11 bursts to go [Q R S T K O B I C N A Q M L J]
time 5722ms: Recalculating tau for process P: old tau 24ms ==> new tau 51ms [Q R S T K O B I C N A Q M L J]
time 5722ms: Process P switching out of CPU; blocking on I/O until time 5741ms [Q R S T K O B I C N A Q M L J]
time 5726ms: Process R (tau 100ms) started using the CPU for 272ms burst [Q S T K O B I C N A Q M L J]
time 5741ms: Process P (tau 51ms) completed I/O; added to ready queue [Q P S T K O B I C N A Q M L J]
time 5886ms: Process G (tau 274ms) completed I/O; added to ready queue [Q P S T K O B I C N A G Q M L J]
time 5998ms: Process R (tau 100ms) completed a CPU burst; 62 bursts to go [Q P S T K O B I C N A G Q M L J]
time 5998ms: Recalculating tau for process R: old tau 100ms ==> new tau 266ms [Q P S T K O B I C N A G Q M L J]
time 5998ms: Process R switching out of CPU; blocking on I/O until time 6087ms [Q P S T K O B I C N A G Q M L J]
time 6002ms: Process P (tau 51ms) started using the CPU for 16ms burst [Q S T K O B I C N A G Q M L J]
time 6018ms: Process P (tau 51ms) completed a CPU burst; 10 bursts to go [Q S T K O B I C N A G Q M L J]
time 6018ms: Recalculating tau for process P: old tau 51ms ==> new tau 18ms [Q S T K O B I C N A G Q M L J]
time 6018ms: Process P switching out of CPU; blocking on I/O until time 6051ms [Q S T K O B I C N A G Q M L J]
time 6022ms: Process S (tau 100ms) started using the CPU for 2432ms burst [Q T K O B I C N A G Q M L J]
time 6051ms: Process P (tau 18ms) completed I/O; added to ready queue [Q P T K O B I C N A G Q M L J]
time 6087ms: Process R (tau 266ms) completed I/O; added to ready queue [Q P T K O B I C N A R G Q M L J]
time 6329ms: Process F (tau 96ms) completed I/O; added to ready queue [Q P F T K O B I C N A R G Q M L J]
time 6421ms: Process E (tau 50ms) completed I/O; added to ready queue [Q P E F T K O B I C N A R G Q M L J]
time 6827ms: Process D (tau 41ms) completed I/O; added to ready queue [Q P D E F T K O B I C N A R G Q M L J]
time 8454ms: Process S (tau 100ms) completed a CPU burst; 52 bursts to go [Q P D E F T K O B I C N A R G Q M L J]
time 8454ms: Recalculating tau for process S: old tau 100ms ==> new tau 2339ms [Q P D E F T K O B I C N A R G Q M L J]
time 8454ms: Process S switching out of CPU; blocking on I/O until time 8538ms [Q P D E F T K O B I C N A R G Q M L J]
time 8458ms: Process P (tau 18ms) started using the CPU for 728ms burst [Q D E F T K O B I C N A R G Q M L J]
time 8538ms: Process S (tau 2339ms) completed I/O; added to ready queue [Q D E F T K O B I C N A R G Q M L J S]
time 9186ms: Process P (tau 18ms) completed a CPU burst; 9 bursts to go [Q D E F T K O B I C N A R G Q M L J S]
time 9186ms: Recalculating tau for process P: old tau 18ms ==> new tau 700ms [Q D E F T K O B I C N A R G Q M L J S]
time 9186ms: Process P switching out of CPU; blocking on I/O until time 9200ms [Q D E F T K O B I C N A R G Q M L J S]
time 9190ms: Process D (tau 41ms) started using the CPU for 118ms burst [Q E F T K O B I C N A R G Q M L J S]
time 9200ms: Process P (tau 700ms) completed I/O; added to ready queue [Q E F T K O B I C N A R G Q M L P J S]
time 9308ms: Process D (tau 41ms) completed a CPU burst; 43 bursts to go [Q E F T K O B I C N A R G Q M L P J S]
time 9308ms: Recalculating tau for process D: old tau 41ms ==> new tau 115ms [Q E F T K O B I C N A R G Q M L P J S]
time 9308ms: Process D switching out of CPU; blocking on I/O until time 9760ms [Q E F T K O B I C N A R G Q M L P J S]
time 9312ms: Process E (tau 50ms) started using the CPU for 154ms burst [Q F T K O B I C N A R G Q M L P J S]
time 9368ms: Process H (tau 4ms) completed I/O; added to ready queue [Q H F T K O B I C N A R G Q M L P J S]
time 9466ms: Process E (tau 50ms) completed a CPU burst; 55 bursts to go [Q H F T K O B I C N A R G Q M L P J S]
time 9466ms: Recalculating tau for process E: old tau 50ms ==> new tau 150ms [Q H F T K O B I C N A R G Q M L P J S]
time 9466ms: Process E switching out of CPU; blocking on I/O until time 10468ms [Q H F T K O B I C N A R G Q M L P J S]
time 9470ms: Process H (tau 4ms) started using the CPU for 74ms burst [Q F T K O B I C N A R G Q M L P J S]
time 9544ms: Process H (tau 4ms) completed a CPU burst; 47 bursts to go [Q F T K O B I C N A R G Q M L P J S]
time 9544ms: Recalculating tau for process H: old tau 4ms ==> new tau 72ms [Q F T K O B I C N A R G Q M L P J S]
time 9544ms: Process H switching out of CPU; blocking on I/O until time 14186ms [Q F T K O B I C N A R G Q M L P J S]
time 9548ms: Process F (tau 96ms) started using the CPU for 64ms burst [Q T K O B I C N A R G Q M L P J S]
time 9612ms: Process F (tau 96ms) completed a CPU burst; 41 bursts to go [Q T K O B I C N A R G Q M L P J S]
time 9612ms: Recalculating tau for process F: old tau 96ms ==> new tau 66ms [Q T K O B I C N A R G Q M L P J S]
time 9612ms: Process F switching out of CPU; blocking on I/O until time 11444ms [Q T K O B I C N A R G Q M L P J S]
time 9616ms: Process T (tau 100ms) started using the CPU for 20ms burst [Q K O B I C N A R G Q M L P J S]
time 9636ms: Process T (tau 100ms) completed a CPU burst; 16 bursts to go [Q K O B I C N A R G Q M L P J S]
time 9636ms: Recalculating tau for process T: old tau 100ms ==> new tau 24ms [Q K O B I C N A R G Q M L P J S]
time 9636ms: Process T switching out of CPU; blocking on I/O until time 9969ms [Q K O B I C N A R G Q M L P J S]
time 9640ms: Process K (tau 116ms) started using the CPU for 368ms burst [Q O B I C N A R G Q M L P J S]
time 9760ms: Process D (tau 115ms) completed I/O; added to ready queue [Q D O B I C N A R G Q M L P J S]
time 9969ms: Process T (tau 24ms) completed I/O; added to ready queue [Q T D O B I C N A R G Q M L P J S]
time 28756ms: Process I terminated [Q F A C P T L K M Q N R O J S]
time 29089ms: Process C terminated [Q P T L K M Q N R O J S]
time 36993ms: Process P terminated [Q E H L K M Q N R O T J S]
time 74878ms: Process D terminated [Q B L K O T N R Q J S M]
time 74897ms: Process B terminated [Q L K O T N R Q J S M]
time 80546ms: Process F terminated [Q K O L T N R Q J S M]
time 81706ms: Process H terminated [Q O K L T N R Q J S M]
time 87605ms: Process G terminated [Q O L K T N R Q J S M]
time 100764ms: Process L terminated [Q O K T N R Q J S M]
time 110291ms: Process E terminated [Q N K R O Q J S M]
time 116050ms: Process T terminated [Q A N K R O Q J S M]
time 122095ms: Process A terminated [Q N R O K Q J S M]
time 124779ms: Process K terminated [Q R O N Q J S M]
time 135775ms: Process O terminated [Q Q R N J S M]
time 193107ms: Process N terminated [Q Q R S M]
time 195107ms: Process Q terminated [Q J R S M]
time 195987ms: Process J terminated [Q R S M]
time 217471ms: Process R terminated [Q S M]
time 242324ms: Process M terminated [Q <empty>]
time 246451ms: Process S terminated [Q <empty>]
time 246453ms: Simulator ended for SJF [Q <empty>]

time 0ms: Simulator started for SRT [Q <empty>]
time 3ms: Process L (tau 100ms) arrived; added to ready queue [Q L]
time 5ms: Process L (tau 100ms) started using the CPU for 500ms burst [Q <empty>]
time 9ms: Process O (tau 100ms) arrived; added to ready queue [Q O]
time 15ms: Process Q (tau 100ms) arrived; added to ready queue [Q O Q]
time 18ms: Process F (tau 100ms) arrived; added to ready queue [Q F O Q]
time 18ms: Process J (tau 100ms) arrived; added to ready queue [Q F J O Q]
time 23ms: Process I (tau 100ms) arrived; added to ready queue [Q F I J O Q]
time 30ms: Process H (tau 100ms) arrived; added to ready queue [Q F H I J O Q]
time 39ms: Process E (tau 100ms) arrived; added to ready queue [Q E F H I J O Q]
time 45ms: Process A (tau 100ms) arrived; added to ready queue [Q A E F H I J O Q]
time 59ms: Process R (tau 100ms) arrived; added to ready queue [Q A E F H I J O Q R]
time 76ms: Process B (tau 100ms) arrived; added to ready queue [Q A B E F H I J O Q R]
time 114ms: Process C (tau 100ms) arrived; added to ready queue [Q A B C E F H I J O Q R]
time 115ms: Process N (tau 100ms) arrived; added to ready queue [Q A B C E F H I J N O Q R]
time 116ms: Process T (tau 100ms) arrived; added to ready queue [Q A B C E F H I J N O Q R T]
time 155ms: Process S (tau 100ms) arrived; added to ready queue [Q A B C E F H I J N O Q R S T]
time 160ms: Process M (tau 100ms) arrived; added to ready queue [Q A B C E F H I J M N O Q R S T]
time 212ms: Process P (tau 100ms) arrived; added to ready queue [Q A B C E F H I J M N O P Q R S T]
time 227ms: Process D (tau 100ms) arrived; added to ready queue [Q A B C D E F H I J M N O P Q R S T]
time 274ms: Process G (tau 100ms) arrived; added to ready queue [Q A B C D E F G H I J M N O P Q R S T]
time 414ms: Process K (tau 100ms) arrived; added to ready queue [Q A B C D E F G H I J K M N O P Q R S T]
time 505ms: Process L (tau 100ms) completed a CPU burst; 37 bursts to go [Q A B C D E F G H I J K M N O P Q R S T]
time 505ms: Recalculating tau for process L: old tau 100ms ==> new tau 485ms [Q A B C D E F G H I J K M N O P Q R S T]
time 505ms: Process L switching out of CPU; blocking on I/O until time 518ms [Q A B C D E F G H I J K M N O P Q R S T]
time 509ms: Process A (tau 100ms) started using the CPU for 49ms burst [Q B C D E F G H I J K M N O P Q R S T]
time 518ms: Process L (tau 485ms) completed I/O; added to ready queue [Q B C D E F G H I J K M N O P Q R S T L]
time 558ms: Process A (tau 100ms) completed a CPU burst; 59 bursts to go [Q B C D E F G H I J K M N O P Q R S T L]
time 558ms: Recalculating tau for process A: old tau 100ms ==> new tau 52ms [Q B C D E F G H I J K M N O P Q R S T L]
time 558ms: Process A switching out of CPU; blocking on I/O until time 1350ms [Q B C D E F G H I J K M N O P Q R S T L]
time 562ms: Process B (tau 100ms) started using the CPU for 14ms burst [Q C D E F G H I J K M N O P Q R S T L]
time 576ms: Process B (tau 100ms) completed a CPU burst; 34 bursts to go [Q C D E F G H I J K M N O P Q R S T L]
time 576ms: Recalculating tau for process B: old tau 100ms ==> new tau 18ms [Q C D E F G H I J K M N O P Q R S T L]
time 576ms: Process B switching out of CPU; blocking on I/O until time 1018ms [Q C D E F G H I J K M N O P Q R S T L]
time 580ms: Process C (tau 100ms) started using the CPU for 204ms burst [Q D E F G H I J K M N O P Q R S T L]
time 784ms: Process C (tau 100ms) completed a CPU burst; 12 bursts to go [Q D E F G H I J K M N O P Q R S T L]
time 784ms: Recalculating tau for process C: old tau 100ms ==> new tau 200ms [Q D E F G H I J K M N O P Q R S T L]
time 784ms: Process C switching out of CPU; blocking on I/O until time 1796ms [Q D E F G H I J K M N O P Q R S T L]
time 788ms: Process D (tau 100ms) started using the CPU for 59ms burst [Q E F G H I J K M N O P Q R S T L]
time 847ms: Process D (tau 100ms) completed a CPU burst; 47 bursts to go [Q E F G H I J K M N O P Q R S T L]
time 847ms: Recalculating tau for process D: old tau 100ms ==> new tau 61ms [Q E F G H I J K M N O P Q R S T L]
time 847ms: Process D switching out of CPU; blocking on I/O until time 1549ms [Q E F G H I J K M N O P Q R S T L]
time 851ms: Process E (tau 100ms) started using the CPU for 28ms burst [Q F G H I J K M N O P Q R S T L]
time 879ms: Process E (tau 100ms) completed a CPU burst; 59 bursts to go [Q F G H I J K M N O P Q R S T L]
time 879ms: Recalculating tau for process E: old tau 100ms ==> new tau 31ms [Q F G H I J K M N O P Q R S T L]
time 879ms: Process E switching out of CPU; blocking on I/O until time 1651ms [Q F G H I J K M N O P Q R S T L]
time 883ms: Process F (tau 100ms) started using the CPU for 28ms burst [Q G H I J K M N O P Q R S T L]
time 911ms: Process F (tau 100ms) completed a CPU burst; 43 bursts to go [Q G H I J K M N O P Q R S T L]
time 911ms: Recalculating tau for process F: old tau 100ms ==> new tau 31ms [Q G H I J K M N O P Q R S T L]
time 911ms: Process F switching out of CPU; blocking on I/O until time 2183ms [Q G H I J K M N O P Q R S T L]
time 915ms: Process G (tau 100ms) started using the CPU for 3ms burst [Q H I J K M N O P Q R S T L]
time 918ms: Process G (tau 100ms) completed a CPU burst; 52 bursts to go [Q H I J K M N O P Q R S T L]
time 918ms: Recalculating tau for process G: old tau 100ms ==> new tau 7ms [Q H I J K M N O P Q R S T L]
time 918ms: Process G switching out of CPU; blocking on I/O until time 1640ms [Q H I J K M N O P Q R S T L]
time 922ms: Process H (tau 100ms) started using the CPU for 71ms burst [Q I J K M N O P Q R S T L]
time 993ms: Process H (tau 100ms) completed a CPU burst; 50 bursts to go [Q I J K M N O P Q R S T L]
time 993ms: Recalculating tau for process H: old tau 100ms ==> new tau 73ms [Q I J K M N O P Q R S T L]
time 993ms: Process H switching out of CPU; blocking on I/O until time 4805ms [Q I J K M N O P Q R S T L]
time 997ms: Process I (tau 100ms) started using the CPU for 192ms burst [Q J K M N O P Q R S T L]
time 1018ms: Process B (tau 18ms) completed I/O; preempting I [Q B J K M N O P Q R S T L]
time 1022ms: Process B (tau 18ms) started using the CPU for 160ms burst [Q I J K M N O P Q R S T L]
time 1182ms: Process B (tau 18ms) completed a CPU burst; 33 bursts to go [Q I J K M N O P Q R S T L]
time 1182ms: Recalculating tau for process B: old tau 18ms ==> new tau 155ms [Q I J K M N O P Q R S T L]
time 1182ms: Process B switching out of CPU; blocking on I/O until time 1454ms [Q I J K M N O P Q R S T L]
time 1186ms: Process I (tau 100ms) started using the CPU for remaining 171ms of 192ms burst [Q J K M N O P Q R S T L]
time 1350ms: Process A (tau 52ms) completed I/O; added to ready queue [Q A J K M N O P Q R S T L]
time 1357ms: Process I (tau 100ms) completed a CPU burst; 5 bursts to go [Q A J K M N O P Q R S T L]
time 1357ms: Recalculating tau for process I: old tau 100ms ==> new tau 189ms [Q A J K M N O P Q R S T L]
time 1357ms: Process I switching out of CPU; blocking on I/O until time 1387ms [Q A J K M N O P Q R S T L]
time 1361ms: Process A (tau 52ms) started using the CPU for 274ms burst [Q J K M N O P Q R S T L]
time 1387ms: Process I (tau 189ms) completed I/O; added to ready queue [Q J K M N O P Q R S T I L]
time 1454ms: Process B (tau 155ms) completed I/O; added to ready queue [Q J K M N O P Q R S T B I L]
time 1549ms: Process D (tau 61ms) completed I/O; added to ready queue [Q D J K M N O P Q R S T B I L]
time 1635ms: Process A (tau 52ms) completed a CPU burst; 58 bursts to go [Q D J K M N O P Q R S T B I L]
time 1635ms: Recalculating tau for process A: old tau 52ms ==> new tau 266ms [Q D J K M N O P Q R S T B I L]
time 1635ms: Process A switching out of CPU; blocking on I/O until time 2487ms [Q D J K M N O P Q R S T B I L]
time 1639ms: Process D (tau 61ms) started using the CPU for 72ms burst [Q J K M N O P Q R S T B I L]
time 1640ms: Process G (tau 7ms) completed I/O; preempting D [Q G J K M N O P Q R S T B I L]
time 1644ms: Process G (tau 7ms) started using the CPU for 8ms burst [Q D J K M N O P Q R S T B I L]
time 1651ms: Process E (tau 31ms) completed I/O; added to ready queue [Q E D J K M N O P Q R S T B I L]
time 1652ms: Process G (tau 7ms) completed a CPU burst; 51 bursts to go [Q E D J K M N O P Q R S T B I L]
time 1652ms: Recalculating tau for process G: old tau 7ms ==> new tau 8ms [Q E D J K M N O P Q R S T B I L]
time 1652ms: Process G switching out of CPU; blocking on I/O until time 2864ms [Q E D J K M N O P Q R S T B I L]
time 1656ms: Process E (tau 31ms) started using the CPU for 33ms burst [Q D J K M N O P Q R S T B I L]
time 1689ms: Process E (tau 31ms) completed a CPU burst; 58 bursts to go [Q D J K M N O P Q R S T B I L]
time 1689ms: Recalculating tau for process E: old tau 31ms ==> new tau 33ms [Q D J K M N O P Q R S T B I L]
time 1689ms: Process E switching out of CPU; blocking on I/O until time 1731ms [Q D J K M N O P Q R S T B I L]
time 1693ms: Process D (tau 61ms) started using the CPU for remaining 71ms of 72ms burst [Q J K M N O P Q R S T B I L]
time 1731ms: Process E (tau 33ms) completed I/O; added to ready queue [Q E J K M N O P Q R S T B I L]
time 1764ms: Process D (tau 61ms) completed a CPU burst; 46 bursts to go [Q E J K M N O P Q R S T B I L]
time 1764ms: Recalculating tau for process D: old tau 61ms ==> new tau 72ms [Q E J K M N O P Q R S T B I L]
time 1764ms: Process D switching out of CPU; blocking on I/O until time 2016ms [Q E J K M N O P Q R S T B I L]
time 1768ms: Process E (tau 33ms) started using the CPU for 14ms burst [Q J K M N O P Q R S T B I L]
time 1782ms: Process E (tau 33ms) completed a CPU burst; 57 bursts to go [Q J K M N O P Q R S T B I L]
time 1782ms: Recalculating tau for process E: old tau 33ms ==> new tau 15ms [Q J K M N O P Q R S T B I L]
time 1782ms: Process E switching out of CPU; blocking on I/O until time 3394ms [Q J K M N O P Q R S T B I L]
time 1786ms: Process J (tau 100ms) started using the CPU for 2048ms burst [Q K M N O P Q R S T B I L]
time 1796ms: Process C (tau 200ms) completed I/O; added to ready queue [Q K M N O P Q R S T B I C L]
time 2016ms: Process D (tau 72ms) completed I/O; added to ready queue [Q D K M N O P Q R S T B I C L]
time 2183ms: Process F (tau 31ms) completed I/O; added to ready queue [Q F D K M N O P Q R S T B I C L]
time 2487ms: Process A (tau 266ms) completed I/O; added to ready queue [Q F D K M N O P Q R S T B I C A L]
time 2864ms: Process G (tau 8ms) completed I/O; added to ready queue [Q G F D K M N O P Q R S T B I C A L]
time 3394ms: Process E (tau 15ms) completed I/O; added to ready queue [Q G E F D K M N O P Q R S T B I C A L]
time 3834ms: Process J (tau 100ms) completed a CPU burst; 34 bursts to go [Q G E F D K M N O P Q R S T B I C A L]
time 3834ms: Recalculating tau for process J: old tau 100ms ==> new tau 1971ms [Q G E F D K M N O P Q R S T B I C A L]
time 3834ms: Process J switching out of CPU; blocking on I/O until time 3888ms [Q G E F D K M N O P Q R S T B I C A L]
time 3838ms: Process G (tau 8ms) started using the CPU for 3ms burst [Q E F D K M N O P Q R S T B I C A L]
time 3841ms: Process G (tau 8ms) completed a CPU burst; 50 bursts to go [Q E F D K M N O P Q R S T B I C A L]
time 3841ms: Recalculating tau for process G: old tau 8ms ==> new tau 4ms [Q E F D K M N O P Q R S T B I C A L]
time 3841ms: Process G switching out of CPU; blocking on I/O until time 5213ms [Q E F D K M N O P Q R S T B I C A L]
time 3845ms: Process E (tau 15ms) started using the CPU for 51ms burst [Q F D K M N O P Q R S T B I C A L]
time 3888ms: Process J (tau 1971ms) completed I/O; added to ready queue [Q F D K M N O P Q R S T B I C A L J]
time 3896ms: Process E (tau 15ms) completed a CPU burst; 56 bursts to go [Q F D K M N O P Q R S T B I C A L J]
time 3896ms: Recalculating tau for process E: old tau 15ms ==> new tau 50ms [Q F D K M N O P Q R S T B I C A L J]
time 3896ms: Process E switching out of CPU; blocking on I/O until time 4658ms [Q F D K M N O P Q R S T B I C A L J]
time 3900ms: Process F (tau 31ms) started using the CPU for 98ms burst [Q D K M N O P Q R S T B I C A L J]
time 3998ms: Process F (tau 31ms) completed a CPU burst; 42 bursts to go [Q D K M N O P Q R S T B I C A L J]
time 3998ms: Recalculating tau for process F: old tau 31ms ==> new tau 96ms [Q D K M N O P Q R S T B I C A L J]
time 3998ms: Process F switching out of CPU; blocking on I/O until time 6410ms [Q D K M N O P Q R S T B I C A L J]
time 4002ms: Process D (tau 72ms) started using the CPU for 15ms burst [Q K M N O P Q R S T B I C A L J]
time 4017ms: Process D (tau 72ms) completed a CPU burst; 45 bursts to go [Q K M N O P Q R S T B I C A L J]
time 4017ms: Recalculating tau for process D: old tau 72ms ==> new tau 18ms [Q K M N O P Q R S T B I C A L J]
time 4017ms: Process D switching out of CPU; blocking on I/O until time 4879ms [Q K M N O P Q R S T B I C A L J]
time 4021ms: Process K (tau 100ms) started using the CPU for 116ms burst [Q M N O P Q R S T B I C A L J]
time 4137ms: Process K (tau 100ms) completed a CPU burst; 60 bursts to go [Q M N O P Q R S T B I C A L J]
time 4137ms: Recalculating tau for process K: old tau 100ms ==> new tau 116ms [Q M N O P Q R S T B I C A L J]
time 4137ms: Process K switching out of CPU; blocking on I/O until time 4141ms [Q M N O P Q R S T B I C A L J]
time 4141ms: Process M (tau 100ms) started using the CPU for 396ms burst [Q N O P Q R S T B I C A L J]
time 4141ms: Process K (tau 116ms) completed I/O; added to ready queue [Q N O P Q R S T K B I C A L J]
time 4537ms: Process M (tau 100ms) completed a CPU burst; 49 bursts to go [Q N O P Q R S T K B I C A L J]
time 4537ms: Recalculating tau for process M: old tau 100ms ==> new tau 385ms [Q N O P Q R S T K B I C A L J]
time 4537ms: Process M switching out of CPU; blocking on I/O until time 4699ms [Q N O P Q R S T K B I C A L J]
time 4541ms: Process N (tau 100ms) started using the CPU for 256ms burst [Q O P Q R S T K B I C A L J]
time 4658ms: Process E (tau 50ms) completed I/O; added to ready queue [Q E O P Q R S T K B I C A L J]
time 4699ms: Process M (tau 385ms) completed I/O; added to ready queue [Q E O P Q R S T K B I C A M L J]
time 4797ms: Process N (tau 100ms) completed a CPU burst; 62 bursts to go [Q E O P Q R S T K B I C A M L J]
time 4797ms: Recalculating tau for process N: old tau 100ms ==> new tau 250ms [Q E O P Q R S T K B I C A M L J]
time 4797ms: Process N switching out of CPU; blocking on I/O until time 4807ms [Q E O P Q R S T K B I C A M L J]
time 4801ms: Process E (tau 50ms) started using the CPU for 154ms burst [Q O P Q R S T K B I C A M L J]
time 4805ms: Process H (tau 73ms) completed I/O; added to ready queue [Q H O P Q R S T K B I C A M L J]
time 4807ms: Process N (tau 250ms) completed I/O; added to ready queue [Q H O P Q R S T K B I C N A M L J]
time 4879ms: Process D (tau 18ms) completed I/O; added to ready queue [Q D H O P Q R S T K B I C N A M L J]
time 4955ms: Process E (tau 50ms) completed a CPU burst; 55 bursts to go [Q D H O P Q R S T K B I C N A M L J]
time 4955ms: Recalculating tau for process E: old tau 50ms ==> new tau 150ms [Q D H O P Q R S T K B I C N A M L J]
time 4955ms: Process E switching out of CPU; blocking on I/O until time 5957ms [Q D H O P Q R S T K B I C N A M L J]
time 4959ms: Process D (tau 18ms) started using the CPU for 41ms burst [Q H O P Q R S T K B I C N A M L J]
time 5000ms: Process D (tau 18ms) completed a CPU burst; 44 bursts to go [Q H O P Q R S T K B I C N A M L J]
time 5000ms: Recalculating tau for process D: old tau 18ms ==> new tau 41ms [Q H O P Q R S T K B I C N A M L J]
time 5000ms: Process D switching out of CPU; blocking on I/O until time 6892ms [Q H O P Q R S T K B I C N A M L J]
time 5004ms: Process H (tau 73ms) started using the CPU for 20ms burst [Q O P Q R S T K B I C N A M L J]
time 5024ms: Process H (tau 73ms) completed a CPU burst; 49 bursts to go [Q O P Q R S T K B I C N A M L J]
time 5024ms: Recalculating tau for process H: old tau 73ms ==> new tau 23ms [Q O P Q R S T K B I C N A M L J]
time 5024ms: Process H switching out of CPU; blocking on I/O until time 5076ms [Q O P Q R S T K B I C N A M L J]
time 5028ms: Process O (tau 100ms) started using the CPU for 152ms burst [Q P Q R S T K B I C N A M L J]
time 5076ms: Process H (tau 23ms) completed I/O; preempting O [Q H P Q R S T K B I C N A M L J]
time 5080ms: Process H (tau 23ms) started using the CPU for 3ms burst [Q O P Q R S T K B I C N A M L J]
time 5083ms: Process H (tau 23ms) completed a CPU burst; 48 bursts to go [Q O P Q R S T K B I C N A M L J]
time 5083ms: Recalculating tau for process H: old tau 23ms ==> new tau 4ms [Q O P Q R S T K B I C N A M L J]
time 5083ms: Process H switching out of CPU; blocking on I/O until time 8785ms [Q O P Q R S T K B I C N A M L J]
time 5087ms: Process O (tau 100ms) started using the CPU for remaining 104ms of 152ms burst [Q P Q R S T K B I C N A M L J]
time 5191ms: Process O (tau 100ms) completed a CPU burst; 51 bursts to go [Q P Q R S T K B I C N A M L J]
time 5191ms: Recalculating tau for process O: old tau 100ms ==> new tau 150ms [Q P Q R S T K B I C N A M L J]
time 5191ms: Process O switching out of CPU; blocking on I/O until time 5390ms [Q P Q R S T K B I C N A M L J]
time 5195ms: Process P (tau 100ms) started using the CPU for 20ms burst [Q Q R S T K B I C N A M L J]
time 5213ms: Process G (tau 4ms) completed I/O; preempting P [Q G Q R S T K B I C N A M L J]
time 5217ms: Process G (tau 4ms) started using the CPU for 285ms burst [Q P Q R S T K B I C N A M L J]
time 5390ms: Process O (tau 150ms) completed I/O; added to ready queue [Q P Q R S T K O B I C N A M L J]
time 5502ms: Process G (tau 4ms) completed a CPU burst; 49 bursts to go [Q P Q R S T K O B I C N A M L J]
time 5502ms: Recalculating tau for process G: old tau 4ms ==> new tau 274ms [Q P Q R S T K O B I C N A M L J]
time 5502ms: Process G switching out of CPU; blocking on I/O until time 5784ms [Q P Q R S T K O B I C N A M L J]
time 5506ms: Process P (tau 100ms) started using the CPU for remaining 2ms of 20ms burst [Q Q R S T K O B I C N A M L J]
time 5508ms: Process P (tau 100ms) completed a CPU burst; 12 bursts to go [Q Q R S T K O B I C N A M L J]
time 5508ms: Recalculating tau for process P: old tau 100ms ==> new tau 24ms [Q Q R S T K O B I C N A M L J]
time 5508ms: Process P switching out of CPU; blocking on I/O until time 5623ms [Q Q R S T K O B I C N A M L J]
time 5512ms: Process Q (tau 100ms) started using the CPU for 328ms burst [Q R S T K O B I C N A M L J]
time 5623ms: Process P (tau 24ms) completed I/O; added to ready queue [Q P R S T K O B I C N A M L J]
time 5784ms: Process G (tau 274ms) completed I/O; added to ready queue [Q P R S T K O B I C N A G M L J]
time 5840ms: Process Q (tau 100ms) completed a CPU burst; 50 bursts to go [Q P R S T K O B I C N A G M L J]
time 5840ms: Recalculating tau for process Q: old tau 100ms ==> new tau 319ms [Q P R S T K O B I C N A G M L J]
time 5840ms: Process Q switching out of CPU; blocking on I/O until time 6129ms [Q P R S T K O B I C N A G M L J]
time 5844ms: Process P (tau 24ms) started using the CPU for 52ms burst [Q R S T K O B I C N A G M L J]
time 5896ms: Process P (tau 24ms) completed a CPU burst; 11 bursts to go [Q R S T K O B I C N A G M L J]
time 5896ms: Recalculating tau for process P: old tau 24ms ==> new tau 51ms [Q R S T K O B I C N A G M L J]
time 5896ms: Process P switching out of CPU; blocking on I/O until time 5915ms [Q R S T K O B I C N A G M L J]
time 5900ms: Process R (tau 100ms) started using the CPU for 272ms burst [Q S T K O B I C N A G M L J]
time 5915ms: Process P (tau 51ms) completed I/O; preempting R [Q P S T K O B I C N A G M L J]
time 5919ms: Process P (tau 51ms) started using the CPU for 16ms burst [Q R S T K O B I C N A G M L J]
time 5935ms: Process P (tau 51ms) completed a CPU burst; 10 bursts to go [Q R S T K O B I C N A G M L J]
time 5935ms: Recalculating tau for process P: old tau 51ms ==> new tau 18ms [Q R S T K O B I C N A G M L J]
time 5935ms: Process P switching out of CPU; blocking on I/O until time 5968ms [Q R S T K O B I C N A G M L J]
time 5939ms: Process R (tau 100ms) started using the CPU for remaining 257ms of 272ms burst [Q S T K O B I C N A G M L J]
time 5957ms: Process E (tau 150ms) completed I/O; added to ready queue [Q S T K E O B I C N A G M L J]
time 5968ms: Process P (tau 18ms) completed I/O; preempting R [Q P S T K E O B I C N A G M L J]
time 5972ms: Process P (tau 18ms) started using the CPU for 728ms burst [Q R S T K E O B I C N A G M L J]
time 6129ms: Process Q (tau 319ms) completed I/O; added to ready queue [Q R S T K E O B I C N A G Q M L J]
time 6410ms: Process F (tau 96ms) completed I/O; added to ready queue [Q R F S T K E O B I C N A G Q M L J]
time 6700ms: Process P (tau 18ms) completed a CPU burst; 9 bursts to go [Q R F S T K E O B I C N A G Q M L J]
time 6700ms: Recalculating tau for process P: old tau 18ms ==> new tau 700ms [Q R F S T K E O B I C N A G Q M L J]
time 6700ms: Process P switching out of CPU; blocking on I/O until time 6714ms [Q R F S T K E O B I C N A G Q M L J]
time 6704ms: Process R (tau 100ms) started using the CPU for remaining 228ms of 272ms burst [Q F S T K E O B I C N A G Q M L J]
time 6714ms: Process P (tau 700ms) completed I/O; added to ready queue [Q F S T K E O B I C N A G Q M L P J]
time 6892ms: Process D (tau 41ms) completed I/O; added to ready queue [Q D F S T K E O B I C N A G Q M L P J]
time 6932ms: Process R (tau 100ms) completed a CPU burst; 62 bursts to go [Q D F S T K E O B I C N A G Q M L P J]
time 6932ms: Recalculating tau for process R: old tau 100ms ==> new tau 266ms [Q D F S T K E O B I C N A G Q M L P J]
time 6932ms: Process R switching out of CPU; blocking on I/O until time 7021ms [Q D F S T K E O B I C N A G Q M L P J]
time 6936ms: Process D (tau 41ms) started using the CPU for 118ms burst [Q F S T K E O B I C N A G Q M L P J]
time 7021ms: Process R (tau 266ms) completed I/O; added to ready queue [Q F S T K E O B I C N A R G Q M L P J]
time 7054ms: Process D (tau 41ms) completed a CPU burst; 43 bursts to go [Q F S T K E O B I C N A R G Q M L P J]
time 7054ms: Recalculating tau for process D: old tau 41ms ==> new tau 115ms [Q F S T K E O B I C N A R G Q M L P J]
time 7054ms: Process D switching out of CPU; blocking on I/O until time 7506ms [Q F S T K E O B I C N A R G Q M L P J]
time 7058ms: Process F (tau 96ms) started using the CPU for 64ms burst [Q S T K E O B I C N A R G Q M L P J]
time 7122ms: Process F (tau 96ms) completed a CPU burst; 41 bursts to go [Q S T K E O B I C N A R G Q M L P J]
time 7122ms: Recalculating tau for process F: old tau 96ms ==> new tau 66ms [Q S T K E O B I C N A R G Q M L P J]
time 7122ms: Process F switching out of CPU; blocking on I/O until time 8954ms [Q S T K E O B I C N A R G Q M L P J]
time 7126ms: Process S (tau 100ms) started using the CPU for 2432ms burst [Q T K E O B I C N A R G Q M L P J]
time 7506ms: Process D (tau 115ms) completed I/O; added to ready queue [Q T D K E O B I C N A R G Q M L P J]
time 8785ms: Process H (tau 4ms) completed I/O; added to ready queue [Q H T D K E O B I C N A R G Q M L P J]
time 8954ms: Process F (tau 66ms) completed I/O; added to ready queue [Q H F T D K E O B I C N A R G Q M L P J]
time 9558ms: Process S (tau 100ms) completed a CPU burst; 52 bursts to go [Q H F T D K E O B I C N A R G Q M L P J]
time 9558ms: Recalculating tau for process S: old tau 100ms ==> new tau 2339ms [Q H F T D K E O B I C N A R G Q M L P J]
time 9558ms: Process S switching out of CPU; blocking on I/O until time 9642ms [Q H F T D K E O B I C N A R G Q M L P J]
time 9562ms: Process H (tau 4ms) started using the CPU for 74ms burst [Q F T D K E O B I C N A R G Q M L P J]
time 9636ms: Process H (tau 4ms) completed a CPU burst; 47 bursts to go [Q F T D K E O B I C N A R G Q M L P J]
time 9636ms: Recalculating tau for process H: old tau 4ms ==> new tau 72ms [Q F T D K E O B I C N A R G Q M L P J]
time 9636ms: Process H switching out of CPU; blocking on I/O until time 14278ms [Q F T D K E O B I C N A R G Q M L P J]
time 9640ms: Process F (tau 66ms) started using the CPU for 15ms burst [Q T D K E O B I C N A R G Q M L P J]
time 9642ms: Process S (tau 2339ms) completed I/O; added to ready queue [Q T D K E O B I C N A R G Q M L P J S]
time 9655ms: Process F (tau 66ms) completed a CPU burst; 40 bursts to go [Q T D K E O B I C N A R G Q M L P J S]
time 9655ms: Recalculating tau for process F: old tau 66ms ==> new tau 18ms [Q T D K E O B I C N A R G Q M L P J S]
time 9655ms: Process F switching out of CPU; blocking on I/O until time 9717ms [Q T D K E O B I C N A R G Q M L P J S]
time 9659ms: Process T (tau 100ms) started using the CPU for 20ms burst [Q D K E O B I C N A R G Q M L P J S]
time 9679ms: Process T (tau 100ms) completed a CPU burst; 16 bursts to go [Q D K E O B I C N A R G Q M L P J S]
time 9679ms: Recalculating tau for process T: old tau 100ms ==> new tau 24ms [Q D K E O B I C N A R G Q M L P J S]
time 9679ms: Process T switching out of CPU; blocking on I/O until time 10012ms [Q D K E O B I C N A R G Q M L P J S]
time 9683ms: Process D (tau 115ms) started using the CPU for 55ms burst [Q K E O B I C N A R G Q M L P J S]
time 9717ms: Process F (tau 18ms) completed I/O; preempting D [Q F K E O B I C N A R G Q M L P J S]
time 9721ms: Process F (tau 18ms) started using the CPU for 23ms burst [Q D K E O B I C N A R G Q M L P J S]
time 9744ms: Process F (tau 18ms) completed a CPU burst; 39 bursts to go [Q D K E O B I C N A R G Q M L P J S]
time 9744ms: Recalculating tau for process F: old tau 18ms ==> new tau 23ms [Q D K E O B I C N A R G Q M L P J S]
time 9744ms: Process F switching out of CPU; blocking on I/O until time 10486ms [Q D K E O B I C N A R G Q M L P J S]
time 9748ms: Process D (tau 115ms) started using the CPU for remaining 21ms of 55ms burst [Q K E O B I C N A R G Q M L P J S]
time 9769ms: Process D (tau 115ms) completed a CPU burst; 42 bursts to go [Q K E O B I C N A R G Q M L P J S]
time 9769ms: Recalculating tau for process D: old tau 115ms ==> new tau 58ms [Q K E O B I C N A R G Q M L P J S]
time 9769ms: Process D switching out of CPU; blocking on I/O until time 10431ms [Q K E O B I C N A R G Q M L P J S]
time 9773ms: Process K (tau 116ms) started using the CPU for 368ms burst [Q E O B I C N A R G Q M L P J S]
time 29820ms: Process C terminated [Q A F Q I P T L K M N R O J S]
time 34463ms: Process I terminated [Q H P T L K M Q N R O J S]
time 39626ms: Process P terminated [Q L K M Q N R O T J S]
time 61097ms: Process B terminated [Q Q L N R O T J S M]
time 66693ms: Process D terminated [Q A H K L N R O T Q J S M]
time 71219ms: Process H terminated [Q K L N R O T Q J S M]
time 75568ms: Process F terminated [Q N K R O L T Q J S M]
time 79867ms: Process G terminated [Q K R O L T N Q J S M]
time 98972ms: Process E terminated [Q O K L T N R Q J S M]
time 100762ms: Process K terminated [Q O L T N R Q J S M]
time 106132ms: Process A terminated [Q L O T N R Q J S M]
time 108163ms: Process L terminated [Q O T N R Q J S M]
time 121680ms: Process T terminated [Q R O Q J S M]
time 144956ms: Process O terminated [Q Q R J N S M]
time 180771ms: Process J terminated [Q Q R N S M]
time 192959ms: Process Q terminated [Q N R S M]
time 194205ms: Process R terminated [Q N S M]
time 209779ms: Process N terminated [Q S M]
time 241314ms: Process S terminated [Q M]
time 248863ms: Process M terminated [Q <empty>]
time 248865ms: Simulator ended for SRT [Q <empty>]

time 0ms: Simulator started for RR [Q <empty>]
time 3ms: Process L arrived; added to ready queue [Q L]
time 5ms: Process L started using the CPU for 500ms burst [Q <empty>]
time 9ms: Process O arrived; added to ready queue [Q O]
time 15ms: Process Q arrived; added to ready queue [Q O Q]
time 18ms: Process F arrived; added to ready queue [Q O Q F]
time 18ms: Process J arrived; added to ready queue [Q O Q F J]
time 23ms: Process I arrived; added to ready queue [Q O Q F J I]
time 30ms: Process H arrived; added to ready queue [Q O Q F J I H]
time 39ms: Process E arrived; added to ready queue [Q O Q F J I H E]
time 45ms: Process A arrived; added to ready queue [Q O Q F J I H E A]
time 59ms: Process R arrived; added to ready queue [Q O Q F J I H E A R]
time 69ms: Time slice expired; preempting process L with 436ms remaining [Q O Q F J I H E A R]
time 73ms: Process O started using the CPU for 152ms burst [Q Q F J I H E A R L]
time 76ms: Process B arrived; added to ready queue [Q Q F J I H E A R L B]
time 114ms: Process C arrived; added to ready queue [Q Q F J I H E A R L B C]
time 115ms: Process N arrived; added to ready queue [Q Q F J I H E A R L B C N]
time 116ms: Process T arrived; added to ready queue [Q Q F J I H E A R L B C N T]
time 137ms: Time slice expired; preempting process O with 88ms remaining [Q Q F J I H E A R L B C N T]
time 141ms: Process Q started using the CPU for 328ms burst [Q F J I H E A R L B C N T O]
time 155ms: Process S arrived; added to ready queue [Q F J I H E A R L B C N T O S]
time 160ms: Process M arrived; added to ready queue [Q F J I H E A R L B C N T O S M]
time 205ms: Time slice expired; preempting process Q with 264ms remaining [Q F J I H E A R L B C N T O S M]
time 209ms: Process F started using the CPU for 28ms burst [Q J I H E A R L B C N T O S M Q]
time 212ms: Process P arrived; added to ready queue [Q J I H E A R L B C N T O S M Q P]
time 227ms: Process D arrived; added to ready queue [Q J I H E A R L B C N T O S M Q P D]
time 237ms: Process F completed a CPU burst; 43 bursts to go [Q J I H E A R L B C N T O S M Q P D]
time 237ms: Process F switching out of CPU; blocking on I/O until time 1509ms [Q J I H E A R L B C N T O S M Q P D]
time 241ms: Process J started using the CPU for 2048ms burst [Q I H E A R L B C N T O S M Q P D]
time 274ms: Process G arrived; added to ready queue [Q I H E A R L B C N T O S M Q P D G]
time 305ms: Time slice expired; preempting process J with 1984ms remaining [Q I H E A R L B C N T O S M Q P D G]
time 309ms: Process I started using the CPU for 192ms burst [Q H E A R L B C N T O S M Q P D G J]
time 373ms: Time slice expired; preempting process I with 128ms remaining [Q H E A R L B C N T O S M Q P D G J]
time 377ms: Process H started using the CPU for 71ms burst [Q E A R L B C N T O S M Q P D G J I]
time 414ms: Process K arrived; added to ready queue [Q E A R L B C N T O S M Q P D G J I K]
time 441ms: Time slice expired; preempting process H with 7ms remaining [Q E A R L B C N T O S M Q P D G J I K]
time 445ms: Process E started using the CPU for 28ms burst [Q A R L B C N T O S M Q P D G J I K H]
time 473ms: Process E completed a CPU burst; 59 bursts to go [Q A R L B C N T O S M Q P D G J I K H]
time 473ms: Process E switching out of CPU; blocking on I/O until time 1245ms [Q A R L B C N T O S M Q P D G J I K H]
time 477ms: Process A started using the CPU for 49ms burst [Q R L B C N T O S M Q P D G J I K H]
time 526ms: Process A completed a CPU burst; 59 bursts to go [Q R L B C N T O S M Q P D G J I K H]
time 526ms: Process A switching out of CPU; blocking on I/O until time 1318ms [Q R L B C N T O S M Q P D G J I K H]
time 530ms: Process R started using the CPU for 272ms burst [Q L B C N T O S M Q P D G J I K H]
time 594ms: Time slice expired; preempting process R with 208ms remaining [Q L B C N T O S M Q P D G J I K H]
time 598ms: Process L started using the CPU for remaining 436ms of 500ms burst [Q B C N T O S M Q P D G J I K H R]
time 662ms: Time slice expired; preempting process L with 372ms remaining [Q B C N T O S M Q P D G J I K H R]
time 666ms: Process B started using the CPU for 14ms burst [Q C N T O S M Q P D G J I K H R L]
time 680ms: Process B completed a CPU burst; 34 bursts to go [Q C N T O S M Q P D G J I K H R L]
time 680ms: Process B switching out of CPU; blocking on I/O until time 1122ms [Q C N T O S M Q P D G J I K H R L]
time 684ms: Process C started using the CPU for 204ms burst [Q N T O S M Q P D G J I K H R L]
time 748ms: Time slice expired; preempting process C with 140ms remaining [Q N T O S M Q P D G J I K H R L]
time 752ms: Process N started using the CPU for 256ms burst [Q T O S M Q P D G J I K H R L C]
time 816ms: Time slice expired; preempting process N with 192ms remaining [Q T O S M Q P D G J I K H R L C]
time 820ms: Process T started using the CPU for 20ms burst [Q O S M Q P D G J I K H R L C N]
time 840ms: Process T completed a CPU burst; 16 bursts to go [Q O S M Q P D G J I K H R L C N]
time 840ms: Process T switching out of CPU; blocking on I/O until time 1173ms [Q O S M Q P D G J I K H R L C N]
time 844ms: Process O started using the CPU for remaining 88ms of 152ms burst [Q S M Q P D G J I K H R L C N]
time 908ms: Time slice expired; preempting process O with 24ms remaining [Q S M Q P D G J I K H R L C N]
time 912ms: Process S started using the CPU for 2432ms burst [Q M Q P D G J I K H R L C N O]
time 976ms: Time slice expired; preempting process S with 2368ms remaining [Q M Q P D G J I K H R L C N O]
time 980ms: Process M started using the CPU for 396ms burst [Q Q P D G J I K H R L C N O S]
time 1044ms: Time slice expired; preempting process M with 332ms remaining [Q Q P D G J I K H R L C N O S]
time 1048ms: Process Q started using the CPU for remaining 264ms of 328ms burst [Q P D G J I K H R L C N O S M]
time 1112ms: Time slice expired; preempting process Q with 200ms remaining [Q P D G J I K H R L C N O S M]
time 1116ms: Process P started using the CPU for 20ms burst [Q D G J I K H R L C N O S M Q]
time 1122ms: Process B completed I/O; added to ready queue [Q D G J I K H R L C N O S M Q B]
time 1136ms: Process P completed a CPU burst; 12 bursts to go [Q D G J I K H R L C N O S M Q B]
time 1136ms: Process P switching out of CPU; blocking on I/O until time 1251ms [Q D G J I K H R L C N O S M Q B]
time 1140ms: Process D started using the CPU for 59ms burst [Q G J I K H R L C N O S M Q B]
time 1173ms: Process T completed I/O; added to ready queue [Q G J I K H R L C N O S M Q B T]
time 1199ms: Process D completed a CPU burst; 47 bursts to go [Q G J I K H R L C N O S M Q B T]
time 1199ms: Process D switching out of CPU; blocking on I/O until time 1901ms [Q G J I K H R L C N O S M Q B T]
time 1203ms: Process G started using the CPU for 3ms burst [Q J I K H R L C N O S M Q B T]
time 1206ms: Process G completed a CPU burst; 52 bursts to go [Q J I K H R L C N O S M Q B T]
time 1206ms: Process G switching out of CPU; blocking on I/O until time 1928ms [Q J I K H R L C N O S M Q B T]
time 1210ms: Process J started using the CPU for remaining 1984ms of 2048ms burst [Q I K H R L C N O S M Q B T]
time 1245ms: Process E completed I/O; added to ready queue [Q I K H R L C N O S M Q B T E]
time 1251ms: Process P completed I/O; added to ready queue [Q I K H R L C N O S M Q B T E P]
time 1274ms: Time slice expired; preempting process J with 1920ms remaining [Q I K H R L C N O S M Q B T E P]
time 1278ms: Process I started using the CPU for remaining 128ms of 192ms burst [Q K H R L C N O S M Q B T E P J]
time 1318ms: Process A completed I/O; added to ready queue [Q K H R L C N O S M Q B T E P J A]
time 1342ms: Time slice expired; preempting process I with 64ms remaining [Q K H R L C N O S M Q B T E P J A]
time 1346ms: Process K started using the CPU for 116ms burst [Q H R L C N O S M Q B T E P J A I]
time 1410ms: Time slice expired; preempting process K with 52ms remaining [Q H R L C N O S M Q B T E P J A I]
time 1414ms: Process H started using the CPU for remaining 7ms of 71ms burst [Q R L C N O S M Q B T E P J A I K]
time 1421ms: Process H completed a CPU burst; 50 bursts to go [Q R L C N O S M Q B T E P J A I K]
time 1421ms: Process H switching out of CPU; blocking on I/O until time 5233ms [Q R L C N O S M Q B T E P J A I K]
time 1425ms: Process R started using the CPU for remaining 208ms of 272ms burst [Q L C N O S M Q B T E P J A I K]
time 1489ms: Time slice expired; preempting process R with 144ms remaining [Q L C N O S M Q B T E P J A I K]
time 1493ms: Process L started using the CPU for remaining 372ms of 500ms burst [Q C N O S M Q B T E P J A I K R]
time 1509ms: Process F completed I/O; added to ready queue [Q C N O S M Q B T E P J A I K R F]
time 1557ms: Time slice expired; preempting process L with 308ms remaining [Q C N O S M Q B T E P J A I K R F]
time 1561ms: Process C started using the CPU for remaining 140ms of 204ms burst [Q N O S M Q B T E P J A I K R F L]
time 1625ms: Time slice expired; preempting process C with 76ms remaining [Q N O S M Q B T E P J A I K R F L]
time 1629ms: Process N started using the CPU for remaining 192ms of 256ms burst [Q O S M Q B T E P J A I K R F L C]
time 1693ms: Time slice expired; preempting process N with 128ms remaining [Q O S M Q B T E P J A I K R F L C]
time 1697ms: Process O started using the CPU for remaining 24ms of 152ms burst [Q S M Q B T E P J A I K R F L C N]
time 1721ms: Process O completed a CPU burst; 51 bursts to go [Q S M Q B T E P J A I K R F L C N]
time 1721ms: Process O switching out of CPU; blocking on I/O until time 1920ms [Q S M Q B T E P J A I K R F L C N]
time 1725ms: Process S started using the CPU for remaining 2368ms of 2432ms burst [Q M Q B T E P J A I K R F L C N]
time 1789ms: Time slice expired; preempting process S with 2304ms remaining [Q M Q B T E P J A I K R F L C N]
time 1793ms: Process M started using the CPU for remaining 332ms of 396ms burst [Q Q B T E P J A I K R F L C N S]
time 1857ms: Time slice expired; preempting process M with 268ms remaining [Q Q B T E P J A I K R F L C N S]
time 1861ms: Process Q started using the CPU for remaining 200ms of 328ms burst [Q B T E P J A I K R F L C N S M]
time 1901ms: Process D completed I/O; added to ready queue [Q B T E P J A I K R F L C N S M D]
time 1920ms: Process O completed I/O; added to ready queue [Q B T E P J A I K R F L C N S M D O]
time 1925ms: Time slice expired; preempting process Q with 136ms remaining [Q B T E P J A I K R F L C N S M D O]
time 1928ms: Process G completed I/O; added to ready queue [Q T E P J A I K R F L C N S M D O Q G]
time 1929ms: Process B started using the CPU for 160ms burst [Q T E P J A I K R F L C N S M D O Q G]
time 1993ms: Time slice expired; preempting process B with 96ms remaining [Q T E P J A I K R F L C N S M D O Q G]
time 1997ms: Process T started using the CPU for 436ms burst [Q E P J A I K R F L C N S M D O Q G B]
time 2061ms: Time slice expired; preempting process T with 372ms remaining [Q E P J A I K R F L C N S M D O Q G B]
time 2065ms: Process E started using the CPU for 33ms burst [Q P J A I K R F L C N S M D O Q G B T]
time 2098ms: Process E completed a CPU burst; 58 bursts to go [Q P J A I K R F L C N S M D O Q G B T]
time 2098ms: Process E switching out of CPU; blocking on I/O until time 2140ms [Q P J A I K R F L C N S M D O Q G B T]
time 2102ms: Process P started using the CPU for 52ms burst [Q J A I K R F L C N S M D O Q G B T]
time 2140ms: Process E completed I/O; added to ready queue [Q J A I K R F L C N S M D O Q G B T E]
time 2154ms: Process P completed a CPU burst; 11 bursts to go [Q J A I K R F L C N S M D O Q G B T E]
time 2154ms: Process P switching out of CPU; blocking on I/O until time 2173ms [Q J A I K R F L C N S M D O Q G B T E]
time 2158ms: Process J started using the CPU for remaining 1920ms of 2048ms burst [Q A I K R F L C N S M D O Q G B T E]
time 2173ms: Process P completed I/O; added to ready queue [Q A I K R F L C N S M D O Q G B T E P]
time 2222ms: Time slice expired; preempting process J with 1856ms remaining [Q A I K R F L C N S M D O Q G B T E P]
time 2226ms: Process A started using the CPU for 274ms burst [Q I K R F L C N S M D O Q G B T E P J]
time 2290ms: Time slice expired; preempting process A with 210ms remaining [Q I K R F L C N S M D O Q G B T E P J]
time 2294ms: Process I started using the CPU for remaining 64ms of 192ms burst [Q K R F L C N S M D O Q G B T E P J A]
time 2358ms: Process I completed a CPU burst; 5 bursts to go [Q K R F L C N S M D O Q G B T E P J A]
time 2358ms: Process I switching out of CPU; blocking on I/O until time 2388ms [Q K R F L C N S M D O Q G B T E P J A]
time 2362ms: Process K started using the CPU for remaining 52ms of 116ms burst [Q R F L C N S M D O Q G B T E P J A]
time 2388ms: Process I completed I/O; added to ready queue [Q R F L C N S M D O Q G B T E P J A I]
time 2414ms: Process K completed a CPU burst; 60 bursts to go [Q R F L C N S M D O Q G B T E P J A I]
time 2414ms: Process K switching out of CPU; blocking on I/O until time 2418ms [Q R F L C N S M D O Q G B T E P J A I]
time 2418ms: Process R started using the CPU for remaining 144ms of 272ms burst [Q F L C N S M D O Q G B T E P J A I]
time 2418ms: Process K completed I/O; added to ready queue [Q F L C N S M D O Q G B T E P J A I K]
time 2482ms: Time slice expired; preempting process R with 80ms remaining [Q F L C N S M D O Q G B T E P J A I K]
time 2486ms: Process F started using the CPU for 98ms burst [Q L C N S M D O Q G B T E P J A I K R]
time 2550ms: Time slice expired; preempting process F with 34ms remaining [Q L C N S M D O Q G B T E P J A I K R]
time 2554ms: Process L started using the CPU for remaining 308ms of 500ms burst [Q C N S M D O Q G B T E P J A I K R F]
time 2618ms: Time slice expired; preempting process L with 244ms remaining [Q C N S M D O Q G B T E P J A I K R F]
time 2622ms: Process C started using the CPU for remaining 76ms of 204ms burst [Q N S M D O Q G B T E P J A I K R F L]
time 2686ms: Time slice expired; preempting process C with 12ms remaining [Q N S M D O Q G B T E P J A I K R F L]
time 2690ms: Process N started using the CPU for remaining 128ms of 256ms burst [Q S M D O Q G B T E P J A I K R F L C]
time 2754ms: Time slice expired; preempting process N with 64ms remaining [Q S M D O Q G B T E P J A I K R F L C]
time 2758ms: Process S started using the CPU for remaining 2304ms of 2432ms burst [Q M D O Q G B T E P J A I K R F L C N]
time 2822ms: Time slice expired; preempting process S with 2240ms remaining [Q M D O Q G B T E P J A I K R F L C N]
time 2826ms: Process M started using the CPU for remaining 268ms of 396ms burst [Q D O Q G B T E P J A I K R F L C N S]
time 2890ms: Time slice expired; preempting process M with 204ms remaining [Q D O Q G B T E P J A I K R F L C N S]
time 2894ms: Process D started using the CPU for 72ms burst [Q O Q G B T E P J A I K R F L C N S M]
time 2958ms: Time slice expired; preempting process D with 8ms remaining [Q O Q G B T E P J A I K R F L C N S M]
time 2962ms: Process O started using the CPU for 180ms burst [Q Q G B T E P J A I K R F L C N S M D]
time 3026ms: Time slice expired; preempting process O with 116ms remaining [Q Q G B T E P J A I K R F L C N S M D]
time 3030ms: Process Q started using the CPU for remaining 136ms of 328ms burst [Q G B T E P J A I K R F L C N S M D O]
time 3094ms: Time slice expired; preempting process Q with 72ms remaining [Q G B T E P J A I K R F L C N S M D O]
time 3098ms: Process G started using the CPU for 8ms burst [Q B T E P J A I K R F L C N S M D O Q]
time 3106ms: Process G completed a CPU burst; 51 bursts to go [Q B T E P J A I K R F L C N S M D O Q]
time 3106ms: Process G switching out of CPU; blocking on I/O until time 4318ms [Q B T E P J A I K R F L C N S M D O Q]
time 3110ms: Process B started using the CPU for remaining 96ms of 160ms burst [Q T E P J A I K R F L C N S M D O Q]
time 3174ms: Time slice expired; preempting process B with 32ms remaining [Q T E P J A I K R F L C N S M D O Q]
time 3178ms: Process T started using the CPU for remaining 372ms of 436ms burst [Q E P J A I K R F L C N S M D O Q B]
time 3242ms: Time slice expired; preempting process T with 308ms remaining [Q E P J A I K R F L C N S M D O Q B]
time 3246ms: Process E started using the CPU for 14ms burst [Q P J A I K R F L C N S M D O Q B T]
time 3260ms: Process E completed a CPU burst; 57 bursts to go [Q P J A I K R F L C N S M D O Q B T]
time 3260ms: Process E switching out of CPU; blocking on I/O until time 4872ms [Q P J A I K R F L C N S M D O Q B T]
time 3264ms: Process P started using the CPU for 16ms burst [Q J A I K R F L C N S M D O Q B T]
time 3280ms: Process P completed a CPU burst; 10 bursts to go [Q J A I K R F L C N S M D O Q B T]
time 3280ms: Process P switching out of CPU; blocking on I/O until time 3313ms [Q J A I K R F L C N S M D O Q B T]
time 3284ms: Process J started using the CPU for remaining 1856ms of 2048ms burst [Q A I K R F L C N S M D O Q B T]
time 3313ms: Process P completed I/O; added to ready queue [Q A I K R F L C N S M D O Q B T P]
time 3348ms: Time slice expired; preempting process J with 1792ms remaining [Q A I K R F L C N S M D O Q B T P]
time 3352ms: Process A started using the CPU for remaining 210ms of 274ms burst [Q I K R F L C N S M D O Q B T P J]
time 3416ms: Time slice expired; preempting process A with 146ms remaining [Q I K R F L C N S M D O Q B T P J]
time 3420ms: Process I started using the CPU for 64ms burst [Q K R F L C N S M D O Q B T P J A]
time 3484ms: Process I completed a CPU burst; 4 bursts to go [Q K R F L C N S M D O Q B T P J A]
time 3484ms: Process I switching out of CPU; blocking on I/O until time 3671ms [Q K R F L C N S M D O Q B T P J A]
time 3488ms: Process K started using the CPU for 368ms burst [Q R F L C N S M D O Q B T P J A]
time 3552ms: Time slice expired; preempting process K with 304ms remaining [Q R F L C N S M D O Q B T P J A]
time 3556ms: Process R started using the CPU for remaining 80ms of 272ms burst [Q F L C N S M D O Q B T P J A K]
time 3620ms: Time slice expired; preempting process R with 16ms remaining [Q F L C N S M D O Q B T P J A K]
time 3624ms: Process F started using the CPU for remaining 34ms of 98ms burst [Q L C N S M D O Q B T P J A K R]
time 3658ms: Process F completed a CPU burst; 42 bursts to go [Q L C N S M D O Q B T P J A K R]
time 3658ms: Process F switching out of CPU; blocking on I/O until time 6070ms [Q L C N S M D O Q B T P J A K R]
time 3662ms: Process L started using the CPU for remaining 244ms of 500ms burst [Q C N S M D O Q B T P J A K R]
time 3671ms: Process I completed I/O; added to ready queue [Q C N S M D O Q B T P J A K R I]
time 3726ms: Time slice expired; preempting process L with 180ms remaining [Q C N S M D O Q B T P J A K R I]
time 3730ms: Process C started using the CPU for remaining 12ms of 204ms burst [Q N S M D O Q B T P J A K R I L]
time 3742ms: Process C completed a CPU burst; 12 bursts to go [Q N S M D O Q B T P J A K R I L]
time 3742ms: Process C switching out of CPU; blocking on I/O until time 4754ms [Q N S M D O Q B T P J A K R I L]
time 3746ms: Process N started using the CPU for remaining 64ms of 256ms burst [Q S M D O Q B T P J A K R I L]
time 3810ms: Process N completed a CPU burst; 62 bursts to go [Q S M D O Q B T P J A K R I L]
time 3810ms: Process N switching out of CPU; blocking on I/O until time 3820ms [Q S M D O Q B T P J A K R I L]
time 3814ms: Process S started using the CPU for remaining 2240ms of 2432ms burst [Q M D O Q B T P J A K R I L]
time 3820ms: Process N completed I/O; added to ready queue [Q M D O Q B T P J A K R I L N]
time 3878ms: Time slice expired; preempting process S with 2176ms remaining [Q M D O Q B T P J A K R I L N]
time 3882ms: Process M started using the CPU for remaining 204ms of 396ms burst [Q D O Q B T P J A K R I L N S]
time 3946ms: Time slice expired; preempting process M with 140ms remaining [Q D O Q B T P J A K R I L N S]
time 3950ms: Process D started using the CPU for remaining 8ms of 72ms burst [Q O Q B T P J A K R I L N S M]
time 3958ms: Process D completed a CPU burst; 46 bursts to go [Q O Q B T P J A K R I L N S M]
time 3958ms: Process D switching out of CPU; blocking on I/O until time 4210ms [Q O Q B T P J A K R I L N S M]
time 3962ms: Process O started using the CPU for remaining 116ms of 180ms burst [Q Q B T P J A K R I L N S M]
time 4026ms: Time slice expired; preempting process O with 52ms remaining [Q Q B T P J A K R I L N S M]
time 4030ms: Process Q started using the CPU for remaining 72ms of 328ms burst [Q B T P J A K R I L N S M O]
time 4094ms: Time slice expired; preempting process Q with 8ms remaining [Q B T P J A K R I L N S M O]
time 4098ms: Process B started using the CPU for remaining 32ms of 160ms burst [Q T P J A K R I L N S M O Q]
time 4130ms: Process B completed a CPU burst; 33 bursts to go [Q T P J A K R I L N S M O Q]
time 4130ms: Process B switching out of CPU; blocking on I/O until time 4402ms [Q T P J A K R I L N S M O Q]
time 4134ms: Process T started using the CPU for remaining 308ms of 436ms burst [Q P J A K R I L N S M O Q]
time 4198ms: Time slice expired; preempting process T with 244ms remaining [Q P J A K R I L N S M O Q]
time 4202ms: Process P started using the CPU for 728ms burst [Q J A K R I L N S M O Q T]
time 4210ms: Process D completed I/O; added to ready queue [Q J A K R I L N S M O Q T D]
time 4266ms: Time slice expired; preempting process P with 664ms remaining [Q J A K R I L N S M O Q T D]
time 4270ms: Process J started using the CPU for remaining 1792ms of 2048ms burst [Q A K R I L N S M O Q T D P]
time 4318ms: Process G completed I/O; added to ready queue [Q A K R I L N S M O Q T D P G]
time 4334ms: Time slice expired; preempting process J with 1728ms remaining [Q A K R I L N S M O Q T D P G]
time 4338ms: Process A started using the CPU for remaining 146ms of 274ms burst [Q K R I L N S M O Q T D P G J]
time 4402ms: Time slice expired; preempting process A with 82ms remaining [Q K R I L N S M O Q T D P G J]
time 4402ms: Process B completed I/O; added to ready queue [Q K R I L N S M O Q T D P G J B]
time 4406ms: Process K started using the CPU for remaining 304ms of 368ms burst [Q R I L N S M O Q T D P G J B A]
time 4470ms: Time slice expired; preempting process K with 240ms remaining [Q R I L N S M O Q T D P G J B A]
time 4474ms: Process R started using the CPU for remaining 16ms of 272ms burst [Q I L N S M O Q T D P G J B A K]
time 4490ms: Process R completed a CPU burst; 62 bursts to go [Q I L N S M O Q T D P G J B A K]
time 4490ms: Process R switching out of CPU; blocking on I/O until time 4579ms [Q I L N S M O Q T D P G J B A K]
time 4494ms: Process I started using the CPU for 244ms burst [Q L N S M O Q T D P G J B A K]
time 4558ms: Time slice expired; preempting process I with 180ms remaining [Q L N S M O Q T D P G J B A K]
time 4562ms: Process L started using the CPU for remaining 180ms of 500ms burst [Q N S M O Q T D P G J B A K I]
time 4579ms: Process R completed I/O; added to ready queue [Q N S M O Q T D P G J B A K I R]
time 4626ms: Time slice expired; preempting process L with 116ms remaining [Q N S M O Q T D P G J B A K I R]
time 4630ms: Process N started using the CPU for 380ms burst [Q S M O Q T D P G J B A K I R L]
time 4694ms: Time slice expired; preempting process N with 316ms remaining [Q S M O Q T D P G J B A K I R L]
time 4698ms: Process S started using the CPU for remaining 2176ms of 2432ms burst [Q M O Q T D P G J B A K I R L N]
time 4754ms: Process C completed I/O; added to ready queue [Q M O Q T D P G J B A K I R L N C]
time 4762ms: Time slice expired; preempting process S with 2112ms remaining [Q M O Q T D P G J B A K I R L N C]
time 4766ms: Process M started using the CPU for remaining 140ms of 396ms burst [Q O Q T D P G J B A K I R L N C S]
time 4830ms: Time slice expired; preempting process M with 76ms remaining [Q O Q T D P G J B A K I R L N C S]
time 4834ms: Process O started using the CPU for remaining 52ms of 180ms burst [Q Q T D P G J B A K I R L N C S M]
time 4872ms: Process E completed I/O; added to ready queue [Q Q T D P G J B A K I R L N C S M E]
time 4886ms: Process O completed a CPU burst; 50 bursts to go [Q Q T D P G J B A K I R L N C S M E]
time 4886ms: Process O switching out of CPU; blocking on I/O until time 4953ms [Q Q T D P G J B A K I R L N C S M E]
time 4890ms: Process Q started using the CPU for remaining 8ms of 328ms burst [Q T D P G J B A K I R L N C S M E]
time 4898ms: Process Q completed a CPU burst; 50 bursts to go [Q T D P G J B A K I R L N C S M E]
time 4898ms: Process Q switching out of CPU; blocking on I/O until time 5187ms [Q T D P G J B A K I R L N C S M E]
time 4902ms: Process T started using the CPU for remaining 244ms of 436ms burst [Q D P G J B A K I R L N C S M E]
time 4953ms: Process O completed I/O; added to ready queue [Q D P G J B A K I R L N C S M E O]
time 4966ms: Time slice expired; preempting process T with 180ms remaining [Q D P G J B A K I R L N C S M E O]
time 4970ms: Process D started using the CPU for 15ms burst [Q P G J B A K I R L N C S M E O T]
time 4985ms: Process D completed a CPU burst; 45 bursts to go [Q P G J B A K I R L N C S M E O T]
time 4985ms: Process D switching out of CPU; blocking on I/O until time 5847ms [Q P G J B A K I R L N C S M E O T]
time 4989ms: Process P started using the CPU for remaining 664ms of 728ms burst [Q G J B A K I R L N C S M E O T]
time 5053ms: Time slice expired; preempting process P with 600ms remaining [Q G J B A K I R L N C S M E O T]
time 5057ms: Process G started using the CPU for 3ms burst [Q J B A K I R L N C S M E O T P]
time 5060ms: Process G completed a CPU burst; 50 bursts to go [Q J B A K I R L N C S M E O T P]
time 5060ms: Process G switching out of CPU; blocking on I/O until time 6432ms [Q J B A K I R L N C S M E O T P]
time 5064ms: Process J started using the CPU for remaining 1728ms of 2048ms burst [Q B A K I R L N C S M E O T P]
time 5128ms: Time slice expired; preempting process J with 1664ms remaining [Q B A K I R L N C S M E O T P]
time 5132ms: Process B started using the CPU for 214ms burst [Q A K I R L N C S M E O T P J]
time 5187ms: Process Q completed I/O; added to ready queue [Q A K I R L N C S M E O T P J Q]
time 5196ms: Time slice expired; preempting process B with 150ms remaining [Q A K I R L N C S M E O T P J Q]
time 5200ms: Process A started using the CPU for remaining 82ms of 274ms burst [Q K I R L N C S M E O T P J Q B]
time 5233ms: Process H completed I/O; added to ready queue [Q K I R L N C S M E O T P J Q B H]
time 5264ms: Time slice expired; preempting process A with 18ms remaining [Q K I R L N C S M E O T P J Q B H]
time 5268ms: Process K started using the CPU for remaining 240ms of 368ms burst [Q I R L N C S M E O T P J Q B H A]
time 5332ms: Time slice expired; preempting process K with 176ms remaining [Q I R L N C S M E O T P J Q B H A]
time 5336ms: Process I started using the CPU for remaining 180ms of 244ms burst [Q R L N C S M E O T P J Q B H A K]
time 5400ms: Time slice expired; preempting process I with 116ms remaining [Q R L N C S M E O T P J Q B H A K]
time 5404ms: Process R started using the CPU for 1088ms burst [Q L N C S M E O T P J Q B H A K I]
time 5468ms: Time slice expired; preempting process R with 1024ms remaining [Q L N C S M E O T P J Q B H A K I]
time 5472ms: Process L started using the CPU for remaining 116ms of 500ms burst [Q N C S M E O T P J Q B H A K I R]
time 5536ms: Time slice expired; preempting process L with 52ms remaining [Q N C S M E O T P J Q B H A K I R]
time 5540ms: Process N started using the CPU for remaining 316ms of 380ms burst [Q C S M E O T P J Q B H A K I R L]
time 5604ms: Time slice expired; preempting process N with 252ms remaining [Q C S M E O T P J Q B H A K I R L]
time 5608ms: Process C started using the CPU for 25ms burst [Q S M E O T P J Q B H A K I R L N]
time 5633ms: Process C completed a CPU burst; 11 bursts to go [Q S M E O T P J Q B H A K I R L N]
time 5633ms: Process C switching out of CPU; blocking on I/O until time 9895ms [Q S M E O T P J Q B H A K I R L N]
time 5637ms: Process S started using the CPU for remaining 2112ms of 2432ms burst [Q M E O T P J Q B H A K I R L N]
time 5701ms: Time slice expired; preempting process S with 2048ms remaining [Q M E O T P J Q B H A K I R L N]
time 5705ms: Process M started using the CPU for remaining 76ms of 396ms burst [Q E O T P J Q B H A K I R L N S]
time 5769ms: Time slice expired; preempting process M with 12ms remaining [Q E O T P J Q B H A K I R L N S]
time 5773ms: Process E started using the CPU for 51ms burst [Q O T P J Q B H A K I R L N S M]
time 5824ms: Process E completed a CPU burst; 56 bursts to go [Q O T P J Q B H A K I R L N S M]
time 5824ms: Process E switching out of CPU; blocking on I/O until time 6586ms [Q O T P J Q B H A K I R L N S M]
time 5828ms: Process O started using the CPU for 144ms burst [Q T P J Q B H A K I R L N S M]
time 5847ms: Process D completed I/O; added to ready queue [Q T P J Q B H A K I R L N S M D]
time 5892ms: Time slice expired; preempting process O with 80ms remaining [Q T P J Q B H A K I R L N S M D]
time 5896ms: Process T started using the CPU for remaining 180ms of 436ms burst [Q P J Q B H A K I R L N S M D O]
time 5960ms: Time slice expired; preempting process T with 116ms remaining [Q P J Q B H A K I R L N S M D O]
time 5964ms: Process P started using the CPU for remaining 600ms of 728ms burst [Q J Q B H A K I R L N S M D O T]
time 6028ms: Time slice expired; preempting process P with 536ms remaining [Q J Q B H A K I R L N S M D O T]
time 6032ms: Process J started using the CPU for remaining 1664ms of 2048ms burst [Q Q B H A K I R L N S M D O T P]
time 6070ms: Process F completed I/O; added to ready queue [Q Q B H A K I R L N S M D O T P F]
time 6096ms: Time slice expired; preempting process J with 1600ms remaining [Q Q B H A K I R L N S M D O T P F]
time 6100ms: Process Q started using the CPU for 56ms burst [Q B H A K I R L N S M D O T P F J]
time 6156ms: Process Q completed a CPU burst; 49 bursts to go [Q B H A K I R L N S M D O T P F J]
time 6156ms: Process Q switching out of CPU; blocking on I/O until time 6380ms [Q B H A K I R L N S M D O T P F J]
time 6160ms: Process B started using the CPU for remaining 150ms of 214ms burst [Q H A K I R L N S M D O T P F J]
time 6224ms: Time slice expired; preempting process B with 86ms remaining [Q H A K I R L N S M D O T P F J]
time 6228ms: Process H started using the CPU for 20ms burst [Q A K I R L N S M D O T P F J B]
time 6248ms: Process H completed a CPU burst; 49 bursts to go [Q A K I R L N S M D O T P F J B]
time 6248ms: Process H switching out of CPU; blocking on I/O until time 6300ms [Q A K I R L N S M D O T P F J B]
time 6252ms: Process A started using the CPU for remaining 18ms of 274ms burst [Q K I R L N S M D O T P F J B]
time 6270ms: Process A completed a CPU burst; 58 bursts to go [Q K I R L N S M D O T P F J B]
time 6270ms: Process A switching out of CPU; blocking on I/O until time 7122ms [Q K I R L N S M D O T P F J B]
time 6274ms: Process K started using the CPU for remaining 176ms of 368ms burst [Q I R L N S M D O T P F J B]
