<<< PROJECT PART I -- process set (n=20) with 12 CPU-bound processes >>>
I/O-bound process A: arrival time 45ms; 60 CPU bursts
I/O-bound process B: arrival time 76ms; 35 CPU bursts
I/O-bound process C: arrival time 114ms; 13 CPU bursts
I/O-bound process D: arrival time 227ms; 48 CPU bursts
I/O-bound process E: arrival time 39ms; 60 CPU bursts
I/O-bound process F: arrival time 18ms; 44 CPU bursts
I/O-bound process G: arrival time 274ms; 53 CPU bursts
I/O-bound process H: arrival time 30ms; 51 CPU bursts
CPU-bound process I: arrival time 23ms; 6 CPU bursts
CPU-bound process J: arrival time 18ms; 35 CPU bursts
CPU-bound process K: arrival time 414ms; 61 CPU bursts
CPU-bound process L: arrival time 3ms; 38 CPU bursts
CPU-bound process M: arrival time 160ms; 50 CPU bursts
CPU-bound process N: arrival time 115ms; 63 CPU bursts
CPU-bound process O: arrival time 9ms; 52 CPU bursts
CPU-bound process P: arrival time 212ms; 13 CPU bursts
CPU-bound process Q: arrival time 15ms; 51 CPU bursts
CPU-bound process R: arrival time 59ms; 63 CPU bursts
CPU-bound process S: arrival time 155ms; 53 CPU bursts
CPU-bound process T: arrival time 116ms; 17 CPU bursts

<<< PROJECT PART II -- t_cs=4ms; alpha=0.96; t_slice=64ms >>>
time 0ms: Simulator started for FCFS [Q <empty>]
time 3ms: Process L arrived; added to ready queue [Q L]
time 5ms: Process L started using the CPU for 500ms burst [Q <empty>]
time 9ms: Process O arrived; added to ready queue [Q O]
time 15ms: Process Q arrived; added to ready queue [Q O Q]
time 18ms: Process F arrived; added to ready queue [Q O Q F]
time 18ms: Process J arrived; added to ready queue [Q O Q F J]
time 23ms: Process I arrived; added to ready queue [Q O Q F J I]
time 30ms: Process H arrived; added to ready queue [Q O Q F J I H]
time 39ms: Process E arrived; added to ready queue [Q O Q F J I H E]
time 45ms: Process A arrived; added to ready queue [Q O Q F J I H E A]
time 59ms: Process R arrived; added to ready queue [Q O Q F J I H E A R]
time 76ms: Process B arrived; added to ready queue [Q O Q F J I H E A R B]
time 114ms: Process C arrived; added to ready queue [Q O Q F J I H E A R B C]
time 115ms: Process N arrived; added to ready queue [Q O Q F J I H E A R B C N]
time 116ms: Process T arrived; added to ready queue [Q O Q F J I H E A R B C N T]
time 155ms: Process S arrived; added to ready queue [Q O Q F J I H E A R B C N T S]
time 160ms: Process M arrived; added to ready queue [Q O Q F J I H E A R B C N T S M]
time 212ms: Process P arrived; added to ready queue [Q O Q F J I H E A R B C N T S M P]
time 227ms: Process D arrived; added to ready queue [Q O Q F J I H E A R B C N T S M P D]
time 274ms: Process G arrived; added to ready queue [Q O Q F J I H E A R B C N T S M P D G]
time 414ms: Process K arrived; added to ready queue [Q O Q F J I H E A R B C N T S M P D G K]
time 505ms: Process L completed a CPU burst; 37 bursts to go [Q O Q F J I H E A R B C N T S M P D G K]
time 505ms: Process L switching out of CPU; blocking on I/O until time 518ms [Q O Q F J I H E A R B C N T S M P D G K]
time 509ms: Process O started using the CPU for 152ms burst [Q Q F J I H E A R B C N T S M P D G K]
time 518ms: Process L completed I/O; added to ready queue [Q Q F J I H E A R B C N T S M P D G K L]
time 661ms: Process O completed a CPU burst; 51 bursts to go [Q Q F J I H E A R B C N T S M P D G K L]
time 661ms: Process O switching out of CPU; blocking on I/O until time 860ms [Q Q F J I H E A R B C N T S M P D G K L]
time 665ms: Process Q started using the CPU for 328ms burst [Q F J I H E A R B C N T S M P D G K L]
time 860ms: Process O completed I/O; added to ready queue [Q F J I H E A R B C N T S M P D G K L O]
time 993ms: Process Q completed a CPU burst; 50 bursts to go [Q F J I H E A R B C N T S M P D G K L O]
time 993ms: Process Q switching out of CPU; blocking on I/O until time 1282ms [Q F J I H E A R B C N T S M P D G K L O]
time 997ms: Process F started using the CPU for 28ms burst [Q J I H E A R B C N T S M P D G K L O]
time 1025ms: Process F completed a CPU burst; 43 bursts to go [Q J I H E A R B C N T S M P D G K L O]
time 1025ms: Process F switching out of CPU; blocking on I/O until time 2297ms [Q J I H E A R B C N T S M P D G K L O]
time 1029ms: Process J started using the CPU for 2048ms burst [Q I H E A R B C N T S M P D G K L O]
time 1282ms: Process Q completed I/O; added to ready queue [Q I H E A R B C N T S M P D G K L O Q]
time 2297ms: Process F completed I/O; added to ready queue [Q I H E A R B C N T S M P D G K L O Q F]
time 3077ms: Process J completed a CPU burst; 34 bursts to go [Q I H E A R B C N T S M P D G K L O Q F]
time 3077ms: Process J switching out of CPU; blocking on I/O until time 3131ms [Q I H E A R B C N T S M P D G K L O Q F]
time 3081ms: Process I started using the CPU for 192ms burst [Q H E A R B C N T S M P D G K L O Q F]
time 3131ms: Process J completed I/O; added to ready queue [Q H E A R B C N T S M P D G K L O Q F J]
time 3273ms: Process I completed a CPU burst; 5 bursts to go [Q H E A R B C N T S M P D G K L O Q F J]
time 3273ms: Process I switching out of CPU; blocking on I/O until time 3303ms [Q H E A R B C N T S M P D G K L O Q F J]
time 3277ms: Process H started using the CPU for 71ms burst [Q E A R B C N T S M P D G K L O Q F J]
time 3303ms: Process I completed I/O; added to ready queue [Q E A R B C N T S M P D G K L O Q F J I]
time 3348ms: Process H completed a CPU burst; 50 bursts to go [Q E A R B C N T S M P D G K L O Q F J I]
time 3348ms: Process H switching out of CPU; blocking on I/O until time 7160ms [Q E A R B C N T S M P D G K L O Q F J I]
time 3352ms: Process E started using the CPU for 28ms burst [Q A R B C N T S M P D G K L O Q F J I]
time 3380ms: Process E completed a CPU burst; 59 bursts to go [Q A R B C N T S M P D G K L O Q F J I]
time 3380ms: Process E switching out of CPU; blocking on I/O until time 4152ms [Q A R B C N T S M P D G K L O Q F J I]
time 3384ms: Process A started using the CPU for 49ms burst [Q R B C N T S M P D G K L O Q F J I]
time 3433ms: Process A completed a CPU burst; 59 bursts to go [Q R B C N T S M P D G K L O Q F J I]
time 3433ms: Process A switching out of CPU; blocking on I/O until time 4225ms [Q R B C N T S M P D G K L O Q F J I]
time 3437ms: Process R started using the CPU for 272ms burst [Q B C N T S M P D G K L O Q F J I]
time 3709ms: Process R completed a CPU burst; 62 bursts to go [Q B C N T S M P D G K L O Q F J I]
time 3709ms: Process R switching out of CPU; blocking on I/O until time 3798ms [Q B C N T S M P D G K L O Q F J I]
time 3713ms: Process B started using the CPU for 14ms burst [Q C N T S M P D G K L O Q F J I]
time 3727ms: Process B completed a CPU burst; 34 bursts to go [Q C N T S M P D G K L O Q F J I]
time 3727ms: Process B switching out of CPU; blocking on I/O until time 4169ms [Q C N T S M P D G K L O Q F J I]
time 3731ms: Process C started using the CPU for 204ms burst [Q N T S M P D G K L O Q F J I]
time 3798ms: Process R completed I/O; added to ready queue [Q N T S M P D G K L O Q F J I R]
time 3935ms: Process C completed a CPU burst; 12 bursts to go [Q N T S M P D G K L O Q F J I R]
time 3935ms: Process C switching out of CPU; blocking on I/O until time 4947ms [Q N T S M P D G K L O Q F J I R]
time 3939ms: Process N started using the CPU for 256ms burst [Q T S M P D G K L O Q F J I R]
time 4152ms: Process E completed I/O; added to ready queue [Q T S M P D G K L O Q F J I R E]
time 4169ms: Process B completed I/O; added to ready queue [Q T S M P D G K L O Q F J I R E B]
time 4195ms: Process N completed a CPU burst; 62 bursts to go [Q T S M P D G K L O Q F J I R E B]
time 4195ms: Process N switching out of CPU; blocking on I/O until time 4205ms [Q T S M P D G K L O Q F J I R E B]
time 4199ms: Process T started using the CPU for 20ms burst [Q S M P D G K L O Q F J I R E B]
time 4205ms: Process N completed I/O; added to ready queue [Q S M P D G K L O Q F J I R E B N]
time 4219ms: Process T completed a CPU burst; 16 bursts to go [Q S M P D G K L O Q F J I R E B N]
time 4219ms: Process T switching out of CPU; blocking on I/O until time 4552ms [Q S M P D G K L O Q F J I R E B N]
time 4223ms: Process S started using the CPU for 2432ms burst [Q M P D G K L O Q F J I R E B N]
time 4225ms: Process A completed I/O; added to ready queue [Q M P D G K L O Q F J I R E B N A]
time 4552ms: Process T completed I/O; added to ready queue [Q M P D G K L O Q F J I R E B N A T]
time 4947ms: Process C completed I/O; added to ready queue [Q M P D G K L O Q F J I R E B N A T C]
time 6655ms: Process S completed a CPU burst; 52 bursts to go [Q M P D G K L O Q F J I R E B N A T C]
time 6655ms: Process S switching out of CPU; blocking on I/O until time 6739ms [Q M P D G K L O Q F J I R E B N A T C]
time 6659ms: Process M started using the CPU for 396ms burst [Q P D G K L O Q F J I R E B N A T C]
time 6739ms: Process S completed I/O; added to ready queue [Q P D G K L O Q F J I R E B N A T C S]
time 7055ms: Process M completed a CPU burst; 49 bursts to go [Q P D G K L O Q F J I R E B N A T C S]
time 7055ms: Process M switching out of CPU; blocking on I/O until time 7217ms [Q P D G K L O Q F J I R E B N A T C S]
time 7059ms: Process P started using the CPU for 20ms burst [Q D G K L O Q F J I R E B N A T C S]
time 7079ms: Process P completed a CPU burst; 12 bursts to go [Q D G K L O Q F J I R E B N A T C S]
time 7079ms: Process P switching out of CPU; blocking on I/O until time 7194ms [Q D G K L O Q F J I R E B N A T C S]
time 7083ms: Process D started using the CPU for 59ms burst [Q G K L O Q F J I R E B N A T C S]
time 7142ms: Process D completed a CPU burst; 47 bursts to go [Q G K L O Q F J I R E B N A T C S]
time 7142ms: Process D switching out of CPU; blocking on I/O until time 7844ms [Q G K L O Q F J I R E B N A T C S]
time 7146ms: Process G started using the CPU for 3ms burst [Q K L O Q F J I R E B N A T C S]
time 7149ms: Process G completed a CPU burst; 52 bursts to go [Q K L O Q F J I R E B N A T C S]
time 7149ms: Process G switching out of CPU; blocking on I/O until time 7871ms [Q K L O Q F J I R E B N A T C S]
time 7153ms: Process K started using the CPU for 116ms burst [Q L O Q F J I R E B N A T C S]
time 7160ms: Process H completed I/O; added to ready queue [Q L O Q F J I R E B N A T C S H]
time 7194ms: Process P completed I/O; added to ready queue [Q L O Q F J I R E B N A T C S H P]
time 7217ms: Process M completed I/O; added to ready queue [Q L O Q F J I R E B N A T C S H P M]
time 7269ms: Process K completed a CPU burst; 60 bursts to go [Q L O Q F J I R E B N A T C S H P M]
time 7269ms: Process K switching out of CPU; blocking on I/O until time 7273ms [Q L O Q F J I R E B N A T C S H P M]
time 7273ms: Process L started using the CPU for 56ms burst [Q O Q F J I R E B N A T C S H P M]
time 7273ms: Process K completed I/O; added to ready queue [Q O Q F J I R E B N A T C S H P M K]
time 7329ms: Process L completed a CPU burst; 36 bursts to go [Q O Q F J I R E B N A T C S H P M K]
time 7329ms: Process L switching out of CPU; blocking on I/O until time 7366ms [Q O Q F J I R E B N A T C S H P M K]
time 7333ms: Process O started using the CPU for 180ms burst [Q Q F J I R E B N A T C S H P M K]
time 7366ms: Process L completed I/O; added to ready queue [Q Q F J I R E B N A T C S H P M K L]
time 7513ms: Process O completed a CPU burst; 50 bursts to go [Q Q F J I R E B N A T C S H P M K L]
time 7513ms: Process O switching out of CPU; blocking on I/O until time 7580ms [Q Q F J I R E B N A T C S H P M K L]
time 7517ms: Process Q started using the CPU for 56ms burst [Q F J I R E B N A T C S H P M K L]
time 7573ms: Process Q completed a CPU burst; 49 bursts to go [Q F J I R E B N A T C S H P M K L]
time 7573ms: Process Q switching out of CPU; blocking on I/O until time 7797ms [Q F J I R E B N A T C S H P M K L]
time 7577ms: Process F started using the CPU for 98ms burst [Q J I R E B N A T C S H P M K L]
time 7580ms: Process O completed I/O; added to ready queue [Q J I R E B N A T C S H P M K L O]
time 7675ms: Process F completed a CPU burst; 42 bursts to go [Q J I R E B N A T C S H P M K L O]
time 7675ms: Process F switching out of CPU; blocking on I/O until time 10087ms [Q J I R E B N A T C S H P M K L O]
time 7679ms: Process J started using the CPU for 100ms burst [Q I R E B N A T C S H P M K L O]
time 7779ms: Process J completed a CPU burst; 33 bursts to go [Q I R E B N A T C S H P M K L O]
time 7779ms: Process J switching out of CPU; blocking on I/O until time 7887ms [Q I R E B N A T C S H P M K L O]
time 7783ms: Process I started using the CPU for 64ms burst [Q R E B N A T C S H P M K L O]
time 7797ms: Process Q completed I/O; added to ready queue [Q R E B N A T C S H P M K L O Q]
time 7844ms: Process D completed I/O; added to ready queue [Q R E B N A T C S H P M K L O Q D]
time 7847ms: Process I completed a CPU burst; 4 bursts to go [Q R E B N A T C S H P M K L O Q D]
time 7847ms: Process I switching out of CPU; blocking on I/O until time 8034ms [Q R E B N A T C S H P M K L O Q D]
time 7851ms: Process R started using the CPU for 1088ms burst [Q E B N A T C S H P M K L O Q D]
time 7871ms: Process G completed I/O; added to ready queue [Q E B N A T C S H P M K L O Q D G]
time 7887ms: Process J completed I/O; added to ready queue [Q E B N A T C S H P M K L O Q D G J]
time 8034ms: Process I completed I/O; added to ready queue [Q E B N A T C S H P M K L O Q D G J I]
time 8939ms: Process R completed a CPU burst; 61 bursts to go [Q E B N A T C S H P M K L O Q D G J I]
time 8939ms: Process R switching out of CPU; blocking on I/O until time 9182ms [Q E B N A T C S H P M K L O Q D G J I]
time 8943ms: Process E started using the CPU for 33ms burst [Q B N A T C S H P M K L O Q D G J I]
time 8976ms: Process E completed a CPU burst; 58 bursts to go [Q B N A T C S H P M K L O Q D G J I]
time 8976ms: Process E switching out of CPU; blocking on I/O until time 9018ms [Q B N A T C S H P M K L O Q D G J I]
time 8980ms: Process B started using the CPU for 160ms burst [Q N A T C S H P M K L O Q D G J I]
time 9018ms: Process E completed I/O; added to ready queue [Q N A T C S H P M K L O Q D G J I E]
time 9140ms: Process B completed a CPU burst; 33 bursts to go [Q N A T C S H P M K L O Q D G J I E]
time 9140ms: Process B switching out of CPU; blocking on I/O until time 9412ms [Q N A T C S H P M K L O Q D G J I E]
time 9144ms: Process N started using the CPU for 380ms burst [Q A T C S H P M K L O Q D G J I E]
time 9182ms: Process R completed I/O; added to ready queue [Q A T C S H P M K L O Q D G J I E R]
time 9412ms: Process B completed I/O; added to ready queue [Q A T C S H P M K L O Q D G J I E R B]
time 9524ms: Process N completed a CPU burst; 61 bursts to go [Q A T C S H P M K L O Q D G J I E R B]
time 9524ms: Process N switching out of CPU; blocking on I/O until time 9634ms [Q A T C S H P M K L O Q D G J I E R B]
time 9528ms: Process A started using the CPU for 274ms burst [Q T C S H P M K L O Q D G J I E R B]
time 9634ms: Process N completed I/O; added to ready queue [Q T C S H P M K L O Q D G J I E R B N]
time 9802ms: Process A completed a CPU burst; 58 bursts to go [Q T C S H P M K L O Q D G J I E R B N]
time 9802ms: Process A switching out of CPU; blocking on I/O until time 10654ms [Q T C S H P M K L O Q D G J I E R B N]
time 9806ms: Process T started using the CPU for 436ms burst [Q C S H P M K L O Q D G J I E R B N]
time 10087ms: Process F completed I/O; added to ready queue [Q C S H P M K L O Q D G J I E R B N F]
time 10242ms: Process T completed a CPU burst; 15 bursts to go [Q C S H P M K L O Q D G J I E R B N F]
time 10242ms: Process T switching out of CPU; blocking on I/O until time 10252ms [Q C S H P M K L O Q D G J I E R B N F]
time 10246ms: Process C started using the CPU for 25ms burst [Q S H P M K L O Q D G J I E R B N F]
time 10252ms: Process T completed I/O; added to ready queue [Q S H P M K L O Q D G J I E R B N F T]
time 10271ms: Process C completed a CPU burst; 11 bursts to go [Q S H P M K L O Q D G J I E R B N F T]
time 10271ms: Process C switching out of CPU; blocking on I/O until time 14533ms [Q S H P M K L O Q D G J I E R B N F T]
time 10275ms: Process S started using the CPU for 1444ms burst [Q H P M K L O Q D G J I E R B N F T]
time 10654ms: Process A completed I/O; added to ready queue [Q H P M K L O Q D G J I E R B N F T A]
time 11719ms: Process S completed a CPU burst; 51 bursts to go [Q H P M K L O Q D G J I E R B N F T A]
time 11719ms: Process S switching out of CPU; blocking on I/O until time 11787ms [Q H P M K L O Q D G J I E R B N F T A]
time 11723ms: Process H started using the CPU for 20ms burst [Q P M K L O Q D G J I E R B N F T A]
time 11743ms: Process H completed a CPU burst; 49 bursts to go [Q P M K L O Q D G J I E R B N F T A]
time 11743ms: Process H switching out of CPU; blocking on I/O until time 11795ms [Q P M K L O Q D G J I E R B N F T A]
time 11747ms: Process P started using the CPU for 52ms burst [Q M K L O Q D G J I E R B N F T A]
time 11787ms: Process S completed I/O; added to ready queue [Q M K L O Q D G J I E R B N F T A S]
time 11795ms: Process H completed I/O; added to ready queue [Q M K L O Q D G J I E R B N F T A S H]
time 11799ms: Process P completed a CPU burst; 11 bursts to go [Q M K L O Q D G J I E R B N F T A S H]
time 11799ms: Process P switching out of CPU; blocking on I/O until time 11818ms [Q M K L O Q D G J I E R B N F T A S H]
time 11803ms: Process M started using the CPU for 896ms burst [Q K L O Q D G J I E R B N F T A S H]
time 11818ms: Process P completed I/O; added to ready queue [Q K L O Q D G J I E R B N F T A S H P]
time 12699ms: Process M completed a CPU burst; 48 bursts to go [Q K L O Q D G J I E R B N F T A S H P]
time 12699ms: Process M switching out of CPU; blocking on I/O until time 12823ms [Q K L O Q D G J I E R B N F T A S H P]
time 12703ms: Process K started using the CPU for 368ms burst [Q L O Q D G J I E R B N F T A S H P]
time 12823ms: Process M completed I/O; added to ready queue [Q L O Q D G J I E R B N F T A S H P M]
time 13071ms: Process K completed a CPU burst; 59 bursts to go [Q L O Q D G J I E R B N F T A S H P M]
time 13071ms: Process K switching out of CPU; blocking on I/O until time 13176ms [Q L O Q D G J I E R B N F T A S H P M]
time 13075ms: Process L started using the CPU for 856ms burst [Q O Q D G J I E R B N F T A S H P M]
time 13176ms: Process K completed I/O; added to ready queue [Q O Q D G J I E R B N F T A S H P M K]
time 13931ms: Process L completed a CPU burst; 35 bursts to go [Q O Q D G J I E R B N F T A S H P M K]
time 13931ms: Process L switching out of CPU; blocking on I/O until time 14526ms [Q O Q D G J I E R B N F T A S H P M K]
time 13935ms: Process O started using the CPU for 144ms burst [Q Q D G J I E R B N F T A S H P M K]
time 14079ms: Process O completed a CPU burst; 49 bursts to go [Q Q D G J I E R B N F T A S H P M K]
time 14079ms: Process O switching out of CPU; blocking on I/O until time 14614ms [Q Q D G J I E R B N F T A S H P M K]
time 14083ms: Process Q started using the CPU for 128ms burst [Q D G J I E R B N F T A S H P M K]
time 14211ms: Process Q completed a CPU burst; 48 bursts to go [Q D G J I E R B N F T A S H P M K]
time 14211ms: Process Q switching out of CPU; blocking on I/O until time 14290ms [Q D G J I E R B N F T A S H P M K]
time 14215ms: Process D started using the CPU for 72ms burst [Q G J I E R B N F T A S H P M K]
time 14287ms: Process D completed a CPU burst; 46 bursts to go [Q G J I E R B N F T A S H P M K]
time 14287ms: Process D switching out of CPU; blocking on I/O until time 14539ms [Q G J I E R B N F T A S H P M K]
time 14290ms: Process Q completed I/O; added to ready queue [Q J I E R B N F T A S H P M K Q]
time 14291ms: Process G started using the CPU for 8ms burst [Q J I E R B N F T A S H P M K Q]
time 14299ms: Process G completed a CPU burst; 51 bursts to go [Q J I E R B N F T A S H P M K Q]
time 14299ms: Process G switching out of CPU; blocking on I/O until time 15511ms [Q J I E R B N F T A S H P M K Q]
time 14303ms: Process J started using the CPU for 780ms burst [Q I E R B N F T A S H P M K Q]
time 14526ms: Process L completed I/O; added to ready queue [Q I E R B N F T A S H P M K Q L]
time 14533ms: Process C completed I/O; added to ready queue [Q I E R B N F T A S H P M K Q L C]
time 14539ms: Process D completed I/O; added to ready queue [Q I E R B N F T A S H P M K Q L C D]
time 14614ms: Process O completed I/O; added to ready queue [Q I E R B N F T A S H P M K Q L C D O]
time 15083ms: Process J completed a CPU burst; 32 bursts to go [Q I E R B N F T A S H P M K Q L C D O]
time 15083ms: Process J switching out of CPU; blocking on I/O until time 15182ms [Q I E R B N F T A S H P M K Q L C D O]
time 15087ms: Process I started using the CPU for 244ms burst [Q E R B N F T A S H P M K Q L C D O]
time 15182ms: Process J completed I/O; added to ready queue [Q E R B N F T A S H P M K Q L C D O J]
time 15331ms: Process I completed a CPU burst; 3 bursts to go [Q E R B N F T A S H P M K Q L C D O J]
time 15331ms: Process I switching out of CPU; blocking on I/O until time 15531ms [Q E R B N F T A S H P M K Q L C D O J]
time 15335ms: Process E started using the CPU for 14ms burst [Q R B N F T A S H P M K Q L C D O J]
time 15349ms: Process E completed a CPU burst; 57 bursts to go [Q R B N F T A S H P M K Q L C D O J]
time 15349ms: Process E switching out of CPU; blocking on I/O until time 16961ms [Q R B N F T A S H P M K Q L C D O J]
time 15353ms: Process R started using the CPU for 1440ms burst [Q B N F T A S H P M K Q L C D O J]
time 15511ms: Process G completed I/O; added to ready queue [Q B N F T A S H P M K Q L C D O J G]
time 15531ms: Process I completed I/O; added to ready queue [Q B N F T A S H P M K Q L C D O J G I]
time 16793ms: Process R completed a CPU burst; 60 bursts to go [Q B N F T A S H P M K Q L C D O J G I]
time 16793ms: Process R switching out of CPU; blocking on I/O until time 17371ms [Q B N F T A S H P M K Q L C D O J G I]
time 16797ms: Process B started using the CPU for 214ms burst [Q N F T A S H P M K Q L C D O J G I]
time 16961ms: Process E completed I/O; added to ready queue [Q N F T A S H P M K Q L C D O J G I E]
time 17011ms: Process B completed a CPU burst; 32 bursts to go [Q N F T A S H P M K Q L C D O J G I E]
time 17011ms: Process B switching out of CPU; blocking on I/O until time 17533ms [Q N F T A S H P M K Q L C D O J G I E]
time 17015ms: Process N started using the CPU for 976ms burst [Q F T A S H P M K Q L C D O J G I E]
time 17371ms: Process R completed I/O; added to ready queue [Q F T A S H P M K Q L C D O J G I E R]
time 17533ms: Process B completed I/O; added to ready queue [Q F T A S H P M K Q L C D O J G I E R B]
time 17991ms: Process N completed a CPU burst; 60 bursts to go [Q F T A S H P M K Q L C D O J G I E R B]
time 17991ms: Process N switching out of CPU; blocking on I/O until time 18104ms [Q F T A S H P M K Q L C D O J G I E R B]
time 17995ms: Process F started using the CPU for 64ms burst [Q T A S H P M K Q L C D O J G I E R B]
time 18059ms: Process F completed a CPU burst; 41 bursts to go [Q T A S H P M K Q L C D O J G I E R B]
time 18059ms: Process F switching out of CPU; blocking on I/O until time 19891ms [Q T A S H P M K Q L C D O J G I E R B]
time 18063ms: Process T started using the CPU for 756ms burst [Q A S H P M K Q L C D O J G I E R B]
time 18104ms: Process N completed I/O; added to ready queue [Q A S H P M K Q L C D O J G I E R B N]
time 18819ms: Process T completed a CPU burst; 14 bursts to go [Q A S H P M K Q L C D O J G I E R B N]
time 18819ms: Process T switching out of CPU; blocking on I/O until time 18904ms [Q A S H P M K Q L C D O J G I E R B N]
time 18823ms: Process A started using the CPU for 228ms burst [Q S H P M K Q L C D O J G I E R B N]
time 18904ms: Process T completed I/O; added to ready queue [Q S H P M K Q L C D O J G I E R B N T]
time 19051ms: Process A completed a CPU burst; 57 bursts to go [Q S H P M K Q L C D O J G I E R B N T]
time 19051ms: Process A switching out of CPU; blocking on I/O until time 19113ms [Q S H P M K Q L C D O J G I E R B N T]
time 19055ms: Process S started using the CPU for 152ms burst [Q H P M K Q L C D O J G I E R B N T]
time 19113ms: Process A completed I/O; added to ready queue [Q H P M K Q L C D O J G I E R B N T A]
time 19207ms: Process S completed a CPU burst; 50 bursts to go [Q H P M K Q L C D O J G I E R B N T A]
time 19207ms: Process S switching out of CPU; blocking on I/O until time 19347ms [Q H P M K Q L C D O J G I E R B N T A]
time 19211ms: Process H started using the CPU for 3ms burst [Q P M K Q L C D O J G I E R B N T A]
time 19214ms: Process H completed a CPU burst; 48 bursts to go [Q P M K Q L C D O J G I E R B N T A]
time 19214ms: Process H switching out of CPU; blocking on I/O until time 22916ms [Q P M K Q L C D O J G I E R B N T A]
time 19218ms: Process P started using the CPU for 16ms burst [Q M K Q L C D O J G I E R B N T A]
time 19234ms: Process P completed a CPU burst; 10 bursts to go [Q M K Q L C D O J G I E R B N T A]
time 19234ms: Process P switching out of CPU; blocking on I/O until time 19267ms [Q M K Q L C D O J G I E R B N T A]
time 19238ms: Process M started using the CPU for 140ms burst [Q K Q L C D O J G I E R B N T A]
time 19267ms: Process P completed I/O; added to ready queue [Q K Q L C D O J G I E R B N T A P]
time 19347ms: Process S completed I/O; added to ready queue [Q K Q L C D O J G I E R B N T A P S]
time 19378ms: Process M completed a CPU burst; 47 bursts to go [Q K Q L C D O J G I E R B N T A P S]
time 19378ms: Process M switching out of CPU; blocking on I/O until time 19527ms [Q K Q L C D O J G I E R B N T A P S]
time 19382ms: Process K started using the CPU for 860ms burst [Q Q L C D O J G I E R B N T A P S]
time 19527ms: Process M completed I/O; added to ready queue [Q Q L C D O J G I E R B N T A P S M]
time 19891ms: Process F completed I/O; added to ready queue [Q Q L C D O J G I E R B N T A P S M F]
time 20242ms: Process K completed a CPU burst; 58 bursts to go [Q Q L C D O J G I E R B N T A P S M F]
time 20242ms: Process K switching out of CPU; blocking on I/O until time 20335ms [Q Q L C D O J G I E R B N T A P S M F]
time 20246ms: Process Q started using the CPU for 508ms burst [Q L C D O J G I E R B N T A P S M F]
time 20335ms: Process K completed I/O; added to ready queue [Q L C D O J G I E R B N T A P S M F K]
time 20754ms: Process Q completed a CPU burst; 47 bursts to go [Q L C D O J G I E R B N T A P S M F K]
time 20754ms: Process Q switching out of CPU; blocking on I/O until time 20864ms [Q L C D O J G I E R B N T A P S M F K]
time 20758ms: Process L started using the CPU for 356ms burst [Q C D O J G I E R B N T A P S M F K]
time 20864ms: Process Q completed I/O; added to ready queue [Q C D O J G I E R B N T A P S M F K Q]
time 21114ms: Process L completed a CPU burst; 34 bursts to go [Q C D O J G I E R B N T A P S M F K Q]
time 21114ms: Process L switching out of CPU; blocking on I/O until time 21227ms [Q C D O J G I E R B N T A P S M F K Q]
time 21118ms: Process C started using the CPU for 50ms burst [Q D O J G I E R B N T A P S M F K Q]
time 21168ms: Process C completed a CPU burst; 10 bursts to go [Q D O J G I E R B N T A P S M F K Q]
time 21168ms: Process C switching out of CPU; blocking on I/O until time 22010ms [Q D O J G I E R B N T A P S M F K Q]
time 21172ms: Process D started using the CPU for 15ms burst [Q O J G I E R B N T A P S M F K Q]
time 21187ms: Process D completed a CPU burst; 45 bursts to go [Q O J G I E R B N T A P S M F K Q]
time 21187ms: Process D switching out of CPU; blocking on I/O until time 22049ms [Q O J G I E R B N T A P S M F K Q]
time 21191ms: Process O started using the CPU for 1124ms burst [Q J G I E R B N T A P S M F K Q]
time 21227ms: Process L completed I/O; added to ready queue [Q J G I E R B N T A P S M F K Q L]
time 22010ms: Process C completed I/O; added to ready queue [Q J G I E R B N T A P S M F K Q L C]
time 22049ms: Process D completed I/O; added to ready queue [Q J G I E R B N T A P S M F K Q L C D]
time 22315ms: Process O completed a CPU burst; 48 bursts to go [Q J G I E R B N T A P S M F K Q L C D]
time 22315ms: Process O switching out of CPU; blocking on I/O until time 22822ms [Q J G I E R B N T A P S M F K Q L C D]
time 22319ms: Process J started using the CPU for 1172ms burst [Q G I E R B N T A P S M F K Q L C D]
time 22822ms: Process O completed I/O; added to ready queue [Q G I E R B N T A P S M F K Q L C D O]
time 22916ms: Process H completed I/O; added to ready queue [Q G I E R B N T A P S M F K Q L C D O H]
time 23491ms: Process J completed a CPU burst; 31 bursts to go [Q G I E R B N T A P S M F K Q L C D O H]
time 23491ms: Process J switching out of CPU; blocking on I/O until time 23531ms [Q G I E R B N T A P S M F K Q L C D O H]
time 23495ms: Process G started using the CPU for 3ms burst [Q I E R B N T A P S M F K Q L C D O H]
time 23498ms: Process G completed a CPU burst; 50 bursts to go [Q I E R B N T A P S M F K Q L C D O H]
time 23498ms: Process G switching out of CPU; blocking on I/O until time 24870ms [Q I E R B N T A P S M F K Q L C D O H]
time 23502ms: Process I started using the CPU for 392ms burst [Q E R B N T A P S M F K Q L C D O H]
time 23531ms: Process J completed I/O; added to ready queue [Q E R B N T A P S M F K Q L C D O H J]
time 23894ms: Process I completed a CPU burst; 2 bursts to go [Q E R B N T A P S M F K Q L C D O H J]
time 23894ms: Process I switching out of CPU; blocking on I/O until time 23992ms [Q E R B N T A P S M F K Q L C D O H J]
time 23898ms: Process E started using the CPU for 51ms burst [Q R B N T A P S M F K Q L C D O H J]
time 23949ms: Process E completed a CPU burst; 56 bursts to go [Q R B N T A P S M F K Q L C D O H J]
time 23949ms: Process E switching out of CPU; blocking on I/O until time 24711ms [Q R B N T A P S M F K Q L C D O H J]
time 23953ms: Process R started using the CPU for 64ms burst [Q B N T A P S M F K Q L C D O H J]
time 23992ms: Process I completed I/O; added to ready queue [Q B N T A P S M F K Q L C D O H J I]
time 24017ms: Process R completed a CPU burst; 59 bursts to go [Q B N T A P S M F K Q L C D O H J I]
time 24017ms: Process R switching out of CPU; blocking on I/O until time 24105ms [Q B N T A P S M F K Q L C D O H J I]
time 24021ms: Process B started using the CPU for 10ms burst [Q N T A P S M F K Q L C D O H J I]
time 24031ms: Process B completed a CPU burst; 31 bursts to go [Q N T A P S M F K Q L C D O H J I]
time 24031ms: Process B switching out of CPU; blocking on I/O until time 25013ms [Q N T A P S M F K Q L C D O H J I]
time 24035ms: Process N started using the CPU for 352ms burst [Q T A P S M F K Q L C D O H J I]
time 24105ms: Process R completed I/O; added to ready queue [Q T A P S M F K Q L C D O H J I R]
time 24387ms: Process N completed a CPU burst; 59 bursts to go [Q T A P S M F K Q L C D O H J I R]
time 24387ms: Process N switching out of CPU; blocking on I/O until time 24415ms [Q T A P S M F K Q L C D O H J I R]
time 24391ms: Process T started using the CPU for 1420ms burst [Q A P S M F K Q L C D O H J I R]
time 24415ms: Process N completed I/O; added to ready queue [Q A P S M F K Q L C D O H J I R N]
time 24711ms: Process E completed I/O; added to ready queue [Q A P S M F K Q L C D O H J I R N E]
time 24870ms: Process G completed I/O; added to ready queue [Q A P S M F K Q L C D O H J I R N E G]
time 25013ms: Process B completed I/O; added to ready queue [Q A P S M F K Q L C D O H J I R N E G B]
time 25811ms: Process T completed a CPU burst; 13 bursts to go [Q A P S M F K Q L C D O H J I R N E G B]
time 25811ms: Process T switching out of CPU; blocking on I/O until time 25984ms [Q A P S M F K Q L C D O H J I R N E G B]
time 25815ms: Process A started using the CPU for 256ms burst [Q P S M F K Q L C D O H J I R N E G B]
time 25984ms: Process T completed I/O; added to ready queue [Q P S M F K Q L C D O H J I R N E G B T]
time 26071ms: Process A completed a CPU burst; 56 bursts to go [Q P S M F K Q L C D O H J I R N E G B T]
time 26071ms: Process A switching out of CPU; blocking on I/O until time 27443ms [Q P S M F K Q L C D O H J I R N E G B T]
time 26075ms: Process P started using the CPU for 728ms burst [Q S M F K Q L C D O H J I R N E G B T]
time 26803ms: Process P completed a CPU burst; 9 bursts to go [Q S M F K Q L C D O H J I R N E G B T]
time 26803ms: Process P switching out of CPU; blocking on I/O until time 26817ms [Q S M F K Q L C D O H J I R N E G B T]
time 26807ms: Process S started using the CPU for 1260ms burst [Q M F K Q L C D O H J I R N E G B T]
time 26817ms: Process P completed I/O; added to ready queue [Q M F K Q L C D O H J I R N E G B T P]
time 27443ms: Process A completed I/O; added to ready queue [Q M F K Q L C D O H J I R N E G B T P A]
time 28067ms: Process S completed a CPU burst; 49 bursts to go [Q M F K Q L C D O H J I R N E G B T P A]
time 28067ms: Process S switching out of CPU; blocking on I/O until time 28276ms [Q M F K Q L C D O H J I R N E G B T P A]
time 28071ms: Process M started using the CPU for 884ms burst [Q F K Q L C D O H J I R N E G B T P A]
time 28276ms: Process S completed I/O; added to ready queue [Q F K Q L C D O H J I R N E G B T P A S]
time 28955ms: Process M completed a CPU burst; 46 bursts to go [Q F K Q L C D O H J I R N E G B T P A S]
time 28955ms: Process M switching out of CPU; blocking on I/O until time 28998ms [Q F K Q L C D O H J I R N E G B T P A S]
time 28959ms: Process F started using the CPU for 15ms burst [Q K Q L C D O H J I R N E G B T P A S]
time 28974ms: Process F completed a CPU burst; 40 bursts to go [Q K Q L C D O H J I R N E G B T P A S]
time 28974ms: Process F switching out of CPU; blocking on I/O until time 29036ms [Q K Q L C D O H J I R N E G B T P A S]
time 28978ms: Process K started using the CPU for 448ms burst [Q Q L C D O H J I R N E G B T P A S]
time 28998ms: Process M completed I/O; added to ready queue [Q Q L C D O H J I R N E G B T P A S M]
time 29036ms: Process F completed I/O; added to ready queue [Q Q L C D O H J I R N E G B T P A S M F]
time 29426ms: Process K completed a CPU burst; 57 bursts to go [Q Q L C D O H J I R N E G B T P A S M F]
time 29426ms: Process K switching out of CPU; blocking on I/O until time 29521ms [Q Q L C D O H J I R N E G B T P A S M F]
time 29430ms: Process Q started using the CPU for 256ms burst [Q L C D O H J I R N E G B T P A S M F]
time 29521ms: Process K completed I/O; added to ready queue [Q L C D O H J I R N E G B T P A S M F K]
time 29686ms: Process Q completed a CPU burst; 46 bursts to go [Q L C D O H J I R N E G B T P A S M F K]
time 29686ms: Process Q switching out of CPU; blocking on I/O until time 29710ms [Q L C D O H J I R N E G B T P A S M F K]
time 29690ms: Process L started using the CPU for 424ms burst [Q C D O H J I R N E G B T P A S M F K]
time 29710ms: Process Q completed I/O; added to ready queue [Q C D O H J I R N E G B T P A S M F K Q]
time 30114ms: Process L completed a CPU burst; 33 bursts to go [Q C D O H J I R N E G B T P A S M F K Q]
time 30114ms: Process L switching out of CPU; blocking on I/O until time 30122ms [Q C D O H J I R N E G B T P A S M F K Q]
time 30118ms: Process C started using the CPU for 158ms burst [Q D O H J I R N E G B T P A S M F K Q]
time 30122ms: Process L completed I/O; added to ready queue [Q D O H J I R N E G B T P A S M F K Q L]
time 30276ms: Process C completed a CPU burst; 9 bursts to go [Q D O H J I R N E G B T P A S M F K Q L]
time 30276ms: Process C switching out of CPU; blocking on I/O until time 32528ms [Q D O H J I R N E G B T P A S M F K Q L]
time 30280ms: Process D started using the CPU for 41ms burst [Q O H J I R N E G B T P A S M F K Q L]
time 30321ms: Process D completed a CPU burst; 44 bursts to go [Q O H J I R N E G B T P A S M F K Q L]
time 30321ms: Process D switching out of CPU; blocking on I/O until time 32213ms [Q O H J I R N E G B T P A S M F K Q L]
time 30325ms: Process O started using the CPU for 180ms burst [Q H J I R N E G B T P A S M F K Q L]
time 30505ms: Process O completed a CPU burst; 47 bursts to go [Q H J I R N E G B T P A S M F K Q L]
time 30505ms: Process O switching out of CPU; blocking on I/O until time 30614ms [Q H J I R N E G B T P A S M F K Q L]
time 30509ms: Process H started using the CPU for 74ms burst [Q J I R N E G B T P A S M F K Q L]
time 30583ms: Process H completed a CPU burst; 47 bursts to go [Q J I R N E G B T P A S M F K Q L]
time 30583ms: Process H switching out of CPU; blocking on I/O until time 35225ms [Q J I R N E G B T P A S M F K Q L]
time 30587ms: Process J started using the CPU for 232ms burst [Q I R N E G B T P A S M F K Q L]
time 30614ms: Process O completed I/O; added to ready queue [Q I R N E G B T P A S M F K Q L O]
time 30819ms: Process J completed a CPU burst; 30 bursts to go [Q I R N E G B T P A S M F K Q L O]
time 30819ms: Process J switching out of CPU; blocking on I/O until time 30889ms [Q I R N E G B T P A S M F K Q L O]
time 30823ms: Process I started using the CPU for 672ms burst [Q R N E G B T P A S M F K Q L O]
time 30889ms: Process J completed I/O; added to ready queue [Q R N E G B T P A S M F K Q L O J]
time 31495ms: Process I completed a CPU burst; 1 burst to go [Q R N E G B T P A S M F K Q L O J]
time 31495ms: Process I switching out of CPU; blocking on I/O until time 31540ms [Q R N E G B T P A S M F K Q L O J]
time 31499ms: Process R started using the CPU for 860ms burst [Q N E G B T P A S M F K Q L O J]
time 31540ms: Process I completed I/O; added to ready queue [Q N E G B T P A S M F K Q L O J I]
time 32213ms: Process D completed I/O; added to ready queue [Q N E G B T P A S M F K Q L O J I D]
time 32359ms: Process R completed a CPU burst; 58 bursts to go [Q N E G B T P A S M F K Q L O J I D]
time 32359ms: Process R switching out of CPU; blocking on I/O until time 32482ms [Q N E G B T P A S M F K Q L O J I D]
time 32363ms: Process N started using the CPU for 1436ms burst [Q E G B T P A S M F K Q L O J I D]
time 32482ms: Process R completed I/O; added to ready queue [Q E G B T P A S M F K Q L O J I D R]
time 32528ms: Process C completed I/O; added to ready queue [Q E G B T P A S M F K Q L O J I D R C]
time 33799ms: Process N completed a CPU burst; 58 bursts to go [Q E G B T P A S M F K Q L O J I D R C]
time 33799ms: Process N switching out of CPU; blocking on I/O until time 34103ms [Q E G B T P A S M F K Q L O J I D R C]
time 33803ms: Process E started using the CPU for 154ms burst [Q G B T P A S M F K Q L O J I D R C]
time 33957ms: Process E completed a CPU burst; 55 bursts to go [Q G B T P A S M F K Q L O J I D R C]
time 33957ms: Process E switching out of CPU; blocking on I/O until time 34959ms [Q G B T P A S M F K Q L O J I D R C]
time 33961ms: Process G started using the CPU for 285ms burst [Q B T P A S M F K Q L O J I D R C]
time 34103ms: Process N completed I/O; added to ready queue [Q B T P A S M F K Q L O J I D R C N]
time 34246ms: Process G completed a CPU burst; 49 bursts to go [Q B T P A S M F K Q L O J I D R C N]
time 34246ms: Process G switching out of CPU; blocking on I/O until time 34528ms [Q B T P A S M F K Q L O J I D R C N]
time 34250ms: Process B started using the CPU for 50ms burst [Q T P A S M F K Q L O J I D R C N]
time 34300ms: Process B completed a CPU burst; 30 bursts to go [Q T P A S M F K Q L O J I D R C N]
time 34300ms: Process B switching out of CPU; blocking on I/O until time 34642ms [Q T P A S M F K Q L O J I D R C N]
time 34304ms: Process T started using the CPU for 1132ms burst [Q P A S M F K Q L O J I D R C N]
time 34528ms: Process G completed I/O; added to ready queue [Q P A S M F K Q L O J I D R C N G]
time 34642ms: Process B completed I/O; added to ready queue [Q P A S M F K Q L O J I D R C N G B]
time 34959ms: Process E completed I/O; added to ready queue [Q P A S M F K Q L O J I D R C N G B E]
time 35225ms: Process H completed I/O; added to ready queue [Q P A S M F K Q L O J I D R C N G B E H]
time 35436ms: Process T completed a CPU burst; 12 bursts to go [Q P A S M F K Q L O J I D R C N G B E H]
time 35436ms: Process T switching out of CPU; blocking on I/O until time 35486ms [Q P A S M F K Q L O J I D R C N G B E H]
time 35440ms: Process P started using the CPU for 180ms burst [Q A S M F K Q L O J I D R C N G B E H]
time 35486ms: Process T completed I/O; added to ready queue [Q A S M F K Q L O J I D R C N G B E H T]
time 35620ms: Process P completed a CPU burst; 8 bursts to go [Q A S M F K Q L O J I D R C N G B E H T]
time 35620ms: Process P switching out of CPU; blocking on I/O until time 35888ms [Q A S M F K Q L O J I D R C N G B E H T]
time 35624ms: Process A started using the CPU for 119ms burst [Q S M F K Q L O J I D R C N G B E H T]
time 35743ms: Process A completed a CPU burst; 55 bursts to go [Q S M F K Q L O J I D R C N G B E H T]
time 35743ms: Process A switching out of CPU; blocking on I/O until time 36515ms [Q S M F K Q L O J I D R C N G B E H T]
time 35747ms: Process S started using the CPU for 184ms burst [Q M F K Q L O J I D R C N G B E H T]
time 35888ms: Process P completed I/O; added to ready queue [Q M F K Q L O J I D R C N G B E H T P]
time 35931ms: Process S completed a CPU burst; 48 bursts to go [Q M F K Q L O J I D R C N G B E H T P]
time 35931ms: Process S switching out of CPU; blocking on I/O until time 36045ms [Q M F K Q L O J I D R C N G B E H T P]
time 35935ms: Process M started using the CPU for 2436ms burst [Q F K Q L O J I D R C N G B E H T P]
time 36045ms: Process S completed I/O; added to ready queue [Q F K Q L O J I D R C N G B E H T P S]
time 36515ms: Process A completed I/O; added to ready queue [Q F K Q L O J I D R C N G B E H T P S A]
time 38371ms: Process M completed a CPU burst; 45 bursts to go [Q F K Q L O J I D R C N G B E H T P S A]
time 38371ms: Process M switching out of CPU; blocking on I/O until time 38459ms [Q F K Q L O J I D R C N G B E H T P S A]
time 38375ms: Process F started using the CPU for 23ms burst [Q K Q L O J I D R C N G B E H T P S A]
time 38398ms: Process F completed a CPU burst; 39 bursts to go [Q K Q L O J I D R C N G B E H T P S A]
time 38398ms: Process F switching out of CPU; blocking on I/O until time 39140ms [Q K Q L O J I D R C N G B E H T P S A]
time 38402ms: Process K started using the CPU for 644ms burst [Q Q L O J I D R C N G B E H T P S A]
time 38459ms: Process M completed I/O; added to ready queue [Q Q L O J I D R C N G B E H T P S A M]
time 39046ms: Process K completed a CPU burst; 56 bursts to go [Q Q L O J I D R C N G B E H T P S A M]
time 39046ms: Process K switching out of CPU; blocking on I/O until time 39049ms [Q Q L O J I D R C N G B E H T P S A M]
time 39049ms: Process K completed I/O; added to ready queue [Q L O J I D R C N G B E H T P S A M K]
time 39050ms: Process Q started using the CPU for 88ms burst [Q L O J I D R C N G B E H T P S A M K]
time 39138ms: Process Q completed a CPU burst; 45 bursts to go [Q L O J I D R C N G B E H T P S A M K]
time 39138ms: Process Q switching out of CPU; blocking on I/O until time 39187ms [Q L O J I D R C N G B E H T P S A M K]
time 39140ms: Process F completed I/O; added to ready queue [Q L O J I D R C N G B E H T P S A M K F]
time 39142ms: Process L started using the CPU for 248ms burst [Q O J I D R C N G B E H T P S A M K F]
time 39187ms: Process Q completed I/O; added to ready queue [Q O J I D R C N G B E H T P S A M K F Q]
time 39390ms: Process L completed a CPU burst; 32 bursts to go [Q O J I D R C N G B E H T P S A M K F Q]
time 39390ms: Process L switching out of CPU; blocking on I/O until time 39892ms [Q O J I D R C N G B E H T P S A M K F Q]
time 39394ms: Process O started using the CPU for 1248ms burst [Q J I D R C N G B E H T P S A M K F Q]
time 39892ms: Process L completed I/O; added to ready queue [Q J I D R C N G B E H T P S A M K F Q L]
time 40642ms: Process O completed a CPU burst; 46 bursts to go [Q J I D R C N G B E H T P S A M K F Q L]
time 40642ms: Process O switching out of CPU; blocking on I/O until time 40706ms [Q J I D R C N G B E H T P S A M K F Q L]
time 40646ms: Process J started using the CPU for 380ms burst [Q I D R C N G B E H T P S A M K F Q L]
time 40706ms: Process O completed I/O; added to ready queue [Q I D R C N G B E H T P S A M K F Q L O]
time 41026ms: Process J completed a CPU burst; 29 bursts to go [Q I D R C N G B E H T P S A M K F Q L O]
time 41026ms: Process J switching out of CPU; blocking on I/O until time 41118ms [Q I D R C N G B E H T P S A M K F Q L O]
time 41030ms: Process I started using the CPU for 392ms burst [Q D R C N G B E H T P S A M K F Q L O]
time 41118ms: Process J completed I/O; added to ready queue [Q D R C N G B E H T P S A M K F Q L O J]
time 41422ms: Process I terminated [Q D R C N G B E H T P S A M K F Q L O J]
time 41426ms: Process D started using the CPU for 118ms burst [Q R C N G B E H T P S A M K F Q L O J]
time 41544ms: Process D completed a CPU burst; 43 bursts to go [Q R C N G B E H T P S A M K F Q L O J]
time 41544ms: Process D switching out of CPU; blocking on I/O until time 41996ms [Q R C N G B E H T P S A M K F Q L O J]
time 41548ms: Process R started using the CPU for 316ms burst [Q C N G B E H T P S A M K F Q L O J]
time 41864ms: Process R completed a CPU burst; 57 bursts to go [Q C N G B E H T P S A M K F Q L O J]
time 41864ms: Process R switching out of CPU; blocking on I/O until time 42001ms [Q C N G B E H T P S A M K F Q L O J]
time 41868ms: Process C started using the CPU for 75ms burst [Q N G B E H T P S A M K F Q L O J]
time 41943ms: Process C completed a CPU burst; 8 bursts to go [Q N G B E H T P S A M K F Q L O J]
time 41943ms: Process C switching out of CPU; blocking on I/O until time 42835ms [Q N G B E H T P S A M K F Q L O J]
time 41947ms: Process N started using the CPU for 296ms burst [Q G B E H T P S A M K F Q L O J]
time 41996ms: Process D completed I/O; added to ready queue [Q G B E H T P S A M K F Q L O J D]
time 42001ms: Process R completed I/O; added to ready queue [Q G B E H T P S A M K F Q L O J D R]
time 42243ms: Process N completed a CPU burst; 57 bursts to go [Q G B E H T P S A M K F Q L O J D R]
time 42243ms: Process N switching out of CPU; blocking on I/O until time 42285ms [Q G B E H T P S A M K F Q L O J D R]
time 42247ms: Process G started using the CPU for 70ms burst [Q B E H T P S A M K F Q L O J D R]
time 42285ms: Process N completed I/O; added to ready queue [Q B E H T P S A M K F Q L O J D R N]
time 42317ms: Process G completed a CPU burst; 48 bursts to go [Q B E H T P S A M K F Q L O J D R N]
time 42317ms: Process G switching out of CPU; blocking on I/O until time 42529ms [Q B E H T P S A M K F Q L O J D R N]
time 42321ms: Process B started using the CPU for 223ms burst [Q E H T P S A M K F Q L O J D R N]
time 42529ms: Process G completed I/O; added to ready queue [Q E H T P S A M K F Q L O J D R N G]
time 42544ms: Process B completed a CPU burst; 29 bursts to go [Q E H T P S A M K F Q L O J D R N G]
time 42544ms: Process B switching out of CPU; blocking on I/O until time 44426ms [Q E H T P S A M K F Q L O J D R N G]
time 42548ms: Process E started using the CPU for 105ms burst [Q H T P S A M K F Q L O J D R N G]
time 42653ms: Process E completed a CPU burst; 54 bursts to go [Q H T P S A M K F Q L O J D R N G]
time 42653ms: Process E switching out of CPU; blocking on I/O until time 42835ms [Q H T P S A M K F Q L O J D R N G]
time 42657ms: Process H started using the CPU for 133ms burst [Q T P S A M K F Q L O J D R N G]
time 42790ms: Process H completed a CPU burst; 46 bursts to go [Q T P S A M K F Q L O J D R N G]
time 42790ms: Process H switching out of CPU; blocking on I/O until time 44382ms [Q T P S A M K F Q L O J D R N G]
time 42794ms: Process T started using the CPU for 648ms burst [Q P S A M K F Q L O J D R N G]
time 42835ms: Process C completed I/O; added to ready queue [Q P S A M K F Q L O J D R N G C]
time 42835ms: Process E completed I/O; added to ready queue [Q P S A M K F Q L O J D R N G C E]
time 43442ms: Process T completed a CPU burst; 11 bursts to go [Q P S A M K F Q L O J D R N G C E]
time 43442ms: Process T switching out of CPU; blocking on I/O until time 43550ms [Q P S A M K F Q L O J D R N G C E]
time 43446ms: Process P started using the CPU for 220ms burst [Q S A M K F Q L O J D R N G C E]
time 43550ms: Process T completed I/O; added to ready queue [Q S A M K F Q L O J D R N G C E T]
time 43666ms: Process P completed a CPU burst; 7 bursts to go [Q S A M K F Q L O J D R N G C E T]
time 43666ms: Process P switching out of CPU; blocking on I/O until time 43718ms [Q S A M K F Q L O J D R N G C E T]
time 43670ms: Process S started using the CPU for 208ms burst [Q A M K F Q L O J D R N G C E T]
time 43718ms: Process P completed I/O; added to ready queue [Q A M K F Q L O J D R N G C E T P]
time 43878ms: Process S completed a CPU burst; 47 bursts to go [Q A M K F Q L O J D R N G C E T P]
time 43878ms: Process S switching out of CPU; blocking on I/O until time 44080ms [Q A M K F Q L O J D R N G C E T P]
time 43882ms: Process A started using the CPU for 7ms burst [Q M K F Q L O J D R N G C E T P]
time 43889ms: Process A completed a CPU burst; 54 bursts to go [Q M K F Q L O J D R N G C E T P]
time 43889ms: Process A switching out of CPU; blocking on I/O until time 45701ms [Q M K F Q L O J D R N G C E T P]
time 43893ms: Process M started using the CPU for 340ms burst [Q K F Q L O J D R N G C E T P]
time 44080ms: Process S completed I/O; added to ready queue [Q K F Q L O J D R N G C E T P S]
time 44233ms: Process M completed a CPU burst; 44 bursts to go [Q K F Q L O J D R N G C E T P S]
time 44233ms: Process M switching out of CPU; blocking on I/O until time 44312ms [Q K F Q L O J D R N G C E T P S]
time 44237ms: Process K started using the CPU for 312ms burst [Q F Q L O J D R N G C E T P S]
time 44312ms: Process M completed I/O; added to ready queue [Q F Q L O J D R N G C E T P S M]
time 44382ms: Process H completed I/O; added to ready queue [Q F Q L O J D R N G C E T P S M H]
time 44426ms: Process B completed I/O; added to ready queue [Q F Q L O J D R N G C E T P S M H B]
time 44549ms: Process K completed a CPU burst; 55 bursts to go [Q F Q L O J D R N G C E T P S M H B]
time 44549ms: Process K switching out of CPU; blocking on I/O until time 44698ms [Q F Q L O J D R N G C E T P S M H B]
time 44553ms: Process F started using the CPU for 54ms burst [Q Q L O J D R N G C E T P S M H B]
time 44607ms: Process F completed a CPU burst; 38 bursts to go [Q Q L O J D R N G C E T P S M H B]
time 44607ms: Process F switching out of CPU; blocking on I/O until time 44989ms [Q Q L O J D R N G C E T P S M H B]
time 44611ms: Process Q started using the CPU for 280ms burst [Q L O J D R N G C E T P S M H B]
time 44698ms: Process K completed I/O; added to ready queue [Q L O J D R N G C E T P S M H B K]
time 44891ms: Process Q completed a CPU burst; 44 bursts to go [Q L O J D R N G C E T P S M H B K]
time 44891ms: Process Q switching out of CPU; blocking on I/O until time 44910ms [Q L O J D R N G C E T P S M H B K]
time 44895ms: Process L started using the CPU for 576ms burst [Q O J D R N G C E T P S M H B K]
time 44910ms: Process Q completed I/O; added to ready queue [Q O J D R N G C E T P S M H B K Q]
time 44989ms: Process F completed I/O; added to ready queue [Q O J D R N G C E T P S M H B K Q F]
time 45471ms: Process L completed a CPU burst; 31 bursts to go [Q O J D R N G C E T P S M H B K Q F]
time 45471ms: Process L switching out of CPU; blocking on I/O until time 45521ms [Q O J D R N G C E T P S M H B K Q F]
time 45475ms: Process O started using the CPU for 596ms burst [Q J D R N G C E T P S M H B K Q F]
time 45521ms: Process L completed I/O; added to ready queue [Q J D R N G C E T P S M H B K Q F L]
time 45701ms: Process A completed I/O; added to ready queue [Q J D R N G C E T P S M H B K Q F L A]
time 46071ms: Process O completed a CPU burst; 45 bursts to go [Q J D R N G C E T P S M H B K Q F L A]
time 46071ms: Process O switching out of CPU; blocking on I/O until time 46075ms [Q J D R N G C E T P S M H B K Q F L A]
time 46075ms: Process J started using the CPU for 476ms burst [Q D R N G C E T P S M H B K Q F L A]
time 46075ms: Process O completed I/O; added to ready queue [Q D R N G C E T P S M H B K Q F L A O]
time 46551ms: Process J completed a CPU burst; 28 bursts to go [Q D R N G C E T P S M H B K Q F L A O]
time 46551ms: Process J switching out of CPU; blocking on I/O until time 46606ms [Q D R N G C E T P S M H B K Q F L A O]
time 46555ms: Process D started using the CPU for 55ms burst [Q R N G C E T P S M H B K Q F L A O]
time 46606ms: Process J completed I/O; added to ready queue [Q R N G C E T P S M H B K Q F L A O J]
time 46610ms: Process D completed a CPU burst; 42 bursts to go [Q R N G C E T P S M H B K Q F L A O J]
time 46610ms: Process D switching out of CPU; blocking on I/O until time 47272ms [Q R N G C E T P S M H B K Q F L A O J]
time 46614ms: Process R started using the CPU for 24ms burst [Q N G C E T P S M H B K Q F L A O J]
time 46638ms: Process R completed a CPU burst; 56 bursts to go [Q N G C E T P S M H B K Q F L A O J]
time 46638ms: Process R switching out of CPU; blocking on I/O until time 46720ms [Q N G C E T P S M H B K Q F L A O J]
time 46642ms: Process N started using the CPU for 620ms burst [Q G C E T P S M H B K Q F L A O J]
time 46720ms: Process R completed I/O; added to ready queue [Q G C E T P S M H B K Q F L A O J R]
time 47262ms: Process N completed a CPU burst; 56 bursts to go [Q G C E T P S M H B K Q F L A O J R]
time 47262ms: Process N switching out of CPU; blocking on I/O until time 47502ms [Q G C E T P S M H B K Q F L A O J R]
time 47266ms: Process G started using the CPU for 39ms burst [Q C E T P S M H B K Q F L A O J R]
time 47272ms: Process D completed I/O; added to ready queue [Q C E T P S M H B K Q F L A O J R D]
time 47305ms: Process G completed a CPU burst; 47 bursts to go [Q C E T P S M H B K Q F L A O J R D]
time 47305ms: Process G switching out of CPU; blocking on I/O until time 47417ms [Q C E T P S M H B K Q F L A O J R D]
time 47309ms: Process C started using the CPU for 5ms burst [Q E T P S M H B K Q F L A O J R D]
time 47314ms: Process C completed a CPU burst; 7 bursts to go [Q E T P S M H B K Q F L A O J R D]
time 47314ms: Process C switching out of CPU; blocking on I/O until time 48916ms [Q E T P S M H B K Q F L A O J R D]
time 47318ms: Process E started using the CPU for 39ms burst [Q T P S M H B K Q F L A O J R D]
time 47357ms: Process E completed a CPU burst; 53 bursts to go [Q T P S M H B K Q F L A O J R D]
time 47357ms: Process E switching out of CPU; blocking on I/O until time 48149ms [Q T P S M H B K Q F L A O J R D]
time 47361ms: Process T started using the CPU for 632ms burst [Q P S M H B K Q F L A O J R D]
time 47417ms: Process G completed I/O; added to ready queue [Q P S M H B K Q F L A O J R D G]
time 47502ms: Process N completed I/O; added to ready queue [Q P S M H B K Q F L A O J R D G N]
time 47993ms: Process T completed a CPU burst; 10 bursts to go [Q P S M H B K Q F L A O J R D G N]
time 47993ms: Process T switching out of CPU; blocking on I/O until time 48055ms [Q P S M H B K Q F L A O J R D G N]
time 47997ms: Process P started using the CPU for 244ms burst [Q S M H B K Q F L A O J R D G N]
time 48055ms: Process T completed I/O; added to ready queue [Q S M H B K Q F L A O J R D G N T]
time 48149ms: Process E completed I/O; added to ready queue [Q S M H B K Q F L A O J R D G N T E]
time 48241ms: Process P completed a CPU burst; 6 bursts to go [Q S M H B K Q F L A O J R D G N T E]
time 48241ms: Process P switching out of CPU; blocking on I/O until time 48310ms [Q S M H B K Q F L A O J R D G N T E]
time 48245ms: Process S started using the CPU for 732ms burst [Q M H B K Q F L A O J R D G N T E]
time 48310ms: Process P completed I/O; added to ready queue [Q M H B K Q F L A O J R D G N T E P]
time 48916ms: Process C completed I/O; added to ready queue [Q M H B K Q F L A O J R D G N T E P C]
time 48977ms: Process S completed a CPU burst; 46 bursts to go [Q M H B K Q F L A O J R D G N T E P C]
time 48977ms: Process S switching out of CPU; blocking on I/O until time 48987ms [Q M H B K Q F L A O J R D G N T E P C]
time 48981ms: Process M started using the CPU for 376ms burst [Q H B K Q F L A O J R D G N T E P C]
time 48987ms: Process S completed I/O; added to ready queue [Q H B K Q F L A O J R D G N T E P C S]
time 49357ms: Process M completed a CPU burst; 43 bursts to go [Q H B K Q F L A O J R D G N T E P C S]
time 49357ms: Process M switching out of CPU; blocking on I/O until time 49576ms [Q H B K Q F L A O J R D G N T E P C S]
time 49361ms: Process H started using the CPU for 24ms burst [Q B K Q F L A O J R D G N T E P C S]
time 49385ms: Process H completed a CPU burst; 45 bursts to go [Q B K Q F L A O J R D G N T E P C S]
time 49385ms: Process H switching out of CPU; blocking on I/O until time 52217ms [Q B K Q F L A O J R D G N T E P C S]
time 49389ms: Process B started using the CPU for 37ms burst [Q K Q F L A O J R D G N T E P C S]
time 49426ms: Process B completed a CPU burst; 28 bursts to go [Q K Q F L A O J R D G N T E P C S]
time 49426ms: Process B switching out of CPU; blocking on I/O until time 51118ms [Q K Q F L A O J R D G N T E P C S]
time 49430ms: Process K started using the CPU for 244ms burst [Q Q F L A O J R D G N T E P C S]
time 49576ms: Process M completed I/O; added to ready queue [Q Q F L A O J R D G N T E P C S M]
time 49674ms: Process K completed a CPU burst; 54 bursts to go [Q Q F L A O J R D G N T E P C S M]
time 49674ms: Process K switching out of CPU; blocking on I/O until time 49687ms [Q Q F L A O J R D G N T E P C S M]
time 49678ms: Process Q started using the CPU for 948ms burst [Q F L A O J R D G N T E P C S M]
time 49687ms: Process K completed I/O; added to ready queue [Q F L A O J R D G N T E P C S M K]
time 50626ms: Process Q completed a CPU burst; 43 bursts to go [Q F L A O J R D G N T E P C S M K]
time 50626ms: Process Q switching out of CPU; blocking on I/O until time 50725ms [Q F L A O J R D G N T E P C S M K]
time 50630ms: Process F started using the CPU for 123ms burst [Q L A O J R D G N T E P C S M K]
time 50725ms: Process Q completed I/O; added to ready queue [Q L A O J R D G N T E P C S M K Q]
time 50753ms: Process F completed a CPU burst; 37 bursts to go [Q L A O J R D G N T E P C S M K Q]
time 50753ms: Process F switching out of CPU; blocking on I/O until time 51225ms [Q L A O J R D G N T E P C S M K Q]
time 50757ms: Process L started using the CPU for 968ms burst [Q A O J R D G N T E P C S M K Q]
time 51118ms: Process B completed I/O; added to ready queue [Q A O J R D G N T E P C S M K Q B]
time 51225ms: Process F completed I/O; added to ready queue [Q A O J R D G N T E P C S M K Q B F]
time 51725ms: Process L completed a CPU burst; 30 bursts to go [Q A O J R D G N T E P C S M K Q B F]
time 51725ms: Process L switching out of CPU; blocking on I/O until time 51744ms [Q A O J R D G N T E P C S M K Q B F]
time 51729ms: Process A started using the CPU for 46ms burst [Q O J R D G N T E P C S M K Q B F]
time 51744ms: Process L completed I/O; added to ready queue [Q O J R D G N T E P C S M K Q B F L]
time 51775ms: Process A completed a CPU burst; 53 bursts to go [Q O J R D G N T E P C S M K Q B F L]
time 51775ms: Process A switching out of CPU; blocking on I/O until time 57477ms [Q O J R D G N T E P C S M K Q B F L]
time 51779ms: Process O started using the CPU for 232ms burst [Q J R D G N T E P C S M K Q B F L]
time 52011ms: Process O completed a CPU burst; 44 bursts to go [Q J R D G N T E P C S M K Q B F L]
time 52011ms: Process O switching out of CPU; blocking on I/O until time 52039ms [Q J R D G N T E P C S M K Q B F L]
time 52015ms: Process J started using the CPU for 184ms burst [Q R D G N T E P C S M K Q B F L]
time 52039ms: Process O completed I/O; added to ready queue [Q R D G N T E P C S M K Q B F L O]
time 52199ms: Process J completed a CPU burst; 27 bursts to go [Q R D G N T E P C S M K Q B F L O]
time 52199ms: Process J switching out of CPU; blocking on I/O until time 52331ms [Q R D G N T E P C S M K Q B F L O]
time 52203ms: Process R started using the CPU for 24ms burst [Q D G N T E P C S M K Q B F L O]
time 52217ms: Process H completed I/O; added to ready queue [Q D G N T E P C S M K Q B F L O H]
time 52227ms: Process R completed a CPU burst; 55 bursts to go [Q D G N T E P C S M K Q B F L O H]
time 52227ms: Process R switching out of CPU; blocking on I/O until time 52324ms [Q D G N T E P C S M K Q B F L O H]
time 52231ms: Process D started using the CPU for 101ms burst [Q G N T E P C S M K Q B F L O H]
time 52324ms: Process R completed I/O; added to ready queue [Q G N T E P C S M K Q B F L O H R]
time 52331ms: Process J completed I/O; added to ready queue [Q G N T E P C S M K Q B F L O H R J]
time 52332ms: Process D completed a CPU burst; 41 bursts to go [Q G N T E P C S M K Q B F L O H R J]
time 52332ms: Process D switching out of CPU; blocking on I/O until time 53804ms [Q G N T E P C S M K Q B F L O H R J]
time 52336ms: Process G started using the CPU for 205ms burst [Q N T E P C S M K Q B F L O H R J]
time 52541ms: Process G completed a CPU burst; 46 bursts to go [Q N T E P C S M K Q B F L O H R J]
time 52541ms: Process G switching out of CPU; blocking on I/O until time 53273ms [Q N T E P C S M K Q B F L O H R J]
time 52545ms: Process N started using the CPU for 448ms burst [Q T E P C S M K Q B F L O H R J]
time 52993ms: Process N completed a CPU burst; 55 bursts to go [Q T E P C S M K Q B F L O H R J]
time 52993ms: Process N switching out of CPU; blocking on I/O until time 53155ms [Q T E P C S M K Q B F L O H R J]
time 52997ms: Process T started using the CPU for 248ms burst [Q E P C S M K Q B F L O H R J]
time 53155ms: Process N completed I/O; added to ready queue [Q E P C S M K Q B F L O H R J N]
time 53245ms: Process T completed a CPU burst; 9 bursts to go [Q E P C S M K Q B F L O H R J N]
time 53245ms: Process T switching out of CPU; blocking on I/O until time 53430ms [Q E P C S M K Q B F L O H R J N]
time 53249ms: Process E started using the CPU for 40ms burst [Q P C S M K Q B F L O H R J N]
time 53273ms: Process G completed I/O; added to ready queue [Q P C S M K Q B F L O H R J N G]
time 53289ms: Process E completed a CPU burst; 52 bursts to go [Q P C S M K Q B F L O H R J N G]
time 53289ms: Process E switching out of CPU; blocking on I/O until time 54451ms [Q P C S M K Q B F L O H R J N G]
time 53293ms: Process P started using the CPU for 48ms burst [Q C S M K Q B F L O H R J N G]
time 53341ms: Process P completed a CPU burst; 5 bursts to go [Q C S M K Q B F L O H R J N G]
time 53341ms: Process P switching out of CPU; blocking on I/O until time 53360ms [Q C S M K Q B F L O H R J N G]
time 53345ms: Process C started using the CPU for 312ms burst [Q S M K Q B F L O H R J N G]
time 53360ms: Process P completed I/O; added to ready queue [Q S M K Q B F L O H R J N G P]
time 53430ms: Process T completed I/O; added to ready queue [Q S M K Q B F L O H R J N G P T]
time 53657ms: Process C completed a CPU burst; 6 bursts to go [Q S M K Q B F L O H R J N G P T]
time 53657ms: Process C switching out of CPU; blocking on I/O until time 53899ms [Q S M K Q B F L O H R J N G P T]
time 53661ms: Process S started using the CPU for 660ms burst [Q M K Q B F L O H R J N G P T]
time 53804ms: Process D completed I/O; added to ready queue [Q M K Q B F L O H R J N G P T D]
time 53899ms: Process C completed I/O; added to ready queue [Q M K Q B F L O H R J N G P T D C]
time 54321ms: Process S completed a CPU burst; 45 bursts to go [Q M K Q B F L O H R J N G P T D C]
time 54321ms: Process S switching out of CPU; blocking on I/O until time 54433ms [Q M K Q B F L O H R J N G P T D C]
time 54325ms: Process M started using the CPU for 272ms burst [Q K Q B F L O H R J N G P T D C]
time 54433ms: Process S completed I/O; added to ready queue [Q K Q B F L O H R J N G P T D C S]
time 54451ms: Process E completed I/O; added to ready queue [Q K Q B F L O H R J N G P T D C S E]
time 54597ms: Process M completed a CPU burst; 42 bursts to go [Q K Q B F L O H R J N G P T D C S E]
time 54597ms: Process M switching out of CPU; blocking on I/O until time 54636ms [Q K Q B F L O H R J N G P T D C S E]
time 54601ms: Process K started using the CPU for 52ms burst [Q Q B F L O H R J N G P T D C S E]
time 54636ms: Process M completed I/O; added to ready queue [Q Q B F L O H R J N G P T D C S E M]
time 54653ms: Process K completed a CPU burst; 53 bursts to go [Q Q B F L O H R J N G P T D C S E M]
time 54653ms: Process K switching out of CPU; blocking on I/O until time 54728ms [Q Q B F L O H R J N G P T D C S E M]
time 54657ms: Process Q started using the CPU for 1588ms burst [Q B F L O H R J N G P T D C S E M]
time 54728ms: Process K completed I/O; added to ready queue [Q B F L O H R J N G P T D C S E M K]
time 56245ms: Process Q completed a CPU burst; 42 bursts to go [Q B F L O H R J N G P T D C S E M K]
time 56245ms: Process Q switching out of CPU; blocking on I/O until time 56295ms [Q B F L O H R J N G P T D C S E M K]
time 56249ms: Process B started using the CPU for 89ms burst [Q F L O H R J N G P T D C S E M K]
time 56295ms: Process Q completed I/O; added to ready queue [Q F L O H R J N G P T D C S E M K Q]
time 56338ms: Process B completed a CPU burst; 27 bursts to go [Q F L O H R J N G P T D C S E M K Q]
time 56338ms: Process B switching out of CPU; blocking on I/O until time 56410ms [Q F L O H R J N G P T D C S E M K Q]
time 56342ms: Process F started using the CPU for 78ms burst [Q L O H R J N G P T D C S E M K Q]
time 56410ms: Process B completed I/O; added to ready queue [Q L O H R J N G P T D C S E M K Q B]
time 56420ms: Process F completed a CPU burst; 36 bursts to go [Q L O H R J N G P T D C S E M K Q B]
time 56420ms: Process F switching out of CPU; blocking on I/O until time 57642ms [Q L O H R J N G P T D C S E M K Q B]
time 56424ms: Process L started using the CPU for 48ms burst [Q O H R J N G P T D C S E M K Q B]
time 56472ms: Process L completed a CPU burst; 29 bursts to go [Q O H R J N G P T D C S E M K Q B]
time 56472ms: Process L switching out of CPU; blocking on I/O until time 56480ms [Q O H R J N G P T D C S E M K Q B]
time 56476ms: Process O started using the CPU for 416ms burst [Q H R J N G P T D C S E M K Q B]
time 56480ms: Process L completed I/O; added to ready queue [Q H R J N G P T D C S E M K Q B L]
time 56892ms: Process O completed a CPU burst; 43 bursts to go [Q H R J N G P T D C S E M K Q B L]
time 56892ms: Process O switching out of CPU; blocking on I/O until time 57022ms [Q H R J N G P T D C S E M K Q B L]
time 56896ms: Process H started using the CPU for 11ms burst [Q R J N G P T D C S E M K Q B L]
time 56907ms: Process H completed a CPU burst; 44 bursts to go [Q R J N G P T D C S E M K Q B L]
time 56907ms: Process H switching out of CPU; blocking on I/O until time 57059ms [Q R J N G P T D C S E M K Q B L]
time 56911ms: Process R started using the CPU for 44ms burst [Q J N G P T D C S E M K Q B L]
time 56955ms: Process R completed a CPU burst; 54 bursts to go [Q J N G P T D C S E M K Q B L]
time 56955ms: Process R switching out of CPU; blocking on I/O until time 57057ms [Q J N G P T D C S E M K Q B L]
time 56959ms: Process J started using the CPU for 896ms burst [Q N G P T D C S E M K Q B L]
time 57022ms: Process O completed I/O; added to ready queue [Q N G P T D C S E M K Q B L O]
time 57057ms: Process R completed I/O; added to ready queue [Q N G P T D C S E M K Q B L O R]
time 57059ms: Process H completed I/O; added to ready queue [Q N G P T D C S E M K Q B L O R H]
time 57477ms: Process A completed I/O; added to ready queue [Q N G P T D C S E M K Q B L O R H A]
time 57642ms: Process F completed I/O; added to ready queue [Q N G P T D C S E M K Q B L O R H A F]
time 57855ms: Process J completed a CPU burst; 26 bursts to go [Q N G P T D C S E M K Q B L O R H A F]
time 57855ms: Process J switching out of CPU; blocking on I/O until time 57979ms [Q N G P T D C S E M K Q B L O R H A F]
time 57859ms: Process N started using the CPU for 36ms burst [Q G P T D C S E M K Q B L O R H A F]
time 57895ms: Process N completed a CPU burst; 54 bursts to go [Q G P T D C S E M K Q B L O R H A F]
time 57895ms: Process N switching out of CPU; blocking on I/O until time 58005ms [Q G P T D C S E M K Q B L O R H A F]
time 57899ms: Process G started using the CPU for 47ms burst [Q P T D C S E M K Q B L O R H A F]
time 57946ms: Process G completed a CPU burst; 45 bursts to go [Q P T D C S E M K Q B L O R H A F]
time 57946ms: Process G switching out of CPU; blocking on I/O until time 58518ms [Q P T D C S E M K Q B L O R H A F]
time 57950ms: Process P started using the CPU for 124ms burst [Q T D C S E M K Q B L O R H A F]
time 57979ms: Process J completed I/O; added to ready queue [Q T D C S E M K Q B L O R H A F J]
time 58005ms: Process N completed I/O; added to ready queue [Q T D C S E M K Q B L O R H A F J N]
time 58074ms: Process P completed a CPU burst; 4 bursts to go [Q T D C S E M K Q B L O R H A F J N]
time 58074ms: Process P switching out of CPU; blocking on I/O until time 58084ms [Q T D C S E M K Q B L O R H A F J N]
time 58078ms: Process T started using the CPU for 596ms burst [Q D C S E M K Q B L O R H A F J N]
time 58084ms: Process P completed I/O; added to ready queue [Q D C S E M K Q B L O R H A F J N P]
time 58518ms: Process G completed I/O; added to ready queue [Q D C S E M K Q B L O R H A F J N P G]
time 58674ms: Process T completed a CPU burst; 8 bursts to go [Q D C S E M K Q B L O R H A F J N P G]
time 58674ms: Process T switching out of CPU; blocking on I/O until time 59347ms [Q D C S E M K Q B L O R H A F J N P G]
time 58678ms: Process D started using the CPU for 47ms burst [Q C S E M K Q B L O R H A F J N P G]
time 58725ms: Process D completed a CPU burst; 40 bursts to go [Q C S E M K Q B L O R H A F J N P G]
time 58725ms: Process D switching out of CPU; blocking on I/O until time 58937ms [Q C S E M K Q B L O R H A F J N P G]
time 58729ms: Process C started using the CPU for 69ms burst [Q S E M K Q B L O R H A F J N P G]
time 58798ms: Process C completed a CPU burst; 5 bursts to go [Q S E M K Q B L O R H A F J N P G]
time 58798ms: Process C switching out of CPU; blocking on I/O until time 60110ms [Q S E M K Q B L O R H A F J N P G]
time 58802ms: Process S started using the CPU for 204ms burst [Q E M K Q B L O R H A F J N P G]
time 58937ms: Process D completed I/O; added to ready queue [Q E M K Q B L O R H A F J N P G D]
time 59006ms: Process S completed a CPU burst; 44 bursts to go [Q E M K Q B L O R H A F J N P G D]
time 59006ms: Process S switching out of CPU; blocking on I/O until time 59053ms [Q E M K Q B L O R H A F J N P G D]
time 59010ms: Process E started using the CPU for 4ms burst [Q M K Q B L O R H A F J N P G D]
time 59014ms: Process E completed a CPU burst; 51 bursts to go [Q M K Q B L O R H A F J N P G D]
time 59014ms: Process E switching out of CPU; blocking on I/O until time 60796ms [Q M K Q B L O R H A F J N P G D]
time 59018ms: Process M started using the CPU for 684ms burst [Q K Q B L O R H A F J N P G D]
time 59053ms: Process S completed I/O; added to ready queue [Q K Q B L O R H A F J N P G D S]
time 59347ms: Process T completed I/O; added to ready queue [Q K Q B L O R H A F J N P G D S T]
time 59702ms: Process M completed a CPU burst; 41 bursts to go [Q K Q B L O R H A F J N P G D S T]
time 59702ms: Process M switching out of CPU; blocking on I/O until time 59775ms [Q K Q B L O R H A F J N P G D S T]
time 59706ms: Process K started using the CPU for 440ms burst [Q Q B L O R H A F J N P G D S T]
time 59775ms: Process M completed I/O; added to ready queue [Q Q B L O R H A F J N P G D S T M]
time 60110ms: Process C completed I/O; added to ready queue [Q Q B L O R H A F J N P G D S T M C]
time 60146ms: Process K completed a CPU burst; 52 bursts to go [Q Q B L O R H A F J N P G D S T M C]
time 60146ms: Process K switching out of CPU; blocking on I/O until time 60153ms [Q Q B L O R H A F J N P G D S T M C]
time 60150ms: Process Q started using the CPU for 504ms burst [Q B L O R H A F J N P G D S T M C]
time 60153ms: Process K completed I/O; added to ready queue [Q B L O R H A F J N P G D S T M C K]
time 60654ms: Process Q completed a CPU burst; 41 bursts to go [Q B L O R H A F J N P G D S T M C K]
time 60654ms: Process Q switching out of CPU; blocking on I/O until time 61108ms [Q B L O R H A F J N P G D S T M C K]
time 60658ms: Process B started using the CPU for 152ms burst [Q L O R H A F J N P G D S T M C K]
time 60796ms: Process E completed I/O; added to ready queue [Q L O R H A F J N P G D S T M C K E]
time 60810ms: Process B completed a CPU burst; 26 bursts to go [Q L O R H A F J N P G D S T M C K E]
time 60810ms: Process B switching out of CPU; blocking on I/O until time 61972ms [Q L O R H A F J N P G D S T M C K E]
time 60814ms: Process L started using the CPU for 120ms burst [Q O R H A F J N P G D S T M C K E]
time 60934ms: Process L completed a CPU burst; 28 bursts to go [Q O R H A F J N P G D S T M C K E]
time 60934ms: Process L switching out of CPU; blocking on I/O until time 60953ms [Q O R H A F J N P G D S T M C K E]
time 60938ms: Process O started using the CPU for 144ms burst [Q R H A F J N P G D S T M C K E]
time 60953ms: Process L completed I/O; added to ready queue [Q R H A F J N P G D S T M C K E L]
time 61082ms: Process O completed a CPU burst; 42 bursts to go [Q R H A F J N P G D S T M C K E L]
time 61082ms: Process O switching out of CPU; blocking on I/O until time 61167ms [Q R H A F J N P G D S T M C K E L]
time 61086ms: Process R started using the CPU for 196ms burst [Q H A F J N P G D S T M C K E L]
time 61108ms: Process Q completed I/O; added to ready queue [Q H A F J N P G D S T M C K E L Q]
time 61167ms: Process O completed I/O; added to ready queue [Q H A F J N P G D S T M C K E L Q O]
time 61282ms: Process R completed a CPU burst; 53 bursts to go [Q H A F J N P G D S T M C K E L Q O]
time 61282ms: Process R switching out of CPU; blocking on I/O until time 61366ms [Q H A F J N P G D S T M C K E L Q O]
time 61286ms: Process H started using the CPU for 140ms burst [Q A F J N P G D S T M C K E L Q O]
time 61366ms: Process R completed I/O; added to ready queue [Q A F J N P G D S T M C K E L Q O R]
time 61426ms: Process H completed a CPU burst; 43 bursts to go [Q A F J N P G D S T M C K E L Q O R]
time 61426ms: Process H switching out of CPU; blocking on I/O until time 62248ms [Q A F J N P G D S T M C K E L Q O R]
time 61430ms: Process A started using the CPU for 67ms burst [Q F J N P G D S T M C K E L Q O R]
time 61497ms: Process A completed a CPU burst; 52 bursts to go [Q F J N P G D S T M C K E L Q O R]
time 61497ms: Process A switching out of CPU; blocking on I/O until time 62019ms [Q F J N P G D S T M C K E L Q O R]
time 61501ms: Process F started using the CPU for 65ms burst [Q J N P G D S T M C K E L Q O R]
time 61566ms: Process F completed a CPU burst; 35 bursts to go [Q J N P G D S T M C K E L Q O R]
time 61566ms: Process F switching out of CPU; blocking on I/O until time 63398ms [Q J N P G D S T M C K E L Q O R]
time 61570ms: Process J started using the CPU for 896ms burst [Q N P G D S T M C K E L Q O R]
time 61972ms: Process B completed I/O; added to ready queue [Q N P G D S T M C K E L Q O R B]
time 62019ms: Process A completed I/O; added to ready queue [Q N P G D S T M C K E L Q O R B A]
time 62248ms: Process H completed I/O; added to ready queue [Q N P G D S T M C K E L Q O R B A H]
time 62466ms: Process J completed a CPU burst; 25 bursts to go [Q N P G D S T M C K E L Q O R B A H]
time 62466ms: Process J switching out of CPU; blocking on I/O until time 62618ms [Q N P G D S T M C K E L Q O R B A H]
time 62470ms: Process N started using the CPU for 904ms burst [Q P G D S T M C K E L Q O R B A H]
time 62618ms: Process J completed I/O; added to ready queue [Q P G D S T M C K E L Q O R B A H J]
time 63374ms: Process N completed a CPU burst; 53 bursts to go [Q P G D S T M C K E L Q O R B A H J]
time 63374ms: Process N switching out of CPU; blocking on I/O until time 63459ms [Q P G D S T M C K E L Q O R B A H J]
time 63378ms: Process P started using the CPU for 112ms burst [Q G D S T M C K E L Q O R B A H J]
time 63398ms: Process F completed I/O; added to ready queue [Q G D S T M C K E L Q O R B A H J F]
time 63459ms: Process N completed I/O; added to ready queue [Q G D S T M C K E L Q O R B A H J F N]
time 63490ms: Process P completed a CPU burst; 3 bursts to go [Q G D S T M C K E L Q O R B A H J F N]
time 63490ms: Process P switching out of CPU; blocking on I/O until time 63545ms [Q G D S T M C K E L Q O R B A H J F N]
time 63494ms: Process G started using the CPU for 66ms burst [Q D S T M C K E L Q O R B A H J F N]
time 63545ms: Process P completed I/O; added to ready queue [Q D S T M C K E L Q O R B A H J F N P]
time 63560ms: Process G completed a CPU burst; 44 bursts to go [Q D S T M C K E L Q O R B A H J F N P]
time 63560ms: Process G switching out of CPU; blocking on I/O until time 67802ms [Q D S T M C K E L Q O R B A H J F N P]
time 63564ms: Process D started using the CPU for 17ms burst [Q S T M C K E L Q O R B A H J F N P]
time 63581ms: Process D completed a CPU burst; 39 bursts to go [Q S T M C K E L Q O R B A H J F N P]
time 63581ms: Process D switching out of CPU; blocking on I/O until time 66863ms [Q S T M C K E L Q O R B A H J F N P]
time 63585ms: Process S started using the CPU for 32ms burst [Q T M C K E L Q O R B A H J F N P]
time 63617ms: Process S completed a CPU burst; 43 bursts to go [Q T M C K E L Q O R B A H J F N P]
time 63617ms: Process S switching out of CPU; blocking on I/O until time 63629ms [Q T M C K E L Q O R B A H J F N P]
time 63621ms: Process T started using the CPU for 172ms burst [Q M C K E L Q O R B A H J F N P]
time 63629ms: Process S completed I/O; added to ready queue [Q M C K E L Q O R B A H J F N P S]
time 63793ms: Process T completed a CPU burst; 7 bursts to go [Q M C K E L Q O R B A H J F N P S]
time 63793ms: Process T switching out of CPU; blocking on I/O until time 63861ms [Q M C K E L Q O R B A H J F N P S]
time 63797ms: Process M started using the CPU for 1000ms burst [Q C K E L Q O R B A H J F N P S]
time 63861ms: Process T completed I/O; added to ready queue [Q C K E L Q O R B A H J F N P S T]
time 64797ms: Process M completed a CPU burst; 40 bursts to go [Q C K E L Q O R B A H J F N P S T]
time 64797ms: Process M switching out of CPU; blocking on I/O until time 64862ms [Q C K E L Q O R B A H J F N P S T]
time 64801ms: Process C started using the CPU for 201ms burst [Q K E L Q O R B A H J F N P S T]
time 64862ms: Process M completed I/O; added to ready queue [Q K E L Q O R B A H J F N P S T M]
time 65002ms: Process C completed a CPU burst; 4 bursts to go [Q K E L Q O R B A H J F N P S T M]
time 65002ms: Process C switching out of CPU; blocking on I/O until time 65494ms [Q K E L Q O R B A H J F N P S T M]
time 65006ms: Process K started using the CPU for 128ms burst [Q E L Q O R B A H J F N P S T M]
time 65134ms: Process K completed a CPU burst; 51 bursts to go [Q E L Q O R B A H J F N P S T M]
time 65134ms: Process K switching out of CPU; blocking on I/O until time 65318ms [Q E L Q O R B A H J F N P S T M]
time 65138ms: Process E started using the CPU for 49ms burst [Q L Q O R B A H J F N P S T M]
time 65187ms: Process E completed a CPU burst; 50 bursts to go [Q L Q O R B A H J F N P S T M]
time 65187ms: Process E switching out of CPU; blocking on I/O until time 69389ms [Q L Q O R B A H J F N P S T M]
time 65191ms: Process L started using the CPU for 284ms burst [Q Q O R B A H J F N P S T M]
time 65318ms: Process K completed I/O; added to ready queue [Q Q O R B A H J F N P S T M K]
time 65475ms: Process L completed a CPU burst; 27 bursts to go [Q Q O R B A H J F N P S T M K]
time 65475ms: Process L switching out of CPU; blocking on I/O until time 65580ms [Q Q O R B A H J F N P S T M K]
time 65479ms: Process Q started using the CPU for 192ms burst [Q O R B A H J F N P S T M K]
time 65494ms: Process C completed I/O; added to ready queue [Q O R B A H J F N P S T M K C]
time 65580ms: Process L completed I/O; added to ready queue [Q O R B A H J F N P S T M K C L]
time 65671ms: Process Q completed a CPU burst; 40 bursts to go [Q O R B A H J F N P S T M K C L]
time 65671ms: Process Q switching out of CPU; blocking on I/O until time 65955ms [Q O R B A H J F N P S T M K C L]
time 65675ms: Process O started using the CPU for 128ms burst [Q R B A H J F N P S T M K C L]
time 65803ms: Process O completed a CPU burst; 41 bursts to go [Q R B A H J F N P S T M K C L]
time 65803ms: Process O switching out of CPU; blocking on I/O until time 65902ms [Q R B A H J F N P S T M K C L]
time 65807ms: Process R started using the CPU for 280ms burst [Q B A H J F N P S T M K C L]
time 65902ms: Process O completed I/O; added to ready queue [Q B A H J F N P S T M K C L O]
time 65955ms: Process Q completed I/O; added to ready queue [Q B A H J F N P S T M K C L O Q]
time 66087ms: Process R completed a CPU burst; 52 bursts to go [Q B A H J F N P S T M K C L O Q]
time 66087ms: Process R switching out of CPU; blocking on I/O until time 66235ms [Q B A H J F N P S T M K C L O Q]
time 66091ms: Process B started using the CPU for 151ms burst [Q A H J F N P S T M K C L O Q]
time 66235ms: Process R completed I/O; added to ready queue [Q A H J F N P S T M K C L O Q R]
time 66242ms: Process B completed a CPU burst; 25 bursts to go [Q A H J F N P S T M K C L O Q R]
time 66242ms: Process B switching out of CPU; blocking on I/O until time 67754ms [Q A H J F N P S T M K C L O Q R]
time 66246ms: Process A started using the CPU for 103ms burst [Q H J F N P S T M K C L O Q R]
time 66349ms: Process A completed a CPU burst; 51 bursts to go [Q H J F N P S T M K C L O Q R]
time 66349ms: Process A switching out of CPU; blocking on I/O until time 67181ms [Q H J F N P S T M K C L O Q R]
time 66353ms: Process H started using the CPU for 317ms burst [Q J F N P S T M K C L O Q R]
time 66670ms: Process H completed a CPU burst; 42 bursts to go [Q J F N P S T M K C L O Q R]
time 66670ms: Process H switching out of CPU; blocking on I/O until time 66732ms [Q J F N P S T M K C L O Q R]
time 66674ms: Process J started using the CPU for 384ms burst [Q F N P S T M K C L O Q R]
time 66732ms: Process H completed I/O; added to ready queue [Q F N P S T M K C L O Q R H]
time 66863ms: Process D completed I/O; added to ready queue [Q F N P S T M K C L O Q R H D]
time 67058ms: Process J completed a CPU burst; 24 bursts to go [Q F N P S T M K C L O Q R H D]
time 67058ms: Process J switching out of CPU; blocking on I/O until time 67122ms [Q F N P S T M K C L O Q R H D]
time 67062ms: Process F started using the CPU for 39ms burst [Q N P S T M K C L O Q R H D]
time 67101ms: Process F completed a CPU burst; 34 bursts to go [Q N P S T M K C L O Q R H D]
time 67101ms: Process F switching out of CPU; blocking on I/O until time 69293ms [Q N P S T M K C L O Q R H D]
time 67105ms: Process N started using the CPU for 176ms burst [Q P S T M K C L O Q R H D]
time 67122ms: Process J completed I/O; added to ready queue [Q P S T M K C L O Q R H D J]
time 67181ms: Process A completed I/O; added to ready queue [Q P S T M K C L O Q R H D J A]
time 67281ms: Process N completed a CPU burst; 52 bursts to go [Q P S T M K C L O Q R H D J A]
time 67281ms: Process N switching out of CPU; blocking on I/O until time 67300ms [Q P S T M K C L O Q R H D J A]
time 67285ms: Process P started using the CPU for 112ms burst [Q S T M K C L O Q R H D J A]
time 67300ms: Process N completed I/O; added to ready queue [Q S T M K C L O Q R H D J A N]
time 67397ms: Process P completed a CPU burst; 2 bursts to go [Q S T M K C L O Q R H D J A N]
time 67397ms: Process P switching out of CPU; blocking on I/O until time 67742ms [Q S T M K C L O Q R H D J A N]
time 67401ms: Process S started using the CPU for 188ms burst [Q T M K C L O Q R H D J A N]
time 67589ms: Process S completed a CPU burst; 42 bursts to go [Q T M K C L O Q R H D J A N]
time 67589ms: Process S switching out of CPU; blocking on I/O until time 67674ms [Q T M K C L O Q R H D J A N]
time 67593ms: Process T started using the CPU for 672ms burst [Q M K C L O Q R H D J A N]
time 67674ms: Process S completed I/O; added to ready queue [Q M K C L O Q R H D J A N S]
time 67742ms: Process P completed I/O; added to ready queue [Q M K C L O Q R H D J A N S P]
time 67754ms: Process B completed I/O; added to ready queue [Q M K C L O Q R H D J A N S P B]
time 67802ms: Process G completed I/O; added to ready queue [Q M K C L O Q R H D J A N S P B G]
time 68265ms: Process T completed a CPU burst; 6 bursts to go [Q M K C L O Q R H D J A N S P B G]
time 68265ms: Process T switching out of CPU; blocking on I/O until time 68714ms [Q M K C L O Q R H D J A N S P B G]
time 68269ms: Process M started using the CPU for 440ms burst [Q K C L O Q R H D J A N S P B G]
time 68709ms: Process M completed a CPU burst; 39 bursts to go [Q K C L O Q R H D J A N S P B G]
time 68709ms: Process M switching out of CPU; blocking on I/O until time 68762ms [Q K C L O Q R H D J A N S P B G]
time 68713ms: Process K started using the CPU for 28ms burst [Q C L O Q R H D J A N S P B G]
time 68714ms: Process T completed I/O; added to ready queue [Q C L O Q R H D J A N S P B G T]
time 68741ms: Process K completed a CPU burst; 50 bursts to go [Q C L O Q R H D J A N S P B G T]
time 68741ms: Process K switching out of CPU; blocking on I/O until time 68764ms [Q C L O Q R H D J A N S P B G T]
time 68745ms: Process C started using the CPU for 17ms burst [Q L O Q R H D J A N S P B G T]
time 68762ms: Process C completed a CPU burst; 3 bursts to go [Q L O Q R H D J A N S P B G T]
time 68762ms: Process C switching out of CPU; blocking on I/O until time 69114ms [Q L O Q R H D J A N S P B G T]
time 68762ms: Process M completed I/O; added to ready queue [Q L O Q R H D J A N S P B G T M]
time 68764ms: Process K completed I/O; added to ready queue [Q L O Q R H D J A N S P B G T M K]
time 68766ms: Process L started using the CPU for 780ms burst [Q O Q R H D J A N S P B G T M K]
time 69114ms: Process C completed I/O; added to ready queue [Q O Q R H D J A N S P B G T M K C]
time 69293ms: Process F completed I/O; added to ready queue [Q O Q R H D J A N S P B G T M K C F]
time 69389ms: Process E completed I/O; added to ready queue [Q O Q R H D J A N S P B G T M K C F E]
time 69546ms: Process L completed a CPU burst; 26 bursts to go [Q O Q R H D J A N S P B G T M K C F E]
time 69546ms: Process L switching out of CPU; blocking on I/O until time 69585ms [Q O Q R H D J A N S P B G T M K C F E]
time 69550ms: Process O started using the CPU for 620ms burst [Q Q R H D J A N S P B G T M K C F E]
time 69585ms: Process L completed I/O; added to ready queue [Q Q R H D J A N S P B G T M K C F E L]
time 70170ms: Process O completed a CPU burst; 40 bursts to go [Q Q R H D J A N S P B G T M K C F E L]
time 70170ms: Process O switching out of CPU; blocking on I/O until time 70347ms [Q Q R H D J A N S P B G T M K C F E L]
time 70174ms: Process Q started using the CPU for 264ms burst [Q R H D J A N S P B G T M K C F E L]
time 70347ms: Process O completed I/O; added to ready queue [Q R H D J A N S P B G T M K C F E L O]
time 70438ms: Process Q completed a CPU burst; 39 bursts to go [Q R H D J A N S P B G T M K C F E L O]
time 70438ms: Process Q switching out of CPU; blocking on I/O until time 70787ms [Q R H D J A N S P B G T M K C F E L O]
time 70442ms: Process R started using the CPU for 28ms burst [Q H D J A N S P B G T M K C F E L O]
time 70470ms: Process R completed a CPU burst; 51 bursts to go [Q H D J A N S P B G T M K C F E L O]
time 70470ms: Process R switching out of CPU; blocking on I/O until time 71053ms [Q H D J A N S P B G T M K C F E L O]
time 70474ms: Process H started using the CPU for 104ms burst [Q D J A N S P B G T M K C F E L O]
time 70578ms: Process H completed a CPU burst; 41 bursts to go [Q D J A N S P B G T M K C F E L O]
time 70578ms: Process H switching out of CPU; blocking on I/O until time 71720ms [Q D J A N S P B G T M K C F E L O]
time 70582ms: Process D started using the CPU for 66ms burst [Q J A N S P B G T M K C F E L O]
time 70648ms: Process D completed a CPU burst; 38 bursts to go [Q J A N S P B G T M K C F E L O]
time 70648ms: Process D switching out of CPU; blocking on I/O until time 70980ms [Q J A N S P B G T M K C F E L O]
time 70652ms: Process J started using the CPU for 372ms burst [Q A N S P B G T M K C F E L O]
time 70787ms: Process Q completed I/O; added to ready queue [Q A N S P B G T M K C F E L O Q]
time 70980ms: Process D completed I/O; added to ready queue [Q A N S P B G T M K C F E L O Q D]
time 71024ms: Process J completed a CPU burst; 23 bursts to go [Q A N S P B G T M K C F E L O Q D]
time 71024ms: Process J switching out of CPU; blocking on I/O until time 71096ms [Q A N S P B G T M K C F E L O Q D]
time 71028ms: Process A started using the CPU for 31ms burst [Q N S P B G T M K C F E L O Q D]
time 71053ms: Process R completed I/O; added to ready queue [Q N S P B G T M K C F E L O Q D R]
time 71059ms: Process A completed a CPU burst; 50 bursts to go [Q N S P B G T M K C F E L O Q D R]
time 71059ms: Process A switching out of CPU; blocking on I/O until time 74541ms [Q N S P B G T M K C F E L O Q D R]
time 71063ms: Process N started using the CPU for 224ms burst [Q S P B G T M K C F E L O Q D R]
time 71096ms: Process J completed I/O; added to ready queue [Q S P B G T M K C F E L O Q D R J]
time 71287ms: Process N completed a CPU burst; 51 bursts to go [Q S P B G T M K C F E L O Q D R J]
time 71287ms: Process N switching out of CPU; blocking on I/O until time 71295ms [Q S P B G T M K C F E L O Q D R J]
time 71291ms: Process S started using the CPU for 172ms burst [Q P B G T M K C F E L O Q D R J]
time 71295ms: Process N completed I/O; added to ready queue [Q P B G T M K C F E L O Q D R J N]
time 71463ms: Process S completed a CPU burst; 41 bursts to go [Q P B G T M K C F E L O Q D R J N]
time 71463ms: Process S switching out of CPU; blocking on I/O until time 71518ms [Q P B G T M K C F E L O Q D R J N]
time 71467ms: Process P started using the CPU for 380ms burst [Q B G T M K C F E L O Q D R J N]
time 71518ms: Process S completed I/O; added to ready queue [Q B G T M K C F E L O Q D R J N S]
time 71720ms: Process H completed I/O; added to ready queue [Q B G T M K C F E L O Q D R J N S H]
time 71847ms: Process P completed a CPU burst; 1 burst to go [Q B G T M K C F E L O Q D R J N S H]
time 71847ms: Process P switching out of CPU; blocking on I/O until time 71899ms [Q B G T M K C F E L O Q D R J N S H]
time 71851ms: Process B started using the CPU for 95ms burst [Q G T M K C F E L O Q D R J N S H]
time 71899ms: Process P completed I/O; added to ready queue [Q G T M K C F E L O Q D R J N S H P]
time 71946ms: Process B completed a CPU burst; 24 bursts to go [Q G T M K C F E L O Q D R J N S H P]
time 71946ms: Process B switching out of CPU; blocking on I/O until time 72898ms [Q G T M K C F E L O Q D R J N S H P]
time 71950ms: Process G started using the CPU for 44ms burst [Q T M K C F E L O Q D R J N S H P]
time 71994ms: Process G completed a CPU burst; 43 bursts to go [Q T M K C F E L O Q D R J N S H P]
time 71994ms: Process G switching out of CPU; blocking on I/O until time 73676ms [Q T M K C F E L O Q D R J N S H P]
time 71998ms: Process T started using the CPU for 420ms burst [Q M K C F E L O Q D R J N S H P]
time 72418ms: Process T completed a CPU burst; 5 bursts to go [Q M K C F E L O Q D R J N S H P]
time 72418ms: Process T switching out of CPU; blocking on I/O until time 72453ms [Q M K C F E L O Q D R J N S H P]
time 72422ms: Process M started using the CPU for 896ms burst [Q K C F E L O Q D R J N S H P]
time 72453ms: Process T completed I/O; added to ready queue [Q K C F E L O Q D R J N S H P T]
time 72898ms: Process B completed I/O; added to ready queue [Q K C F E L O Q D R J N S H P T B]
time 73318ms: Process M completed a CPU burst; 38 bursts to go [Q K C F E L O Q D R J N S H P T B]
time 73318ms: Process M switching out of CPU; blocking on I/O until time 73477ms [Q K C F E L O Q D R J N S H P T B]
time 73322ms: Process K started using the CPU for 288ms burst [Q C F E L O Q D R J N S H P T B]
time 73477ms: Process M completed I/O; added to ready queue [Q C F E L O Q D R J N S H P T B M]
time 73610ms: Process K completed a CPU burst; 49 bursts to go [Q C F E L O Q D R J N S H P T B M]
time 73610ms: Process K switching out of CPU; blocking on I/O until time 73678ms [Q C F E L O Q D R J N S H P T B M]
time 73614ms: Process C started using the CPU for 112ms burst [Q F E L O Q D R J N S H P T B M]
time 73676ms: Process G completed I/O; added to ready queue [Q F E L O Q D R J N S H P T B M G]
time 73678ms: Process K completed I/O; added to ready queue [Q F E L O Q D R J N S H P T B M G K]
time 73726ms: Process C completed a CPU burst; 2 bursts to go [Q F E L O Q D R J N S H P T B M G K]
time 73726ms: Process C switching out of CPU; blocking on I/O until time 74228ms [Q F E L O Q D R J N S H P T B M G K]
time 73730ms: Process F started using the CPU for 34ms burst [Q E L O Q D R J N S H P T B M G K]
time 73764ms: Process F completed a CPU burst; 33 bursts to go [Q E L O Q D R J N S H P T B M G K]
time 73764ms: Process F switching out of CPU; blocking on I/O until time 74996ms [Q E L O Q D R J N S H P T B M G K]
time 73768ms: Process E started using the CPU for 32ms burst [Q L O Q D R J N S H P T B M G K]
time 73800ms: Process E completed a CPU burst; 49 bursts to go [Q L O Q D R J N S H P T B M G K]
time 73800ms: Process E switching out of CPU; blocking on I/O until time 74152ms [Q L O Q D R J N S H P T B M G K]
time 73804ms: Process L started using the CPU for 168ms burst [Q O Q D R J N S H P T B M G K]
time 73972ms: Process L completed a CPU burst; 25 bursts to go [Q O Q D R J N S H P T B M G K]
time 73972ms: Process L switching out of CPU; blocking on I/O until time 74011ms [Q O Q D R J N S H P T B M G K]
time 73976ms: Process O started using the CPU for 176ms burst [Q Q D R J N S H P T B M G K]
time 74011ms: Process L completed I/O; added to ready queue [Q Q D R J N S H P T B M G K L]
time 74152ms: Process O completed a CPU burst; 39 bursts to go [Q Q D R J N S H P T B M G K L]
time 74152ms: Process O switching out of CPU; blocking on I/O until time 74271ms [Q Q D R J N S H P T B M G K L]
time 74152ms: Process E completed I/O; added to ready queue [Q Q D R J N S H P T B M G K L E]
time 74156ms: Process Q started using the CPU for 120ms burst [Q D R J N S H P T B M G K L E]
time 74228ms: Process C completed I/O; added to ready queue [Q D R J N S H P T B M G K L E C]
time 74271ms: Process O completed I/O; added to ready queue [Q D R J N S H P T B M G K L E C O]
time 74276ms: Process Q completed a CPU burst; 38 bursts to go [Q D R J N S H P T B M G K L E C O]
time 74276ms: Process Q switching out of CPU; blocking on I/O until time 74415ms [Q D R J N S H P T B M G K L E C O]
time 74280ms: Process D started using the CPU for 12ms burst [Q R J N S H P T B M G K L E C O]
time 74292ms: Process D completed a CPU burst; 37 bursts to go [Q R J N S H P T B M G K L E C O]
time 74292ms: Process D switching out of CPU; blocking on I/O until time 76244ms [Q R J N S H P T B M G K L E C O]
time 74296ms: Process R started using the CPU for 668ms burst [Q J N S H P T B M G K L E C O]
time 74415ms: Process Q completed I/O; added to ready queue [Q J N S H P T B M G K L E C O Q]
time 74541ms: Process A completed I/O; added to ready queue [Q J N S H P T B M G K L E C O Q A]
time 74964ms: Process R completed a CPU burst; 50 bursts to go [Q J N S H P T B M G K L E C O Q A]
time 74964ms: Process R switching out of CPU; blocking on I/O until time 75011ms [Q J N S H P T B M G K L E C O Q A]
time 74968ms: Process J started using the CPU for 40ms burst [Q N S H P T B M G K L E C O Q A]
time 74996ms: Process F completed I/O; added to ready queue [Q N S H P T B M G K L E C O Q A F]
time 75008ms: Process J completed a CPU burst; 22 bursts to go [Q N S H P T B M G K L E C O Q A F]
time 75008ms: Process J switching out of CPU; blocking on I/O until time 75196ms [Q N S H P T B M G K L E C O Q A F]
time 75011ms: Process R completed I/O; added to ready queue [Q S H P T B M G K L E C O Q A F R]
time 75012ms: Process N started using the CPU for 488ms burst [Q S H P T B M G K L E C O Q A F R]
time 75196ms: Process J completed I/O; added to ready queue [Q S H P T B M G K L E C O Q A F R J]
time 75500ms: Process N completed a CPU burst; 50 bursts to go [Q S H P T B M G K L E C O Q A F R J]
time 75500ms: Process N switching out of CPU; blocking on I/O until time 76104ms [Q S H P T B M G K L E C O Q A F R J]
time 75504ms: Process S started using the CPU for 200ms burst [Q H P T B M G K L E C O Q A F R J]
time 75704ms: Process S completed a CPU burst; 40 bursts to go [Q H P T B M G K L E C O Q A F R J]
time 75704ms: Process S switching out of CPU; blocking on I/O until time 75809ms [Q H P T B M G K L E C O Q A F R J]
time 75708ms: Process H started using the CPU for 126ms burst [Q P T B M G K L E C O Q A F R J]
time 75809ms: Process S completed I/O; added to ready queue [Q P T B M G K L E C O Q A F R J S]
time 75834ms: Process H completed a CPU burst; 40 bursts to go [Q P T B M G K L E C O Q A F R J S]
time 75834ms: Process H switching out of CPU; blocking on I/O until time 77196ms [Q P T B M G K L E C O Q A F R J S]
time 75838ms: Process P started using the CPU for 12ms burst [Q T B M G K L E C O Q A F R J S]
time 75850ms: Process P terminated [Q T B M G K L E C O Q A F R J S]
time 75854ms: Process T started using the CPU for 240ms burst [Q B M G K L E C O Q A F R J S]
time 76094ms: Process T completed a CPU burst; 4 bursts to go [Q B M G K L E C O Q A F R J S]
time 76094ms: Process T switching out of CPU; blocking on I/O until time 76241ms [Q B M G K L E C O Q A F R J S]
time 76098ms: Process B started using the CPU for 2ms burst [Q M G K L E C O Q A F R J S]
time 76100ms: Process B completed a CPU burst; 23 bursts to go [Q M G K L E C O Q A F R J S]
time 76100ms: Process B switching out of CPU; blocking on I/O until time 77532ms [Q M G K L E C O Q A F R J S]
time 76104ms: Process M started using the CPU for 856ms burst [Q G K L E C O Q A F R J S]
time 76104ms: Process N completed I/O; added to ready queue [Q G K L E C O Q A F R J S N]
time 76241ms: Process T completed I/O; added to ready queue [Q G K L E C O Q A F R J S N T]
time 76244ms: Process D completed I/O; added to ready queue [Q G K L E C O Q A F R J S N T D]
time 76960ms: Process M completed a CPU burst; 37 bursts to go [Q G K L E C O Q A F R J S N T D]
time 76960ms: Process M switching out of CPU; blocking on I/O until time 76963ms [Q G K L E C O Q A F R J S N T D]
time 76963ms: Process M completed I/O; added to ready queue [Q K L E C O Q A F R J S N T D M]
time 76964ms: Process G started using the CPU for 26ms burst [Q K L E C O Q A F R J S N T D M]
time 76990ms: Process G completed a CPU burst; 42 bursts to go [Q K L E C O Q A F R J S N T D M]
time 76990ms: Process G switching out of CPU; blocking on I/O until time 77062ms [Q K L E C O Q A F R J S N T D M]
time 76994ms: Process K started using the CPU for 12ms burst [Q L E C O Q A F R J S N T D M]
time 77006ms: Process K completed a CPU burst; 48 bursts to go [Q L E C O Q A F R J S N T D M]
time 77006ms: Process K switching out of CPU; blocking on I/O until time 77084ms [Q L E C O Q A F R J S N T D M]
time 77010ms: Process L started using the CPU for 1192ms burst [Q E C O Q A F R J S N T D M]
time 77062ms: Process G completed I/O; added to ready queue [Q E C O Q A F R J S N T D M G]
time 77084ms: Process K completed I/O; added to ready queue [Q E C O Q A F R J S N T D M G K]
time 77196ms: Process H completed I/O; added to ready queue [Q E C O Q A F R J S N T D M G K H]
