<<< PROJECT PART I -- process set (n=3) with 1 CPU-bound process >>>
I/O-bound process A: arrival time 136ms; 17 CPU bursts
I/O-bound process B: arrival time 929ms; 12 CPU bursts
CPU-bound process C: arrival time 26ms; 60 CPU bursts

<<< PROJECT PART II -- t_cs=4ms; alpha=0.75; t_slice=256ms >>>
time 0ms: Simulator started for FCFS [Q <empty>]
time 26ms: Process C arrived; added to ready queue [Q C]
time 28ms: Process C started using the CPU for 2920ms burst [Q <empty>]
time 136ms: Process A arrived; added to ready queue [Q A]
time 929ms: Process B arrived; added to ready queue [Q A B]
time 2948ms: Process C completed a CPU burst; 59 bursts to go [Q A B]
time 2948ms: Process C switching out of CPU; blocking on I/O until time 3318ms [Q A B]
time 2952ms: Process A started using the CPU for 1330ms burst [Q B]
time 3318ms: Process C completed I/O; added to ready queue [Q B C]
time 4282ms: Process A completed a CPU burst; 16 bursts to go [Q B C]
time 4282ms: Process A switching out of CPU; blocking on I/O until time 10024ms [Q B C]
time 4286ms: Process B started using the CPU for 2438ms burst [Q C]
time 6724ms: Process B completed a CPU burst; 11 bursts to go [Q C]
time 6724ms: Process B switching out of CPU; blocking on I/O until time 7606ms [Q C]
time 6728ms: Process C started using the CPU for 2328ms burst [Q <empty>]
time 7606ms: Process B completed I/O; added to ready queue [Q B]
time 9056ms: Process C completed a CPU burst; 58 bursts to go [Q B]
time 9056ms: Process C switching out of CPU; blocking on I/O until time 12170ms [Q B]
time 9060ms: Process B started using the CPU for 1173ms burst [Q <empty>]
time 10024ms: Process A completed I/O; added to ready queue [Q A]
time 10233ms: Process B completed a CPU burst; 10 bursts to go [Q A]
time 10233ms: Process B switching out of CPU; blocking on I/O until time 10775ms [Q A]
time 10237ms: Process A started using the CPU for 735ms burst [Q <empty>]
time 10775ms: Process B completed I/O; added to ready queue [Q B]
time 10972ms: Process A completed a CPU burst; 15 bursts to go [Q B]
time 10972ms: Process A switching out of CPU; blocking on I/O until time 11634ms [Q B]
time 10976ms: Process B started using the CPU for 492ms burst [Q <empty>]
time 11468ms: Process B completed a CPU burst; 9 bursts to go [Q <empty>]
time 11468ms: Process B switching out of CPU; blocking on I/O until time 23820ms [Q <empty>]
time 11634ms: Process A completed I/O; added to ready queue [Q A]
time 11636ms: Process A started using the CPU for 24ms burst [Q <empty>]
time 11660ms: Process A completed a CPU burst; 14 bursts to go [Q <empty>]
time 11660ms: Process A switching out of CPU; blocking on I/O until time 12112ms [Q <empty>]
time 12112ms: Process A completed I/O; added to ready queue [Q A]
time 12114ms: Process A started using the CPU for 683ms burst [Q <empty>]
time 12170ms: Process C completed I/O; added to ready queue [Q C]
time 12797ms: Process A completed a CPU burst; 13 bursts to go [Q C]
time 12797ms: Process A switching out of CPU; blocking on I/O until time 14649ms [Q C]
time 12801ms: Process C started using the CPU for 1180ms burst [Q <empty>]
time 13981ms: Process C completed a CPU burst; 57 bursts to go [Q <empty>]
time 13981ms: Process C switching out of CPU; blocking on I/O until time 15303ms [Q <empty>]
time 14649ms: Process A completed I/O; added to ready queue [Q A]
time 14651ms: Process A started using the CPU for 1100ms burst [Q <empty>]
time 15303ms: Process C completed I/O; added to ready queue [Q C]
time 15751ms: Process A completed a CPU burst; 12 bursts to go [Q C]
time 15751ms: Process A switching out of CPU; blocking on I/O until time 29973ms [Q C]
time 15755ms: Process C started using the CPU for 11336ms burst [Q <empty>]
time 23820ms: Process B completed I/O; added to ready queue [Q B]
time 27091ms: Process C completed a CPU burst; 56 bursts to go [Q B]
time 27091ms: Process C switching out of CPU; blocking on I/O until time 27769ms [Q B]
time 27095ms: Process B started using the CPU for 2670ms burst [Q <empty>]
time 27769ms: Process C completed I/O; added to ready queue [Q C]
time 29765ms: Process B completed a CPU burst; 8 bursts to go [Q C]
time 29765ms: Process B switching out of CPU; blocking on I/O until time 34827ms [Q C]
time 29769ms: Process C started using the CPU for 5132ms burst [Q <empty>]
time 29973ms: Process A completed I/O; added to ready queue [Q A]
time 34827ms: Process B completed I/O; added to ready queue [Q A B]
time 34901ms: Process C completed a CPU burst; 55 bursts to go [Q A B]
time 34901ms: Process C switching out of CPU; blocking on I/O until time 36750ms [Q A B]
time 34905ms: Process A started using the CPU for 1000ms burst [Q B]
time 35905ms: Process A completed a CPU burst; 11 bursts to go [Q B]
time 35905ms: Process A switching out of CPU; blocking on I/O until time 42857ms [Q B]
time 35909ms: Process B started using the CPU for 610ms burst [Q <empty>]
time 36519ms: Process B completed a CPU burst; 7 bursts to go [Q <empty>]
time 36519ms: Process B switching out of CPU; blocking on I/O until time 62341ms [Q <empty>]
time 36750ms: Process C completed I/O; added to ready queue [Q C]
time 36752ms: Process C started using the CPU for 2896ms burst [Q <empty>]
time 39648ms: Process C completed a CPU burst; 54 bursts to go [Q <empty>]
time 39648ms: Process C switching out of CPU; blocking on I/O until time 42968ms [Q <empty>]
time 42857ms: Process A completed I/O; added to ready queue [Q A]
time 42859ms: Process A started using the CPU for 1166ms burst [Q <empty>]
time 42968ms: Process C completed I/O; added to ready queue [Q C]
time 44025ms: Process A completed a CPU burst; 10 bursts to go [Q C]
time 44025ms: Process A switching out of CPU; blocking on I/O until time 49317ms [Q C]
time 44029ms: Process C started using the CPU for 160ms burst [Q <empty>]
time 44189ms: Process C completed a CPU burst; 53 bursts to go [Q <empty>]
time 44189ms: Process C switching out of CPU; blocking on I/O until time 45986ms [Q <empty>]
time 45986ms: Process C completed I/O; added to ready queue [Q C]
time 45988ms: Process C started using the CPU for 2968ms burst [Q <empty>]
time 48956ms: Process C completed a CPU burst; 52 bursts to go [Q <empty>]
time 48956ms: Process C switching out of CPU; blocking on I/O until time 50001ms [Q <empty>]
time 49317ms: Process A completed I/O; added to ready queue [Q A]
time 49319ms: Process A started using the CPU for 1561ms burst [Q <empty>]
time 50001ms: Process C completed I/O; added to ready queue [Q C]
time 50880ms: Process A completed a CPU burst; 9 bursts to go [Q C]
time 50880ms: Process A switching out of CPU; blocking on I/O until time 53702ms [Q C]
time 50884ms: Process C started using the CPU for 4428ms burst [Q <empty>]
time 53702ms: Process A completed I/O; added to ready queue [Q A]
time 55312ms: Process C completed a CPU burst; 51 bursts to go [Q A]
time 55312ms: Process C switching out of CPU; blocking on I/O until time 56591ms [Q A]
time 55316ms: Process A started using the CPU for 149ms burst [Q <empty>]
time 55465ms: Process A completed a CPU burst; 8 bursts to go [Q <empty>]
time 55465ms: Process A switching out of CPU; blocking on I/O until time 56187ms [Q <empty>]
time 56187ms: Process A completed I/O; added to ready queue [Q A]
time 56189ms: Process A started using the CPU for 388ms burst [Q <empty>]
time 56577ms: Process A completed a CPU burst; 7 bursts to go [Q <empty>]
time 56577ms: Process A switching out of CPU; blocking on I/O until time 63949ms [Q <empty>]
time 56591ms: Process C completed I/O; added to ready queue [Q C]
time 56593ms: Process C started using the CPU for 7280ms burst [Q <empty>]
time 62341ms: Process B completed I/O; added to ready queue [Q B]
time 63873ms: Process C completed a CPU burst; 50 bursts to go [Q B]
time 63873ms: Process C switching out of CPU; blocking on I/O until time 64492ms [Q B]
time 63877ms: Process B started using the CPU for 1452ms burst [Q <empty>]
time 63949ms: Process A completed I/O; added to ready queue [Q A]
time 64492ms: Process C completed I/O; added to ready queue [Q A C]
time 65329ms: Process B completed a CPU burst; 6 bursts to go [Q A C]
time 65329ms: Process B switching out of CPU; blocking on I/O until time 69981ms [Q A C]
time 65333ms: Process A started using the CPU for 34ms burst [Q C]
time 65367ms: Process A completed a CPU burst; 6 bursts to go [Q C]
time 65367ms: Process A switching out of CPU; blocking on I/O until time 74909ms [Q C]
time 65371ms: Process C started using the CPU for 7180ms burst [Q <empty>]
time 69981ms: Process B completed I/O; added to ready queue [Q B]
time 72551ms: Process C completed a CPU burst; 49 bursts to go [Q B]
time 72551ms: Process C switching out of CPU; blocking on I/O until time 74099ms [Q B]
time 72555ms: Process B started using the CPU for 878ms burst [Q <empty>]
time 73433ms: Process B completed a CPU burst; 5 bursts to go [Q <empty>]
time 73433ms: Process B switching out of CPU; blocking on I/O until time 85415ms [Q <empty>]
time 74099ms: Process C completed I/O; added to ready queue [Q C]
time 74101ms: Process C started using the CPU for 8120ms burst [Q <empty>]
time 74909ms: Process A completed I/O; added to ready queue [Q A]
time 82221ms: Process C completed a CPU burst; 48 bursts to go [Q A]
time 82221ms: Process C switching out of CPU; blocking on I/O until time 83781ms [Q A]
time 82225ms: Process A started using the CPU for 954ms burst [Q <empty>]
time 83179ms: Process A completed a CPU burst; 5 bursts to go [Q <empty>]
time 83179ms: Process A switching out of CPU; blocking on I/O until time 93141ms [Q <empty>]
time 83781ms: Process C completed I/O; added to ready queue [Q C]
time 83783ms: Process C started using the CPU for 692ms burst [Q <empty>]
time 84475ms: Process C completed a CPU burst; 47 bursts to go [Q <empty>]
time 84475ms: Process C switching out of CPU; blocking on I/O until time 85072ms [Q <empty>]
time 85072ms: Process C completed I/O; added to ready queue [Q C]
time 85074ms: Process C started using the CPU for 3172ms burst [Q <empty>]
time 85415ms: Process B completed I/O; added to ready queue [Q B]
time 88246ms: Process C completed a CPU burst; 46 bursts to go [Q B]
time 88246ms: Process C switching out of CPU; blocking on I/O until time 88694ms [Q B]
time 88250ms: Process B started using the CPU for 1999ms burst [Q <empty>]
time 88694ms: Process C completed I/O; added to ready queue [Q C]
time 90249ms: Process B completed a CPU burst; 4 bursts to go [Q C]
time 90249ms: Process B switching out of CPU; blocking on I/O until time 98271ms [Q C]
time 90253ms: Process C started using the CPU for 7724ms burst [Q <empty>]
time 93141ms: Process A completed I/O; added to ready queue [Q A]
time 97977ms: Process C completed a CPU burst; 45 bursts to go [Q A]
time 97977ms: Process C switching out of CPU; blocking on I/O until time 98794ms [Q A]
time 97981ms: Process A started using the CPU for 236ms burst [Q <empty>]
time 98217ms: Process A completed a CPU burst; 4 bursts to go [Q <empty>]
time 98217ms: Process A switching out of CPU; blocking on I/O until time 115229ms [Q <empty>]
time 98271ms: Process B completed I/O; added to ready queue [Q B]
time 98273ms: Process B started using the CPU for 1970ms burst [Q <empty>]
time 98794ms: Process C completed I/O; added to ready queue [Q C]
time 100243ms: Process B completed a CPU burst; 3 bursts to go [Q C]
time 100243ms: Process B switching out of CPU; blocking on I/O until time 113305ms [Q C]
time 100247ms: Process C started using the CPU for 3628ms burst [Q <empty>]
time 103875ms: Process C completed a CPU burst; 44 bursts to go [Q <empty>]
time 103875ms: Process C switching out of CPU; blocking on I/O until time 103935ms [Q <empty>]
time 103935ms: Process C completed I/O; added to ready queue [Q C]
time 103937ms: Process C started using the CPU for 2696ms burst [Q <empty>]
time 106633ms: Process C completed a CPU burst; 43 bursts to go [Q <empty>]
time 106633ms: Process C switching out of CPU; blocking on I/O until time 106666ms [Q <empty>]
time 106666ms: Process C completed I/O; added to ready queue [Q C]
time 106668ms: Process C started using the CPU for 9204ms burst [Q <empty>]
time 113305ms: Process B completed I/O; added to ready queue [Q B]
time 115229ms: Process A completed I/O; added to ready queue [Q B A]
time 115872ms: Process C completed a CPU burst; 42 bursts to go [Q B A]
time 115872ms: Process C switching out of CPU; blocking on I/O until time 119261ms [Q B A]
time 115876ms: Process B started using the CPU for 303ms burst [Q A]
time 116179ms: Process B completed a CPU burst; 2 bursts to go [Q A]
time 116179ms: Process B switching out of CPU; blocking on I/O until time 145671ms [Q A]
time 116183ms: Process A started using the CPU for 734ms burst [Q <empty>]
time 116917ms: Process A completed a CPU burst; 3 bursts to go [Q <empty>]
time 116917ms: Process A switching out of CPU; blocking on I/O until time 122769ms [Q <empty>]
time 119261ms: Process C completed I/O; added to ready queue [Q C]
time 119263ms: Process C started using the CPU for 7356ms burst [Q <empty>]
time 122769ms: Process A completed I/O; added to ready queue [Q A]
time 126619ms: Process C completed a CPU burst; 41 bursts to go [Q A]
time 126619ms: Process C switching out of CPU; blocking on I/O until time 127431ms [Q A]
time 126623ms: Process A started using the CPU for 1124ms burst [Q <empty>]
time 127431ms: Process C completed I/O; added to ready queue [Q C]
time 127747ms: Process A completed a CPU burst; 2 bursts to go [Q C]
time 127747ms: Process A switching out of CPU; blocking on I/O until time 147389ms [Q C]
time 127751ms: Process C started using the CPU for 676ms burst [Q <empty>]
time 128427ms: Process C completed a CPU burst; 40 bursts to go [Q <empty>]
time 128427ms: Process C switching out of CPU; blocking on I/O until time 128774ms [Q <empty>]
time 128774ms: Process C completed I/O; added to ready queue [Q C]
time 128776ms: Process C started using the CPU for 4132ms burst [Q <empty>]
time 132908ms: Process C completed a CPU burst; 39 bursts to go [Q <empty>]
time 132908ms: Process C switching out of CPU; blocking on I/O until time 133362ms [Q <empty>]
time 133362ms: Process C completed I/O; added to ready queue [Q C]
time 133364ms: Process C started using the CPU for 3364ms burst [Q <empty>]
time 136728ms: Process C completed a CPU burst; 38 bursts to go [Q <empty>]
time 136728ms: Process C switching out of CPU; blocking on I/O until time 138403ms [Q <empty>]
time 138403ms: Process C completed I/O; added to ready queue [Q C]
time 138405ms: Process C started using the CPU for 6900ms burst [Q <empty>]
time 145305ms: Process C completed a CPU burst; 37 bursts to go [Q <empty>]
time 145305ms: Process C switching out of CPU; blocking on I/O until time 147577ms [Q <empty>]
time 145671ms: Process B completed I/O; added to ready queue [Q B]
time 145673ms: Process B started using the CPU for 2245ms burst [Q <empty>]
time 147389ms: Process A completed I/O; added to ready queue [Q A]
time 147577ms: Process C completed I/O; added to ready queue [Q A C]
time 147918ms: Process B completed a CPU burst; 1 burst to go [Q A C]
time 147918ms: Process B switching out of CPU; blocking on I/O until time 175430ms [Q A C]
time 147922ms: Process A started using the CPU for 62ms burst [Q C]
time 147984ms: Process A completed a CPU burst; 1 burst to go [Q C]
time 147984ms: Process A switching out of CPU; blocking on I/O until time 150336ms [Q C]
time 147988ms: Process C started using the CPU for 6916ms burst [Q <empty>]
time 150336ms: Process A completed I/O; added to ready queue [Q A]
time 154904ms: Process C completed a CPU burst; 36 bursts to go [Q A]
time 154904ms: Process C switching out of CPU; blocking on I/O until time 155569ms [Q A]
time 154908ms: Process A started using the CPU for 647ms burst [Q <empty>]
time 155555ms: Process A terminated [Q <empty>]
time 155569ms: Process C completed I/O; added to ready queue [Q C]
time 155571ms: Process C started using the CPU for 7244ms burst [Q <empty>]
time 162815ms: Process C completed a CPU burst; 35 bursts to go [Q <empty>]
time 162815ms: Process C switching out of CPU; blocking on I/O until time 162972ms [Q <empty>]
time 162972ms: Process C completed I/O; added to ready queue [Q C]
time 162974ms: Process C started using the CPU for 2396ms burst [Q <empty>]
time 165370ms: Process C completed a CPU burst; 34 bursts to go [Q <empty>]
time 165370ms: Process C switching out of CPU; blocking on I/O until time 165879ms [Q <empty>]
time 165879ms: Process C completed I/O; added to ready queue [Q C]
time 165881ms: Process C started using the CPU for 7736ms burst [Q <empty>]
time 173617ms: Process C completed a CPU burst; 33 bursts to go [Q <empty>]
time 173617ms: Process C switching out of CPU; blocking on I/O until time 175422ms [Q <empty>]
time 175422ms: Process C completed I/O; added to ready queue [Q C]
time 175424ms: Process C started using the CPU for 4484ms burst [Q <empty>]
time 175430ms: Process B completed I/O; added to ready queue [Q B]
time 179908ms: Process C completed a CPU burst; 32 bursts to go [Q B]
time 179908ms: Process C switching out of CPU; blocking on I/O until time 182138ms [Q B]
time 179912ms: Process B started using the CPU for 615ms burst [Q <empty>]
time 180527ms: Process B terminated [Q <empty>]
time 182138ms: Process C completed I/O; added to ready queue [Q C]
time 182140ms: Process C started using the CPU for 7564ms burst [Q <empty>]
time 189704ms: Process C completed a CPU burst; 31 bursts to go [Q <empty>]
time 189704ms: Process C switching out of CPU; blocking on I/O until time 190928ms [Q <empty>]
time 190928ms: Process C completed I/O; added to ready queue [Q C]
time 190930ms: Process C started using the CPU for 3724ms burst [Q <empty>]
time 194654ms: Process C completed a CPU burst; 30 bursts to go [Q <empty>]
time 194654ms: Process C switching out of CPU; blocking on I/O until time 194777ms [Q <empty>]
time 194777ms: Process C completed I/O; added to ready queue [Q C]
time 194779ms: Process C started using the CPU for 1608ms burst [Q <empty>]
time 196387ms: Process C completed a CPU burst; 29 bursts to go [Q <empty>]
time 196387ms: Process C switching out of CPU; blocking on I/O until time 196824ms [Q <empty>]
time 196824ms: Process C completed I/O; added to ready queue [Q C]
time 196826ms: Process C started using the CPU for 6880ms burst [Q <empty>]
time 203706ms: Process C completed a CPU burst; 28 bursts to go [Q <empty>]
time 203706ms: Process C switching out of CPU; blocking on I/O until time 205185ms [Q <empty>]
time 205185ms: Process C completed I/O; added to ready queue [Q C]
time 205187ms: Process C started using the CPU for 972ms burst [Q <empty>]
time 206159ms: Process C completed a CPU burst; 27 bursts to go [Q <empty>]
time 206159ms: Process C switching out of CPU; blocking on I/O until time 206478ms [Q <empty>]
time 206478ms: Process C completed I/O; added to ready queue [Q C]
time 206480ms: Process C started using the CPU for 176ms burst [Q <empty>]
time 206656ms: Process C completed a CPU burst; 26 bursts to go [Q <empty>]
time 206656ms: Process C switching out of CPU; blocking on I/O until time 208784ms [Q <empty>]
time 208784ms: Process C completed I/O; added to ready queue [Q C]
time 208786ms: Process C started using the CPU for 412ms burst [Q <empty>]
time 209198ms: Process C completed a CPU burst; 25 bursts to go [Q <empty>]
time 209198ms: Process C switching out of CPU; blocking on I/O until time 209765ms [Q <empty>]
time 209765ms: Process C completed I/O; added to ready queue [Q C]
time 209767ms: Process C started using the CPU for 576ms burst [Q <empty>]
time 210343ms: Process C completed a CPU burst; 24 bursts to go [Q <empty>]
time 210343ms: Process C switching out of CPU; blocking on I/O until time 210416ms [Q <empty>]
time 210416ms: Process C completed I/O; added to ready queue [Q C]
time 210418ms: Process C started using the CPU for 4928ms burst [Q <empty>]
time 215346ms: Process C completed a CPU burst; 23 bursts to go [Q <empty>]
time 215346ms: Process C switching out of CPU; blocking on I/O until time 216050ms [Q <empty>]
time 216050ms: Process C completed I/O; added to ready queue [Q C]
time 216052ms: Process C started using the CPU for 2804ms burst [Q <empty>]
time 218856ms: Process C completed a CPU burst; 22 bursts to go [Q <empty>]
time 218856ms: Process C switching out of CPU; blocking on I/O until time 219876ms [Q <empty>]
time 219876ms: Process C completed I/O; added to ready queue [Q C]
time 219878ms: Process C started using the CPU for 2120ms burst [Q <empty>]
time 221998ms: Process C completed a CPU burst; 21 bursts to go [Q <empty>]
time 221998ms: Process C switching out of CPU; blocking on I/O until time 223862ms [Q <empty>]
time 223862ms: Process C completed I/O; added to ready queue [Q C]
time 223864ms: Process C started using the CPU for 1944ms burst [Q <empty>]
time 225808ms: Process C completed a CPU burst; 20 bursts to go [Q <empty>]
time 225808ms: Process C switching out of CPU; blocking on I/O until time 225813ms [Q <empty>]
time 225813ms: Process C completed I/O; added to ready queue [Q C]
time 225815ms: Process C started using the CPU for 2472ms burst [Q <empty>]
time 228287ms: Process C completed a CPU burst; 19 bursts to go [Q <empty>]
time 228287ms: Process C switching out of CPU; blocking on I/O until time 228477ms [Q <empty>]
time 228477ms: Process C completed I/O; added to ready queue [Q C]
time 228479ms: Process C started using the CPU for 868ms burst [Q <empty>]
time 229347ms: Process C completed a CPU burst; 18 bursts to go [Q <empty>]
time 229347ms: Process C switching out of CPU; blocking on I/O until time 230372ms [Q <empty>]
time 230372ms: Process C completed I/O; added to ready queue [Q C]
time 230374ms: Process C started using the CPU for 3208ms burst [Q <empty>]
time 233582ms: Process C completed a CPU burst; 17 bursts to go [Q <empty>]
time 233582ms: Process C switching out of CPU; blocking on I/O until time 234687ms [Q <empty>]
time 234687ms: Process C completed I/O; added to ready queue [Q C]
time 234689ms: Process C started using the CPU for 1672ms burst [Q <empty>]
time 236361ms: Process C completed a CPU burst; 16 bursts to go [Q <empty>]
time 236361ms: Process C switching out of CPU; blocking on I/O until time 238940ms [Q <empty>]
time 238940ms: Process C completed I/O; added to ready queue [Q C]
time 238942ms: Process C started using the CPU for 3536ms burst [Q <empty>]
time 242478ms: Process C completed a CPU burst; 15 bursts to go [Q <empty>]
time 242478ms: Process C switching out of CPU; blocking on I/O until time 246017ms [Q <empty>]
time 246017ms: Process C completed I/O; added to ready queue [Q C]
time 246019ms: Process C started using the CPU for 2988ms burst [Q <empty>]
time 249007ms: Process C completed a CPU burst; 14 bursts to go [Q <empty>]
time 249007ms: Process C switching out of CPU; blocking on I/O until time 251085ms [Q <empty>]
time 251085ms: Process C completed I/O; added to ready queue [Q C]
time 251087ms: Process C started using the CPU for 7804ms burst [Q <empty>]
time 258891ms: Process C completed a CPU burst; 13 bursts to go [Q <empty>]
time 258891ms: Process C switching out of CPU; blocking on I/O until time 260160ms [Q <empty>]
time 260160ms: Process C completed I/O; added to ready queue [Q C]
time 260162ms: Process C started using the CPU for 5608ms burst [Q <empty>]
time 265770ms: Process C completed a CPU burst; 12 bursts to go [Q <empty>]
time 265770ms: Process C switching out of CPU; blocking on I/O until time 266069ms [Q <empty>]
time 266069ms: Process C completed I/O; added to ready queue [Q C]
time 266071ms: Process C started using the CPU for 1160ms burst [Q <empty>]
time 267231ms: Process C completed a CPU burst; 11 bursts to go [Q <empty>]
time 267231ms: Process C switching out of CPU; blocking on I/O until time 267874ms [Q <empty>]
time 267874ms: Process C completed I/O; added to ready queue [Q C]
time 267876ms: Process C started using the CPU for 3048ms burst [Q <empty>]
time 270924ms: Process C completed a CPU burst; 10 bursts to go [Q <empty>]
time 270924ms: Process C switching out of CPU; blocking on I/O until time 270937ms [Q <empty>]
time 270937ms: Process C completed I/O; added to ready queue [Q C]
time 270939ms: Process C started using the CPU for 1120ms burst [Q <empty>]
time 272059ms: Process C completed a CPU burst; 9 bursts to go [Q <empty>]
time 272059ms: Process C switching out of CPU; blocking on I/O until time 272808ms [Q <empty>]
time 272808ms: Process C completed I/O; added to ready queue [Q C]
time 272810ms: Process C started using the CPU for 8872ms burst [Q <empty>]
time 281682ms: Process C completed a CPU burst; 8 bursts to go [Q <empty>]
time 281682ms: Process C switching out of CPU; blocking on I/O until time 284127ms [Q <empty>]
time 284127ms: Process C completed I/O; added to ready queue [Q C]
time 284129ms: Process C started using the CPU for 3112ms burst [Q <empty>]
time 287241ms: Process C completed a CPU burst; 7 bursts to go [Q <empty>]
time 287241ms: Process C switching out of CPU; blocking on I/O until time 287911ms [Q <empty>]
time 287911ms: Process C completed I/O; added to ready queue [Q C]
time 287913ms: Process C started using the CPU for 1904ms burst [Q <empty>]
time 289817ms: Process C completed a CPU burst; 6 bursts to go [Q <empty>]
time 289817ms: Process C switching out of CPU; blocking on I/O until time 290536ms [Q <empty>]
time 290536ms: Process C completed I/O; added to ready queue [Q C]
time 290538ms: Process C started using the CPU for 5488ms burst [Q <empty>]
time 296026ms: Process C completed a CPU burst; 5 bursts to go [Q <empty>]
time 296026ms: Process C switching out of CPU; blocking on I/O until time 298703ms [Q <empty>]
time 298703ms: Process C completed I/O; added to ready queue [Q C]
time 298705ms: Process C started using the CPU for 3340ms burst [Q <empty>]
time 302045ms: Process C completed a CPU burst; 4 bursts to go [Q <empty>]
time 302045ms: Process C switching out of CPU; blocking on I/O until time 302489ms [Q <empty>]
time 302489ms: Process C completed I/O; added to ready queue [Q C]
time 302491ms: Process C started using the CPU for 7076ms burst [Q <empty>]
time 309567ms: Process C completed a CPU burst; 3 bursts to go [Q <empty>]
time 309567ms: Process C switching out of CPU; blocking on I/O until time 310356ms [Q <empty>]
time 310356ms: Process C completed I/O; added to ready queue [Q C]
time 310358ms: Process C started using the CPU for 9540ms burst [Q <empty>]
time 319898ms: Process C completed a CPU burst; 2 bursts to go [Q <empty>]
time 319898ms: Process C switching out of CPU; blocking on I/O until time 319941ms [Q <empty>]
time 319941ms: Process C completed I/O; added to ready queue [Q C]
time 319943ms: Process C started using the CPU for 1784ms burst [Q <empty>]
time 321727ms: Process C completed a CPU burst; 1 burst to go [Q <empty>]
time 321727ms: Process C switching out of CPU; blocking on I/O until time 322355ms [Q <empty>]
time 322355ms: Process C completed I/O; added to ready queue [Q C]
time 322357ms: Process C started using the CPU for 1704ms burst [Q <empty>]
time 324061ms: Process C terminated [Q <empty>]
time 324063ms: Simulator ended for FCFS [Q <empty>]

time 0ms: Simulator started for SJF [Q <empty>]
time 26ms: Process C (tau 1000ms) arrived; added to ready queue [Q C]
time 28ms: Process C (tau 1000ms) started using the CPU for 2920ms burst [Q <empty>]
time 136ms: Process A (tau 1000ms) arrived; added to ready queue [Q A]
time 929ms: Process B (tau 1000ms) arrived; added to ready queue [Q A B]
time 2948ms: Process C (tau 1000ms) completed a CPU burst; 59 bursts to go [Q A B]
time 2948ms: Recalculating tau for process C: old tau 1000ms ==> new tau 2440ms [Q A B]
time 2948ms: Process C switching out of CPU; blocking on I/O until time 3318ms [Q A B]
time 2952ms: Process A (tau 1000ms) started using the CPU for 1330ms burst [Q B]
time 3318ms: Process C (tau 2440ms) completed I/O; added to ready queue [Q B C]
time 4282ms: Process A (tau 1000ms) completed a CPU burst; 16 bursts to go [Q B C]
time 4282ms: Recalculating tau for process A: old tau 1000ms ==> new tau 1248ms [Q B C]
time 4282ms: Process A switching out of CPU; blocking on I/O until time 10024ms [Q B C]
time 4286ms: Process B (tau 1000ms) started using the CPU for 2438ms burst [Q C]
time 6724ms: Process B (tau 1000ms) completed a CPU burst; 11 bursts to go [Q C]
time 6724ms: Recalculating tau for process B: old tau 1000ms ==> new tau 2079ms [Q C]
time 6724ms: Process B switching out of CPU; blocking on I/O until time 7606ms [Q C]
time 6728ms: Process C (tau 2440ms) started using the CPU for 2328ms burst [Q <empty>]
time 7606ms: Process B (tau 2079ms) completed I/O; added to ready queue [Q B]
time 9056ms: Process C (tau 2440ms) completed a CPU burst; 58 bursts to go [Q B]
time 9056ms: Recalculating tau for process C: old tau 2440ms ==> new tau 2356ms [Q B]
time 9056ms: Process C switching out of CPU; blocking on I/O until time 12170ms [Q B]
time 9060ms: Process B (tau 2079ms) started using the CPU for 1173ms burst [Q <empty>]
time 10024ms: Process A (tau 1248ms) completed I/O; added to ready queue [Q A]
time 10233ms: Process B (tau 2079ms) completed a CPU burst; 10 bursts to go [Q A]
time 10233ms: Recalculating tau for process B: old tau 2079ms ==> new tau 1400ms [Q A]
time 10233ms: Process B switching out of CPU; blocking on I/O until time 10775ms [Q A]
time 10237ms: Process A (tau 1248ms) started using the CPU for 735ms burst [Q <empty>]
time 10775ms: Process B (tau 1400ms) completed I/O; added to ready queue [Q B]
time 10972ms: Process A (tau 1248ms) completed a CPU burst; 15 bursts to go [Q B]
time 10972ms: Recalculating tau for process A: old tau 1248ms ==> new tau 864ms [Q B]
time 10972ms: Process A switching out of CPU; blocking on I/O until time 11634ms [Q B]
time 10976ms: Process B (tau 1400ms) started using the CPU for 492ms burst [Q <empty>]
time 11468ms: Process B (tau 1400ms) completed a CPU burst; 9 bursts to go [Q <empty>]
time 11468ms: Recalculating tau for process B: old tau 1400ms ==> new tau 719ms [Q <empty>]
time 11468ms: Process B switching out of CPU; blocking on I/O until time 23820ms [Q <empty>]
time 11634ms: Process A (tau 864ms) completed I/O; added to ready queue [Q A]
time 11636ms: Process A (tau 864ms) started using the CPU for 24ms burst [Q <empty>]
time 11660ms: Process A (tau 864ms) completed a CPU burst; 14 bursts to go [Q <empty>]
time 11660ms: Recalculating tau for process A: old tau 864ms ==> new tau 234ms [Q <empty>]
time 11660ms: Process A switching out of CPU; blocking on I/O until time 12112ms [Q <empty>]
time 12112ms: Process A (tau 234ms) completed I/O; added to ready queue [Q A]
time 12114ms: Process A (tau 234ms) started using the CPU for 683ms burst [Q <empty>]
time 12170ms: Process C (tau 2356ms) completed I/O; added to ready queue [Q C]
time 12797ms: Process A (tau 234ms) completed a CPU burst; 13 bursts to go [Q C]
time 12797ms: Recalculating tau for process A: old tau 234ms ==> new tau 571ms [Q C]
time 12797ms: Process A switching out of CPU; blocking on I/O until time 14649ms [Q C]
time 12801ms: Process C (tau 2356ms) started using the CPU for 1180ms burst [Q <empty>]
time 13981ms: Process C (tau 2356ms) completed a CPU burst; 57 bursts to go [Q <empty>]
time 13981ms: Recalculating tau for process C: old tau 2356ms ==> new tau 1474ms [Q <empty>]
time 13981ms: Process C switching out of CPU; blocking on I/O until time 15303ms [Q <empty>]
time 14649ms: Process A (tau 571ms) completed I/O; added to ready queue [Q A]
time 14651ms: Process A (tau 571ms) started using the CPU for 1100ms burst [Q <empty>]
time 15303ms: Process C (tau 1474ms) completed I/O; added to ready queue [Q C]
time 15751ms: Process A (tau 571ms) completed a CPU burst; 12 bursts to go [Q C]
time 15751ms: Recalculating tau for process A: old tau 571ms ==> new tau 968ms [Q C]
time 15751ms: Process A switching out of CPU; blocking on I/O until time 29973ms [Q C]
time 15755ms: Process C (tau 1474ms) started using the CPU for 11336ms burst [Q <empty>]
time 23820ms: Process B (tau 719ms) completed I/O; added to ready queue [Q B]
time 27091ms: Process C (tau 1474ms) completed a CPU burst; 56 bursts to go [Q B]
time 27091ms: Recalculating tau for process C: old tau 1474ms ==> new tau 8871ms [Q B]
time 27091ms: Process C switching out of CPU; blocking on I/O until time 27769ms [Q B]
time 27095ms: Process B (tau 719ms) started using the CPU for 2670ms burst [Q <empty>]
time 27769ms: Process C (tau 8871ms) completed I/O; added to ready queue [Q C]
time 29765ms: Process B (tau 719ms) completed a CPU burst; 8 bursts to go [Q C]
time 29765ms: Recalculating tau for process B: old tau 719ms ==> new tau 2183ms [Q C]
time 29765ms: Process B switching out of CPU; blocking on I/O until time 34827ms [Q C]
time 29769ms: Process C (tau 8871ms) started using the CPU for 5132ms burst [Q <empty>]
time 29973ms: Process A (tau 968ms) completed I/O; added to ready queue [Q A]
time 34827ms: Process B (tau 2183ms) completed I/O; added to ready queue [Q A B]
time 34901ms: Process C (tau 8871ms) completed a CPU burst; 55 bursts to go [Q A B]
time 34901ms: Recalculating tau for process C: old tau 8871ms ==> new tau 6067ms [Q A B]
time 34901ms: Process C switching out of CPU; blocking on I/O until time 36750ms [Q A B]
time 34905ms: Process A (tau 968ms) started using the CPU for 1000ms burst [Q B]
time 35905ms: Process A (tau 968ms) completed a CPU burst; 11 bursts to go [Q B]
time 35905ms: Recalculating tau for process A: old tau 968ms ==> new tau 992ms [Q B]
time 35905ms: Process A switching out of CPU; blocking on I/O until time 42857ms [Q B]
time 35909ms: Process B (tau 2183ms) started using the CPU for 610ms burst [Q <empty>]
time 36519ms: Process B (tau 2183ms) completed a CPU burst; 7 bursts to go [Q <empty>]
time 36519ms: Recalculating tau for process B: old tau 2183ms ==> new tau 1004ms [Q <empty>]
time 36519ms: Process B switching out of CPU; blocking on I/O until time 62341ms [Q <empty>]
time 36750ms: Process C (tau 6067ms) completed I/O; added to ready queue [Q C]
time 36752ms: Process C (tau 6067ms) started using the CPU for 2896ms burst [Q <empty>]
time 39648ms: Process C (tau 6067ms) completed a CPU burst; 54 bursts to go [Q <empty>]
time 39648ms: Recalculating tau for process C: old tau 6067ms ==> new tau 3689ms [Q <empty>]
time 39648ms: Process C switching out of CPU; blocking on I/O until time 42968ms [Q <empty>]
time 42857ms: Process A (tau 992ms) completed I/O; added to ready queue [Q A]
time 42859ms: Process A (tau 992ms) started using the CPU for 1166ms burst [Q <empty>]
time 42968ms: Process C (tau 3689ms) completed I/O; added to ready queue [Q C]
time 44025ms: Process A (tau 992ms) completed a CPU burst; 10 bursts to go [Q C]
time 44025ms: Recalculating tau for process A: old tau 992ms ==> new tau 1123ms [Q C]
time 44025ms: Process A switching out of CPU; blocking on I/O until time 49317ms [Q C]
time 44029ms: Process C (tau 3689ms) started using the CPU for 160ms burst [Q <empty>]
time 44189ms: Process C (tau 3689ms) completed a CPU burst; 53 bursts to go [Q <empty>]
time 44189ms: Recalculating tau for process C: old tau 3689ms ==> new tau 1043ms [Q <empty>]
time 44189ms: Process C switching out of CPU; blocking on I/O until time 45986ms [Q <empty>]
time 45986ms: Process C (tau 1043ms) completed I/O; added to ready queue [Q C]
time 45988ms: Process C (tau 1043ms) started using the CPU for 2968ms burst [Q <empty>]
time 48956ms: Process C (tau 1043ms) completed a CPU burst; 52 bursts to go [Q <empty>]
time 48956ms: Recalculating tau for process C: old tau 1043ms ==> new tau 2487ms [Q <empty>]
time 48956ms: Process C switching out of CPU; blocking on I/O until time 50001ms [Q <empty>]
time 49317ms: Process A (tau 1123ms) completed I/O; added to ready queue [Q A]
time 49319ms: Process A (tau 1123ms) started using the CPU for 1561ms burst [Q <empty>]
time 50001ms: Process C (tau 2487ms) completed I/O; added to ready queue [Q C]
time 50880ms: Process A (tau 1123ms) completed a CPU burst; 9 bursts to go [Q C]
time 50880ms: Recalculating tau for process A: old tau 1123ms ==> new tau 1452ms [Q C]
time 50880ms: Process A switching out of CPU; blocking on I/O until time 53702ms [Q C]
time 50884ms: Process C (tau 2487ms) started using the CPU for 4428ms burst [Q <empty>]
time 53702ms: Process A (tau 1452ms) completed I/O; added to ready queue [Q A]
time 55312ms: Process C (tau 2487ms) completed a CPU burst; 51 bursts to go [Q A]
time 55312ms: Recalculating tau for process C: old tau 2487ms ==> new tau 3943ms [Q A]
time 55312ms: Process C switching out of CPU; blocking on I/O until time 56591ms [Q A]
time 55316ms: Process A (tau 1452ms) started using the CPU for 149ms burst [Q <empty>]
time 55465ms: Process A (tau 1452ms) completed a CPU burst; 8 bursts to go [Q <empty>]
time 55465ms: Recalculating tau for process A: old tau 1452ms ==> new tau 475ms [Q <empty>]
time 55465ms: Process A switching out of CPU; blocking on I/O until time 56187ms [Q <empty>]
time 56187ms: Process A (tau 475ms) completed I/O; added to ready queue [Q A]
time 56189ms: Process A (tau 475ms) started using the CPU for 388ms burst [Q <empty>]
time 56577ms: Process A (tau 475ms) completed a CPU burst; 7 bursts to go [Q <empty>]
time 56577ms: Recalculating tau for process A: old tau 475ms ==> new tau 410ms [Q <empty>]
time 56577ms: Process A switching out of CPU; blocking on I/O until time 63949ms [Q <empty>]
time 56591ms: Process C (tau 3943ms) completed I/O; added to ready queue [Q C]
time 56593ms: Process C (tau 3943ms) started using the CPU for 7280ms burst [Q <empty>]
time 62341ms: Process B (tau 1004ms) completed I/O; added to ready queue [Q B]
time 63873ms: Process C (tau 3943ms) completed a CPU burst; 50 bursts to go [Q B]
time 63873ms: Recalculating tau for process C: old tau 3943ms ==> new tau 6446ms [Q B]
time 63873ms: Process C switching out of CPU; blocking on I/O until time 64492ms [Q B]
time 63877ms: Process B (tau 1004ms) started using the CPU for 1452ms burst [Q <empty>]
time 63949ms: Process A (tau 410ms) completed I/O; added to ready queue [Q A]
time 64492ms: Process C (tau 6446ms) completed I/O; added to ready queue [Q A C]
time 65329ms: Process B (tau 1004ms) completed a CPU burst; 6 bursts to go [Q A C]
time 65329ms: Recalculating tau for process B: old tau 1004ms ==> new tau 1340ms [Q A C]
time 65329ms: Process B switching out of CPU; blocking on I/O until time 69981ms [Q A C]
time 65333ms: Process A (tau 410ms) started using the CPU for 34ms burst [Q C]
time 65367ms: Process A (tau 410ms) completed a CPU burst; 6 bursts to go [Q C]
time 65367ms: Recalculating tau for process A: old tau 410ms ==> new tau 128ms [Q C]
time 65367ms: Process A switching out of CPU; blocking on I/O until time 74909ms [Q C]
time 65371ms: Process C (tau 6446ms) started using the CPU for 7180ms burst [Q <empty>]
time 69981ms: Process B (tau 1340ms) completed I/O; added to ready queue [Q B]
time 72551ms: Process C (tau 6446ms) completed a CPU burst; 49 bursts to go [Q B]
time 72551ms: Recalculating tau for process C: old tau 6446ms ==> new tau 6997ms [Q B]
time 72551ms: Process C switching out of CPU; blocking on I/O until time 74099ms [Q B]
time 72555ms: Process B (tau 1340ms) started using the CPU for 878ms burst [Q <empty>]
time 73433ms: Process B (tau 1340ms) completed a CPU burst; 5 bursts to go [Q <empty>]
time 73433ms: Recalculating tau for process B: old tau 1340ms ==> new tau 994ms [Q <empty>]
time 73433ms: Process B switching out of CPU; blocking on I/O until time 85415ms [Q <empty>]
time 74099ms: Process C (tau 6997ms) completed I/O; added to ready queue [Q C]
time 74101ms: Process C (tau 6997ms) started using the CPU for 8120ms burst [Q <empty>]
time 74909ms: Process A (tau 128ms) completed I/O; added to ready queue [Q A]
time 82221ms: Process C (tau 6997ms) completed a CPU burst; 48 bursts to go [Q A]
time 82221ms: Recalculating tau for process C: old tau 6997ms ==> new tau 7840ms [Q A]
time 82221ms: Process C switching out of CPU; blocking on I/O until time 83781ms [Q A]
time 82225ms: Process A (tau 128ms) started using the CPU for 954ms burst [Q <empty>]
time 83179ms: Process A (tau 128ms) completed a CPU burst; 5 bursts to go [Q <empty>]
time 83179ms: Recalculating tau for process A: old tau 128ms ==> new tau 748ms [Q <empty>]
time 83179ms: Process A switching out of CPU; blocking on I/O until time 93141ms [Q <empty>]
time 83781ms: Process C (tau 7840ms) completed I/O; added to ready queue [Q C]
time 83783ms: Process C (tau 7840ms) started using the CPU for 692ms burst [Q <empty>]
time 84475ms: Process C (tau 7840ms) completed a CPU burst; 47 bursts to go [Q <empty>]
time 84475ms: Recalculating tau for process C: old tau 7840ms ==> new tau 2479ms [Q <empty>]
time 84475ms: Process C switching out of CPU; blocking on I/O until time 85072ms [Q <empty>]
time 85072ms: Process C (tau 2479ms) completed I/O; added to ready queue [Q C]
time 85074ms: Process C (tau 2479ms) started using the CPU for 3172ms burst [Q <empty>]
time 85415ms: Process B (tau 994ms) completed I/O; added to ready queue [Q B]
time 88246ms: Process C (tau 2479ms) completed a CPU burst; 46 bursts to go [Q B]
time 88246ms: Recalculating tau for process C: old tau 2479ms ==> new tau 2999ms [Q B]
time 88246ms: Process C switching out of CPU; blocking on I/O until time 88694ms [Q B]
time 88250ms: Process B (tau 994ms) started using the CPU for 1999ms burst [Q <empty>]
time 88694ms: Process C (tau 2999ms) completed I/O; added to ready queue [Q C]
time 90249ms: Process B (tau 994ms) completed a CPU burst; 4 bursts to go [Q C]
time 90249ms: Recalculating tau for process B: old tau 994ms ==> new tau 1748ms [Q C]
time 90249ms: Process B switching out of CPU; blocking on I/O until time 98271ms [Q C]
time 90253ms: Process C (tau 2999ms) started using the CPU for 7724ms burst [Q <empty>]
time 93141ms: Process A (tau 748ms) completed I/O; added to ready queue [Q A]
time 97977ms: Process C (tau 2999ms) completed a CPU burst; 45 bursts to go [Q A]
time 97977ms: Recalculating tau for process C: old tau 2999ms ==> new tau 6543ms [Q A]
time 97977ms: Process C switching out of CPU; blocking on I/O until time 98794ms [Q A]
time 97981ms: Process A (tau 748ms) started using the CPU for 236ms burst [Q <empty>]
time 98217ms: Process A (tau 748ms) completed a CPU burst; 4 bursts to go [Q <empty>]
time 98217ms: Recalculating tau for process A: old tau 748ms ==> new tau 364ms [Q <empty>]
time 98217ms: Process A switching out of CPU; blocking on I/O until time 115229ms [Q <empty>]
time 98271ms: Process B (tau 1748ms) completed I/O; added to ready queue [Q B]
time 98273ms: Process B (tau 1748ms) started using the CPU for 1970ms burst [Q <empty>]
time 98794ms: Process C (tau 6543ms) completed I/O; added to ready queue [Q C]
time 100243ms: Process B (tau 1748ms) completed a CPU burst; 3 bursts to go [Q C]
time 100243ms: Recalculating tau for process B: old tau 1748ms ==> new tau 1915ms [Q C]
time 100243ms: Process B switching out of CPU; blocking on I/O until time 113305ms [Q C]
time 100247ms: Process C (tau 6543ms) started using the CPU for 3628ms burst [Q <empty>]
time 103875ms: Process C (tau 6543ms) completed a CPU burst; 44 bursts to go [Q <empty>]
time 103875ms: Recalculating tau for process C: old tau 6543ms ==> new tau 4357ms [Q <empty>]
time 103875ms: Process C switching out of CPU; blocking on I/O until time 103935ms [Q <empty>]
time 103935ms: Process C (tau 4357ms) completed I/O; added to ready queue [Q C]
time 103937ms: Process C (tau 4357ms) started using the CPU for 2696ms burst [Q <empty>]
time 106633ms: Process C (tau 4357ms) completed a CPU burst; 43 bursts to go [Q <empty>]
time 106633ms: Recalculating tau for process C: old tau 4357ms ==> new tau 3112ms [Q <empty>]
time 106633ms: Process C switching out of CPU; blocking on I/O until time 106666ms [Q <empty>]
time 106666ms: Process C (tau 3112ms) completed I/O; added to ready queue [Q C]
time 106668ms: Process C (tau 3112ms) started using the CPU for 9204ms burst [Q <empty>]
time 113305ms: Process B (tau 1915ms) completed I/O; added to ready queue [Q B]
time 115229ms: Process A (tau 364ms) completed I/O; added to ready queue [Q A B]
time 115872ms: Process C (tau 3112ms) completed a CPU burst; 42 bursts to go [Q A B]
time 115872ms: Recalculating tau for process C: old tau 3112ms ==> new tau 7681ms [Q A B]
time 115872ms: Process C switching out of CPU; blocking on I/O until time 119261ms [Q A B]
time 115876ms: Process A (tau 364ms) started using the CPU for 734ms burst [Q B]
time 116610ms: Process A (tau 364ms) completed a CPU burst; 3 bursts to go [Q B]
time 116610ms: Recalculating tau for process A: old tau 364ms ==> new tau 642ms [Q B]
time 116610ms: Process A switching out of CPU; blocking on I/O until time 122462ms [Q B]
time 116614ms: Process B (tau 1915ms) started using the CPU for 303ms burst [Q <empty>]
time 116917ms: Process B (tau 1915ms) completed a CPU burst; 2 bursts to go [Q <empty>]
time 116917ms: Recalculating tau for process B: old tau 1915ms ==> new tau 706ms [Q <empty>]
time 116917ms: Process B switching out of CPU; blocking on I/O until time 146409ms [Q <empty>]
time 119261ms: Process C (tau 7681ms) completed I/O; added to ready queue [Q C]
time 119263ms: Process C (tau 7681ms) started using the CPU for 7356ms burst [Q <empty>]
time 122462ms: Process A (tau 642ms) completed I/O; added to ready queue [Q A]
time 126619ms: Process C (tau 7681ms) completed a CPU burst; 41 bursts to go [Q A]
time 126619ms: Recalculating tau for process C: old tau 7681ms ==> new tau 7438ms [Q A]
time 126619ms: Process C switching out of CPU; blocking on I/O until time 127431ms [Q A]
time 126623ms: Process A (tau 642ms) started using the CPU for 1124ms burst [Q <empty>]
time 127431ms: Process C (tau 7438ms) completed I/O; added to ready queue [Q C]
time 127747ms: Process A (tau 642ms) completed a CPU burst; 2 bursts to go [Q C]
time 127747ms: Recalculating tau for process A: old tau 642ms ==> new tau 1004ms [Q C]
time 127747ms: Process A switching out of CPU; blocking on I/O until time 147389ms [Q C]
time 127751ms: Process C (tau 7438ms) started using the CPU for 676ms burst [Q <empty>]
time 128427ms: Process C (tau 7438ms) completed a CPU burst; 40 bursts to go [Q <empty>]
time 128427ms: Recalculating tau for process C: old tau 7438ms ==> new tau 2367ms [Q <empty>]
time 128427ms: Process C switching out of CPU; blocking on I/O until time 128774ms [Q <empty>]
time 128774ms: Process C (tau 2367ms) completed I/O; added to ready queue [Q C]
time 128776ms: Process C (tau 2367ms) started using the CPU for 4132ms burst [Q <empty>]
time 132908ms: Process C (tau 2367ms) completed a CPU burst; 39 bursts to go [Q <empty>]
time 132908ms: Recalculating tau for process C: old tau 2367ms ==> new tau 3691ms [Q <empty>]
time 132908ms: Process C switching out of CPU; blocking on I/O until time 133362ms [Q <empty>]
time 133362ms: Process C (tau 3691ms) completed I/O; added to ready queue [Q C]
time 133364ms: Process C (tau 3691ms) started using the CPU for 3364ms burst [Q <empty>]
time 136728ms: Process C (tau 3691ms) completed a CPU burst; 38 bursts to go [Q <empty>]
time 136728ms: Recalculating tau for process C: old tau 3691ms ==> new tau 3446ms [Q <empty>]
time 136728ms: Process C switching out of CPU; blocking on I/O until time 138403ms [Q <empty>]
time 138403ms: Process C (tau 3446ms) completed I/O; added to ready queue [Q C]
time 138405ms: Process C (tau 3446ms) started using the CPU for 6900ms burst [Q <empty>]
time 145305ms: Process C (tau 3446ms) completed a CPU burst; 37 bursts to go [Q <empty>]
time 145305ms: Recalculating tau for process C: old tau 3446ms ==> new tau 6037ms [Q <empty>]
time 145305ms: Process C switching out of CPU; blocking on I/O until time 147577ms [Q <empty>]
time 146409ms: Process B (tau 706ms) completed I/O; added to ready queue [Q B]
time 146411ms: Process B (tau 706ms) started using the CPU for 2245ms burst [Q <empty>]
time 147389ms: Process A (tau 1004ms) completed I/O; added to ready queue [Q A]
time 147577ms: Process C (tau 6037ms) completed I/O; added to ready queue [Q A C]
time 148656ms: Process B (tau 706ms) completed a CPU burst; 1 burst to go [Q A C]
time 148656ms: Recalculating tau for process B: old tau 706ms ==> new tau 1861ms [Q A C]
time 148656ms: Process B switching out of CPU; blocking on I/O until time 176168ms [Q A C]
time 148660ms: Process A (tau 1004ms) started using the CPU for 62ms burst [Q C]
time 148722ms: Process A (tau 1004ms) completed a CPU burst; 1 burst to go [Q C]
time 148722ms: Recalculating tau for process A: old tau 1004ms ==> new tau 298ms [Q C]
time 148722ms: Process A switching out of CPU; blocking on I/O until time 151074ms [Q C]
time 148726ms: Process C (tau 6037ms) started using the CPU for 6916ms burst [Q <empty>]
time 151074ms: Process A (tau 298ms) completed I/O; added to ready queue [Q A]
time 155642ms: Process C (tau 6037ms) completed a CPU burst; 36 bursts to go [Q A]
time 155642ms: Recalculating tau for process C: old tau 6037ms ==> new tau 6697ms [Q A]
time 155642ms: Process C switching out of CPU; blocking on I/O until time 156307ms [Q A]
time 155646ms: Process A (tau 298ms) started using the CPU for 647ms burst [Q <empty>]
time 156293ms: Process A terminated [Q <empty>]
time 156307ms: Process C (tau 6697ms) completed I/O; added to ready queue [Q C]
time 156309ms: Process C (tau 6697ms) started using the CPU for 7244ms burst [Q <empty>]
time 163553ms: Process C (tau 6697ms) completed a CPU burst; 35 bursts to go [Q <empty>]
time 163553ms: Recalculating tau for process C: old tau 6697ms ==> new tau 7108ms [Q <empty>]
time 163553ms: Process C switching out of CPU; blocking on I/O until time 163710ms [Q <empty>]
time 163710ms: Process C (tau 7108ms) completed I/O; added to ready queue [Q C]
time 163712ms: Process C (tau 7108ms) started using the CPU for 2396ms burst [Q <empty>]
time 166108ms: Process C (tau 7108ms) completed a CPU burst; 34 bursts to go [Q <empty>]
time 166108ms: Recalculating tau for process C: old tau 7108ms ==> new tau 3574ms [Q <empty>]
time 166108ms: Process C switching out of CPU; blocking on I/O until time 166617ms [Q <empty>]
time 166617ms: Process C (tau 3574ms) completed I/O; added to ready queue [Q C]
time 166619ms: Process C (tau 3574ms) started using the CPU for 7736ms burst [Q <empty>]
time 174355ms: Process C (tau 3574ms) completed a CPU burst; 33 bursts to go [Q <empty>]
time 174355ms: Recalculating tau for process C: old tau 3574ms ==> new tau 6696ms [Q <empty>]
time 174355ms: Process C switching out of CPU; blocking on I/O until time 176160ms [Q <empty>]
time 176160ms: Process C (tau 6696ms) completed I/O; added to ready queue [Q C]
time 176162ms: Process C (tau 6696ms) started using the CPU for 4484ms burst [Q <empty>]
time 176168ms: Process B (tau 1861ms) completed I/O; added to ready queue [Q B]
time 180646ms: Process C (tau 6696ms) completed a CPU burst; 32 bursts to go [Q B]
time 180646ms: Recalculating tau for process C: old tau 6696ms ==> new tau 5037ms [Q B]
time 180646ms: Process C switching out of CPU; blocking on I/O until time 182876ms [Q B]
time 180650ms: Process B (tau 1861ms) started using the CPU for 615ms burst [Q <empty>]
time 181265ms: Process B terminated [Q <empty>]
time 182876ms: Process C (tau 5037ms) completed I/O; added to ready queue [Q C]
time 182878ms: Process C (tau 5037ms) started using the CPU for 7564ms burst [Q <empty>]
time 190442ms: Process C (tau 5037ms) completed a CPU burst; 31 bursts to go [Q <empty>]
time 190442ms: Recalculating tau for process C: old tau 5037ms ==> new tau 6933ms [Q <empty>]
time 190442ms: Process C switching out of CPU; blocking on I/O until time 191666ms [Q <empty>]
time 191666ms: Process C (tau 6933ms) completed I/O; added to ready queue [Q C]
time 191668ms: Process C (tau 6933ms) started using the CPU for 3724ms burst [Q <empty>]
time 195392ms: Process C (tau 6933ms) completed a CPU burst; 30 bursts to go [Q <empty>]
time 195392ms: Recalculating tau for process C: old tau 6933ms ==> new tau 4527ms [Q <empty>]
time 195392ms: Process C switching out of CPU; blocking on I/O until time 195515ms [Q <empty>]
time 195515ms: Process C (tau 4527ms) completed I/O; added to ready queue [Q C]
time 195517ms: Process C (tau 4527ms) started using the CPU for 1608ms burst [Q <empty>]
time 197125ms: Process C (tau 4527ms) completed a CPU burst; 29 bursts to go [Q <empty>]
time 197125ms: Recalculating tau for process C: old tau 4527ms ==> new tau 2338ms [Q <empty>]
time 197125ms: Process C switching out of CPU; blocking on I/O until time 197562ms [Q <empty>]
time 197562ms: Process C (tau 2338ms) completed I/O; added to ready queue [Q C]
time 197564ms: Process C (tau 2338ms) started using the CPU for 6880ms burst [Q <empty>]
time 204444ms: Process C (tau 2338ms) completed a CPU burst; 28 bursts to go [Q <empty>]
time 204444ms: Recalculating tau for process C: old tau 2338ms ==> new tau 5745ms [Q <empty>]
time 204444ms: Process C switching out of CPU; blocking on I/O until time 205923ms [Q <empty>]
time 205923ms: Process C (tau 5745ms) completed I/O; added to ready queue [Q C]
time 205925ms: Process C (tau 5745ms) started using the CPU for 972ms burst [Q <empty>]
time 206897ms: Process C (tau 5745ms) completed a CPU burst; 27 bursts to go [Q <empty>]
time 206897ms: Recalculating tau for process C: old tau 5745ms ==> new tau 2166ms [Q <empty>]
time 206897ms: Process C switching out of CPU; blocking on I/O until time 207216ms [Q <empty>]
time 207216ms: Process C (tau 2166ms) completed I/O; added to ready queue [Q C]
time 207218ms: Process C (tau 2166ms) started using the CPU for 176ms burst [Q <empty>]
time 207394ms: Process C (tau 2166ms) completed a CPU burst; 26 bursts to go [Q <empty>]
time 207394ms: Recalculating tau for process C: old tau 2166ms ==> new tau 674ms [Q <empty>]
time 207394ms: Process C switching out of CPU; blocking on I/O until time 209522ms [Q <empty>]
time 209522ms: Process C (tau 674ms) completed I/O; added to ready queue [Q C]
time 209524ms: Process C (tau 674ms) started using the CPU for 412ms burst [Q <empty>]
time 209936ms: Process C (tau 674ms) completed a CPU burst; 25 bursts to go [Q <empty>]
time 209936ms: Recalculating tau for process C: old tau 674ms ==> new tau 478ms [Q <empty>]
time 209936ms: Process C switching out of CPU; blocking on I/O until time 210503ms [Q <empty>]
time 210503ms: Process C (tau 478ms) completed I/O; added to ready queue [Q C]
time 210505ms: Process C (tau 478ms) started using the CPU for 576ms burst [Q <empty>]
time 211081ms: Process C (tau 478ms) completed a CPU burst; 24 bursts to go [Q <empty>]
time 211081ms: Recalculating tau for process C: old tau 478ms ==> new tau 552ms [Q <empty>]
time 211081ms: Process C switching out of CPU; blocking on I/O until time 211154ms [Q <empty>]
time 211154ms: Process C (tau 552ms) completed I/O; added to ready queue [Q C]
time 211156ms: Process C (tau 552ms) started using the CPU for 4928ms burst [Q <empty>]
time 216084ms: Process C (tau 552ms) completed a CPU burst; 23 bursts to go [Q <empty>]
time 216084ms: Recalculating tau for process C: old tau 552ms ==> new tau 3834ms [Q <empty>]
time 216084ms: Process C switching out of CPU; blocking on I/O until time 216788ms [Q <empty>]
time 216788ms: Process C (tau 3834ms) completed I/O; added to ready queue [Q C]
time 216790ms: Process C (tau 3834ms) started using the CPU for 2804ms burst [Q <empty>]
time 219594ms: Process C (tau 3834ms) completed a CPU burst; 22 bursts to go [Q <empty>]
time 219594ms: Recalculating tau for process C: old tau 3834ms ==> new tau 3062ms [Q <empty>]
time 219594ms: Process C switching out of CPU; blocking on I/O until time 220614ms [Q <empty>]
time 220614ms: Process C (tau 3062ms) completed I/O; added to ready queue [Q C]
time 220616ms: Process C (tau 3062ms) started using the CPU for 2120ms burst [Q <empty>]
time 222736ms: Process C (tau 3062ms) completed a CPU burst; 21 bursts to go [Q <empty>]
time 222736ms: Recalculating tau for process C: old tau 3062ms ==> new tau 2356ms [Q <empty>]
time 222736ms: Process C switching out of CPU; blocking on I/O until time 224600ms [Q <empty>]
time 224600ms: Process C (tau 2356ms) completed I/O; added to ready queue [Q C]
time 224602ms: Process C (tau 2356ms) started using the CPU for 1944ms burst [Q <empty>]
time 226546ms: Process C (tau 2356ms) completed a CPU burst; 20 bursts to go [Q <empty>]
time 226546ms: Recalculating tau for process C: old tau 2356ms ==> new tau 2047ms [Q <empty>]
time 226546ms: Process C switching out of CPU; blocking on I/O until time 226551ms [Q <empty>]
time 226551ms: Process C (tau 2047ms) completed I/O; added to ready queue [Q C]
time 226553ms: Process C (tau 2047ms) started using the CPU for 2472ms burst [Q <empty>]
time 229025ms: Process C (tau 2047ms) completed a CPU burst; 19 bursts to go [Q <empty>]
time 229025ms: Recalculating tau for process C: old tau 2047ms ==> new tau 2366ms [Q <empty>]
time 229025ms: Process C switching out of CPU; blocking on I/O until time 229215ms [Q <empty>]
time 229215ms: Process C (tau 2366ms) completed I/O; added to ready queue [Q C]
time 229217ms: Process C (tau 2366ms) started using the CPU for 868ms burst [Q <empty>]
time 230085ms: Process C (tau 2366ms) completed a CPU burst; 18 bursts to go [Q <empty>]
time 230085ms: Recalculating tau for process C: old tau 2366ms ==> new tau 1243ms [Q <empty>]
time 230085ms: Process C switching out of CPU; blocking on I/O until time 231110ms [Q <empty>]
time 231110ms: Process C (tau 1243ms) completed I/O; added to ready queue [Q C]
time 231112ms: Process C (tau 1243ms) started using the CPU for 3208ms burst [Q <empty>]
time 234320ms: Process C (tau 1243ms) completed a CPU burst; 17 bursts to go [Q <empty>]
time 234320ms: Recalculating tau for process C: old tau 1243ms ==> new tau 2717ms [Q <empty>]
time 234320ms: Process C switching out of CPU; blocking on I/O until time 235425ms [Q <empty>]
time 235425ms: Process C (tau 2717ms) completed I/O; added to ready queue [Q C]
time 235427ms: Process C (tau 2717ms) started using the CPU for 1672ms burst [Q <empty>]
time 237099ms: Process C (tau 2717ms) completed a CPU burst; 16 bursts to go [Q <empty>]
time 237099ms: Recalculating tau for process C: old tau 2717ms ==> new tau 1934ms [Q <empty>]
time 237099ms: Process C switching out of CPU; blocking on I/O until time 239678ms [Q <empty>]
time 239678ms: Process C (tau 1934ms) completed I/O; added to ready queue [Q C]
time 239680ms: Process C (tau 1934ms) started using the CPU for 3536ms burst [Q <empty>]
time 243216ms: Process C (tau 1934ms) completed a CPU burst; 15 bursts to go [Q <empty>]
time 243216ms: Recalculating tau for process C: old tau 1934ms ==> new tau 3136ms [Q <empty>]
time 243216ms: Process C switching out of CPU; blocking on I/O until time 246755ms [Q <empty>]
time 246755ms: Process C (tau 3136ms) completed I/O; added to ready queue [Q C]
time 246757ms: Process C (tau 3136ms) started using the CPU for 2988ms burst [Q <empty>]
time 249745ms: Process C (tau 3136ms) completed a CPU burst; 14 bursts to go [Q <empty>]
time 249745ms: Recalculating tau for process C: old tau 3136ms ==> new tau 3025ms [Q <empty>]
time 249745ms: Process C switching out of CPU; blocking on I/O until time 251823ms [Q <empty>]
time 251823ms: Process C (tau 3025ms) completed I/O; added to ready queue [Q C]
time 251825ms: Process C (tau 3025ms) started using the CPU for 7804ms burst [Q <empty>]
time 259629ms: Process C (tau 3025ms) completed a CPU burst; 13 bursts to go [Q <empty>]
time 259629ms: Recalculating tau for process C: old tau 3025ms ==> new tau 6610ms [Q <empty>]
time 259629ms: Process C switching out of CPU; blocking on I/O until time 260898ms [Q <empty>]
time 260898ms: Process C (tau 6610ms) completed I/O; added to ready queue [Q C]
time 260900ms: Process C (tau 6610ms) started using the CPU for 5608ms burst [Q <empty>]
time 266508ms: Process C (tau 6610ms) completed a CPU burst; 12 bursts to go [Q <empty>]
time 266508ms: Recalculating tau for process C: old tau 6610ms ==> new tau 5859ms [Q <empty>]
time 266508ms: Process C switching out of CPU; blocking on I/O until time 266807ms [Q <empty>]
time 266807ms: Process C (tau 5859ms) completed I/O; added to ready queue [Q C]
time 266809ms: Process C (tau 5859ms) started using the CPU for 1160ms burst [Q <empty>]
time 267969ms: Process C (tau 5859ms) completed a CPU burst; 11 bursts to go [Q <empty>]
time 267969ms: Recalculating tau for process C: old tau 5859ms ==> new tau 2335ms [Q <empty>]
time 267969ms: Process C switching out of CPU; blocking on I/O until time 268612ms [Q <empty>]
time 268612ms: Process C (tau 2335ms) completed I/O; added to ready queue [Q C]
time 268614ms: Process C (tau 2335ms) started using the CPU for 3048ms burst [Q <empty>]
time 271662ms: Process C (tau 2335ms) completed a CPU burst; 10 bursts to go [Q <empty>]
time 271662ms: Recalculating tau for process C: old tau 2335ms ==> new tau 2870ms [Q <empty>]
time 271662ms: Process C switching out of CPU; blocking on I/O until time 271675ms [Q <empty>]
time 271675ms: Process C (tau 2870ms) completed I/O; added to ready queue [Q C]
time 271677ms: Process C (tau 2870ms) started using the CPU for 1120ms burst [Q <empty>]
time 272797ms: Process C (tau 2870ms) completed a CPU burst; 9 bursts to go [Q <empty>]
time 272797ms: Recalculating tau for process C: old tau 2870ms ==> new tau 1558ms [Q <empty>]
time 272797ms: Process C switching out of CPU; blocking on I/O until time 273546ms [Q <empty>]
time 273546ms: Process C (tau 1558ms) completed I/O; added to ready queue [Q C]
time 273548ms: Process C (tau 1558ms) started using the CPU for 8872ms burst [Q <empty>]
time 282420ms: Process C (tau 1558ms) completed a CPU burst; 8 bursts to go [Q <empty>]
time 282420ms: Recalculating tau for process C: old tau 1558ms ==> new tau 7044ms [Q <empty>]
time 282420ms: Process C switching out of CPU; blocking on I/O until time 284865ms [Q <empty>]
time 284865ms: Process C (tau 7044ms) completed I/O; added to ready queue [Q C]
time 284867ms: Process C (tau 7044ms) started using the CPU for 3112ms burst [Q <empty>]
time 287979ms: Process C (tau 7044ms) completed a CPU burst; 7 bursts to go [Q <empty>]
time 287979ms: Recalculating tau for process C: old tau 7044ms ==> new tau 4095ms [Q <empty>]
time 287979ms: Process C switching out of CPU; blocking on I/O until time 288649ms [Q <empty>]
time 288649ms: Process C (tau 4095ms) completed I/O; added to ready queue [Q C]
time 288651ms: Process C (tau 4095ms) started using the CPU for 1904ms burst [Q <empty>]
time 290555ms: Process C (tau 4095ms) completed a CPU burst; 6 bursts to go [Q <empty>]
time 290555ms: Recalculating tau for process C: old tau 4095ms ==> new tau 2452ms [Q <empty>]
time 290555ms: Process C switching out of CPU; blocking on I/O until time 291274ms [Q <empty>]
time 291274ms: Process C (tau 2452ms) completed I/O; added to ready queue [Q C]
time 291276ms: Process C (tau 2452ms) started using the CPU for 5488ms burst [Q <empty>]
time 296764ms: Process C (tau 2452ms) completed a CPU burst; 5 bursts to go [Q <empty>]
time 296764ms: Recalculating tau for process C: old tau 2452ms ==> new tau 4729ms [Q <empty>]
time 296764ms: Process C switching out of CPU; blocking on I/O until time 299441ms [Q <empty>]
time 299441ms: Process C (tau 4729ms) completed I/O; added to ready queue [Q C]
time 299443ms: Process C (tau 4729ms) started using the CPU for 3340ms burst [Q <empty>]
time 302783ms: Process C (tau 4729ms) completed a CPU burst; 4 bursts to go [Q <empty>]
time 302783ms: Recalculating tau for process C: old tau 4729ms ==> new tau 3688ms [Q <empty>]
time 302783ms: Process C switching out of CPU; blocking on I/O until time 303227ms [Q <empty>]
time 303227ms: Process C (tau 3688ms) completed I/O; added to ready queue [Q C]
time 303229ms: Process C (tau 3688ms) started using the CPU for 7076ms burst [Q <empty>]
time 310305ms: Process C (tau 3688ms) completed a CPU burst; 3 bursts to go [Q <empty>]
time 310305ms: Recalculating tau for process C: old tau 3688ms ==> new tau 6229ms [Q <empty>]
time 310305ms: Process C switching out of CPU; blocking on I/O until time 311094ms [Q <empty>]
time 311094ms: Process C (tau 6229ms) completed I/O; added to ready queue [Q C]
time 311096ms: Process C (tau 6229ms) started using the CPU for 9540ms burst [Q <empty>]
time 320636ms: Process C (tau 6229ms) completed a CPU burst; 2 bursts to go [Q <empty>]
time 320636ms: Recalculating tau for process C: old tau 6229ms ==> new tau 8713ms [Q <empty>]
time 320636ms: Process C switching out of CPU; blocking on I/O until time 320679ms [Q <empty>]
time 320679ms: Process C (tau 8713ms) completed I/O; added to ready queue [Q C]
time 320681ms: Process C (tau 8713ms) started using the CPU for 1784ms burst [Q <empty>]
time 322465ms: Process C (tau 8713ms) completed a CPU burst; 1 burst to go [Q <empty>]
time 322465ms: Recalculating tau for process C: old tau 8713ms ==> new tau 3517ms [Q <empty>]
time 322465ms: Process C switching out of CPU; blocking on I/O until time 323093ms [Q <empty>]
time 323093ms: Process C (tau 3517ms) completed I/O; added to ready queue [Q C]
time 323095ms: Process C (tau 3517ms) started using the CPU for 1704ms burst [Q <empty>]
time 324799ms: Process C terminated [Q <empty>]
time 324801ms: Simulator ended for SJF [Q <empty>]

time 0ms: Simulator started for SRT [Q <empty>]
time 26ms: Process C (tau 1000ms) arrived; added to ready queue [Q C]
time 28ms: Process C (tau 1000ms) started using the CPU for 2920ms burst [Q <empty>]
time 136ms: Process A (tau 1000ms) arrived; added to ready queue [Q A]
time 929ms: Process B (tau 1000ms) arrived; added to ready queue [Q A B]
time 2948ms: Process C (tau 1000ms) completed a CPU burst; 59 bursts to go [Q A B]
time 2948ms: Recalculating tau for process C: old tau 1000ms ==> new tau 2440ms [Q A B]
time 2948ms: Process C switching out of CPU; blocking on I/O until time 3318ms [Q A B]
time 2952ms: Process A (tau 1000ms) started using the CPU for 1330ms burst [Q B]
time 3318ms: Process C (tau 2440ms) completed I/O; added to ready queue [Q B C]
time 4282ms: Process A (tau 1000ms) completed a CPU burst; 16 bursts to go [Q B C]
time 4282ms: Recalculating tau for process A: old tau 1000ms ==> new tau 1248ms [Q B C]
time 4282ms: Process A switching out of CPU; blocking on I/O until time 10024ms [Q B C]
time 4286ms: Process B (tau 1000ms) started using the CPU for 2438ms burst [Q C]
time 6724ms: Process B (tau 1000ms) completed a CPU burst; 11 bursts to go [Q C]
time 6724ms: Recalculating tau for process B: old tau 1000ms ==> new tau 2079ms [Q C]
time 6724ms: Process B switching out of CPU; blocking on I/O until time 7606ms [Q C]
time 6728ms: Process C (tau 2440ms) started using the CPU for 2328ms burst [Q <empty>]
time 7606ms: Process B (tau 2079ms) completed I/O; added to ready queue [Q B]
time 9056ms: Process C (tau 2440ms) completed a CPU burst; 58 bursts to go [Q B]
time 9056ms: Recalculating tau for process C: old tau 2440ms ==> new tau 2356ms [Q B]
time 9056ms: Process C switching out of CPU; blocking on I/O until time 12170ms [Q B]
time 9060ms: Process B (tau 2079ms) started using the CPU for 1173ms burst [Q <empty>]
time 10024ms: Process A (tau 1248ms) completed I/O; added to ready queue [Q A]
time 10233ms: Process B (tau 2079ms) completed a CPU burst; 10 bursts to go [Q A]
time 10233ms: Recalculating tau for process B: old tau 2079ms ==> new tau 1400ms [Q A]
time 10233ms: Process B switching out of CPU; blocking on I/O until time 10775ms [Q A]
time 10237ms: Process A (tau 1248ms) started using the CPU for 735ms burst [Q <empty>]
time 10775ms: Process B (tau 1400ms) completed I/O; added to ready queue [Q B]
time 10972ms: Process A (tau 1248ms) completed a CPU burst; 15 bursts to go [Q B]
time 10972ms: Recalculating tau for process A: old tau 1248ms ==> new tau 864ms [Q B]
time 10972ms: Process A switching out of CPU; blocking on I/O until time 11634ms [Q B]
time 10976ms: Process B (tau 1400ms) started using the CPU for 492ms burst [Q <empty>]
time 11468ms: Process B (tau 1400ms) completed a CPU burst; 9 bursts to go [Q <empty>]
time 11468ms: Recalculating tau for process B: old tau 1400ms ==> new tau 719ms [Q <empty>]
time 11468ms: Process B switching out of CPU; blocking on I/O until time 23820ms [Q <empty>]
time 11634ms: Process A (tau 864ms) completed I/O; added to ready queue [Q A]
time 11636ms: Process A (tau 864ms) started using the CPU for 24ms burst [Q <empty>]
time 11660ms: Process A (tau 864ms) completed a CPU burst; 14 bursts to go [Q <empty>]
time 11660ms: Recalculating tau for process A: old tau 864ms ==> new tau 234ms [Q <empty>]
time 11660ms: Process A switching out of CPU; blocking on I/O until time 12112ms [Q <empty>]
time 12112ms: Process A (tau 234ms) completed I/O; added to ready queue [Q A]
time 12114ms: Process A (tau 234ms) started using the CPU for 683ms burst [Q <empty>]
time 12170ms: Process C (tau 2356ms) completed I/O; added to ready queue [Q C]
time 12797ms: Process A (tau 234ms) completed a CPU burst; 13 bursts to go [Q C]
time 12797ms: Recalculating tau for process A: old tau 234ms ==> new tau 571ms [Q C]
time 12797ms: Process A switching out of CPU; blocking on I/O until time 14649ms [Q C]
time 12801ms: Process C (tau 2356ms) started using the CPU for 1180ms burst [Q <empty>]
time 13981ms: Process C (tau 2356ms) completed a CPU burst; 57 bursts to go [Q <empty>]
time 13981ms: Recalculating tau for process C: old tau 2356ms ==> new tau 1474ms [Q <empty>]
time 13981ms: Process C switching out of CPU; blocking on I/O until time 15303ms [Q <empty>]
time 14649ms: Process A (tau 571ms) completed I/O; added to ready queue [Q A]
time 14651ms: Process A (tau 571ms) started using the CPU for 1100ms burst [Q <empty>]
time 15303ms: Process C (tau 1474ms) completed I/O; added to ready queue [Q C]
time 15751ms: Process A (tau 571ms) completed a CPU burst; 12 bursts to go [Q C]
time 15751ms: Recalculating tau for process A: old tau 571ms ==> new tau 968ms [Q C]
time 15751ms: Process A switching out of CPU; blocking on I/O until time 29973ms [Q C]
time 15755ms: Process C (tau 1474ms) started using the CPU for 11336ms burst [Q <empty>]
time 23820ms: Process B (tau 719ms) completed I/O; added to ready queue [Q B]
time 27091ms: Process C (tau 1474ms) completed a CPU burst; 56 bursts to go [Q B]
time 27091ms: Recalculating tau for process C: old tau 1474ms ==> new tau 8871ms [Q B]
time 27091ms: Process C switching out of CPU; blocking on I/O until time 27769ms [Q B]
time 27095ms: Process B (tau 719ms) started using the CPU for 2670ms burst [Q <empty>]
time 27769ms: Process C (tau 8871ms) completed I/O; added to ready queue [Q C]
time 29765ms: Process B (tau 719ms) completed a CPU burst; 8 bursts to go [Q C]
time 29765ms: Recalculating tau for process B: old tau 719ms ==> new tau 2183ms [Q C]
time 29765ms: Process B switching out of CPU; blocking on I/O until time 34827ms [Q C]
time 29769ms: Process C (tau 8871ms) started using the CPU for 5132ms burst [Q <empty>]
time 29973ms: Process A (tau 968ms) completed I/O; preempting C [Q A]
time 29977ms: Process A (tau 968ms) started using the CPU for 1000ms burst [Q C]
time 30977ms: Process A (tau 968ms) completed a CPU burst; 11 bursts to go [Q C]
time 30977ms: Recalculating tau for process A: old tau 968ms ==> new tau 992ms [Q C]
time 30977ms: Process A switching out of CPU; blocking on I/O until time 37929ms [Q C]
time 30981ms: Process C (tau 8871ms) started using the CPU for remaining 4928ms of 5132ms burst [Q <empty>]
time 34827ms: Process B (tau 2183ms) completed I/O; preempting C [Q B]
time 34831ms: Process B (tau 2183ms) started using the CPU for 610ms burst [Q C]
time 35441ms: Process B (tau 2183ms) completed a CPU burst; 7 bursts to go [Q C]
time 35441ms: Recalculating tau for process B: old tau 2183ms ==> new tau 1004ms [Q C]
time 35441ms: Process B switching out of CPU; blocking on I/O until time 61263ms [Q C]
time 35445ms: Process C (tau 8871ms) started using the CPU for remaining 1082ms of 5132ms burst [Q <empty>]
time 36527ms: Process C (tau 8871ms) completed a CPU burst; 55 bursts to go [Q <empty>]
time 36527ms: Recalculating tau for process C: old tau 8871ms ==> new tau 6067ms [Q <empty>]
time 36527ms: Process C switching out of CPU; blocking on I/O until time 38376ms [Q <empty>]
time 37929ms: Process A (tau 992ms) completed I/O; added to ready queue [Q A]
time 37931ms: Process A (tau 992ms) started using the CPU for 1166ms burst [Q <empty>]
time 38376ms: Process C (tau 6067ms) completed I/O; added to ready queue [Q C]
time 39097ms: Process A (tau 992ms) completed a CPU burst; 10 bursts to go [Q C]
time 39097ms: Recalculating tau for process A: old tau 992ms ==> new tau 1123ms [Q C]
time 39097ms: Process A switching out of CPU; blocking on I/O until time 44389ms [Q C]
time 39101ms: Process C (tau 6067ms) started using the CPU for 2896ms burst [Q <empty>]
time 41997ms: Process C (tau 6067ms) completed a CPU burst; 54 bursts to go [Q <empty>]
time 41997ms: Recalculating tau for process C: old tau 6067ms ==> new tau 3689ms [Q <empty>]
time 41997ms: Process C switching out of CPU; blocking on I/O until time 45317ms [Q <empty>]
time 44389ms: Process A (tau 1123ms) completed I/O; added to ready queue [Q A]
time 44391ms: Process A (tau 1123ms) started using the CPU for 1561ms burst [Q <empty>]
time 45317ms: Process C (tau 3689ms) completed I/O; added to ready queue [Q C]
time 45952ms: Process A (tau 1123ms) completed a CPU burst; 9 bursts to go [Q C]
time 45952ms: Recalculating tau for process A: old tau 1123ms ==> new tau 1452ms [Q C]
time 45952ms: Process A switching out of CPU; blocking on I/O until time 48774ms [Q C]
time 45956ms: Process C (tau 3689ms) started using the CPU for 160ms burst [Q <empty>]
time 46116ms: Process C (tau 3689ms) completed a CPU burst; 53 bursts to go [Q <empty>]
time 46116ms: Recalculating tau for process C: old tau 3689ms ==> new tau 1043ms [Q <empty>]
time 46116ms: Process C switching out of CPU; blocking on I/O until time 47913ms [Q <empty>]
time 47913ms: Process C (tau 1043ms) completed I/O; added to ready queue [Q C]
time 47915ms: Process C (tau 1043ms) started using the CPU for 2968ms burst [Q <empty>]
time 48774ms: Process A (tau 1452ms) completed I/O; added to ready queue [Q A]
time 50883ms: Process C (tau 1043ms) completed a CPU burst; 52 bursts to go [Q A]
time 50883ms: Recalculating tau for process C: old tau 1043ms ==> new tau 2487ms [Q A]
time 50883ms: Process C switching out of CPU; blocking on I/O until time 51928ms [Q A]
time 50887ms: Process A (tau 1452ms) started using the CPU for 149ms burst [Q <empty>]
time 51036ms: Process A (tau 1452ms) completed a CPU burst; 8 bursts to go [Q <empty>]
time 51036ms: Recalculating tau for process A: old tau 1452ms ==> new tau 475ms [Q <empty>]
time 51036ms: Process A switching out of CPU; blocking on I/O until time 51758ms [Q <empty>]
time 51758ms: Process A (tau 475ms) completed I/O; added to ready queue [Q A]
time 51760ms: Process A (tau 475ms) started using the CPU for 388ms burst [Q <empty>]
time 51928ms: Process C (tau 2487ms) completed I/O; added to ready queue [Q C]
time 52148ms: Process A (tau 475ms) completed a CPU burst; 7 bursts to go [Q C]
time 52148ms: Recalculating tau for process A: old tau 475ms ==> new tau 410ms [Q C]
time 52148ms: Process A switching out of CPU; blocking on I/O until time 59520ms [Q C]
time 52152ms: Process C (tau 2487ms) started using the CPU for 4428ms burst [Q <empty>]
time 56580ms: Process C (tau 2487ms) completed a CPU burst; 51 bursts to go [Q <empty>]
time 56580ms: Recalculating tau for process C: old tau 2487ms ==> new tau 3943ms [Q <empty>]
time 56580ms: Process C switching out of CPU; blocking on I/O until time 57859ms [Q <empty>]
time 57859ms: Process C (tau 3943ms) completed I/O; added to ready queue [Q C]
time 57861ms: Process C (tau 3943ms) started using the CPU for 7280ms burst [Q <empty>]
time 59520ms: Process A (tau 410ms) completed I/O; preempting C [Q A]
time 59524ms: Process A (tau 410ms) started using the CPU for 34ms burst [Q C]
time 59558ms: Process A (tau 410ms) completed a CPU burst; 6 bursts to go [Q C]
time 59558ms: Recalculating tau for process A: old tau 410ms ==> new tau 128ms [Q C]
time 59558ms: Process A switching out of CPU; blocking on I/O until time 69100ms [Q C]
time 59562ms: Process C (tau 3943ms) started using the CPU for remaining 5621ms of 7280ms burst [Q <empty>]
time 61263ms: Process B (tau 1004ms) completed I/O; added to ready queue [Q B]
time 65183ms: Process C (tau 3943ms) completed a CPU burst; 50 bursts to go [Q B]
time 65183ms: Recalculating tau for process C: old tau 3943ms ==> new tau 6446ms [Q B]
time 65183ms: Process C switching out of CPU; blocking on I/O until time 65802ms [Q B]
time 65187ms: Process B (tau 1004ms) started using the CPU for 1452ms burst [Q <empty>]
time 65802ms: Process C (tau 6446ms) completed I/O; added to ready queue [Q C]
time 66639ms: Process B (tau 1004ms) completed a CPU burst; 6 bursts to go [Q C]
time 66639ms: Recalculating tau for process B: old tau 1004ms ==> new tau 1340ms [Q C]
time 66639ms: Process B switching out of CPU; blocking on I/O until time 71291ms [Q C]
time 66643ms: Process C (tau 6446ms) started using the CPU for 7180ms burst [Q <empty>]
time 69100ms: Process A (tau 128ms) completed I/O; preempting C [Q A]
time 69104ms: Process A (tau 128ms) started using the CPU for 954ms burst [Q C]
time 70058ms: Process A (tau 128ms) completed a CPU burst; 5 bursts to go [Q C]
time 70058ms: Recalculating tau for process A: old tau 128ms ==> new tau 748ms [Q C]
time 70058ms: Process A switching out of CPU; blocking on I/O until time 80020ms [Q C]
time 70062ms: Process C (tau 6446ms) started using the CPU for remaining 4723ms of 7180ms burst [Q <empty>]
time 71291ms: Process B (tau 1340ms) completed I/O; preempting C [Q B]
time 71295ms: Process B (tau 1340ms) started using the CPU for 878ms burst [Q C]
time 72173ms: Process B (tau 1340ms) completed a CPU burst; 5 bursts to go [Q C]
time 72173ms: Recalculating tau for process B: old tau 1340ms ==> new tau 994ms [Q C]
time 72173ms: Process B switching out of CPU; blocking on I/O until time 84155ms [Q C]
time 72177ms: Process C (tau 6446ms) started using the CPU for remaining 3494ms of 7180ms burst [Q <empty>]
time 75671ms: Process C (tau 6446ms) completed a CPU burst; 49 bursts to go [Q <empty>]
time 75671ms: Recalculating tau for process C: old tau 6446ms ==> new tau 6997ms [Q <empty>]
time 75671ms: Process C switching out of CPU; blocking on I/O until time 77219ms [Q <empty>]
time 77219ms: Process C (tau 6997ms) completed I/O; added to ready queue [Q C]
time 77221ms: Process C (tau 6997ms) started using the CPU for 8120ms burst [Q <empty>]
time 80020ms: Process A (tau 748ms) completed I/O; preempting C [Q A]
time 80024ms: Process A (tau 748ms) started using the CPU for 236ms burst [Q C]
time 80260ms: Process A (tau 748ms) completed a CPU burst; 4 bursts to go [Q C]
time 80260ms: Recalculating tau for process A: old tau 748ms ==> new tau 364ms [Q C]
time 80260ms: Process A switching out of CPU; blocking on I/O until time 97272ms [Q C]
time 80264ms: Process C (tau 6997ms) started using the CPU for remaining 5321ms of 8120ms burst [Q <empty>]
time 84155ms: Process B (tau 994ms) completed I/O; added to ready queue [Q B]
time 85585ms: Process C (tau 6997ms) completed a CPU burst; 48 bursts to go [Q B]
time 85585ms: Recalculating tau for process C: old tau 6997ms ==> new tau 7840ms [Q B]
time 85585ms: Process C switching out of CPU; blocking on I/O until time 87145ms [Q B]
time 85589ms: Process B (tau 994ms) started using the CPU for 1999ms burst [Q <empty>]
time 87145ms: Process C (tau 7840ms) completed I/O; added to ready queue [Q C]
time 87588ms: Process B (tau 994ms) completed a CPU burst; 4 bursts to go [Q C]
time 87588ms: Recalculating tau for process B: old tau 994ms ==> new tau 1748ms [Q C]
time 87588ms: Process B switching out of CPU; blocking on I/O until time 95610ms [Q C]
time 87592ms: Process C (tau 7840ms) started using the CPU for 692ms burst [Q <empty>]
time 88284ms: Process C (tau 7840ms) completed a CPU burst; 47 bursts to go [Q <empty>]
time 88284ms: Recalculating tau for process C: old tau 7840ms ==> new tau 2479ms [Q <empty>]
time 88284ms: Process C switching out of CPU; blocking on I/O until time 88881ms [Q <empty>]
time 88881ms: Process C (tau 2479ms) completed I/O; added to ready queue [Q C]
time 88883ms: Process C (tau 2479ms) started using the CPU for 3172ms burst [Q <empty>]
time 92055ms: Process C (tau 2479ms) completed a CPU burst; 46 bursts to go [Q <empty>]
time 92055ms: Recalculating tau for process C: old tau 2479ms ==> new tau 2999ms [Q <empty>]
time 92055ms: Process C switching out of CPU; blocking on I/O until time 92503ms [Q <empty>]
time 92503ms: Process C (tau 2999ms) completed I/O; added to ready queue [Q C]
time 92505ms: Process C (tau 2999ms) started using the CPU for 7724ms burst [Q <empty>]
time 95610ms: Process B (tau 1748ms) completed I/O; added to ready queue [Q B]
time 97272ms: Process A (tau 364ms) completed I/O; added to ready queue [Q A B]
time 100229ms: Process C (tau 2999ms) completed a CPU burst; 45 bursts to go [Q A B]
time 100229ms: Recalculating tau for process C: old tau 2999ms ==> new tau 6543ms [Q A B]
time 100229ms: Process C switching out of CPU; blocking on I/O until time 101046ms [Q A B]
time 100233ms: Process A (tau 364ms) started using the CPU for 734ms burst [Q B]
time 100967ms: Process A (tau 364ms) completed a CPU burst; 3 bursts to go [Q B]
time 100967ms: Recalculating tau for process A: old tau 364ms ==> new tau 642ms [Q B]
time 100967ms: Process A switching out of CPU; blocking on I/O until time 106819ms [Q B]
time 100971ms: Process B (tau 1748ms) started using the CPU for 1970ms burst [Q <empty>]
time 101046ms: Process C (tau 6543ms) completed I/O; added to ready queue [Q C]
time 102941ms: Process B (tau 1748ms) completed a CPU burst; 3 bursts to go [Q C]
time 102941ms: Recalculating tau for process B: old tau 1748ms ==> new tau 1915ms [Q C]
time 102941ms: Process B switching out of CPU; blocking on I/O until time 116003ms [Q C]
time 102945ms: Process C (tau 6543ms) started using the CPU for 3628ms burst [Q <empty>]
time 106573ms: Process C (tau 6543ms) completed a CPU burst; 44 bursts to go [Q <empty>]
time 106573ms: Recalculating tau for process C: old tau 6543ms ==> new tau 4357ms [Q <empty>]
time 106573ms: Process C switching out of CPU; blocking on I/O until time 106633ms [Q <empty>]
time 106633ms: Process C (tau 4357ms) completed I/O; added to ready queue [Q C]
time 106635ms: Process C (tau 4357ms) started using the CPU for 2696ms burst [Q <empty>]
time 106819ms: Process A (tau 642ms) completed I/O; preempting C [Q A]
time 106823ms: Process A (tau 642ms) started using the CPU for 1124ms burst [Q C]
time 107947ms: Process A (tau 642ms) completed a CPU burst; 2 bursts to go [Q C]
time 107947ms: Recalculating tau for process A: old tau 642ms ==> new tau 1004ms [Q C]
time 107947ms: Process A switching out of CPU; blocking on I/O until time 127589ms [Q C]
time 107951ms: Process C (tau 4357ms) started using the CPU for remaining 2512ms of 2696ms burst [Q <empty>]
time 110463ms: Process C (tau 4357ms) completed a CPU burst; 43 bursts to go [Q <empty>]
time 110463ms: Recalculating tau for process C: old tau 4357ms ==> new tau 3112ms [Q <empty>]
time 110463ms: Process C switching out of CPU; blocking on I/O until time 110496ms [Q <empty>]
time 110496ms: Process C (tau 3112ms) completed I/O; added to ready queue [Q C]
time 110498ms: Process C (tau 3112ms) started using the CPU for 9204ms burst [Q <empty>]
time 116003ms: Process B (tau 1915ms) completed I/O; added to ready queue [Q B]
time 119702ms: Process C (tau 3112ms) completed a CPU burst; 42 bursts to go [Q B]
time 119702ms: Recalculating tau for process C: old tau 3112ms ==> new tau 7681ms [Q B]
time 119702ms: Process C switching out of CPU; blocking on I/O until time 123091ms [Q B]
time 119706ms: Process B (tau 1915ms) started using the CPU for 303ms burst [Q <empty>]
time 120009ms: Process B (tau 1915ms) completed a CPU burst; 2 bursts to go [Q <empty>]
time 120009ms: Recalculating tau for process B: old tau 1915ms ==> new tau 706ms [Q <empty>]
time 120009ms: Process B switching out of CPU; blocking on I/O until time 149501ms [Q <empty>]
time 123091ms: Process C (tau 7681ms) completed I/O; added to ready queue [Q C]
time 123093ms: Process C (tau 7681ms) started using the CPU for 7356ms burst [Q <empty>]
time 127589ms: Process A (tau 1004ms) completed I/O; preempting C [Q A]
time 127593ms: Process A (tau 1004ms) started using the CPU for 62ms burst [Q C]
time 127655ms: Process A (tau 1004ms) completed a CPU burst; 1 burst to go [Q C]
time 127655ms: Recalculating tau for process A: old tau 1004ms ==> new tau 298ms [Q C]
time 127655ms: Process A switching out of CPU; blocking on I/O until time 130007ms [Q C]
time 127659ms: Process C (tau 7681ms) started using the CPU for remaining 2860ms of 7356ms burst [Q <empty>]
time 130007ms: Process A (tau 298ms) completed I/O; preempting C [Q A]
time 130011ms: Process A (tau 298ms) started using the CPU for 647ms burst [Q C]
time 130658ms: Process A terminated [Q C]
time 130662ms: Process C (tau 7681ms) started using the CPU for remaining 512ms of 7356ms burst [Q <empty>]
time 131174ms: Process C (tau 7681ms) completed a CPU burst; 41 bursts to go [Q <empty>]
time 131174ms: Recalculating tau for process C: old tau 7681ms ==> new tau 7438ms [Q <empty>]
time 131174ms: Process C switching out of CPU; blocking on I/O until time 131986ms [Q <empty>]
time 131986ms: Process C (tau 7438ms) completed I/O; added to ready queue [Q C]
time 131988ms: Process C (tau 7438ms) started using the CPU for 676ms burst [Q <empty>]
time 132664ms: Process C (tau 7438ms) completed a CPU burst; 40 bursts to go [Q <empty>]
time 132664ms: Recalculating tau for process C: old tau 7438ms ==> new tau 2367ms [Q <empty>]
time 132664ms: Process C switching out of CPU; blocking on I/O until time 133011ms [Q <empty>]
time 133011ms: Process C (tau 2367ms) completed I/O; added to ready queue [Q C]
time 133013ms: Process C (tau 2367ms) started using the CPU for 4132ms burst [Q <empty>]
time 137145ms: Process C (tau 2367ms) completed a CPU burst; 39 bursts to go [Q <empty>]
time 137145ms: Recalculating tau for process C: old tau 2367ms ==> new tau 3691ms [Q <empty>]
time 137145ms: Process C switching out of CPU; blocking on I/O until time 137599ms [Q <empty>]
time 137599ms: Process C (tau 3691ms) completed I/O; added to ready queue [Q C]
time 137601ms: Process C (tau 3691ms) started using the CPU for 3364ms burst [Q <empty>]
time 140965ms: Process C (tau 3691ms) completed a CPU burst; 38 bursts to go [Q <empty>]
time 140965ms: Recalculating tau for process C: old tau 3691ms ==> new tau 3446ms [Q <empty>]
time 140965ms: Process C switching out of CPU; blocking on I/O until time 142640ms [Q <empty>]
time 142640ms: Process C (tau 3446ms) completed I/O; added to ready queue [Q C]
time 142642ms: Process C (tau 3446ms) started using the CPU for 6900ms burst [Q <empty>]
time 149501ms: Process B (tau 706ms) completed I/O; added to ready queue [Q B]
time 149542ms: Process C (tau 3446ms) completed a CPU burst; 37 bursts to go [Q B]
time 149542ms: Recalculating tau for process C: old tau 3446ms ==> new tau 6037ms [Q B]
time 149542ms: Process C switching out of CPU; blocking on I/O until time 151814ms [Q B]
time 149546ms: Process B (tau 706ms) started using the CPU for 2245ms burst [Q <empty>]
time 151791ms: Process B (tau 706ms) completed a CPU burst; 1 burst to go [Q <empty>]
time 151791ms: Recalculating tau for process B: old tau 706ms ==> new tau 1861ms [Q <empty>]
time 151791ms: Process B switching out of CPU; blocking on I/O until time 179303ms [Q <empty>]
time 151814ms: Process C (tau 6037ms) completed I/O; added to ready queue [Q C]
time 151816ms: Process C (tau 6037ms) started using the CPU for 6916ms burst [Q <empty>]
time 158732ms: Process C (tau 6037ms) completed a CPU burst; 36 bursts to go [Q <empty>]
time 158732ms: Recalculating tau for process C: old tau 6037ms ==> new tau 6697ms [Q <empty>]
time 158732ms: Process C switching out of CPU; blocking on I/O until time 159397ms [Q <empty>]
time 159397ms: Process C (tau 6697ms) completed I/O; added to ready queue [Q C]
time 159399ms: Process C (tau 6697ms) started using the CPU for 7244ms burst [Q <empty>]
time 166643ms: Process C (tau 6697ms) completed a CPU burst; 35 bursts to go [Q <empty>]
time 166643ms: Recalculating tau for process C: old tau 6697ms ==> new tau 7108ms [Q <empty>]
time 166643ms: Process C switching out of CPU; blocking on I/O until time 166800ms [Q <empty>]
time 166800ms: Process C (tau 7108ms) completed I/O; added to ready queue [Q C]
time 166802ms: Process C (tau 7108ms) started using the CPU for 2396ms burst [Q <empty>]
time 169198ms: Process C (tau 7108ms) completed a CPU burst; 34 bursts to go [Q <empty>]
time 169198ms: Recalculating tau for process C: old tau 7108ms ==> new tau 3574ms [Q <empty>]
time 169198ms: Process C switching out of CPU; blocking on I/O until time 169707ms [Q <empty>]
time 169707ms: Process C (tau 3574ms) completed I/O; added to ready queue [Q C]
time 169709ms: Process C (tau 3574ms) started using the CPU for 7736ms burst [Q <empty>]
time 177445ms: Process C (tau 3574ms) completed a CPU burst; 33 bursts to go [Q <empty>]
time 177445ms: Recalculating tau for process C: old tau 3574ms ==> new tau 6696ms [Q <empty>]
time 177445ms: Process C switching out of CPU; blocking on I/O until time 179250ms [Q <empty>]
time 179250ms: Process C (tau 6696ms) completed I/O; added to ready queue [Q C]
time 179252ms: Process C (tau 6696ms) started using the CPU for 4484ms burst [Q <empty>]
time 179303ms: Process B (tau 1861ms) completed I/O; preempting C [Q B]
time 179307ms: Process B (tau 1861ms) started using the CPU for 615ms burst [Q C]
time 179922ms: Process B terminated [Q C]
time 179926ms: Process C (tau 6696ms) started using the CPU for remaining 4433ms of 4484ms burst [Q <empty>]
time 184359ms: Process C (tau 6696ms) completed a CPU burst; 32 bursts to go [Q <empty>]
time 184359ms: Recalculating tau for process C: old tau 6696ms ==> new tau 5037ms [Q <empty>]
time 184359ms: Process C switching out of CPU; blocking on I/O until time 186589ms [Q <empty>]
time 186589ms: Process C (tau 5037ms) completed I/O; added to ready queue [Q C]
time 186591ms: Process C (tau 5037ms) started using the CPU for 7564ms burst [Q <empty>]
time 194155ms: Process C (tau 5037ms) completed a CPU burst; 31 bursts to go [Q <empty>]
time 194155ms: Recalculating tau for process C: old tau 5037ms ==> new tau 6933ms [Q <empty>]
time 194155ms: Process C switching out of CPU; blocking on I/O until time 195379ms [Q <empty>]
time 195379ms: Process C (tau 6933ms) completed I/O; added to ready queue [Q C]
time 195381ms: Process C (tau 6933ms) started using the CPU for 3724ms burst [Q <empty>]
time 199105ms: Process C (tau 6933ms) completed a CPU burst; 30 bursts to go [Q <empty>]
time 199105ms: Recalculating tau for process C: old tau 6933ms ==> new tau 4527ms [Q <empty>]
time 199105ms: Process C switching out of CPU; blocking on I/O until time 199228ms [Q <empty>]
time 199228ms: Process C (tau 4527ms) completed I/O; added to ready queue [Q C]
time 199230ms: Process C (tau 4527ms) started using the CPU for 1608ms burst [Q <empty>]
time 200838ms: Process C (tau 4527ms) completed a CPU burst; 29 bursts to go [Q <empty>]
time 200838ms: Recalculating tau for process C: old tau 4527ms ==> new tau 2338ms [Q <empty>]
time 200838ms: Process C switching out of CPU; blocking on I/O until time 201275ms [Q <empty>]
time 201275ms: Process C (tau 2338ms) completed I/O; added to ready queue [Q C]
time 201277ms: Process C (tau 2338ms) started using the CPU for 6880ms burst [Q <empty>]
time 208157ms: Process C (tau 2338ms) completed a CPU burst; 28 bursts to go [Q <empty>]
time 208157ms: Recalculating tau for process C: old tau 2338ms ==> new tau 5745ms [Q <empty>]
time 208157ms: Process C switching out of CPU; blocking on I/O until time 209636ms [Q <empty>]
time 209636ms: Process C (tau 5745ms) completed I/O; added to ready queue [Q C]
time 209638ms: Process C (tau 5745ms) started using the CPU for 972ms burst [Q <empty>]
time 210610ms: Process C (tau 5745ms) completed a CPU burst; 27 bursts to go [Q <empty>]
time 210610ms: Recalculating tau for process C: old tau 5745ms ==> new tau 2166ms [Q <empty>]
time 210610ms: Process C switching out of CPU; blocking on I/O until time 210929ms [Q <empty>]
time 210929ms: Process C (tau 2166ms) completed I/O; added to ready queue [Q C]
time 210931ms: Process C (tau 2166ms) started using the CPU for 176ms burst [Q <empty>]
time 211107ms: Process C (tau 2166ms) completed a CPU burst; 26 bursts to go [Q <empty>]
time 211107ms: Recalculating tau for process C: old tau 2166ms ==> new tau 674ms [Q <empty>]
time 211107ms: Process C switching out of CPU; blocking on I/O until time 213235ms [Q <empty>]
time 213235ms: Process C (tau 674ms) completed I/O; added to ready queue [Q C]
time 213237ms: Process C (tau 674ms) started using the CPU for 412ms burst [Q <empty>]
time 213649ms: Process C (tau 674ms) completed a CPU burst; 25 bursts to go [Q <empty>]
time 213649ms: Recalculating tau for process C: old tau 674ms ==> new tau 478ms [Q <empty>]
time 213649ms: Process C switching out of CPU; blocking on I/O until time 214216ms [Q <empty>]
time 214216ms: Process C (tau 478ms) completed I/O; added to ready queue [Q C]
time 214218ms: Process C (tau 478ms) started using the CPU for 576ms burst [Q <empty>]
time 214794ms: Process C (tau 478ms) completed a CPU burst; 24 bursts to go [Q <empty>]
time 214794ms: Recalculating tau for process C: old tau 478ms ==> new tau 552ms [Q <empty>]
time 214794ms: Process C switching out of CPU; blocking on I/O until time 214867ms [Q <empty>]
time 214867ms: Process C (tau 552ms) completed I/O; added to ready queue [Q C]
time 214869ms: Process C (tau 552ms) started using the CPU for 4928ms burst [Q <empty>]
time 219797ms: Process C (tau 552ms) completed a CPU burst; 23 bursts to go [Q <empty>]
time 219797ms: Recalculating tau for process C: old tau 552ms ==> new tau 3834ms [Q <empty>]
time 219797ms: Process C switching out of CPU; blocking on I/O until time 220501ms [Q <empty>]
time 220501ms: Process C (tau 3834ms) completed I/O; added to ready queue [Q C]
time 220503ms: Process C (tau 3834ms) started using the CPU for 2804ms burst [Q <empty>]
time 223307ms: Process C (tau 3834ms) completed a CPU burst; 22 bursts to go [Q <empty>]
time 223307ms: Recalculating tau for process C: old tau 3834ms ==> new tau 3062ms [Q <empty>]
time 223307ms: Process C switching out of CPU; blocking on I/O until time 224327ms [Q <empty>]
time 224327ms: Process C (tau 3062ms) completed I/O; added to ready queue [Q C]
time 224329ms: Process C (tau 3062ms) started using the CPU for 2120ms burst [Q <empty>]
time 226449ms: Process C (tau 3062ms) completed a CPU burst; 21 bursts to go [Q <empty>]
time 226449ms: Recalculating tau for process C: old tau 3062ms ==> new tau 2356ms [Q <empty>]
time 226449ms: Process C switching out of CPU; blocking on I/O until time 228313ms [Q <empty>]
time 228313ms: Process C (tau 2356ms) completed I/O; added to ready queue [Q C]
time 228315ms: Process C (tau 2356ms) started using the CPU for 1944ms burst [Q <empty>]
time 230259ms: Process C (tau 2356ms) completed a CPU burst; 20 bursts to go [Q <empty>]
time 230259ms: Recalculating tau for process C: old tau 2356ms ==> new tau 2047ms [Q <empty>]
time 230259ms: Process C switching out of CPU; blocking on I/O until time 230264ms [Q <empty>]
time 230264ms: Process C (tau 2047ms) completed I/O; added to ready queue [Q C]
time 230266ms: Process C (tau 2047ms) started using the CPU for 2472ms burst [Q <empty>]
time 232738ms: Process C (tau 2047ms) completed a CPU burst; 19 bursts to go [Q <empty>]
time 232738ms: Recalculating tau for process C: old tau 2047ms ==> new tau 2366ms [Q <empty>]
time 232738ms: Process C switching out of CPU; blocking on I/O until time 232928ms [Q <empty>]
time 232928ms: Process C (tau 2366ms) completed I/O; added to ready queue [Q C]
time 232930ms: Process C (tau 2366ms) started using the CPU for 868ms burst [Q <empty>]
time 233798ms: Process C (tau 2366ms) completed a CPU burst; 18 bursts to go [Q <empty>]
time 233798ms: Recalculating tau for process C: old tau 2366ms ==> new tau 1243ms [Q <empty>]
time 233798ms: Process C switching out of CPU; blocking on I/O until time 234823ms [Q <empty>]
time 234823ms: Process C (tau 1243ms) completed I/O; added to ready queue [Q C]
time 234825ms: Process C (tau 1243ms) started using the CPU for 3208ms burst [Q <empty>]
time 238033ms: Process C (tau 1243ms) completed a CPU burst; 17 bursts to go [Q <empty>]
time 238033ms: Recalculating tau for process C: old tau 1243ms ==> new tau 2717ms [Q <empty>]
time 238033ms: Process C switching out of CPU; blocking on I/O until time 239138ms [Q <empty>]
time 239138ms: Process C (tau 2717ms) completed I/O; added to ready queue [Q C]
time 239140ms: Process C (tau 2717ms) started using the CPU for 1672ms burst [Q <empty>]
time 240812ms: Process C (tau 2717ms) completed a CPU burst; 16 bursts to go [Q <empty>]
time 240812ms: Recalculating tau for process C: old tau 2717ms ==> new tau 1934ms [Q <empty>]
time 240812ms: Process C switching out of CPU; blocking on I/O until time 243391ms [Q <empty>]
time 243391ms: Process C (tau 1934ms) completed I/O; added to ready queue [Q C]
time 243393ms: Process C (tau 1934ms) started using the CPU for 3536ms burst [Q <empty>]
time 246929ms: Process C (tau 1934ms) completed a CPU burst; 15 bursts to go [Q <empty>]
time 246929ms: Recalculating tau for process C: old tau 1934ms ==> new tau 3136ms [Q <empty>]
time 246929ms: Process C switching out of CPU; blocking on I/O until time 250468ms [Q <empty>]
time 250468ms: Process C (tau 3136ms) completed I/O; added to ready queue [Q C]
time 250470ms: Process C (tau 3136ms) started using the CPU for 2988ms burst [Q <empty>]
time 253458ms: Process C (tau 3136ms) completed a CPU burst; 14 bursts to go [Q <empty>]
time 253458ms: Recalculating tau for process C: old tau 3136ms ==> new tau 3025ms [Q <empty>]
time 253458ms: Process C switching out of CPU; blocking on I/O until time 255536ms [Q <empty>]
time 255536ms: Process C (tau 3025ms) completed I/O; added to ready queue [Q C]
time 255538ms: Process C (tau 3025ms) started using the CPU for 7804ms burst [Q <empty>]
time 263342ms: Process C (tau 3025ms) completed a CPU burst; 13 bursts to go [Q <empty>]
time 263342ms: Recalculating tau for process C: old tau 3025ms ==> new tau 6610ms [Q <empty>]
time 263342ms: Process C switching out of CPU; blocking on I/O until time 264611ms [Q <empty>]
time 264611ms: Process C (tau 6610ms) completed I/O; added to ready queue [Q C]
time 264613ms: Process C (tau 6610ms) started using the CPU for 5608ms burst [Q <empty>]
time 270221ms: Process C (tau 6610ms) completed a CPU burst; 12 bursts to go [Q <empty>]
time 270221ms: Recalculating tau for process C: old tau 6610ms ==> new tau 5859ms [Q <empty>]
time 270221ms: Process C switching out of CPU; blocking on I/O until time 270520ms [Q <empty>]
time 270520ms: Process C (tau 5859ms) completed I/O; added to ready queue [Q C]
time 270522ms: Process C (tau 5859ms) started using the CPU for 1160ms burst [Q <empty>]
time 271682ms: Process C (tau 5859ms) completed a CPU burst; 11 bursts to go [Q <empty>]
time 271682ms: Recalculating tau for process C: old tau 5859ms ==> new tau 2335ms [Q <empty>]
time 271682ms: Process C switching out of CPU; blocking on I/O until time 272325ms [Q <empty>]
