<<< PROJECT PART I -- process set (n=8) with 6 CPU-bound processes >>>
I/O-bound process A: arrival time 692ms; 12 CPU bursts
I/O-bound process B: arrival time 187ms; 44 CPU bursts
CPU-bound process C: arrival time 1130ms; 35 CPU bursts
CPU-bound process D: arrival time 92ms; 47 CPU bursts
CPU-bound process E: arrival time 81ms; 12 CPU bursts
CPU-bound process F: arrival time 22ms; 6 CPU bursts
CPU-bound process G: arrival time 755ms; 5 CPU bursts
CPU-bound process H: arrival time 981ms; 42 CPU bursts

<<< PROJECT PART II -- t_cs=6ms; alpha=0.90; t_slice=128ms >>>
time 0ms: Simulator started for FCFS [Q <empty>]
time 22ms: Process F arrived; added to ready queue [Q F]
time 25ms: Process F started using the CPU for 596ms burst [Q <empty>]
time 81ms: Process E arrived; added to ready queue [Q E]
time 92ms: Process D arrived; added to ready queue [Q E D]
time 187ms: Process B arrived; added to ready queue [Q E D B]
time 621ms: Process F completed a CPU burst; 5 bursts to go [Q E D B]
time 621ms: Process F switching out of CPU; blocking on I/O until time 900ms [Q E D B]
time 627ms: Process E started using the CPU for 7344ms burst [Q D B]
time 692ms: Process A arrived; added to ready queue [Q D B A]
time 755ms: Process G arrived; added to ready queue [Q D B A G]
time 900ms: Process F completed I/O; added to ready queue [Q D B A G F]
time 981ms: Process H arrived; added to ready queue [Q D B A G F H]
time 1130ms: Process C arrived; added to ready queue [Q D B A G F H C]
time 7971ms: Process E completed a CPU burst; 11 bursts to go [Q D B A G F H C]
time 7971ms: Process E switching out of CPU; blocking on I/O until time 9192ms [Q D B A G F H C]
time 7977ms: Process D started using the CPU for 780ms burst [Q B A G F H C]
time 8757ms: Process D completed a CPU burst; 46 bursts to go [Q B A G F H C]
time 8757ms: Process D switching out of CPU; blocking on I/O until time 8896ms [Q B A G F H C]
time 8763ms: Process B started using the CPU for 974ms burst [Q A G F H C]
time 8896ms: Process D completed I/O; added to ready queue [Q A G F H C D]
time 9192ms: Process E completed I/O; added to ready queue [Q A G F H C D E]
time 9737ms: Process B completed a CPU burst; 43 bursts to go [Q A G F H C D E]
time 9737ms: Process B switching out of CPU; blocking on I/O until time 18690ms [Q A G F H C D E]
time 9743ms: Process A started using the CPU for 1528ms burst [Q G F H C D E]
time 11271ms: Process A completed a CPU burst; 11 bursts to go [Q G F H C D E]
time 11271ms: Process A switching out of CPU; blocking on I/O until time 17654ms [Q G F H C D E]
time 11277ms: Process G started using the CPU for 952ms burst [Q F H C D E]
time 12229ms: Process G completed a CPU burst; 4 bursts to go [Q F H C D E]
time 12229ms: Process G switching out of CPU; blocking on I/O until time 13174ms [Q F H C D E]
time 12235ms: Process F started using the CPU for 3284ms burst [Q H C D E]
time 13174ms: Process G completed I/O; added to ready queue [Q H C D E G]
time 15519ms: Process F completed a CPU burst; 4 bursts to go [Q H C D E G]
time 15519ms: Process F switching out of CPU; blocking on I/O until time 15827ms [Q H C D E G]
time 15525ms: Process H started using the CPU for 920ms burst [Q C D E G]
time 15827ms: Process F completed I/O; added to ready queue [Q C D E G F]
time 16445ms: Process H completed a CPU burst; 41 bursts to go [Q C D E G F]
time 16445ms: Process H switching out of CPU; blocking on I/O until time 16875ms [Q C D E G F]
time 16451ms: Process C started using the CPU for 2256ms burst [Q D E G F]
time 16875ms: Process H completed I/O; added to ready queue [Q D E G F H]
time 17654ms: Process A completed I/O; added to ready queue [Q D E G F H A]
time 18690ms: Process B completed I/O; added to ready queue [Q D E G F H A B]
time 18707ms: Process C completed a CPU burst; 34 bursts to go [Q D E G F H A B]
time 18707ms: Process C switching out of CPU; blocking on I/O until time 19052ms [Q D E G F H A B]
time 18713ms: Process D started using the CPU for 524ms burst [Q E G F H A B]
time 19052ms: Process C completed I/O; added to ready queue [Q E G F H A B C]
time 19237ms: Process D completed a CPU burst; 45 bursts to go [Q E G F H A B C]
time 19237ms: Process D switching out of CPU; blocking on I/O until time 19456ms [Q E G F H A B C]
time 19243ms: Process E started using the CPU for 824ms burst [Q G F H A B C]
time 19456ms: Process D completed I/O; added to ready queue [Q G F H A B C D]
time 20067ms: Process E completed a CPU burst; 10 bursts to go [Q G F H A B C D]
time 20067ms: Process E switching out of CPU; blocking on I/O until time 20577ms [Q G F H A B C D]
time 20073ms: Process G started using the CPU for 1460ms burst [Q F H A B C D]
time 20577ms: Process E completed I/O; added to ready queue [Q F H A B C D E]
time 21533ms: Process G completed a CPU burst; 3 bursts to go [Q F H A B C D E]
time 21533ms: Process G switching out of CPU; blocking on I/O until time 21677ms [Q F H A B C D E]
time 21539ms: Process F started using the CPU for 412ms burst [Q H A B C D E]
time 21677ms: Process G completed I/O; added to ready queue [Q H A B C D E G]
time 21951ms: Process F completed a CPU burst; 3 bursts to go [Q H A B C D E G]
time 21951ms: Process F switching out of CPU; blocking on I/O until time 22770ms [Q H A B C D E G]
time 21957ms: Process H started using the CPU for 584ms burst [Q A B C D E G]
time 22541ms: Process H completed a CPU burst; 40 bursts to go [Q A B C D E G]
time 22541ms: Process H switching out of CPU; blocking on I/O until time 23649ms [Q A B C D E G]
time 22547ms: Process A started using the CPU for 1019ms burst [Q B C D E G]
time 22770ms: Process F completed I/O; added to ready queue [Q B C D E G F]
time 23566ms: Process A completed a CPU burst; 10 bursts to go [Q B C D E G F]
time 23566ms: Process A switching out of CPU; blocking on I/O until time 34519ms [Q B C D E G F]
time 23572ms: Process B started using the CPU for 471ms burst [Q C D E G F]
time 23649ms: Process H completed I/O; added to ready queue [Q C D E G F H]
time 24043ms: Process B completed a CPU burst; 42 bursts to go [Q C D E G F H]
time 24043ms: Process B switching out of CPU; blocking on I/O until time 36496ms [Q C D E G F H]
time 24049ms: Process C started using the CPU for 3096ms burst [Q D E G F H]
time 27145ms: Process C completed a CPU burst; 33 bursts to go [Q D E G F H]
time 27145ms: Process C switching out of CPU; blocking on I/O until time 30236ms [Q D E G F H]
time 27151ms: Process D started using the CPU for 844ms burst [Q E G F H]
time 27995ms: Process D completed a CPU burst; 44 bursts to go [Q E G F H]
time 27995ms: Process D switching out of CPU; blocking on I/O until time 30030ms [Q E G F H]
time 28001ms: Process E started using the CPU for 3280ms burst [Q G F H]
time 30030ms: Process D completed I/O; added to ready queue [Q G F H D]
time 30236ms: Process C completed I/O; added to ready queue [Q G F H D C]
time 31281ms: Process E completed a CPU burst; 9 bursts to go [Q G F H D C]
time 31281ms: Process E switching out of CPU; blocking on I/O until time 31736ms [Q G F H D C]
time 31287ms: Process G started using the CPU for 312ms burst [Q F H D C]
time 31599ms: Process G completed a CPU burst; 2 bursts to go [Q F H D C]
time 31599ms: Process G switching out of CPU; blocking on I/O until time 32295ms [Q F H D C]
time 31605ms: Process F started using the CPU for 860ms burst [Q H D C]
time 31736ms: Process E completed I/O; added to ready queue [Q H D C E]
time 32295ms: Process G completed I/O; added to ready queue [Q H D C E G]
time 32465ms: Process F completed a CPU burst; 2 bursts to go [Q H D C E G]
time 32465ms: Process F switching out of CPU; blocking on I/O until time 32585ms [Q H D C E G]
time 32471ms: Process H started using the CPU for 10728ms burst [Q D C E G]
time 32585ms: Process F completed I/O; added to ready queue [Q D C E G F]
time 34519ms: Process A completed I/O; added to ready queue [Q D C E G F A]
time 36496ms: Process B completed I/O; added to ready queue [Q D C E G F A B]
time 43199ms: Process H completed a CPU burst; 39 bursts to go [Q D C E G F A B]
time 43199ms: Process H switching out of CPU; blocking on I/O until time 45032ms [Q D C E G F A B]
time 43205ms: Process D started using the CPU for 2120ms burst [Q C E G F A B]
time 45032ms: Process H completed I/O; added to ready queue [Q C E G F A B H]
time 45325ms: Process D completed a CPU burst; 43 bursts to go [Q C E G F A B H]
time 45325ms: Process D switching out of CPU; blocking on I/O until time 45638ms [Q C E G F A B H]
time 45331ms: Process C started using the CPU for 5156ms burst [Q E G F A B H]
time 45638ms: Process D completed I/O; added to ready queue [Q E G F A B H D]
time 50487ms: Process C completed a CPU burst; 32 bursts to go [Q E G F A B H D]
time 50487ms: Process C switching out of CPU; blocking on I/O until time 51318ms [Q E G F A B H D]
time 50493ms: Process E started using the CPU for 972ms burst [Q G F A B H D]
time 51318ms: Process C completed I/O; added to ready queue [Q G F A B H D C]
time 51465ms: Process E completed a CPU burst; 8 bursts to go [Q G F A B H D C]
time 51465ms: Process E switching out of CPU; blocking on I/O until time 53191ms [Q G F A B H D C]
time 51471ms: Process G started using the CPU for 7048ms burst [Q F A B H D C]
time 53191ms: Process E completed I/O; added to ready queue [Q F A B H D C E]
time 58519ms: Process G completed a CPU burst; 1 burst to go [Q F A B H D C E]
time 58519ms: Process G switching out of CPU; blocking on I/O until time 59198ms [Q F A B H D C E]
time 58525ms: Process F started using the CPU for 744ms burst [Q A B H D C E]
time 59198ms: Process G completed I/O; added to ready queue [Q A B H D C E G]
time 59269ms: Process F completed a CPU burst; 1 burst to go [Q A B H D C E G]
time 59269ms: Process F switching out of CPU; blocking on I/O until time 59325ms [Q A B H D C E G]
time 59275ms: Process A started using the CPU for 412ms burst [Q B H D C E G]
time 59325ms: Process F completed I/O; added to ready queue [Q B H D C E G F]
time 59687ms: Process A completed a CPU burst; 9 bursts to go [Q B H D C E G F]
time 59687ms: Process A switching out of CPU; blocking on I/O until time 63410ms [Q B H D C E G F]
time 59693ms: Process B started using the CPU for 1009ms burst [Q H D C E G F]
time 60702ms: Process B completed a CPU burst; 41 bursts to go [Q H D C E G F]
time 60702ms: Process B switching out of CPU; blocking on I/O until time 61125ms [Q H D C E G F]
time 60708ms: Process H started using the CPU for 7248ms burst [Q D C E G F]
time 61125ms: Process B completed I/O; added to ready queue [Q D C E G F B]
time 63410ms: Process A completed I/O; added to ready queue [Q D C E G F B A]
time 67956ms: Process H completed a CPU burst; 38 bursts to go [Q D C E G F B A]
time 67956ms: Process H switching out of CPU; blocking on I/O until time 67980ms [Q D C E G F B A]
time 67962ms: Process D started using the CPU for 6928ms burst [Q C E G F B A]
time 67980ms: Process H completed I/O; added to ready queue [Q C E G F B A H]
time 74890ms: Process D completed a CPU burst; 42 bursts to go [Q C E G F B A H]
time 74890ms: Process D switching out of CPU; blocking on I/O until time 75871ms [Q C E G F B A H]
time 74896ms: Process C started using the CPU for 6460ms burst [Q E G F B A H]
time 75871ms: Process D completed I/O; added to ready queue [Q E G F B A H D]
time 81356ms: Process C completed a CPU burst; 31 bursts to go [Q E G F B A H D]
time 81356ms: Process C switching out of CPU; blocking on I/O until time 81606ms [Q E G F B A H D]
time 81362ms: Process E started using the CPU for 5432ms burst [Q G F B A H D]
time 81606ms: Process C completed I/O; added to ready queue [Q G F B A H D C]
time 86794ms: Process E completed a CPU burst; 7 bursts to go [Q G F B A H D C]
time 86794ms: Process E switching out of CPU; blocking on I/O until time 86949ms [Q G F B A H D C]
time 86800ms: Process G started using the CPU for 9924ms burst [Q F B A H D C]
time 86949ms: Process E completed I/O; added to ready queue [Q F B A H D C E]
time 96724ms: Process G terminated [Q F B A H D C E]
time 96730ms: Process F started using the CPU for 112ms burst [Q B A H D C E]
time 96842ms: Process F terminated [Q B A H D C E]
time 96848ms: Process B started using the CPU for 220ms burst [Q A H D C E]
time 97068ms: Process B completed a CPU burst; 40 bursts to go [Q A H D C E]
time 97068ms: Process B switching out of CPU; blocking on I/O until time 97181ms [Q A H D C E]
time 97074ms: Process A started using the CPU for 238ms burst [Q H D C E]
time 97181ms: Process B completed I/O; added to ready queue [Q H D C E B]
time 97312ms: Process A completed a CPU burst; 8 bursts to go [Q H D C E B]
time 97312ms: Process A switching out of CPU; blocking on I/O until time 98485ms [Q H D C E B]
time 97318ms: Process H started using the CPU for 5272ms burst [Q D C E B]
time 98485ms: Process A completed I/O; added to ready queue [Q D C E B A]
time 102590ms: Process H completed a CPU burst; 37 bursts to go [Q D C E B A]
time 102590ms: Process H switching out of CPU; blocking on I/O until time 104908ms [Q D C E B A]
time 102596ms: Process D started using the CPU for 3616ms burst [Q C E B A]
time 104908ms: Process H completed I/O; added to ready queue [Q C E B A H]
time 106212ms: Process D completed a CPU burst; 41 bursts to go [Q C E B A H]
time 106212ms: Process D switching out of CPU; blocking on I/O until time 106800ms [Q C E B A H]
time 106218ms: Process C started using the CPU for 5060ms burst [Q E B A H]
time 106800ms: Process D completed I/O; added to ready queue [Q E B A H D]
time 111278ms: Process C completed a CPU burst; 30 bursts to go [Q E B A H D]
time 111278ms: Process C switching out of CPU; blocking on I/O until time 111612ms [Q E B A H D]
time 111284ms: Process E started using the CPU for 2160ms burst [Q B A H D]
time 111612ms: Process C completed I/O; added to ready queue [Q B A H D C]
time 113444ms: Process E completed a CPU burst; 6 bursts to go [Q B A H D C]
time 113444ms: Process E switching out of CPU; blocking on I/O until time 117025ms [Q B A H D C]
time 113450ms: Process B started using the CPU for 343ms burst [Q A H D C]
time 113793ms: Process B completed a CPU burst; 39 bursts to go [Q A H D C]
time 113793ms: Process B switching out of CPU; blocking on I/O until time 117796ms [Q A H D C]
time 113799ms: Process A started using the CPU for 227ms burst [Q H D C]
time 114026ms: Process A completed a CPU burst; 7 bursts to go [Q H D C]
time 114026ms: Process A switching out of CPU; blocking on I/O until time 120009ms [Q H D C]
time 114032ms: Process H started using the CPU for 3688ms burst [Q D C]
time 117025ms: Process E completed I/O; added to ready queue [Q D C E]
time 117720ms: Process H completed a CPU burst; 36 bursts to go [Q D C E]
time 117720ms: Process H switching out of CPU; blocking on I/O until time 118519ms [Q D C E]
time 117726ms: Process D started using the CPU for 2128ms burst [Q C E]
time 117796ms: Process B completed I/O; added to ready queue [Q C E B]
time 118519ms: Process H completed I/O; added to ready queue [Q C E B H]
time 119854ms: Process D completed a CPU burst; 40 bursts to go [Q C E B H]
time 119854ms: Process D switching out of CPU; blocking on I/O until time 120375ms [Q C E B H]
time 119860ms: Process C started using the CPU for 7836ms burst [Q E B H]
time 120009ms: Process A completed I/O; added to ready queue [Q E B H A]
time 120375ms: Process D completed I/O; added to ready queue [Q E B H A D]
time 127696ms: Process C completed a CPU burst; 29 bursts to go [Q E B H A D]
time 127696ms: Process C switching out of CPU; blocking on I/O until time 128957ms [Q E B H A D]
time 127702ms: Process E started using the CPU for 1396ms burst [Q B H A D]
time 128957ms: Process C completed I/O; added to ready queue [Q B H A D C]
time 129098ms: Process E completed a CPU burst; 5 bursts to go [Q B H A D C]
time 129098ms: Process E switching out of CPU; blocking on I/O until time 129219ms [Q B H A D C]
time 129104ms: Process B started using the CPU for 309ms burst [Q H A D C]
time 129219ms: Process E completed I/O; added to ready queue [Q H A D C E]
time 129413ms: Process B completed a CPU burst; 38 bursts to go [Q H A D C E]
time 129413ms: Process B switching out of CPU; blocking on I/O until time 130256ms [Q H A D C E]
time 129419ms: Process H started using the CPU for 6316ms burst [Q A D C E]
time 130256ms: Process B completed I/O; added to ready queue [Q A D C E B]
time 135735ms: Process H completed a CPU burst; 35 bursts to go [Q A D C E B]
time 135735ms: Process H switching out of CPU; blocking on I/O until time 136375ms [Q A D C E B]
time 135741ms: Process A started using the CPU for 129ms burst [Q D C E B]
time 135870ms: Process A completed a CPU burst; 6 bursts to go [Q D C E B]
time 135870ms: Process A switching out of CPU; blocking on I/O until time 146293ms [Q D C E B]
time 135876ms: Process D started using the CPU for 1788ms burst [Q C E B]
time 136375ms: Process H completed I/O; added to ready queue [Q C E B H]
time 137664ms: Process D completed a CPU burst; 39 bursts to go [Q C E B H]
time 137664ms: Process D switching out of CPU; blocking on I/O until time 138067ms [Q C E B H]
time 137670ms: Process C started using the CPU for 6608ms burst [Q E B H]
time 138067ms: Process D completed I/O; added to ready queue [Q E B H D]
time 144278ms: Process C completed a CPU burst; 28 bursts to go [Q E B H D]
time 144278ms: Process C switching out of CPU; blocking on I/O until time 144431ms [Q E B H D]
time 144284ms: Process E started using the CPU for 10556ms burst [Q B H D]
time 144431ms: Process C completed I/O; added to ready queue [Q B H D C]
time 146293ms: Process A completed I/O; added to ready queue [Q B H D C A]
time 154840ms: Process E completed a CPU burst; 4 bursts to go [Q B H D C A]
time 154840ms: Process E switching out of CPU; blocking on I/O until time 156426ms [Q B H D C A]
time 154846ms: Process B started using the CPU for 887ms burst [Q H D C A]
time 155733ms: Process B completed a CPU burst; 37 bursts to go [Q H D C A]
time 155733ms: Process B switching out of CPU; blocking on I/O until time 158256ms [Q H D C A]
time 155739ms: Process H started using the CPU for 1052ms burst [Q D C A]
time 156426ms: Process E completed I/O; added to ready queue [Q D C A E]
time 156791ms: Process H completed a CPU burst; 34 bursts to go [Q D C A E]
time 156791ms: Process H switching out of CPU; blocking on I/O until time 157212ms [Q D C A E]
time 156797ms: Process D started using the CPU for 6336ms burst [Q C A E]
time 157212ms: Process H completed I/O; added to ready queue [Q C A E H]
time 158256ms: Process B completed I/O; added to ready queue [Q C A E H B]
time 163133ms: Process D completed a CPU burst; 38 bursts to go [Q C A E H B]
time 163133ms: Process D switching out of CPU; blocking on I/O until time 165251ms [Q C A E H B]
time 163139ms: Process C started using the CPU for 5908ms burst [Q A E H B]
time 165251ms: Process D completed I/O; added to ready queue [Q A E H B D]
time 169047ms: Process C completed a CPU burst; 27 bursts to go [Q A E H B D]
time 169047ms: Process C switching out of CPU; blocking on I/O until time 172086ms [Q A E H B D]
time 169053ms: Process A started using the CPU for 382ms burst [Q E H B D]
time 169435ms: Process A completed a CPU burst; 5 bursts to go [Q E H B D]
time 169435ms: Process A switching out of CPU; blocking on I/O until time 175838ms [Q E H B D]
time 169441ms: Process E started using the CPU for 2284ms burst [Q H B D]
time 171725ms: Process E completed a CPU burst; 3 bursts to go [Q H B D]
time 171725ms: Process E switching out of CPU; blocking on I/O until time 172504ms [Q H B D]
time 171731ms: Process H started using the CPU for 1596ms burst [Q B D]
time 172086ms: Process C completed I/O; added to ready queue [Q B D C]
time 172504ms: Process E completed I/O; added to ready queue [Q B D C E]
time 173327ms: Process H completed a CPU burst; 33 bursts to go [Q B D C E]
time 173327ms: Process H switching out of CPU; blocking on I/O until time 174227ms [Q B D C E]
time 173333ms: Process B started using the CPU for 369ms burst [Q D C E]
time 173702ms: Process B completed a CPU burst; 36 bursts to go [Q D C E]
time 173702ms: Process B switching out of CPU; blocking on I/O until time 190505ms [Q D C E]
time 173708ms: Process D started using the CPU for 236ms burst [Q C E]
time 173944ms: Process D completed a CPU burst; 37 bursts to go [Q C E]
time 173944ms: Process D switching out of CPU; blocking on I/O until time 174258ms [Q C E]
time 173950ms: Process C started using the CPU for 1068ms burst [Q E]
time 174227ms: Process H completed I/O; added to ready queue [Q E H]
time 174258ms: Process D completed I/O; added to ready queue [Q E H D]
time 175018ms: Process C completed a CPU burst; 26 bursts to go [Q E H D]
time 175018ms: Process C switching out of CPU; blocking on I/O until time 175997ms [Q E H D]
time 175024ms: Process E started using the CPU for 8280ms burst [Q H D]
time 175838ms: Process A completed I/O; added to ready queue [Q H D A]
time 175997ms: Process C completed I/O; added to ready queue [Q H D A C]
time 183304ms: Process E completed a CPU burst; 2 bursts to go [Q H D A C]
time 183304ms: Process E switching out of CPU; blocking on I/O until time 183530ms [Q H D A C]
time 183310ms: Process H started using the CPU for 180ms burst [Q D A C]
time 183490ms: Process H completed a CPU burst; 32 bursts to go [Q D A C]
time 183490ms: Process H switching out of CPU; blocking on I/O until time 183656ms [Q D A C]
time 183496ms: Process D started using the CPU for 7352ms burst [Q A C]
time 183530ms: Process E completed I/O; added to ready queue [Q A C E]
time 183656ms: Process H completed I/O; added to ready queue [Q A C E H]
time 190505ms: Process B completed I/O; added to ready queue [Q A C E H B]
time 190848ms: Process D completed a CPU burst; 36 bursts to go [Q A C E H B]
time 190848ms: Process D switching out of CPU; blocking on I/O until time 192451ms [Q A C E H B]
time 190854ms: Process A started using the CPU for 408ms burst [Q C E H B]
time 191262ms: Process A completed a CPU burst; 4 bursts to go [Q C E H B]
time 191262ms: Process A switching out of CPU; blocking on I/O until time 203695ms [Q C E H B]
time 191268ms: Process C started using the CPU for 260ms burst [Q E H B]
time 191528ms: Process C completed a CPU burst; 25 bursts to go [Q E H B]
time 191528ms: Process C switching out of CPU; blocking on I/O until time 193274ms [Q E H B]
time 191534ms: Process E started using the CPU for 7240ms burst [Q H B]
time 192451ms: Process D completed I/O; added to ready queue [Q H B D]
time 193274ms: Process C completed I/O; added to ready queue [Q H B D C]
time 198774ms: Process E completed a CPU burst; 1 burst to go [Q H B D C]
time 198774ms: Process E switching out of CPU; blocking on I/O until time 198940ms [Q H B D C]
time 198780ms: Process H started using the CPU for 7424ms burst [Q B D C]
time 198940ms: Process E completed I/O; added to ready queue [Q B D C E]
time 203695ms: Process A completed I/O; added to ready queue [Q B D C E A]
time 206204ms: Process H completed a CPU burst; 31 bursts to go [Q B D C E A]
time 206204ms: Process H switching out of CPU; blocking on I/O until time 208948ms [Q B D C E A]
time 206210ms: Process B started using the CPU for 192ms burst [Q D C E A]
time 206402ms: Process B completed a CPU burst; 35 bursts to go [Q D C E A]
time 206402ms: Process B switching out of CPU; blocking on I/O until time 215825ms [Q D C E A]
time 206408ms: Process D started using the CPU for 8908ms burst [Q C E A]
time 208948ms: Process H completed I/O; added to ready queue [Q C E A H]
time 215316ms: Process D completed a CPU burst; 35 bursts to go [Q C E A H]
time 215316ms: Process D switching out of CPU; blocking on I/O until time 215525ms [Q C E A H]
time 215322ms: Process C started using the CPU for 936ms burst [Q E A H]
time 215525ms: Process D completed I/O; added to ready queue [Q E A H D]
time 215825ms: Process B completed I/O; added to ready queue [Q E A H D B]
time 216258ms: Process C completed a CPU burst; 24 bursts to go [Q E A H D B]
time 216258ms: Process C switching out of CPU; blocking on I/O until time 216419ms [Q E A H D B]
time 216264ms: Process E started using the CPU for 1200ms burst [Q A H D B]
time 216419ms: Process C completed I/O; added to ready queue [Q A H D B C]
time 217464ms: Process E terminated [Q A H D B C]
time 217470ms: Process A started using the CPU for 680ms burst [Q H D B C]
time 218150ms: Process A completed a CPU burst; 3 bursts to go [Q H D B C]
time 218150ms: Process A switching out of CPU; blocking on I/O until time 223823ms [Q H D B C]
time 218156ms: Process H started using the CPU for 8008ms burst [Q D B C]
time 223823ms: Process A completed I/O; added to ready queue [Q D B C A]
time 226164ms: Process H completed a CPU burst; 30 bursts to go [Q D B C A]
time 226164ms: Process H switching out of CPU; blocking on I/O until time 226417ms [Q D B C A]
time 226170ms: Process D started using the CPU for 1264ms burst [Q B C A]
time 226417ms: Process H completed I/O; added to ready queue [Q B C A H]
time 227434ms: Process D completed a CPU burst; 34 bursts to go [Q B C A H]
time 227434ms: Process D switching out of CPU; blocking on I/O until time 228337ms [Q B C A H]
time 227440ms: Process B started using the CPU for 941ms burst [Q C A H]
time 228337ms: Process D completed I/O; added to ready queue [Q C A H D]
time 228381ms: Process B completed a CPU burst; 34 bursts to go [Q C A H D]
time 228381ms: Process B switching out of CPU; blocking on I/O until time 243244ms [Q C A H D]
time 228387ms: Process C started using the CPU for 292ms burst [Q A H D]
time 228679ms: Process C completed a CPU burst; 23 bursts to go [Q A H D]
time 228679ms: Process C switching out of CPU; blocking on I/O until time 229594ms [Q A H D]
time 228685ms: Process A started using the CPU for 231ms burst [Q H D]
time 228916ms: Process A completed a CPU burst; 2 bursts to go [Q H D]
time 228916ms: Process A switching out of CPU; blocking on I/O until time 231719ms [Q H D]
time 228922ms: Process H started using the CPU for 2036ms burst [Q D]
time 229594ms: Process C completed I/O; added to ready queue [Q D C]
time 230958ms: Process H completed a CPU burst; 29 bursts to go [Q D C]
time 230958ms: Process H switching out of CPU; blocking on I/O until time 231823ms [Q D C]
time 230964ms: Process D started using the CPU for 2972ms burst [Q C]
time 231719ms: Process A completed I/O; added to ready queue [Q C A]
time 231823ms: Process H completed I/O; added to ready queue [Q C A H]
time 233936ms: Process D completed a CPU burst; 33 bursts to go [Q C A H]
time 233936ms: Process D switching out of CPU; blocking on I/O until time 235620ms [Q C A H]
time 233942ms: Process C started using the CPU for 10732ms burst [Q A H]
time 235620ms: Process D completed I/O; added to ready queue [Q A H D]
time 243244ms: Process B completed I/O; added to ready queue [Q A H D B]
time 244674ms: Process C completed a CPU burst; 22 bursts to go [Q A H D B]
time 244674ms: Process C switching out of CPU; blocking on I/O until time 247912ms [Q A H D B]
time 244680ms: Process A started using the CPU for 119ms burst [Q H D B]
time 244799ms: Process A completed a CPU burst; 1 burst to go [Q H D B]
time 244799ms: Process A switching out of CPU; blocking on I/O until time 245042ms [Q H D B]
time 244805ms: Process H started using the CPU for 2304ms burst [Q D B]
time 245042ms: Process A completed I/O; added to ready queue [Q D B A]
time 247109ms: Process H completed a CPU burst; 28 bursts to go [Q D B A]
time 247109ms: Process H switching out of CPU; blocking on I/O until time 247525ms [Q D B A]
time 247115ms: Process D started using the CPU for 5800ms burst [Q B A]
time 247525ms: Process H completed I/O; added to ready queue [Q B A H]
time 247912ms: Process C completed I/O; added to ready queue [Q B A H C]
time 252915ms: Process D completed a CPU burst; 32 bursts to go [Q B A H C]
time 252915ms: Process D switching out of CPU; blocking on I/O until time 253083ms [Q B A H C]
time 252921ms: Process B started using the CPU for 364ms burst [Q A H C]
time 253083ms: Process D completed I/O; added to ready queue [Q A H C D]
time 253285ms: Process B completed a CPU burst; 33 bursts to go [Q A H C D]
time 253285ms: Process B switching out of CPU; blocking on I/O until time 254198ms [Q A H C D]
time 253291ms: Process A started using the CPU for 1807ms burst [Q H C D]
time 254198ms: Process B completed I/O; added to ready queue [Q H C D B]
time 255098ms: Process A terminated [Q H C D B]
time 255104ms: Process H started using the CPU for 3072ms burst [Q C D B]
time 258176ms: Process H completed a CPU burst; 27 bursts to go [Q C D B]
time 258176ms: Process H switching out of CPU; blocking on I/O until time 259527ms [Q C D B]
time 258182ms: Process C started using the CPU for 6440ms burst [Q D B]
time 259527ms: Process H completed I/O; added to ready queue [Q D B H]
time 264622ms: Process C completed a CPU burst; 21 bursts to go [Q D B H]
time 264622ms: Process C switching out of CPU; blocking on I/O until time 266968ms [Q D B H]
time 264628ms: Process D started using the CPU for 8596ms burst [Q B H]
time 266968ms: Process C completed I/O; added to ready queue [Q B H C]
time 273224ms: Process D completed a CPU burst; 31 bursts to go [Q B H C]
time 273224ms: Process D switching out of CPU; blocking on I/O until time 273553ms [Q B H C]
time 273230ms: Process B started using the CPU for 25ms burst [Q H C]
time 273255ms: Process B completed a CPU burst; 32 bursts to go [Q H C]
time 273255ms: Process B switching out of CPU; blocking on I/O until time 279558ms [Q H C]
time 273261ms: Process H started using the CPU for 5332ms burst [Q C]
time 273553ms: Process D completed I/O; added to ready queue [Q C D]
time 278593ms: Process H completed a CPU burst; 26 bursts to go [Q C D]
time 278593ms: Process H switching out of CPU; blocking on I/O until time 278754ms [Q C D]
time 278599ms: Process C started using the CPU for 464ms burst [Q D]
time 278754ms: Process H completed I/O; added to ready queue [Q D H]
time 279063ms: Process C completed a CPU burst; 20 bursts to go [Q D H]
time 279063ms: Process C switching out of CPU; blocking on I/O until time 281628ms [Q D H]
time 279069ms: Process D started using the CPU for 9572ms burst [Q H]
time 279558ms: Process B completed I/O; added to ready queue [Q H B]
time 281628ms: Process C completed I/O; added to ready queue [Q H B C]
time 288641ms: Process D completed a CPU burst; 30 bursts to go [Q H B C]
time 288641ms: Process D switching out of CPU; blocking on I/O until time 288984ms [Q H B C]
time 288647ms: Process H started using the CPU for 1836ms burst [Q B C]
time 288984ms: Process D completed I/O; added to ready queue [Q B C D]
time 290483ms: Process H completed a CPU burst; 25 bursts to go [Q B C D]
time 290483ms: Process H switching out of CPU; blocking on I/O until time 291778ms [Q B C D]
time 290489ms: Process B started using the CPU for 744ms burst [Q C D]
time 291233ms: Process B completed a CPU burst; 31 bursts to go [Q C D]
time 291233ms: Process B switching out of CPU; blocking on I/O until time 292146ms [Q C D]
time 291239ms: Process C started using the CPU for 556ms burst [Q D]
time 291778ms: Process H completed I/O; added to ready queue [Q D H]
time 291795ms: Process C completed a CPU burst; 19 bursts to go [Q D H]
time 291795ms: Process C switching out of CPU; blocking on I/O until time 293679ms [Q D H]
time 291801ms: Process D started using the CPU for 4552ms burst [Q H]
time 292146ms: Process B completed I/O; added to ready queue [Q H B]
time 293679ms: Process C completed I/O; added to ready queue [Q H B C]
time 296353ms: Process D completed a CPU burst; 29 bursts to go [Q H B C]
time 296353ms: Process D switching out of CPU; blocking on I/O until time 297584ms [Q H B C]
time 296359ms: Process H started using the CPU for 1972ms burst [Q B C]
time 297584ms: Process D completed I/O; added to ready queue [Q B C D]
time 298331ms: Process H completed a CPU burst; 24 bursts to go [Q B C D]
time 298331ms: Process H switching out of CPU; blocking on I/O until time 298474ms [Q B C D]
time 298337ms: Process B started using the CPU for 1040ms burst [Q C D]
time 298474ms: Process H completed I/O; added to ready queue [Q C D H]
time 299377ms: Process B completed a CPU burst; 30 bursts to go [Q C D H]
time 299377ms: Process B switching out of CPU; blocking on I/O until time 303340ms [Q C D H]
time 299383ms: Process C started using the CPU for 1096ms burst [Q D H]
time 300479ms: Process C completed a CPU burst; 18 bursts to go [Q D H]
time 300479ms: Process C switching out of CPU; blocking on I/O until time 300519ms [Q D H]
time 300485ms: Process D started using the CPU for 5016ms burst [Q H]
time 300519ms: Process C completed I/O; added to ready queue [Q H C]
time 303340ms: Process B completed I/O; added to ready queue [Q H C B]
time 305501ms: Process D completed a CPU burst; 28 bursts to go [Q H C B]
time 305501ms: Process D switching out of CPU; blocking on I/O until time 305946ms [Q H C B]
time 305507ms: Process H started using the CPU for 116ms burst [Q C B]
time 305623ms: Process H completed a CPU burst; 23 bursts to go [Q C B]
time 305623ms: Process H switching out of CPU; blocking on I/O until time 306062ms [Q C B]
time 305629ms: Process C started using the CPU for 1092ms burst [Q B]
time 305946ms: Process D completed I/O; added to ready queue [Q B D]
time 306062ms: Process H completed I/O; added to ready queue [Q B D H]
time 306721ms: Process C completed a CPU burst; 17 bursts to go [Q B D H]
time 306721ms: Process C switching out of CPU; blocking on I/O until time 307461ms [Q B D H]
time 306727ms: Process B started using the CPU for 1157ms burst [Q D H]
time 307461ms: Process C completed I/O; added to ready queue [Q D H C]
time 307884ms: Process B completed a CPU burst; 29 bursts to go [Q D H C]
time 307884ms: Process B switching out of CPU; blocking on I/O until time 317857ms [Q D H C]
time 307890ms: Process D started using the CPU for 3248ms burst [Q H C]
time 311138ms: Process D completed a CPU burst; 27 bursts to go [Q H C]
time 311138ms: Process D switching out of CPU; blocking on I/O until time 314461ms [Q H C]
time 311144ms: Process H started using the CPU for 7116ms burst [Q C]
time 314461ms: Process D completed I/O; added to ready queue [Q C D]
time 317857ms: Process B completed I/O; added to ready queue [Q C D B]
time 318260ms: Process H completed a CPU burst; 22 bursts to go [Q C D B]
time 318260ms: Process H switching out of CPU; blocking on I/O until time 318690ms [Q C D B]
time 318266ms: Process C started using the CPU for 6528ms burst [Q D B]
time 318690ms: Process H completed I/O; added to ready queue [Q D B H]
time 324794ms: Process C completed a CPU burst; 16 bursts to go [Q D B H]
time 324794ms: Process C switching out of CPU; blocking on I/O until time 327888ms [Q D B H]
time 324800ms: Process D started using the CPU for 3356ms burst [Q B H]
time 327888ms: Process C completed I/O; added to ready queue [Q B H C]
time 328156ms: Process D completed a CPU burst; 26 bursts to go [Q B H C]
time 328156ms: Process D switching out of CPU; blocking on I/O until time 328810ms [Q B H C]
time 328162ms: Process B started using the CPU for 270ms burst [Q H C]
time 328432ms: Process B completed a CPU burst; 28 bursts to go [Q H C]
time 328432ms: Process B switching out of CPU; blocking on I/O until time 333775ms [Q H C]
time 328438ms: Process H started using the CPU for 2004ms burst [Q C]
time 328810ms: Process D completed I/O; added to ready queue [Q C D]
time 330442ms: Process H completed a CPU burst; 21 bursts to go [Q C D]
time 330442ms: Process H switching out of CPU; blocking on I/O until time 330948ms [Q C D]
time 330448ms: Process C started using the CPU for 5812ms burst [Q D]
time 330948ms: Process H completed I/O; added to ready queue [Q D H]
time 333775ms: Process B completed I/O; added to ready queue [Q D H B]
time 336260ms: Process C completed a CPU burst; 15 bursts to go [Q D H B]
time 336260ms: Process C switching out of CPU; blocking on I/O until time 336308ms [Q D H B]
time 336266ms: Process D started using the CPU for 1656ms burst [Q H B]
time 336308ms: Process C completed I/O; added to ready queue [Q H B C]
time 337922ms: Process D completed a CPU burst; 25 bursts to go [Q H B C]
time 337922ms: Process D switching out of CPU; blocking on I/O until time 339867ms [Q H B C]
time 337928ms: Process H started using the CPU for 2052ms burst [Q B C]
time 339867ms: Process D completed I/O; added to ready queue [Q B C D]
time 339980ms: Process H completed a CPU burst; 20 bursts to go [Q B C D]
time 339980ms: Process H switching out of CPU; blocking on I/O until time 342474ms [Q B C D]
time 339986ms: Process B started using the CPU for 2878ms burst [Q C D]
time 342474ms: Process H completed I/O; added to ready queue [Q C D H]
time 342864ms: Process B completed a CPU burst; 27 bursts to go [Q C D H]
time 342864ms: Process B switching out of CPU; blocking on I/O until time 343407ms [Q C D H]
time 342870ms: Process C started using the CPU for 8508ms burst [Q D H]
time 343407ms: Process B completed I/O; added to ready queue [Q D H B]
time 351378ms: Process C completed a CPU burst; 14 bursts to go [Q D H B]
time 351378ms: Process C switching out of CPU; blocking on I/O until time 351659ms [Q D H B]
time 351384ms: Process D started using the CPU for 7024ms burst [Q H B]
time 351659ms: Process C completed I/O; added to ready queue [Q H B C]
time 358408ms: Process D completed a CPU burst; 24 bursts to go [Q H B C]
time 358408ms: Process D switching out of CPU; blocking on I/O until time 358703ms [Q H B C]
time 358414ms: Process H started using the CPU for 3192ms burst [Q B C]
time 358703ms: Process D completed I/O; added to ready queue [Q B C D]
time 361606ms: Process H completed a CPU burst; 19 bursts to go [Q B C D]
time 361606ms: Process H switching out of CPU; blocking on I/O until time 362319ms [Q B C D]
time 361612ms: Process B started using the CPU for 1161ms burst [Q C D]
time 362319ms: Process H completed I/O; added to ready queue [Q C D H]
time 362773ms: Process B completed a CPU burst; 26 bursts to go [Q C D H]
time 362773ms: Process B switching out of CPU; blocking on I/O until time 386216ms [Q C D H]
time 362779ms: Process C started using the CPU for 1448ms burst [Q D H]
time 364227ms: Process C completed a CPU burst; 13 bursts to go [Q D H]
time 364227ms: Process C switching out of CPU; blocking on I/O until time 364331ms [Q D H]
time 364233ms: Process D started using the CPU for 1892ms burst [Q H]
time 364331ms: Process C completed I/O; added to ready queue [Q H C]
time 366125ms: Process D completed a CPU burst; 23 bursts to go [Q H C]
time 366125ms: Process D switching out of CPU; blocking on I/O until time 367436ms [Q H C]
time 366131ms: Process H started using the CPU for 9268ms burst [Q C]
time 367436ms: Process D completed I/O; added to ready queue [Q C D]
time 375399ms: Process H completed a CPU burst; 18 bursts to go [Q C D]
time 375399ms: Process H switching out of CPU; blocking on I/O until time 376078ms [Q C D]
time 375405ms: Process C started using the CPU for 7956ms burst [Q D]
time 376078ms: Process H completed I/O; added to ready queue [Q D H]
time 383361ms: Process C completed a CPU burst; 12 bursts to go [Q D H]
time 383361ms: Process C switching out of CPU; blocking on I/O until time 384312ms [Q D H]
time 383367ms: Process D started using the CPU for 1268ms burst [Q H]
time 384312ms: Process C completed I/O; added to ready queue [Q H C]
time 384635ms: Process D completed a CPU burst; 22 bursts to go [Q H C]
time 384635ms: Process D switching out of CPU; blocking on I/O until time 385531ms [Q H C]
time 384641ms: Process H started using the CPU for 4812ms burst [Q C]
time 385531ms: Process D completed I/O; added to ready queue [Q C D]
time 386216ms: Process B completed I/O; added to ready queue [Q C D B]
time 389453ms: Process H completed a CPU burst; 17 bursts to go [Q C D B]
time 389453ms: Process H switching out of CPU; blocking on I/O until time 392368ms [Q C D B]
time 389459ms: Process C started using the CPU for 6748ms burst [Q D B]
time 392368ms: Process H completed I/O; added to ready queue [Q D B H]
time 396207ms: Process C completed a CPU burst; 11 bursts to go [Q D B H]
time 396207ms: Process C switching out of CPU; blocking on I/O until time 396936ms [Q D B H]
time 396213ms: Process D started using the CPU for 3452ms burst [Q B H]
time 396936ms: Process C completed I/O; added to ready queue [Q B H C]
time 399665ms: Process D completed a CPU burst; 21 bursts to go [Q B H C]
time 399665ms: Process D switching out of CPU; blocking on I/O until time 399715ms [Q B H C]
time 399671ms: Process B started using the CPU for 60ms burst [Q H C]
time 399715ms: Process D completed I/O; added to ready queue [Q H C D]
time 399731ms: Process B completed a CPU burst; 25 bursts to go [Q H C D]
time 399731ms: Process B switching out of CPU; blocking on I/O until time 429364ms [Q H C D]
time 399737ms: Process H started using the CPU for 2120ms burst [Q C D]
time 401857ms: Process H completed a CPU burst; 16 bursts to go [Q C D]
time 401857ms: Process H switching out of CPU; blocking on I/O until time 402762ms [Q C D]
time 401863ms: Process C started using the CPU for 2276ms burst [Q D]
time 402762ms: Process H completed I/O; added to ready queue [Q D H]
time 404139ms: Process C completed a CPU burst; 10 bursts to go [Q D H]
time 404139ms: Process C switching out of CPU; blocking on I/O until time 405459ms [Q D H]
time 404145ms: Process D started using the CPU for 5308ms burst [Q H]
time 405459ms: Process C completed I/O; added to ready queue [Q H C]
time 409453ms: Process D completed a CPU burst; 20 bursts to go [Q H C]
time 409453ms: Process D switching out of CPU; blocking on I/O until time 412626ms [Q H C]
time 409459ms: Process H started using the CPU for 4116ms burst [Q C]
time 412626ms: Process D completed I/O; added to ready queue [Q C D]
time 413575ms: Process H completed a CPU burst; 15 bursts to go [Q C D]
time 413575ms: Process H switching out of CPU; blocking on I/O until time 414413ms [Q C D]
time 413581ms: Process C started using the CPU for 2204ms burst [Q D]
time 414413ms: Process H completed I/O; added to ready queue [Q D H]
time 415785ms: Process C completed a CPU burst; 9 bursts to go [Q D H]
time 415785ms: Process C switching out of CPU; blocking on I/O until time 416988ms [Q D H]
time 415791ms: Process D started using the CPU for 1536ms burst [Q H]
time 416988ms: Process C completed I/O; added to ready queue [Q H C]
time 417327ms: Process D completed a CPU burst; 19 bursts to go [Q H C]
time 417327ms: Process D switching out of CPU; blocking on I/O until time 418068ms [Q H C]
time 417333ms: Process H started using the CPU for 2580ms burst [Q C]
time 418068ms: Process D completed I/O; added to ready queue [Q C D]
time 419913ms: Process H completed a CPU burst; 14 bursts to go [Q C D]
time 419913ms: Process H switching out of CPU; blocking on I/O until time 421929ms [Q C D]
time 419919ms: Process C started using the CPU for 2292ms burst [Q D]
time 421929ms: Process H completed I/O; added to ready queue [Q D H]
time 422211ms: Process C completed a CPU burst; 8 bursts to go [Q D H]
time 422211ms: Process C switching out of CPU; blocking on I/O until time 423435ms [Q D H]
time 422217ms: Process D started using the CPU for 2096ms burst [Q H]
time 423435ms: Process C completed I/O; added to ready queue [Q H C]
time 424313ms: Process D completed a CPU burst; 18 bursts to go [Q H C]
time 424313ms: Process D switching out of CPU; blocking on I/O until time 424427ms [Q H C]
time 424319ms: Process H started using the CPU for 1428ms burst [Q C]
time 424427ms: Process D completed I/O; added to ready queue [Q C D]
time 425747ms: Process H completed a CPU burst; 13 bursts to go [Q C D]
time 425747ms: Process H switching out of CPU; blocking on I/O until time 427160ms [Q C D]
time 425753ms: Process C started using the CPU for 844ms burst [Q D]
time 426597ms: Process C completed a CPU burst; 7 bursts to go [Q D]
time 426597ms: Process C switching out of CPU; blocking on I/O until time 427798ms [Q D]
time 426603ms: Process D started using the CPU for 476ms burst [Q <empty>]
time 427079ms: Process D completed a CPU burst; 17 bursts to go [Q <empty>]
time 427079ms: Process D switching out of CPU; blocking on I/O until time 427415ms [Q <empty>]
time 427160ms: Process H completed I/O; added to ready queue [Q H]
time 427163ms: Process H started using the CPU for 20ms burst [Q <empty>]
time 427183ms: Process H completed a CPU burst; 12 bursts to go [Q <empty>]
time 427183ms: Process H switching out of CPU; blocking on I/O until time 430353ms [Q <empty>]
time 427415ms: Process D completed I/O; added to ready queue [Q D]
time 427418ms: Process D started using the CPU for 2088ms burst [Q <empty>]
time 427798ms: Process C completed I/O; added to ready queue [Q C]
time 429364ms: Process B completed I/O; added to ready queue [Q C B]
time 429506ms: Process D completed a CPU burst; 16 bursts to go [Q C B]
time 429506ms: Process D switching out of CPU; blocking on I/O until time 430305ms [Q C B]
time 429512ms: Process C started using the CPU for 5128ms burst [Q B]
time 430305ms: Process D completed I/O; added to ready queue [Q B D]
time 430353ms: Process H completed I/O; added to ready queue [Q B D H]
time 434640ms: Process C completed a CPU burst; 6 bursts to go [Q B D H]
time 434640ms: Process C switching out of CPU; blocking on I/O until time 435675ms [Q B D H]
time 434646ms: Process B started using the CPU for 136ms burst [Q D H]
time 434782ms: Process B completed a CPU burst; 24 bursts to go [Q D H]
time 434782ms: Process B switching out of CPU; blocking on I/O until time 460045ms [Q D H]
time 434788ms: Process D started using the CPU for 2512ms burst [Q H]
time 435675ms: Process C completed I/O; added to ready queue [Q H C]
time 437300ms: Process D completed a CPU burst; 15 bursts to go [Q H C]
time 437300ms: Process D switching out of CPU; blocking on I/O until time 437606ms [Q H C]
time 437306ms: Process H started using the CPU for 3080ms burst [Q C]
time 437606ms: Process D completed I/O; added to ready queue [Q C D]
time 440386ms: Process H completed a CPU burst; 11 bursts to go [Q C D]
time 440386ms: Process H switching out of CPU; blocking on I/O until time 440974ms [Q C D]
time 440392ms: Process C started using the CPU for 1572ms burst [Q D]
time 440974ms: Process H completed I/O; added to ready queue [Q D H]
time 441964ms: Process C completed a CPU burst; 5 bursts to go [Q D H]
time 441964ms: Process C switching out of CPU; blocking on I/O until time 443448ms [Q D H]
time 441970ms: Process D started using the CPU for 10300ms burst [Q H]
time 443448ms: Process C completed I/O; added to ready queue [Q H C]
time 452270ms: Process D completed a CPU burst; 14 bursts to go [Q H C]
time 452270ms: Process D switching out of CPU; blocking on I/O until time 453234ms [Q H C]
time 452276ms: Process H started using the CPU for 2020ms burst [Q C]
time 453234ms: Process D completed I/O; added to ready queue [Q C D]
time 454296ms: Process H completed a CPU burst; 10 bursts to go [Q C D]
time 454296ms: Process H switching out of CPU; blocking on I/O until time 455169ms [Q C D]
time 454302ms: Process C started using the CPU for 3824ms burst [Q D]
time 455169ms: Process H completed I/O; added to ready queue [Q D H]
time 458126ms: Process C completed a CPU burst; 4 bursts to go [Q D H]
time 458126ms: Process C switching out of CPU; blocking on I/O until time 459560ms [Q D H]
time 458132ms: Process D started using the CPU for 4168ms burst [Q H]
time 459560ms: Process C completed I/O; added to ready queue [Q H C]
time 460045ms: Process B completed I/O; added to ready queue [Q H C B]
time 462300ms: Process D completed a CPU burst; 13 bursts to go [Q H C B]
time 462300ms: Process D switching out of CPU; blocking on I/O until time 463619ms [Q H C B]
time 462306ms: Process H started using the CPU for 1264ms burst [Q C B]
time 463570ms: Process H completed a CPU burst; 9 bursts to go [Q C B]
time 463570ms: Process H switching out of CPU; blocking on I/O until time 463834ms [Q C B]
time 463576ms: Process C started using the CPU for 616ms burst [Q B]
time 463619ms: Process D completed I/O; added to ready queue [Q B D]
time 463834ms: Process H completed I/O; added to ready queue [Q B D H]
time 464192ms: Process C completed a CPU burst; 3 bursts to go [Q B D H]
time 464192ms: Process C switching out of CPU; blocking on I/O until time 464950ms [Q B D H]
time 464198ms: Process B started using the CPU for 1314ms burst [Q D H]
time 464950ms: Process C completed I/O; added to ready queue [Q D H C]
time 465512ms: Process B completed a CPU burst; 23 bursts to go [Q D H C]
time 465512ms: Process B switching out of CPU; blocking on I/O until time 485845ms [Q D H C]
time 465518ms: Process D started using the CPU for 2104ms burst [Q H C]
time 467622ms: Process D completed a CPU burst; 12 bursts to go [Q H C]
time 467622ms: Process D switching out of CPU; blocking on I/O until time 468010ms [Q H C]
time 467628ms: Process H started using the CPU for 3080ms burst [Q C]
time 468010ms: Process D completed I/O; added to ready queue [Q C D]
time 470708ms: Process H completed a CPU burst; 8 bursts to go [Q C D]
time 470708ms: Process H switching out of CPU; blocking on I/O until time 471349ms [Q C D]
time 470714ms: Process C started using the CPU for 1304ms burst [Q D]
time 471349ms: Process H completed I/O; added to ready queue [Q D H]
time 472018ms: Process C completed a CPU burst; 2 bursts to go [Q D H]
time 472018ms: Process C switching out of CPU; blocking on I/O until time 473034ms [Q D H]
time 472024ms: Process D started using the CPU for 8000ms burst [Q H]
time 473034ms: Process C completed I/O; added to ready queue [Q H C]
time 480024ms: Process D completed a CPU burst; 11 bursts to go [Q H C]
time 480024ms: Process D switching out of CPU; blocking on I/O until time 481067ms [Q H C]
time 480030ms: Process H started using the CPU for 11336ms burst [Q C]
time 481067ms: Process D completed I/O; added to ready queue [Q C D]
time 485845ms: Process B completed I/O; added to ready queue [Q C D B]
time 491366ms: Process H completed a CPU burst; 7 bursts to go [Q C D B]
time 491366ms: Process H switching out of CPU; blocking on I/O until time 491416ms [Q C D B]
time 491372ms: Process C started using the CPU for 528ms burst [Q D B]
time 491416ms: Process H completed I/O; added to ready queue [Q D B H]
time 491900ms: Process C completed a CPU burst; 1 burst to go [Q D B H]
time 491900ms: Process C switching out of CPU; blocking on I/O until time 493105ms [Q D B H]
time 491906ms: Process D started using the CPU for 1664ms burst [Q B H]
time 493105ms: Process C completed I/O; added to ready queue [Q B H C]
time 493570ms: Process D completed a CPU burst; 10 bursts to go [Q B H C]
time 493570ms: Process D switching out of CPU; blocking on I/O until time 494291ms [Q B H C]
time 493576ms: Process B started using the CPU for 911ms burst [Q H C]
time 494291ms: Process D completed I/O; added to ready queue [Q H C D]
time 494487ms: Process B completed a CPU burst; 22 bursts to go [Q H C D]
time 494487ms: Process B switching out of CPU; blocking on I/O until time 498420ms [Q H C D]
time 494493ms: Process H started using the CPU for 1104ms burst [Q C D]
time 495597ms: Process H completed a CPU burst; 6 bursts to go [Q C D]
time 495597ms: Process H switching out of CPU; blocking on I/O until time 498268ms [Q C D]
time 495603ms: Process C started using the CPU for 28ms burst [Q D]
time 495631ms: Process C terminated [Q D]
time 495637ms: Process D started using the CPU for 5984ms burst [Q <empty>]
time 498268ms: Process H completed I/O; added to ready queue [Q H]
time 498420ms: Process B completed I/O; added to ready queue [Q H B]
time 501621ms: Process D completed a CPU burst; 9 bursts to go [Q H B]
time 501621ms: Process D switching out of CPU; blocking on I/O until time 502049ms [Q H B]
time 501627ms: Process H started using the CPU for 1512ms burst [Q B]
time 502049ms: Process D completed I/O; added to ready queue [Q B D]
time 503139ms: Process H completed a CPU burst; 5 bursts to go [Q B D]
time 503139ms: Process H switching out of CPU; blocking on I/O until time 504714ms [Q B D]
time 503145ms: Process B started using the CPU for 495ms burst [Q D]
time 503640ms: Process B completed a CPU burst; 21 bursts to go [Q D]
time 503640ms: Process B switching out of CPU; blocking on I/O until time 511973ms [Q D]
time 503646ms: Process D started using the CPU for 1584ms burst [Q <empty>]
time 504714ms: Process H completed I/O; added to ready queue [Q H]
time 505230ms: Process D completed a CPU burst; 8 bursts to go [Q H]
time 505230ms: Process D switching out of CPU; blocking on I/O until time 505559ms [Q H]
time 505236ms: Process H started using the CPU for 4412ms burst [Q <empty>]
time 505559ms: Process D completed I/O; added to ready queue [Q D]
time 509648ms: Process H completed a CPU burst; 4 bursts to go [Q D]
time 509648ms: Process H switching out of CPU; blocking on I/O until time 510312ms [Q D]
time 509654ms: Process D started using the CPU for 4952ms burst [Q <empty>]
time 510312ms: Process H completed I/O; added to ready queue [Q H]
time 511973ms: Process B completed I/O; added to ready queue [Q H B]
time 514606ms: Process D completed a CPU burst; 7 bursts to go [Q H B]
time 514606ms: Process D switching out of CPU; blocking on I/O until time 515619ms [Q H B]
time 514612ms: Process H started using the CPU for 3152ms burst [Q B]
time 515619ms: Process D completed I/O; added to ready queue [Q B D]
time 517764ms: Process H completed a CPU burst; 3 bursts to go [Q B D]
time 517764ms: Process H switching out of CPU; blocking on I/O until time 518487ms [Q B D]
time 517770ms: Process B started using the CPU for 57ms burst [Q D]
time 517827ms: Process B completed a CPU burst; 20 bursts to go [Q D]
time 517827ms: Process B switching out of CPU; blocking on I/O until time 530930ms [Q D]
time 517833ms: Process D started using the CPU for 136ms burst [Q <empty>]
time 517969ms: Process D completed a CPU burst; 6 bursts to go [Q <empty>]
time 517969ms: Process D switching out of CPU; blocking on I/O until time 518212ms [Q <empty>]
time 518212ms: Process D completed I/O; added to ready queue [Q D]
time 518215ms: Process D started using the CPU for 504ms burst [Q <empty>]
time 518487ms: Process H completed I/O; added to ready queue [Q H]
time 518719ms: Process D completed a CPU burst; 5 bursts to go [Q H]
time 518719ms: Process D switching out of CPU; blocking on I/O until time 519294ms [Q H]
time 518725ms: Process H started using the CPU for 432ms burst [Q <empty>]
time 519157ms: Process H completed a CPU burst; 2 bursts to go [Q <empty>]
time 519157ms: Process H switching out of CPU; blocking on I/O until time 519171ms [Q <empty>]
time 519171ms: Process H completed I/O; added to ready queue [Q H]
time 519174ms: Process H started using the CPU for 4364ms burst [Q <empty>]
time 519294ms: Process D completed I/O; added to ready queue [Q D]
time 523538ms: Process H completed a CPU burst; 1 burst to go [Q D]
time 523538ms: Process H switching out of CPU; blocking on I/O until time 524011ms [Q D]
time 523544ms: Process D started using the CPU for 44ms burst [Q <empty>]
time 523588ms: Process D completed a CPU burst; 4 bursts to go [Q <empty>]
time 523588ms: Process D switching out of CPU; blocking on I/O until time 524199ms [Q <empty>]
time 524011ms: Process H completed I/O; added to ready queue [Q H]
time 524014ms: Process H started using the CPU for 5616ms burst [Q <empty>]
time 524199ms: Process D completed I/O; added to ready queue [Q D]
time 529630ms: Process H terminated [Q D]
time 529636ms: Process D started using the CPU for 4172ms burst [Q <empty>]
time 530930ms: Process B completed I/O; added to ready queue [Q B]
time 533808ms: Process D completed a CPU burst; 3 bursts to go [Q B]
time 533808ms: Process D switching out of CPU; blocking on I/O until time 534911ms [Q B]
time 533814ms: Process B started using the CPU for 365ms burst [Q <empty>]
time 534179ms: Process B completed a CPU burst; 19 bursts to go [Q <empty>]
time 534179ms: Process B switching out of CPU; blocking on I/O until time 553262ms [Q <empty>]
time 534911ms: Process D completed I/O; added to ready queue [Q D]
time 534914ms: Process D started using the CPU for 312ms burst [Q <empty>]
time 535226ms: Process D completed a CPU burst; 2 bursts to go [Q <empty>]
time 535226ms: Process D switching out of CPU; blocking on I/O until time 536426ms [Q <empty>]
time 536426ms: Process D completed I/O; added to ready queue [Q D]
time 536429ms: Process D started using the CPU for 696ms burst [Q <empty>]
time 537125ms: Process D completed a CPU burst; 1 burst to go [Q <empty>]
time 537125ms: Process D switching out of CPU; blocking on I/O until time 538561ms [Q <empty>]
time 538561ms: Process D completed I/O; added to ready queue [Q D]
time 538564ms: Process D started using the CPU for 2436ms burst [Q <empty>]
time 541000ms: Process D terminated [Q <empty>]
time 553262ms: Process B completed I/O; added to ready queue [Q B]
time 553265ms: Process B started using the CPU for 558ms burst [Q <empty>]
time 553823ms: Process B completed a CPU burst; 18 bursts to go [Q <empty>]
time 553823ms: Process B switching out of CPU; blocking on I/O until time 553996ms [Q <empty>]
time 553996ms: Process B completed I/O; added to ready queue [Q B]
time 553999ms: Process B started using the CPU for 527ms burst [Q <empty>]
time 554526ms: Process B completed a CPU burst; 17 bursts to go [Q <empty>]
time 554526ms: Process B switching out of CPU; blocking on I/O until time 557759ms [Q <empty>]
time 557759ms: Process B completed I/O; added to ready queue [Q B]
time 557762ms: Process B started using the CPU for 468ms burst [Q <empty>]
time 558230ms: Process B completed a CPU burst; 16 bursts to go [Q <empty>]
time 558230ms: Process B switching out of CPU; blocking on I/O until time 559803ms [Q <empty>]
time 559803ms: Process B completed I/O; added to ready queue [Q B]
time 559806ms: Process B started using the CPU for 1016ms burst [Q <empty>]
time 560822ms: Process B completed a CPU burst; 15 bursts to go [Q <empty>]
time 560822ms: Process B switching out of CPU; blocking on I/O until time 565795ms [Q <empty>]
time 565795ms: Process B completed I/O; added to ready queue [Q B]
time 565798ms: Process B started using the CPU for 258ms burst [Q <empty>]
time 566056ms: Process B completed a CPU burst; 14 bursts to go [Q <empty>]
time 566056ms: Process B switching out of CPU; blocking on I/O until time 580309ms [Q <empty>]
time 580309ms: Process B completed I/O; added to ready queue [Q B]
time 580312ms: Process B started using the CPU for 309ms burst [Q <empty>]
time 580621ms: Process B completed a CPU burst; 13 bursts to go [Q <empty>]
time 580621ms: Process B switching out of CPU; blocking on I/O until time 588974ms [Q <empty>]
time 588974ms: Process B completed I/O; added to ready queue [Q B]
time 588977ms: Process B started using the CPU for 587ms burst [Q <empty>]
time 589564ms: Process B completed a CPU burst; 12 bursts to go [Q <empty>]
time 589564ms: Process B switching out of CPU; blocking on I/O until time 590457ms [Q <empty>]
time 590457ms: Process B completed I/O; added to ready queue [Q B]
time 590460ms: Process B started using the CPU for 1210ms burst [Q <empty>]
time 591670ms: Process B completed a CPU burst; 11 bursts to go [Q <empty>]
time 591670ms: Process B switching out of CPU; blocking on I/O until time 596323ms [Q <empty>]
time 596323ms: Process B completed I/O; added to ready queue [Q B]
time 596326ms: Process B started using the CPU for 650ms burst [Q <empty>]
time 596976ms: Process B completed a CPU burst; 10 bursts to go [Q <empty>]
time 596976ms: Process B switching out of CPU; blocking on I/O until time 622659ms [Q <empty>]
time 622659ms: Process B completed I/O; added to ready queue [Q B]
time 622662ms: Process B started using the CPU for 867ms burst [Q <empty>]
time 623529ms: Process B completed a CPU burst; 9 bursts to go [Q <empty>]
time 623529ms: Process B switching out of CPU; blocking on I/O until time 624252ms [Q <empty>]
time 624252ms: Process B completed I/O; added to ready queue [Q B]
time 624255ms: Process B started using the CPU for 196ms burst [Q <empty>]
time 624451ms: Process B completed a CPU burst; 8 bursts to go [Q <empty>]
time 624451ms: Process B switching out of CPU; blocking on I/O until time 650444ms [Q <empty>]
time 650444ms: Process B completed I/O; added to ready queue [Q B]
time 650447ms: Process B started using the CPU for 87ms burst [Q <empty>]
time 650534ms: Process B completed a CPU burst; 7 bursts to go [Q <empty>]
time 650534ms: Process B switching out of CPU; blocking on I/O until time 656877ms [Q <empty>]
time 656877ms: Process B completed I/O; added to ready queue [Q B]
time 656880ms: Process B started using the CPU for 2519ms burst [Q <empty>]
time 659399ms: Process B completed a CPU burst; 6 bursts to go [Q <empty>]
time 659399ms: Process B switching out of CPU; blocking on I/O until time 662572ms [Q <empty>]
time 662572ms: Process B completed I/O; added to ready queue [Q B]
time 662575ms: Process B started using the CPU for 406ms burst [Q <empty>]
time 662981ms: Process B completed a CPU burst; 5 bursts to go [Q <empty>]
time 662981ms: Process B switching out of CPU; blocking on I/O until time 667114ms [Q <empty>]
time 667114ms: Process B completed I/O; added to ready queue [Q B]
time 667117ms: Process B started using the CPU for 684ms burst [Q <empty>]
time 667801ms: Process B completed a CPU burst; 4 bursts to go [Q <empty>]
time 667801ms: Process B switching out of CPU; blocking on I/O until time 694474ms [Q <empty>]
time 694474ms: Process B completed I/O; added to ready queue [Q B]
time 694477ms: Process B started using the CPU for 301ms burst [Q <empty>]
time 694778ms: Process B completed a CPU burst; 3 bursts to go [Q <empty>]
time 694778ms: Process B switching out of CPU; blocking on I/O until time 710591ms [Q <empty>]
time 710591ms: Process B completed I/O; added to ready queue [Q B]
time 710594ms: Process B started using the CPU for 9ms burst [Q <empty>]
time 710603ms: Process B completed a CPU burst; 2 bursts to go [Q <empty>]
time 710603ms: Process B switching out of CPU; blocking on I/O until time 718816ms [Q <empty>]
time 718816ms: Process B completed I/O; added to ready queue [Q B]
time 718819ms: Process B started using the CPU for 828ms burst [Q <empty>]
time 719647ms: Process B completed a CPU burst; 1 burst to go [Q <empty>]
time 719647ms: Process B switching out of CPU; blocking on I/O until time 740950ms [Q <empty>]
time 740950ms: Process B completed I/O; added to ready queue [Q B]
time 740953ms: Process B started using the CPU for 45ms burst [Q <empty>]
time 740998ms: Process B terminated [Q <empty>]
time 741001ms: Simulator ended for FCFS [Q <empty>]

time 0ms: Simulator started for SJF [Q <empty>]
time 22ms: Process F (tau 1000ms) arrived; added to ready queue [Q F]
time 25ms: Process F (tau 1000ms) started using the CPU for 596ms burst [Q <empty>]
time 81ms: Process E (tau 1000ms) arrived; added to ready queue [Q E]
time 92ms: Process D (tau 1000ms) arrived; added to ready queue [Q D E]
time 187ms: Process B (tau 1000ms) arrived; added to ready queue [Q B D E]
time 621ms: Process F (tau 1000ms) completed a CPU burst; 5 bursts to go [Q B D E]
time 621ms: Recalculating tau for process F: old tau 1000ms ==> new tau 637ms [Q B D E]
time 621ms: Process F switching out of CPU; blocking on I/O until time 900ms [Q B D E]
time 627ms: Process B (tau 1000ms) started using the CPU for 974ms burst [Q D E]
time 692ms: Process A (tau 1000ms) arrived; added to ready queue [Q A D E]
time 755ms: Process G (tau 1000ms) arrived; added to ready queue [Q A D E G]
time 900ms: Process F (tau 637ms) completed I/O; added to ready queue [Q F A D E G]
time 981ms: Process H (tau 1000ms) arrived; added to ready queue [Q F A D E G H]
time 1130ms: Process C (tau 1000ms) arrived; added to ready queue [Q F A C D E G H]
time 1601ms: Process B (tau 1000ms) completed a CPU burst; 43 bursts to go [Q F A C D E G H]
time 1601ms: Recalculating tau for process B: old tau 1000ms ==> new tau 977ms [Q F A C D E G H]
time 1601ms: Process B switching out of CPU; blocking on I/O until time 10554ms [Q F A C D E G H]
time 1607ms: Process F (tau 637ms) started using the CPU for 3284ms burst [Q A C D E G H]
time 4891ms: Process F (tau 637ms) completed a CPU burst; 4 bursts to go [Q A C D E G H]
time 4891ms: Recalculating tau for process F: old tau 637ms ==> new tau 3020ms [Q A C D E G H]
time 4891ms: Process F switching out of CPU; blocking on I/O until time 5199ms [Q A C D E G H]
time 4897ms: Process A (tau 1000ms) started using the CPU for 1528ms burst [Q C D E G H]
time 5199ms: Process F (tau 3020ms) completed I/O; added to ready queue [Q C D E G H F]
time 6425ms: Process A (tau 1000ms) completed a CPU burst; 11 bursts to go [Q C D E G H F]
time 6425ms: Recalculating tau for process A: old tau 1000ms ==> new tau 1476ms [Q C D E G H F]
time 6425ms: Process A switching out of CPU; blocking on I/O until time 12808ms [Q C D E G H F]
time 6431ms: Process C (tau 1000ms) started using the CPU for 2256ms burst [Q D E G H F]
time 8687ms: Process C (tau 1000ms) completed a CPU burst; 34 bursts to go [Q D E G H F]
time 8687ms: Recalculating tau for process C: old tau 1000ms ==> new tau 2131ms [Q D E G H F]
time 8687ms: Process C switching out of CPU; blocking on I/O until time 9032ms [Q D E G H F]
time 8693ms: Process D (tau 1000ms) started using the CPU for 780ms burst [Q E G H F]
time 9032ms: Process C (tau 2131ms) completed I/O; added to ready queue [Q E G H C F]
time 9473ms: Process D (tau 1000ms) completed a CPU burst; 46 bursts to go [Q E G H C F]
time 9473ms: Recalculating tau for process D: old tau 1000ms ==> new tau 803ms [Q E G H C F]
time 9473ms: Process D switching out of CPU; blocking on I/O until time 9612ms [Q E G H C F]
time 9479ms: Process E (tau 1000ms) started using the CPU for 7344ms burst [Q G H C F]
time 9612ms: Process D (tau 803ms) completed I/O; added to ready queue [Q D G H C F]
time 10554ms: Process B (tau 977ms) completed I/O; added to ready queue [Q D B G H C F]
time 12808ms: Process A (tau 1476ms) completed I/O; added to ready queue [Q D B G H A C F]
time 16823ms: Process E (tau 1000ms) completed a CPU burst; 11 bursts to go [Q D B G H A C F]
time 16823ms: Recalculating tau for process E: old tau 1000ms ==> new tau 6710ms [Q D B G H A C F]
time 16823ms: Process E switching out of CPU; blocking on I/O until time 18044ms [Q D B G H A C F]
time 16829ms: Process D (tau 803ms) started using the CPU for 524ms burst [Q B G H A C F]
time 17353ms: Process D (tau 803ms) completed a CPU burst; 45 bursts to go [Q B G H A C F]
time 17353ms: Recalculating tau for process D: old tau 803ms ==> new tau 552ms [Q B G H A C F]
time 17353ms: Process D switching out of CPU; blocking on I/O until time 17572ms [Q B G H A C F]
time 17359ms: Process B (tau 977ms) started using the CPU for 471ms burst [Q G H A C F]
time 17572ms: Process D (tau 552ms) completed I/O; added to ready queue [Q D G H A C F]
time 17830ms: Process B (tau 977ms) completed a CPU burst; 42 bursts to go [Q D G H A C F]
time 17830ms: Recalculating tau for process B: old tau 977ms ==> new tau 522ms [Q D G H A C F]
time 17830ms: Process B switching out of CPU; blocking on I/O until time 30283ms [Q D G H A C F]
time 17836ms: Process D (tau 552ms) started using the CPU for 844ms burst [Q G H A C F]
time 18044ms: Process E (tau 6710ms) completed I/O; added to ready queue [Q G H A C F E]
time 18680ms: Process D (tau 552ms) completed a CPU burst; 44 bursts to go [Q G H A C F E]
time 18680ms: Recalculating tau for process D: old tau 552ms ==> new tau 815ms [Q G H A C F E]
time 18680ms: Process D switching out of CPU; blocking on I/O until time 20715ms [Q G H A C F E]
time 18686ms: Process G (tau 1000ms) started using the CPU for 952ms burst [Q H A C F E]
time 19638ms: Process G (tau 1000ms) completed a CPU burst; 4 bursts to go [Q H A C F E]
time 19638ms: Recalculating tau for process G: old tau 1000ms ==> new tau 957ms [Q H A C F E]
time 19638ms: Process G switching out of CPU; blocking on I/O until time 20583ms [Q H A C F E]
time 19644ms: Process H (tau 1000ms) started using the CPU for 920ms burst [Q A C F E]
time 20564ms: Process H (tau 1000ms) completed a CPU burst; 41 bursts to go [Q A C F E]
time 20564ms: Recalculating tau for process H: old tau 1000ms ==> new tau 929ms [Q A C F E]
time 20564ms: Process H switching out of CPU; blocking on I/O until time 20994ms [Q A C F E]
time 20570ms: Process A (tau 1476ms) started using the CPU for 1019ms burst [Q C F E]
time 20583ms: Process G (tau 957ms) completed I/O; added to ready queue [Q G C F E]
time 20715ms: Process D (tau 815ms) completed I/O; added to ready queue [Q D G C F E]
time 20994ms: Process H (tau 929ms) completed I/O; added to ready queue [Q D H G C F E]
time 21589ms: Process A (tau 1476ms) completed a CPU burst; 10 bursts to go [Q D H G C F E]
time 21589ms: Recalculating tau for process A: old tau 1476ms ==> new tau 1065ms [Q D H G C F E]
time 21589ms: Process A switching out of CPU; blocking on I/O until time 32542ms [Q D H G C F E]
time 21595ms: Process D (tau 815ms) started using the CPU for 2120ms burst [Q H G C F E]
time 23715ms: Process D (tau 815ms) completed a CPU burst; 43 bursts to go [Q H G C F E]
time 23715ms: Recalculating tau for process D: old tau 815ms ==> new tau 1990ms [Q H G C F E]
time 23715ms: Process D switching out of CPU; blocking on I/O until time 24028ms [Q H G C F E]
time 23721ms: Process H (tau 929ms) started using the CPU for 584ms burst [Q G C F E]
time 24028ms: Process D (tau 1990ms) completed I/O; added to ready queue [Q G D C F E]
time 24305ms: Process H (tau 929ms) completed a CPU burst; 40 bursts to go [Q G D C F E]
time 24305ms: Recalculating tau for process H: old tau 929ms ==> new tau 619ms [Q G D C F E]
time 24305ms: Process H switching out of CPU; blocking on I/O until time 25413ms [Q G D C F E]
time 24311ms: Process G (tau 957ms) started using the CPU for 1460ms burst [Q D C F E]
time 25413ms: Process H (tau 619ms) completed I/O; added to ready queue [Q H D C F E]
time 25771ms: Process G (tau 957ms) completed a CPU burst; 3 bursts to go [Q H D C F E]
time 25771ms: Recalculating tau for process G: old tau 957ms ==> new tau 1410ms [Q H D C F E]
time 25771ms: Process G switching out of CPU; blocking on I/O until time 25915ms [Q H D C F E]
time 25777ms: Process H (tau 619ms) started using the CPU for 10728ms burst [Q D C F E]
time 25915ms: Process G (tau 1410ms) completed I/O; added to ready queue [Q G D C F E]
time 30283ms: Process B (tau 522ms) completed I/O; added to ready queue [Q B G D C F E]
time 32542ms: Process A (tau 1065ms) completed I/O; added to ready queue [Q B A G D C F E]
time 36505ms: Process H (tau 619ms) completed a CPU burst; 39 bursts to go [Q B A G D C F E]
time 36505ms: Recalculating tau for process H: old tau 619ms ==> new tau 9718ms [Q B A G D C F E]
time 36505ms: Process H switching out of CPU; blocking on I/O until time 38338ms [Q B A G D C F E]
time 36511ms: Process B (tau 522ms) started using the CPU for 1009ms burst [Q A G D C F E]
time 37520ms: Process B (tau 522ms) completed a CPU burst; 41 bursts to go [Q A G D C F E]
time 37520ms: Recalculating tau for process B: old tau 522ms ==> new tau 961ms [Q A G D C F E]
time 37520ms: Process B switching out of CPU; blocking on I/O until time 37943ms [Q A G D C F E]
time 37526ms: Process A (tau 1065ms) started using the CPU for 412ms burst [Q G D C F E]
time 37938ms: Process A (tau 1065ms) completed a CPU burst; 9 bursts to go [Q G D C F E]
time 37938ms: Recalculating tau for process A: old tau 1065ms ==> new tau 478ms [Q G D C F E]
time 37938ms: Process A switching out of CPU; blocking on I/O until time 41661ms [Q G D C F E]
time 37943ms: Process B (tau 961ms) completed I/O; added to ready queue [Q B D C F E]
time 37944ms: Process G (tau 1410ms) started using the CPU for 312ms burst [Q B D C F E]
time 38256ms: Process G (tau 1410ms) completed a CPU burst; 2 bursts to go [Q B D C F E]
time 38256ms: Recalculating tau for process G: old tau 1410ms ==> new tau 422ms [Q B D C F E]
time 38256ms: Process G switching out of CPU; blocking on I/O until time 38952ms [Q B D C F E]
time 38262ms: Process B (tau 961ms) started using the CPU for 220ms burst [Q D C F E]
time 38338ms: Process H (tau 9718ms) completed I/O; added to ready queue [Q D C F E H]
time 38482ms: Process B (tau 961ms) completed a CPU burst; 40 bursts to go [Q D C F E H]
time 38482ms: Recalculating tau for process B: old tau 961ms ==> new tau 295ms [Q D C F E H]
time 38482ms: Process B switching out of CPU; blocking on I/O until time 38595ms [Q D C F E H]
time 38488ms: Process D (tau 1990ms) started using the CPU for 6928ms burst [Q C F E H]
time 38595ms: Process B (tau 295ms) completed I/O; added to ready queue [Q B C F E H]
time 38952ms: Process G (tau 422ms) completed I/O; added to ready queue [Q B G C F E H]
time 41661ms: Process A (tau 478ms) completed I/O; added to ready queue [Q B G A C F E H]
time 45416ms: Process D (tau 1990ms) completed a CPU burst; 42 bursts to go [Q B G A C F E H]
time 45416ms: Recalculating tau for process D: old tau 1990ms ==> new tau 6435ms [Q B G A C F E H]
time 45416ms: Process D switching out of CPU; blocking on I/O until time 46397ms [Q B G A C F E H]
time 45422ms: Process B (tau 295ms) started using the CPU for 343ms burst [Q G A C F E H]
time 45765ms: Process B (tau 295ms) completed a CPU burst; 39 bursts to go [Q G A C F E H]
time 45765ms: Recalculating tau for process B: old tau 295ms ==> new tau 339ms [Q G A C F E H]
time 45765ms: Process B switching out of CPU; blocking on I/O until time 49768ms [Q G A C F E H]
time 45771ms: Process G (tau 422ms) started using the CPU for 7048ms burst [Q A C F E H]
time 46397ms: Process D (tau 6435ms) completed I/O; added to ready queue [Q A C F D E H]
time 49768ms: Process B (tau 339ms) completed I/O; added to ready queue [Q B A C F D E H]
time 52819ms: Process G (tau 422ms) completed a CPU burst; 1 burst to go [Q B A C F D E H]
time 52819ms: Recalculating tau for process G: old tau 422ms ==> new tau 6386ms [Q B A C F D E H]
time 52819ms: Process G switching out of CPU; blocking on I/O until time 53498ms [Q B A C F D E H]
time 52825ms: Process B (tau 339ms) started using the CPU for 309ms burst [Q A C F D E H]
time 53134ms: Process B (tau 339ms) completed a CPU burst; 38 bursts to go [Q A C F D E H]
time 53134ms: Recalculating tau for process B: old tau 339ms ==> new tau 313ms [Q A C F D E H]
time 53134ms: Process B switching out of CPU; blocking on I/O until time 53977ms [Q A C F D E H]
time 53140ms: Process A (tau 478ms) started using the CPU for 238ms burst [Q C F D E H]
time 53378ms: Process A (tau 478ms) completed a CPU burst; 8 bursts to go [Q C F D E H]
time 53378ms: Recalculating tau for process A: old tau 478ms ==> new tau 263ms [Q C F D E H]
time 53378ms: Process A switching out of CPU; blocking on I/O until time 54551ms [Q C F D E H]
time 53384ms: Process C (tau 2131ms) started using the CPU for 3096ms burst [Q F D E H]
time 53498ms: Process G (tau 6386ms) completed I/O; added to ready queue [Q F G D E H]
time 53977ms: Process B (tau 313ms) completed I/O; added to ready queue [Q B F G D E H]
time 54551ms: Process A (tau 263ms) completed I/O; added to ready queue [Q A B F G D E H]
time 56480ms: Process C (tau 2131ms) completed a CPU burst; 33 bursts to go [Q A B F G D E H]
time 56480ms: Recalculating tau for process C: old tau 2131ms ==> new tau 3000ms [Q A B F G D E H]
time 56480ms: Process C switching out of CPU; blocking on I/O until time 59571ms [Q A B F G D E H]
time 56486ms: Process A (tau 263ms) started using the CPU for 227ms burst [Q B F G D E H]
time 56713ms: Process A (tau 263ms) completed a CPU burst; 7 bursts to go [Q B F G D E H]
time 56713ms: Recalculating tau for process A: old tau 263ms ==> new tau 231ms [Q B F G D E H]
time 56713ms: Process A switching out of CPU; blocking on I/O until time 62696ms [Q B F G D E H]
time 56719ms: Process B (tau 313ms) started using the CPU for 887ms burst [Q F G D E H]
time 57606ms: Process B (tau 313ms) completed a CPU burst; 37 bursts to go [Q F G D E H]
time 57606ms: Recalculating tau for process B: old tau 313ms ==> new tau 830ms [Q F G D E H]
time 57606ms: Process B switching out of CPU; blocking on I/O until time 60129ms [Q F G D E H]
time 57612ms: Process F (tau 3020ms) started using the CPU for 412ms burst [Q G D E H]
time 58024ms: Process F (tau 3020ms) completed a CPU burst; 3 bursts to go [Q G D E H]
time 58024ms: Recalculating tau for process F: old tau 3020ms ==> new tau 673ms [Q G D E H]
time 58024ms: Process F switching out of CPU; blocking on I/O until time 58843ms [Q G D E H]
time 58030ms: Process G (tau 6386ms) started using the CPU for 9924ms burst [Q D E H]
time 58843ms: Process F (tau 673ms) completed I/O; added to ready queue [Q F D E H]
time 59571ms: Process C (tau 3000ms) completed I/O; added to ready queue [Q F C D E H]
time 60129ms: Process B (tau 830ms) completed I/O; added to ready queue [Q F B C D E H]
time 62696ms: Process A (tau 231ms) completed I/O; added to ready queue [Q A F B C D E H]
time 67954ms: Process G terminated [Q A F B C D E H]
time 67960ms: Process A (tau 231ms) started using the CPU for 129ms burst [Q F B C D E H]
time 68089ms: Process A (tau 231ms) completed a CPU burst; 6 bursts to go [Q F B C D E H]
time 68089ms: Recalculating tau for process A: old tau 231ms ==> new tau 140ms [Q F B C D E H]
time 68089ms: Process A switching out of CPU; blocking on I/O until time 78512ms [Q F B C D E H]
time 68095ms: Process F (tau 673ms) started using the CPU for 860ms burst [Q B C D E H]
time 68955ms: Process F (tau 673ms) completed a CPU burst; 2 bursts to go [Q B C D E H]
time 68955ms: Recalculating tau for process F: old tau 673ms ==> new tau 842ms [Q B C D E H]
time 68955ms: Process F switching out of CPU; blocking on I/O until time 69075ms [Q B C D E H]
time 68961ms: Process B (tau 830ms) started using the CPU for 369ms burst [Q C D E H]
time 69075ms: Process F (tau 842ms) completed I/O; added to ready queue [Q F C D E H]
time 69330ms: Process B (tau 830ms) completed a CPU burst; 36 bursts to go [Q F C D E H]
time 69330ms: Recalculating tau for process B: old tau 830ms ==> new tau 416ms [Q F C D E H]
time 69330ms: Process B switching out of CPU; blocking on I/O until time 86133ms [Q F C D E H]
time 69336ms: Process F (tau 842ms) started using the CPU for 744ms burst [Q C D E H]
time 70080ms: Process F (tau 842ms) completed a CPU burst; 1 burst to go [Q C D E H]
time 70080ms: Recalculating tau for process F: old tau 842ms ==> new tau 754ms [Q C D E H]
time 70080ms: Process F switching out of CPU; blocking on I/O until time 70136ms [Q C D E H]
time 70086ms: Process C (tau 3000ms) started using the CPU for 5156ms burst [Q D E H]
time 70136ms: Process F (tau 754ms) completed I/O; added to ready queue [Q F D E H]
time 75242ms: Process C (tau 3000ms) completed a CPU burst; 32 bursts to go [Q F D E H]
time 75242ms: Recalculating tau for process C: old tau 3000ms ==> new tau 4941ms [Q F D E H]
time 75242ms: Process C switching out of CPU; blocking on I/O until time 76073ms [Q F D E H]
time 75248ms: Process F (tau 754ms) started using the CPU for 112ms burst [Q D E H]
time 75360ms: Process F terminated [Q D E H]
time 75366ms: Process D (tau 6435ms) started using the CPU for 3616ms burst [Q E H]
time 76073ms: Process C (tau 4941ms) completed I/O; added to ready queue [Q C E H]
time 78512ms: Process A (tau 140ms) completed I/O; added to ready queue [Q A C E H]
time 78982ms: Process D (tau 6435ms) completed a CPU burst; 41 bursts to go [Q A C E H]
time 78982ms: Recalculating tau for process D: old tau 6435ms ==> new tau 3898ms [Q A C E H]
time 78982ms: Process D switching out of CPU; blocking on I/O until time 79570ms [Q A C E H]
time 78988ms: Process A (tau 140ms) started using the CPU for 382ms burst [Q C E H]
time 79370ms: Process A (tau 140ms) completed a CPU burst; 5 bursts to go [Q C E H]
time 79370ms: Recalculating tau for process A: old tau 140ms ==> new tau 358ms [Q C E H]
time 79370ms: Process A switching out of CPU; blocking on I/O until time 85773ms [Q C E H]
time 79376ms: Process C (tau 4941ms) started using the CPU for 6460ms burst [Q E H]
time 79570ms: Process D (tau 3898ms) completed I/O; added to ready queue [Q D E H]
time 85773ms: Process A (tau 358ms) completed I/O; added to ready queue [Q A D E H]
time 85836ms: Process C (tau 4941ms) completed a CPU burst; 31 bursts to go [Q A D E H]
time 85836ms: Recalculating tau for process C: old tau 4941ms ==> new tau 6309ms [Q A D E H]
time 85836ms: Process C switching out of CPU; blocking on I/O until time 86086ms [Q A D E H]
time 85842ms: Process A (tau 358ms) started using the CPU for 408ms burst [Q D E H]
time 86086ms: Process C (tau 6309ms) completed I/O; added to ready queue [Q D C E H]
time 86133ms: Process B (tau 416ms) completed I/O; added to ready queue [Q B D C E H]
time 86250ms: Process A (tau 358ms) completed a CPU burst; 4 bursts to go [Q B D C E H]
time 86250ms: Recalculating tau for process A: old tau 358ms ==> new tau 403ms [Q B D C E H]
time 86250ms: Process A switching out of CPU; blocking on I/O until time 98683ms [Q B D C E H]
time 86256ms: Process B (tau 416ms) started using the CPU for 192ms burst [Q D C E H]
time 86448ms: Process B (tau 416ms) completed a CPU burst; 35 bursts to go [Q D C E H]
time 86448ms: Recalculating tau for process B: old tau 416ms ==> new tau 215ms [Q D C E H]
time 86448ms: Process B switching out of CPU; blocking on I/O until time 95871ms [Q D C E H]
time 86454ms: Process D (tau 3898ms) started using the CPU for 2128ms burst [Q C E H]
time 88582ms: Process D (tau 3898ms) completed a CPU burst; 40 bursts to go [Q C E H]
time 88582ms: Recalculating tau for process D: old tau 3898ms ==> new tau 2306ms [Q C E H]
time 88582ms: Process D switching out of CPU; blocking on I/O until time 89103ms [Q C E H]
time 88588ms: Process C (tau 6309ms) started using the CPU for 5060ms burst [Q E H]
time 89103ms: Process D (tau 2306ms) completed I/O; added to ready queue [Q D E H]
time 93648ms: Process C (tau 6309ms) completed a CPU burst; 30 bursts to go [Q D E H]
time 93648ms: Recalculating tau for process C: old tau 6309ms ==> new tau 5185ms [Q D E H]
time 93648ms: Process C switching out of CPU; blocking on I/O until time 93982ms [Q D E H]
time 93654ms: Process D (tau 2306ms) started using the CPU for 1788ms burst [Q E H]
time 93982ms: Process C (tau 5185ms) completed I/O; added to ready queue [Q C E H]
time 95442ms: Process D (tau 2306ms) completed a CPU burst; 39 bursts to go [Q C E H]
time 95442ms: Recalculating tau for process D: old tau 2306ms ==> new tau 1840ms [Q C E H]
time 95442ms: Process D switching out of CPU; blocking on I/O until time 95845ms [Q C E H]
time 95448ms: Process C (tau 5185ms) started using the CPU for 7836ms burst [Q E H]
time 95845ms: Process D (tau 1840ms) completed I/O; added to ready queue [Q D E H]
time 95871ms: Process B (tau 215ms) completed I/O; added to ready queue [Q B D E H]
time 98683ms: Process A (tau 403ms) completed I/O; added to ready queue [Q B A D E H]
time 103284ms: Process C (tau 5185ms) completed a CPU burst; 29 bursts to go [Q B A D E H]
time 103284ms: Recalculating tau for process C: old tau 5185ms ==> new tau 7571ms [Q B A D E H]
time 103284ms: Process C switching out of CPU; blocking on I/O until time 104545ms [Q B A D E H]
time 103290ms: Process B (tau 215ms) started using the CPU for 941ms burst [Q A D E H]
time 104231ms: Process B (tau 215ms) completed a CPU burst; 34 bursts to go [Q A D E H]
time 104231ms: Recalculating tau for process B: old tau 215ms ==> new tau 869ms [Q A D E H]
time 104231ms: Process B switching out of CPU; blocking on I/O until time 119094ms [Q A D E H]
time 104237ms: Process A (tau 403ms) started using the CPU for 680ms burst [Q D E H]
time 104545ms: Process C (tau 7571ms) completed I/O; added to ready queue [Q D E C H]
time 104917ms: Process A (tau 403ms) completed a CPU burst; 3 bursts to go [Q D E C H]
time 104917ms: Recalculating tau for process A: old tau 403ms ==> new tau 653ms [Q D E C H]
time 104917ms: Process A switching out of CPU; blocking on I/O until time 110590ms [Q D E C H]
time 104923ms: Process D (tau 1840ms) started using the CPU for 6336ms burst [Q E C H]
time 110590ms: Process A (tau 653ms) completed I/O; added to ready queue [Q A E C H]
time 111259ms: Process D (tau 1840ms) completed a CPU burst; 38 bursts to go [Q A E C H]
time 111259ms: Recalculating tau for process D: old tau 1840ms ==> new tau 5887ms [Q A E C H]
time 111259ms: Process D switching out of CPU; blocking on I/O until time 113377ms [Q A E C H]
time 111265ms: Process A (tau 653ms) started using the CPU for 231ms burst [Q E C H]
time 111496ms: Process A (tau 653ms) completed a CPU burst; 2 bursts to go [Q E C H]
time 111496ms: Recalculating tau for process A: old tau 653ms ==> new tau 274ms [Q E C H]
time 111496ms: Process A switching out of CPU; blocking on I/O until time 114299ms [Q E C H]
time 111502ms: Process E (tau 6710ms) started using the CPU for 824ms burst [Q C H]
time 112326ms: Process E (tau 6710ms) completed a CPU burst; 10 bursts to go [Q C H]
time 112326ms: Recalculating tau for process E: old tau 6710ms ==> new tau 1413ms [Q C H]
time 112326ms: Process E switching out of CPU; blocking on I/O until time 112836ms [Q C H]
time 112332ms: Process C (tau 7571ms) started using the CPU for 6608ms burst [Q H]
time 112836ms: Process E (tau 1413ms) completed I/O; added to ready queue [Q E H]
time 113377ms: Process D (tau 5887ms) completed I/O; added to ready queue [Q E D H]
time 114299ms: Process A (tau 274ms) completed I/O; added to ready queue [Q A E D H]
time 118940ms: Process C (tau 7571ms) completed a CPU burst; 28 bursts to go [Q A E D H]
time 118940ms: Recalculating tau for process C: old tau 7571ms ==> new tau 6705ms [Q A E D H]
time 118940ms: Process C switching out of CPU; blocking on I/O until time 119093ms [Q A E D H]
time 118946ms: Process A (tau 274ms) started using the CPU for 119ms burst [Q E D H]
time 119065ms: Process A (tau 274ms) completed a CPU burst; 1 burst to go [Q E D H]
time 119065ms: Recalculating tau for process A: old tau 274ms ==> new tau 135ms [Q E D H]
time 119065ms: Process A switching out of CPU; blocking on I/O until time 119308ms [Q E D H]
time 119071ms: Process E (tau 1413ms) started using the CPU for 3280ms burst [Q D H]
time 119093ms: Process C (tau 6705ms) completed I/O; added to ready queue [Q D C H]
time 119094ms: Process B (tau 869ms) completed I/O; added to ready queue [Q B D C H]
time 119308ms: Process A (tau 135ms) completed I/O; added to ready queue [Q A B D C H]
time 122351ms: Process E (tau 1413ms) completed a CPU burst; 9 bursts to go [Q A B D C H]
time 122351ms: Recalculating tau for process E: old tau 1413ms ==> new tau 3094ms [Q A B D C H]
time 122351ms: Process E switching out of CPU; blocking on I/O until time 122806ms [Q A B D C H]
time 122357ms: Process A (tau 135ms) started using the CPU for 1807ms burst [Q B D C H]
time 122806ms: Process E (tau 3094ms) completed I/O; added to ready queue [Q B E D C H]
time 124164ms: Process A terminated [Q B E D C H]
time 124170ms: Process B (tau 869ms) started using the CPU for 364ms burst [Q E D C H]
time 124534ms: Process B (tau 869ms) completed a CPU burst; 33 bursts to go [Q E D C H]
time 124534ms: Recalculating tau for process B: old tau 869ms ==> new tau 415ms [Q E D C H]
time 124534ms: Process B switching out of CPU; blocking on I/O until time 125447ms [Q E D C H]
time 124540ms: Process E (tau 3094ms) started using the CPU for 972ms burst [Q D C H]
time 125447ms: Process B (tau 415ms) completed I/O; added to ready queue [Q B D C H]
time 125512ms: Process E (tau 3094ms) completed a CPU burst; 8 bursts to go [Q B D C H]
time 125512ms: Recalculating tau for process E: old tau 3094ms ==> new tau 1185ms [Q B D C H]
time 125512ms: Process E switching out of CPU; blocking on I/O until time 127238ms [Q B D C H]
time 125518ms: Process B (tau 415ms) started using the CPU for 25ms burst [Q D C H]
time 125543ms: Process B (tau 415ms) completed a CPU burst; 32 bursts to go [Q D C H]
time 125543ms: Recalculating tau for process B: old tau 415ms ==> new tau 65ms [Q D C H]
time 125543ms: Process B switching out of CPU; blocking on I/O until time 131846ms [Q D C H]
time 125549ms: Process D (tau 5887ms) started using the CPU for 236ms burst [Q C H]
time 125785ms: Process D (tau 5887ms) completed a CPU burst; 37 bursts to go [Q C H]
time 125785ms: Recalculating tau for process D: old tau 5887ms ==> new tau 802ms [Q C H]
time 125785ms: Process D switching out of CPU; blocking on I/O until time 126099ms [Q C H]
time 125791ms: Process C (tau 6705ms) started using the CPU for 5908ms burst [Q H]
time 126099ms: Process D (tau 802ms) completed I/O; added to ready queue [Q D H]
time 127238ms: Process E (tau 1185ms) completed I/O; added to ready queue [Q D E H]
time 131699ms: Process C (tau 6705ms) completed a CPU burst; 27 bursts to go [Q D E H]
time 131699ms: Recalculating tau for process C: old tau 6705ms ==> new tau 5988ms [Q D E H]
time 131699ms: Process C switching out of CPU; blocking on I/O until time 134738ms [Q D E H]
time 131705ms: Process D (tau 802ms) started using the CPU for 7352ms burst [Q E H]
time 131846ms: Process B (tau 65ms) completed I/O; added to ready queue [Q B E H]
time 134738ms: Process C (tau 5988ms) completed I/O; added to ready queue [Q B E C H]
time 139057ms: Process D (tau 802ms) completed a CPU burst; 36 bursts to go [Q B E C H]
time 139057ms: Recalculating tau for process D: old tau 802ms ==> new tau 6697ms [Q B E C H]
time 139057ms: Process D switching out of CPU; blocking on I/O until time 140660ms [Q B E C H]
time 139063ms: Process B (tau 65ms) started using the CPU for 744ms burst [Q E C H]
time 139807ms: Process B (tau 65ms) completed a CPU burst; 31 bursts to go [Q E C H]
time 139807ms: Recalculating tau for process B: old tau 65ms ==> new tau 677ms [Q E C H]
time 139807ms: Process B switching out of CPU; blocking on I/O until time 140720ms [Q E C H]
time 139813ms: Process E (tau 1185ms) started using the CPU for 5432ms burst [Q C H]
time 140660ms: Process D (tau 6697ms) completed I/O; added to ready queue [Q C D H]
time 140720ms: Process B (tau 677ms) completed I/O; added to ready queue [Q B C D H]
time 145245ms: Process E (tau 1185ms) completed a CPU burst; 7 bursts to go [Q B C D H]
time 145245ms: Recalculating tau for process E: old tau 1185ms ==> new tau 5008ms [Q B C D H]
time 145245ms: Process E switching out of CPU; blocking on I/O until time 145400ms [Q B C D H]
time 145251ms: Process B (tau 677ms) started using the CPU for 1040ms burst [Q C D H]
time 145400ms: Process E (tau 5008ms) completed I/O; added to ready queue [Q E C D H]
time 146291ms: Process B (tau 677ms) completed a CPU burst; 30 bursts to go [Q E C D H]
time 146291ms: Recalculating tau for process B: old tau 677ms ==> new tau 1004ms [Q E C D H]
time 146291ms: Process B switching out of CPU; blocking on I/O until time 150254ms [Q E C D H]
time 146297ms: Process E (tau 5008ms) started using the CPU for 2160ms burst [Q C D H]
time 148457ms: Process E (tau 5008ms) completed a CPU burst; 6 bursts to go [Q C D H]
time 148457ms: Recalculating tau for process E: old tau 5008ms ==> new tau 2445ms [Q C D H]
time 148457ms: Process E switching out of CPU; blocking on I/O until time 152038ms [Q C D H]
time 148463ms: Process C (tau 5988ms) started using the CPU for 1068ms burst [Q D H]
time 149531ms: Process C (tau 5988ms) completed a CPU burst; 26 bursts to go [Q D H]
time 149531ms: Recalculating tau for process C: old tau 5988ms ==> new tau 1561ms [Q D H]
time 149531ms: Process C switching out of CPU; blocking on I/O until time 150510ms [Q D H]
time 149537ms: Process D (tau 6697ms) started using the CPU for 8908ms burst [Q H]
time 150254ms: Process B (tau 1004ms) completed I/O; added to ready queue [Q B H]
time 150510ms: Process C (tau 1561ms) completed I/O; added to ready queue [Q B C H]
time 152038ms: Process E (tau 2445ms) completed I/O; added to ready queue [Q B C E H]
time 158445ms: Process D (tau 6697ms) completed a CPU burst; 35 bursts to go [Q B C E H]
time 158445ms: Recalculating tau for process D: old tau 6697ms ==> new tau 8687ms [Q B C E H]
time 158445ms: Process D switching out of CPU; blocking on I/O until time 158654ms [Q B C E H]
time 158451ms: Process B (tau 1004ms) started using the CPU for 1157ms burst [Q C E H]
time 158654ms: Process D (tau 8687ms) completed I/O; added to ready queue [Q C E D H]
time 159608ms: Process B (tau 1004ms) completed a CPU burst; 29 bursts to go [Q C E D H]
time 159608ms: Recalculating tau for process B: old tau 1004ms ==> new tau 1142ms [Q C E D H]
time 159608ms: Process B switching out of CPU; blocking on I/O until time 169581ms [Q C E D H]
time 159614ms: Process C (tau 1561ms) started using the CPU for 260ms burst [Q E D H]
time 159874ms: Process C (tau 1561ms) completed a CPU burst; 25 bursts to go [Q E D H]
time 159874ms: Recalculating tau for process C: old tau 1561ms ==> new tau 391ms [Q E D H]
time 159874ms: Process C switching out of CPU; blocking on I/O until time 161620ms [Q E D H]
time 159880ms: Process E (tau 2445ms) started using the CPU for 1396ms burst [Q D H]
time 161276ms: Process E (tau 2445ms) completed a CPU burst; 5 bursts to go [Q D H]
time 161276ms: Recalculating tau for process E: old tau 2445ms ==> new tau 1501ms [Q D H]
time 161276ms: Process E switching out of CPU; blocking on I/O until time 161397ms [Q D H]
time 161282ms: Process D (tau 8687ms) started using the CPU for 1264ms burst [Q H]
time 161397ms: Process E (tau 1501ms) completed I/O; added to ready queue [Q E H]
time 161620ms: Process C (tau 391ms) completed I/O; added to ready queue [Q C E H]
time 162546ms: Process D (tau 8687ms) completed a CPU burst; 34 bursts to go [Q C E H]
time 162546ms: Recalculating tau for process D: old tau 8687ms ==> new tau 2007ms [Q C E H]
time 162546ms: Process D switching out of CPU; blocking on I/O until time 163449ms [Q C E H]
time 162552ms: Process C (tau 391ms) started using the CPU for 936ms burst [Q E H]
time 163449ms: Process D (tau 2007ms) completed I/O; added to ready queue [Q E D H]
time 163488ms: Process C (tau 391ms) completed a CPU burst; 24 bursts to go [Q E D H]
time 163488ms: Recalculating tau for process C: old tau 391ms ==> new tau 882ms [Q E D H]
time 163488ms: Process C switching out of CPU; blocking on I/O until time 163649ms [Q E D H]
time 163494ms: Process E (tau 1501ms) started using the CPU for 10556ms burst [Q D H]
time 163649ms: Process C (tau 882ms) completed I/O; added to ready queue [Q C D H]
time 169581ms: Process B (tau 1142ms) completed I/O; added to ready queue [Q C B D H]
time 174050ms: Process E (tau 1501ms) completed a CPU burst; 4 bursts to go [Q C B D H]
time 174050ms: Recalculating tau for process E: old tau 1501ms ==> new tau 9651ms [Q C B D H]
time 174050ms: Process E switching out of CPU; blocking on I/O until time 175636ms [Q C B D H]
time 174056ms: Process C (tau 882ms) started using the CPU for 292ms burst [Q B D H]
time 174348ms: Process C (tau 882ms) completed a CPU burst; 23 bursts to go [Q B D H]
time 174348ms: Recalculating tau for process C: old tau 882ms ==> new tau 352ms [Q B D H]
time 174348ms: Process C switching out of CPU; blocking on I/O until time 175263ms [Q B D H]
time 174354ms: Process B (tau 1142ms) started using the CPU for 270ms burst [Q D H]
time 174624ms: Process B (tau 1142ms) completed a CPU burst; 28 bursts to go [Q D H]
time 174624ms: Recalculating tau for process B: old tau 1142ms ==> new tau 358ms [Q D H]
time 174624ms: Process B switching out of CPU; blocking on I/O until time 179967ms [Q D H]
time 174630ms: Process D (tau 2007ms) started using the CPU for 2972ms burst [Q H]
time 175263ms: Process C (tau 352ms) completed I/O; added to ready queue [Q C H]
time 175636ms: Process E (tau 9651ms) completed I/O; added to ready queue [Q C E H]
time 177602ms: Process D (tau 2007ms) completed a CPU burst; 33 bursts to go [Q C E H]
time 177602ms: Recalculating tau for process D: old tau 2007ms ==> new tau 2876ms [Q C E H]
time 177602ms: Process D switching out of CPU; blocking on I/O until time 179286ms [Q C E H]
time 177608ms: Process C (tau 352ms) started using the CPU for 10732ms burst [Q E H]
time 179286ms: Process D (tau 2876ms) completed I/O; added to ready queue [Q D E H]
time 179967ms: Process B (tau 358ms) completed I/O; added to ready queue [Q B D E H]
time 188340ms: Process C (tau 352ms) completed a CPU burst; 22 bursts to go [Q B D E H]
time 188340ms: Recalculating tau for process C: old tau 352ms ==> new tau 9694ms [Q B D E H]
time 188340ms: Process C switching out of CPU; blocking on I/O until time 191578ms [Q B D E H]
time 188346ms: Process B (tau 358ms) started using the CPU for 2878ms burst [Q D E H]
time 191224ms: Process B (tau 358ms) completed a CPU burst; 27 bursts to go [Q D E H]
time 191224ms: Recalculating tau for process B: old tau 358ms ==> new tau 2626ms [Q D E H]
time 191224ms: Process B switching out of CPU; blocking on I/O until time 191767ms [Q D E H]
time 191230ms: Process D (tau 2876ms) started using the CPU for 5800ms burst [Q E H]
time 191578ms: Process C (tau 9694ms) completed I/O; added to ready queue [Q E C H]
time 191767ms: Process B (tau 2626ms) completed I/O; added to ready queue [Q B E C H]
time 197030ms: Process D (tau 2876ms) completed a CPU burst; 32 bursts to go [Q B E C H]
time 197030ms: Recalculating tau for process D: old tau 2876ms ==> new tau 5508ms [Q B E C H]
time 197030ms: Process D switching out of CPU; blocking on I/O until time 197198ms [Q B E C H]
time 197036ms: Process B (tau 2626ms) started using the CPU for 1161ms burst [Q E C H]
time 197198ms: Process D (tau 5508ms) completed I/O; added to ready queue [Q D E C H]
time 198197ms: Process B (tau 2626ms) completed a CPU burst; 26 bursts to go [Q D E C H]
time 198197ms: Recalculating tau for process B: old tau 2626ms ==> new tau 1308ms [Q D E C H]
time 198197ms: Process B switching out of CPU; blocking on I/O until time 221640ms [Q D E C H]
time 198203ms: Process D (tau 5508ms) started using the CPU for 8596ms burst [Q E C H]
time 206799ms: Process D (tau 5508ms) completed a CPU burst; 31 bursts to go [Q E C H]
time 206799ms: Recalculating tau for process D: old tau 5508ms ==> new tau 8288ms [Q E C H]
time 206799ms: Process D switching out of CPU; blocking on I/O until time 207128ms [Q E C H]
time 206805ms: Process E (tau 9651ms) started using the CPU for 2284ms burst [Q C H]
time 207128ms: Process D (tau 8288ms) completed I/O; added to ready queue [Q D C H]
time 209089ms: Process E (tau 9651ms) completed a CPU burst; 3 bursts to go [Q D C H]
time 209089ms: Recalculating tau for process E: old tau 9651ms ==> new tau 3021ms [Q D C H]
time 209089ms: Process E switching out of CPU; blocking on I/O until time 209868ms [Q D C H]
time 209095ms: Process D (tau 8288ms) started using the CPU for 9572ms burst [Q C H]
time 209868ms: Process E (tau 3021ms) completed I/O; added to ready queue [Q E C H]
time 218667ms: Process D (tau 8288ms) completed a CPU burst; 30 bursts to go [Q E C H]
time 218667ms: Recalculating tau for process D: old tau 8288ms ==> new tau 9444ms [Q E C H]
time 218667ms: Process D switching out of CPU; blocking on I/O until time 219010ms [Q E C H]
time 218673ms: Process E (tau 3021ms) started using the CPU for 8280ms burst [Q C H]
