<<< PROJECT PART I -- process set (n=16) with 2 CPU-bound processes >>>
I/O-bound process A: arrival time 2341ms; 9 CPU bursts
I/O-bound process B: arrival time 429ms; 9 CPU bursts
I/O-bound process C: arrival time 439ms; 47 CPU bursts
I/O-bound process D: arrival time 1558ms; 51 CPU bursts
I/O-bound process E: arrival time 15ms; 58 CPU bursts
I/O-bound process F: arrival time 839ms; 49 CPU bursts
I/O-bound process G: arrival time 18ms; 20 CPU bursts
I/O-bound process H: arrival time 523ms; 10 CPU bursts
I/O-bound process I: arrival time 254ms; 45 CPU bursts
I/O-bound process J: arrival time 649ms; 14 CPU bursts
I/O-bound process K: arrival time 60ms; 31 CPU bursts
I/O-bound process L: arrival time 2860ms; 29 CPU bursts
I/O-bound process M: arrival time 831ms; 11 CPU bursts
I/O-bound process N: arrival time 852ms; 50 CPU bursts
CPU-bound process O: arrival time 110ms; 59 CPU bursts
CPU-bound process P: arrival time 283ms; 15 CPU bursts

<<< PROJECT PART II -- t_cs=4ms; alpha=0.50; t_slice=32ms >>>
time 0ms: Simulator started for FCFS [Q <empty>]
time 15ms: Process E arrived; added to ready queue [Q E]
time 17ms: Process E started using the CPU for 222ms burst [Q <empty>]
time 18ms: Process G arrived; added to ready queue [Q G]
time 60ms: Process K arrived; added to ready queue [Q G K]
time 110ms: Process O arrived; added to ready queue [Q G K O]
time 239ms: Process E completed a CPU burst; 57 bursts to go [Q G K O]
time 239ms: Process E switching out of CPU; blocking on I/O until time 6661ms [Q G K O]
time 243ms: Process G started using the CPU for 1406ms burst [Q K O]
time 254ms: Process I arrived; added to ready queue [Q K O I]
time 283ms: Process P arrived; added to ready queue [Q K O I P]
time 429ms: Process B arrived; added to ready queue [Q K O I P B]
time 439ms: Process C arrived; added to ready queue [Q K O I P B C]
time 523ms: Process H arrived; added to ready queue [Q K O I P B C H]
time 649ms: Process J arrived; added to ready queue [Q K O I P B C H J]
time 831ms: Process M arrived; added to ready queue [Q K O I P B C H J M]
time 839ms: Process F arrived; added to ready queue [Q K O I P B C H J M F]
time 852ms: Process N arrived; added to ready queue [Q K O I P B C H J M F N]
time 1558ms: Process D arrived; added to ready queue [Q K O I P B C H J M F N D]
time 1649ms: Process G completed a CPU burst; 19 bursts to go [Q K O I P B C H J M F N D]
time 1649ms: Process G switching out of CPU; blocking on I/O until time 1851ms [Q K O I P B C H J M F N D]
time 1653ms: Process K started using the CPU for 474ms burst [Q O I P B C H J M F N D]
time 1851ms: Process G completed I/O; added to ready queue [Q O I P B C H J M F N D G]
time 2127ms: Process K completed a CPU burst; 30 bursts to go [Q O I P B C H J M F N D G]
time 2127ms: Process K switching out of CPU; blocking on I/O until time 4159ms [Q O I P B C H J M F N D G]
time 2131ms: Process O started using the CPU for 464ms burst [Q I P B C H J M F N D G]
time 2341ms: Process A arrived; added to ready queue [Q I P B C H J M F N D G A]
time 2595ms: Process O completed a CPU burst; 58 bursts to go [Q I P B C H J M F N D G A]
time 2595ms: Process O switching out of CPU; blocking on I/O until time 2867ms [Q I P B C H J M F N D G A]
time 2599ms: Process I started using the CPU for 8ms burst [Q P B C H J M F N D G A]
time 2607ms: Process I completed a CPU burst; 44 bursts to go [Q P B C H J M F N D G A]
time 2607ms: Process I switching out of CPU; blocking on I/O until time 13609ms [Q P B C H J M F N D G A]
time 2611ms: Process P started using the CPU for 4176ms burst [Q B C H J M F N D G A]
time 2860ms: Process L arrived; added to ready queue [Q B C H J M F N D G A L]
time 2867ms: Process O completed I/O; added to ready queue [Q B C H J M F N D G A L O]
time 4159ms: Process K completed I/O; added to ready queue [Q B C H J M F N D G A L O K]
time 6661ms: Process E completed I/O; added to ready queue [Q B C H J M F N D G A L O K E]
time 6787ms: Process P completed a CPU burst; 14 bursts to go [Q B C H J M F N D G A L O K E]
time 6787ms: Process P switching out of CPU; blocking on I/O until time 7495ms [Q B C H J M F N D G A L O K E]
time 6791ms: Process B started using the CPU for 258ms burst [Q C H J M F N D G A L O K E]
time 7049ms: Process B completed a CPU burst; 8 bursts to go [Q C H J M F N D G A L O K E]
time 7049ms: Process B switching out of CPU; blocking on I/O until time 12821ms [Q C H J M F N D G A L O K E]
time 7053ms: Process C started using the CPU for 653ms burst [Q H J M F N D G A L O K E]
time 7495ms: Process P completed I/O; added to ready queue [Q H J M F N D G A L O K E P]
time 7706ms: Process C completed a CPU burst; 46 bursts to go [Q H J M F N D G A L O K E P]
time 7706ms: Process C switching out of CPU; blocking on I/O until time 15088ms [Q H J M F N D G A L O K E P]
time 7710ms: Process H started using the CPU for 294ms burst [Q J M F N D G A L O K E P]
time 8004ms: Process H completed a CPU burst; 9 bursts to go [Q J M F N D G A L O K E P]
time 8004ms: Process H switching out of CPU; blocking on I/O until time 11226ms [Q J M F N D G A L O K E P]
time 8008ms: Process J started using the CPU for 352ms burst [Q M F N D G A L O K E P]
time 8360ms: Process J completed a CPU burst; 13 bursts to go [Q M F N D G A L O K E P]
time 8360ms: Process J switching out of CPU; blocking on I/O until time 25432ms [Q M F N D G A L O K E P]
time 8364ms: Process M started using the CPU for 1059ms burst [Q F N D G A L O K E P]
time 9423ms: Process M completed a CPU burst; 10 bursts to go [Q F N D G A L O K E P]
time 9423ms: Process M switching out of CPU; blocking on I/O until time 17905ms [Q F N D G A L O K E P]
time 9427ms: Process F started using the CPU for 129ms burst [Q N D G A L O K E P]
time 9556ms: Process F completed a CPU burst; 48 bursts to go [Q N D G A L O K E P]
time 9556ms: Process F switching out of CPU; blocking on I/O until time 21538ms [Q N D G A L O K E P]
time 9560ms: Process N started using the CPU for 1405ms burst [Q D G A L O K E P]
time 10965ms: Process N completed a CPU burst; 49 bursts to go [Q D G A L O K E P]
time 10965ms: Process N switching out of CPU; blocking on I/O until time 18917ms [Q D G A L O K E P]
time 10969ms: Process D started using the CPU for 573ms burst [Q G A L O K E P]
time 11226ms: Process H completed I/O; added to ready queue [Q G A L O K E P H]
time 11542ms: Process D completed a CPU burst; 50 bursts to go [Q G A L O K E P H]
time 11542ms: Process D switching out of CPU; blocking on I/O until time 28224ms [Q G A L O K E P H]
time 11546ms: Process G started using the CPU for 780ms burst [Q A L O K E P H]
time 12326ms: Process G completed a CPU burst; 18 bursts to go [Q A L O K E P H]
time 12326ms: Process G switching out of CPU; blocking on I/O until time 16598ms [Q A L O K E P H]
time 12330ms: Process A started using the CPU for 1978ms burst [Q L O K E P H]
time 12821ms: Process B completed I/O; added to ready queue [Q L O K E P H B]
time 13609ms: Process I completed I/O; added to ready queue [Q L O K E P H B I]
time 14308ms: Process A completed a CPU burst; 8 bursts to go [Q L O K E P H B I]
time 14308ms: Process A switching out of CPU; blocking on I/O until time 20240ms [Q L O K E P H B I]
time 14312ms: Process L started using the CPU for 697ms burst [Q O K E P H B I]
time 15009ms: Process L completed a CPU burst; 28 bursts to go [Q O K E P H B I]
time 15009ms: Process L switching out of CPU; blocking on I/O until time 15211ms [Q O K E P H B I]
time 15013ms: Process O started using the CPU for 7556ms burst [Q K E P H B I]
time 15088ms: Process C completed I/O; added to ready queue [Q K E P H B I C]
time 15211ms: Process L completed I/O; added to ready queue [Q K E P H B I C L]
time 16598ms: Process G completed I/O; added to ready queue [Q K E P H B I C L G]
time 17905ms: Process M completed I/O; added to ready queue [Q K E P H B I C L G M]
time 18917ms: Process N completed I/O; added to ready queue [Q K E P H B I C L G M N]
time 20240ms: Process A completed I/O; added to ready queue [Q K E P H B I C L G M N A]
time 21538ms: Process F completed I/O; added to ready queue [Q K E P H B I C L G M N A F]
time 22569ms: Process O completed a CPU burst; 57 bursts to go [Q K E P H B I C L G M N A F]
time 22569ms: Process O switching out of CPU; blocking on I/O until time 23126ms [Q K E P H B I C L G M N A F]
time 22573ms: Process K started using the CPU for 1450ms burst [Q E P H B I C L G M N A F]
time 23126ms: Process O completed I/O; added to ready queue [Q E P H B I C L G M N A F O]
time 24023ms: Process K completed a CPU burst; 29 bursts to go [Q E P H B I C L G M N A F O]
time 24023ms: Process K switching out of CPU; blocking on I/O until time 52955ms [Q E P H B I C L G M N A F O]
time 24027ms: Process E started using the CPU for 657ms burst [Q P H B I C L G M N A F O]
time 24684ms: Process E completed a CPU burst; 56 bursts to go [Q P H B I C L G M N A F O]
time 24684ms: Process E switching out of CPU; blocking on I/O until time 33576ms [Q P H B I C L G M N A F O]
time 24688ms: Process P started using the CPU for 120ms burst [Q H B I C L G M N A F O]
time 24808ms: Process P completed a CPU burst; 13 bursts to go [Q H B I C L G M N A F O]
time 24808ms: Process P switching out of CPU; blocking on I/O until time 28525ms [Q H B I C L G M N A F O]
time 24812ms: Process H started using the CPU for 340ms burst [Q B I C L G M N A F O]
time 25152ms: Process H completed a CPU burst; 8 bursts to go [Q B I C L G M N A F O]
time 25152ms: Process H switching out of CPU; blocking on I/O until time 33344ms [Q B I C L G M N A F O]
time 25156ms: Process B started using the CPU for 165ms burst [Q I C L G M N A F O]
time 25321ms: Process B completed a CPU burst; 7 bursts to go [Q I C L G M N A F O]
time 25321ms: Process B switching out of CPU; blocking on I/O until time 34053ms [Q I C L G M N A F O]
time 25325ms: Process I started using the CPU for 437ms burst [Q C L G M N A F O]
time 25432ms: Process J completed I/O; added to ready queue [Q C L G M N A F O J]
time 25762ms: Process I completed a CPU burst; 43 bursts to go [Q C L G M N A F O J]
time 25762ms: Process I switching out of CPU; blocking on I/O until time 28274ms [Q C L G M N A F O J]
time 25766ms: Process C started using the CPU for 35ms burst [Q L G M N A F O J]
time 25801ms: Process C completed a CPU burst; 45 bursts to go [Q L G M N A F O J]
time 25801ms: Process C switching out of CPU; blocking on I/O until time 31243ms [Q L G M N A F O J]
time 25805ms: Process L started using the CPU for 1122ms burst [Q G M N A F O J]
time 26927ms: Process L completed a CPU burst; 27 bursts to go [Q G M N A F O J]
time 26927ms: Process L switching out of CPU; blocking on I/O until time 32219ms [Q G M N A F O J]
time 26931ms: Process G started using the CPU for 193ms burst [Q M N A F O J]
time 27124ms: Process G completed a CPU burst; 17 bursts to go [Q M N A F O J]
time 27124ms: Process G switching out of CPU; blocking on I/O until time 30626ms [Q M N A F O J]
time 27128ms: Process M started using the CPU for 2258ms burst [Q N A F O J]
time 28224ms: Process D completed I/O; added to ready queue [Q N A F O J D]
time 28274ms: Process I completed I/O; added to ready queue [Q N A F O J D I]
time 28525ms: Process P completed I/O; added to ready queue [Q N A F O J D I P]
time 29386ms: Process M completed a CPU burst; 9 bursts to go [Q N A F O J D I P]
time 29386ms: Process M switching out of CPU; blocking on I/O until time 30978ms [Q N A F O J D I P]
time 29390ms: Process N started using the CPU for 1672ms burst [Q A F O J D I P]
time 30626ms: Process G completed I/O; added to ready queue [Q A F O J D I P G]
time 30978ms: Process M completed I/O; added to ready queue [Q A F O J D I P G M]
time 31062ms: Process N completed a CPU burst; 48 bursts to go [Q A F O J D I P G M]
time 31062ms: Process N switching out of CPU; blocking on I/O until time 31954ms [Q A F O J D I P G M]
time 31066ms: Process A started using the CPU for 2611ms burst [Q F O J D I P G M]
time 31243ms: Process C completed I/O; added to ready queue [Q F O J D I P G M C]
time 31954ms: Process N completed I/O; added to ready queue [Q F O J D I P G M C N]
time 32219ms: Process L completed I/O; added to ready queue [Q F O J D I P G M C N L]
time 33344ms: Process H completed I/O; added to ready queue [Q F O J D I P G M C N L H]
time 33576ms: Process E completed I/O; added to ready queue [Q F O J D I P G M C N L H E]
time 33677ms: Process A completed a CPU burst; 7 bursts to go [Q F O J D I P G M C N L H E]
time 33677ms: Process A switching out of CPU; blocking on I/O until time 40349ms [Q F O J D I P G M C N L H E]
time 33681ms: Process F started using the CPU for 77ms burst [Q O J D I P G M C N L H E]
time 33758ms: Process F completed a CPU burst; 47 bursts to go [Q O J D I P G M C N L H E]
time 33758ms: Process F switching out of CPU; blocking on I/O until time 36640ms [Q O J D I P G M C N L H E]
time 33762ms: Process O started using the CPU for 996ms burst [Q J D I P G M C N L H E]
time 34053ms: Process B completed I/O; added to ready queue [Q J D I P G M C N L H E B]
time 34758ms: Process O completed a CPU burst; 56 bursts to go [Q J D I P G M C N L H E B]
time 34758ms: Process O switching out of CPU; blocking on I/O until time 36142ms [Q J D I P G M C N L H E B]
time 34762ms: Process J started using the CPU for 2447ms burst [Q D I P G M C N L H E B]
time 36142ms: Process O completed I/O; added to ready queue [Q D I P G M C N L H E B O]
time 36640ms: Process F completed I/O; added to ready queue [Q D I P G M C N L H E B O F]
time 37209ms: Process J completed a CPU burst; 12 bursts to go [Q D I P G M C N L H E B O F]
time 37209ms: Process J switching out of CPU; blocking on I/O until time 38891ms [Q D I P G M C N L H E B O F]
time 37213ms: Process D started using the CPU for 595ms burst [Q I P G M C N L H E B O F]
time 37808ms: Process D completed a CPU burst; 49 bursts to go [Q I P G M C N L H E B O F]
time 37808ms: Process D switching out of CPU; blocking on I/O until time 38180ms [Q I P G M C N L H E B O F]
time 37812ms: Process I started using the CPU for 562ms burst [Q P G M C N L H E B O F]
time 38180ms: Process D completed I/O; added to ready queue [Q P G M C N L H E B O F D]
time 38374ms: Process I completed a CPU burst; 42 bursts to go [Q P G M C N L H E B O F D]
time 38374ms: Process I switching out of CPU; blocking on I/O until time 43316ms [Q P G M C N L H E B O F D]
time 38378ms: Process P started using the CPU for 1404ms burst [Q G M C N L H E B O F D]
time 38891ms: Process J completed I/O; added to ready queue [Q G M C N L H E B O F D J]
time 39782ms: Process P completed a CPU burst; 12 bursts to go [Q G M C N L H E B O F D J]
time 39782ms: Process P switching out of CPU; blocking on I/O until time 40174ms [Q G M C N L H E B O F D J]
time 39786ms: Process G started using the CPU for 149ms burst [Q M C N L H E B O F D J]
time 39935ms: Process G completed a CPU burst; 16 bursts to go [Q M C N L H E B O F D J]
time 39935ms: Process G switching out of CPU; blocking on I/O until time 43127ms [Q M C N L H E B O F D J]
time 39939ms: Process M started using the CPU for 143ms burst [Q C N L H E B O F D J]
time 40082ms: Process M completed a CPU burst; 8 bursts to go [Q C N L H E B O F D J]
time 40082ms: Process M switching out of CPU; blocking on I/O until time 46454ms [Q C N L H E B O F D J]
time 40086ms: Process C started using the CPU for 325ms burst [Q N L H E B O F D J]
time 40174ms: Process P completed I/O; added to ready queue [Q N L H E B O F D J P]
time 40349ms: Process A completed I/O; added to ready queue [Q N L H E B O F D J P A]
time 40411ms: Process C completed a CPU burst; 44 bursts to go [Q N L H E B O F D J P A]
time 40411ms: Process C switching out of CPU; blocking on I/O until time 43583ms [Q N L H E B O F D J P A]
time 40415ms: Process N started using the CPU for 407ms burst [Q L H E B O F D J P A]
time 40822ms: Process N completed a CPU burst; 47 bursts to go [Q L H E B O F D J P A]
time 40822ms: Process N switching out of CPU; blocking on I/O until time 69434ms [Q L H E B O F D J P A]
time 40826ms: Process L started using the CPU for 950ms burst [Q H E B O F D J P A]
time 41776ms: Process L completed a CPU burst; 26 bursts to go [Q H E B O F D J P A]
time 41776ms: Process L switching out of CPU; blocking on I/O until time 59808ms [Q H E B O F D J P A]
time 41780ms: Process H started using the CPU for 1452ms burst [Q E B O F D J P A]
time 43127ms: Process G completed I/O; added to ready queue [Q E B O F D J P A G]
time 43232ms: Process H completed a CPU burst; 7 bursts to go [Q E B O F D J P A G]
time 43232ms: Process H switching out of CPU; blocking on I/O until time 48044ms [Q E B O F D J P A G]
time 43236ms: Process E started using the CPU for 421ms burst [Q B O F D J P A G]
time 43316ms: Process I completed I/O; added to ready queue [Q B O F D J P A G I]
time 43583ms: Process C completed I/O; added to ready queue [Q B O F D J P A G I C]
time 43657ms: Process E completed a CPU burst; 55 bursts to go [Q B O F D J P A G I C]
time 43657ms: Process E switching out of CPU; blocking on I/O until time 55369ms [Q B O F D J P A G I C]
time 43661ms: Process B started using the CPU for 1119ms burst [Q O F D J P A G I C]
time 44780ms: Process B completed a CPU burst; 6 bursts to go [Q O F D J P A G I C]
time 44780ms: Process B switching out of CPU; blocking on I/O until time 46592ms [Q O F D J P A G I C]
time 44784ms: Process O started using the CPU for 104ms burst [Q F D J P A G I C]
time 44888ms: Process O completed a CPU burst; 55 bursts to go [Q F D J P A G I C]
time 44888ms: Process O switching out of CPU; blocking on I/O until time 45923ms [Q F D J P A G I C]
time 44892ms: Process F started using the CPU for 1036ms burst [Q D J P A G I C]
time 45923ms: Process O completed I/O; added to ready queue [Q D J P A G I C O]
time 45928ms: Process F completed a CPU burst; 46 bursts to go [Q D J P A G I C O]
time 45928ms: Process F switching out of CPU; blocking on I/O until time 46860ms [Q D J P A G I C O]
time 45932ms: Process D started using the CPU for 1138ms burst [Q J P A G I C O]
time 46454ms: Process M completed I/O; added to ready queue [Q J P A G I C O M]
time 46592ms: Process B completed I/O; added to ready queue [Q J P A G I C O M B]
time 46860ms: Process F completed I/O; added to ready queue [Q J P A G I C O M B F]
time 47070ms: Process D completed a CPU burst; 48 bursts to go [Q J P A G I C O M B F]
time 47070ms: Process D switching out of CPU; blocking on I/O until time 56702ms [Q J P A G I C O M B F]
time 47074ms: Process J started using the CPU for 914ms burst [Q P A G I C O M B F]
time 47988ms: Process J completed a CPU burst; 11 bursts to go [Q P A G I C O M B F]
time 47988ms: Process J switching out of CPU; blocking on I/O until time 54530ms [Q P A G I C O M B F]
time 47992ms: Process P started using the CPU for 7192ms burst [Q A G I C O M B F]
time 48044ms: Process H completed I/O; added to ready queue [Q A G I C O M B F H]
time 52955ms: Process K completed I/O; added to ready queue [Q A G I C O M B F H K]
time 54530ms: Process J completed I/O; added to ready queue [Q A G I C O M B F H K J]
time 55184ms: Process P completed a CPU burst; 11 bursts to go [Q A G I C O M B F H K J]
time 55184ms: Process P switching out of CPU; blocking on I/O until time 56503ms [Q A G I C O M B F H K J]
time 55188ms: Process A started using the CPU for 663ms burst [Q G I C O M B F H K J]
time 55369ms: Process E completed I/O; added to ready queue [Q G I C O M B F H K J E]
time 55851ms: Process A completed a CPU burst; 6 bursts to go [Q G I C O M B F H K J E]
time 55851ms: Process A switching out of CPU; blocking on I/O until time 68523ms [Q G I C O M B F H K J E]
time 55855ms: Process G started using the CPU for 207ms burst [Q I C O M B F H K J E]
time 56062ms: Process G completed a CPU burst; 15 bursts to go [Q I C O M B F H K J E]
time 56062ms: Process G switching out of CPU; blocking on I/O until time 56874ms [Q I C O M B F H K J E]
time 56066ms: Process I started using the CPU for 2491ms burst [Q C O M B F H K J E]
time 56503ms: Process P completed I/O; added to ready queue [Q C O M B F H K J E P]
time 56702ms: Process D completed I/O; added to ready queue [Q C O M B F H K J E P D]
time 56874ms: Process G completed I/O; added to ready queue [Q C O M B F H K J E P D G]
time 58557ms: Process I completed a CPU burst; 41 bursts to go [Q C O M B F H K J E P D G]
time 58557ms: Process I switching out of CPU; blocking on I/O until time 74309ms [Q C O M B F H K J E P D G]
time 58561ms: Process C started using the CPU for 412ms burst [Q O M B F H K J E P D G]
time 58973ms: Process C completed a CPU burst; 43 bursts to go [Q O M B F H K J E P D G]
time 58973ms: Process C switching out of CPU; blocking on I/O until time 61065ms [Q O M B F H K J E P D G]
time 58977ms: Process O started using the CPU for 396ms burst [Q M B F H K J E P D G]
time 59373ms: Process O completed a CPU burst; 54 bursts to go [Q M B F H K J E P D G]
time 59373ms: Process O switching out of CPU; blocking on I/O until time 61871ms [Q M B F H K J E P D G]
time 59377ms: Process M started using the CPU for 573ms burst [Q B F H K J E P D G]
time 59808ms: Process L completed I/O; added to ready queue [Q B F H K J E P D G L]
time 59950ms: Process M completed a CPU burst; 7 bursts to go [Q B F H K J E P D G L]
time 59950ms: Process M switching out of CPU; blocking on I/O until time 59992ms [Q B F H K J E P D G L]
time 59954ms: Process B started using the CPU for 1294ms burst [Q F H K J E P D G L]
time 59992ms: Process M completed I/O; added to ready queue [Q F H K J E P D G L M]
time 61065ms: Process C completed I/O; added to ready queue [Q F H K J E P D G L M C]
time 61248ms: Process B completed a CPU burst; 5 bursts to go [Q F H K J E P D G L M C]
time 61248ms: Process B switching out of CPU; blocking on I/O until time 71420ms [Q F H K J E P D G L M C]
time 61252ms: Process F started using the CPU for 1843ms burst [Q H K J E P D G L M C]
time 61871ms: Process O completed I/O; added to ready queue [Q H K J E P D G L M C O]
time 63095ms: Process F completed a CPU burst; 45 bursts to go [Q H K J E P D G L M C O]
time 63095ms: Process F switching out of CPU; blocking on I/O until time 82407ms [Q H K J E P D G L M C O]
time 63099ms: Process H started using the CPU for 266ms burst [Q K J E P D G L M C O]
time 63365ms: Process H completed a CPU burst; 6 bursts to go [Q K J E P D G L M C O]
time 63365ms: Process H switching out of CPU; blocking on I/O until time 67877ms [Q K J E P D G L M C O]
time 63369ms: Process K started using the CPU for 537ms burst [Q J E P D G L M C O]
time 63906ms: Process K completed a CPU burst; 28 bursts to go [Q J E P D G L M C O]
time 63906ms: Process K switching out of CPU; blocking on I/O until time 68068ms [Q J E P D G L M C O]
time 63910ms: Process J started using the CPU for 2391ms burst [Q E P D G L M C O]
time 66301ms: Process J completed a CPU burst; 10 bursts to go [Q E P D G L M C O]
time 66301ms: Process J switching out of CPU; blocking on I/O until time 74513ms [Q E P D G L M C O]
time 66305ms: Process E started using the CPU for 1178ms burst [Q P D G L M C O]
time 67483ms: Process E completed a CPU burst; 54 bursts to go [Q P D G L M C O]
time 67483ms: Process E switching out of CPU; blocking on I/O until time 73235ms [Q P D G L M C O]
time 67487ms: Process P started using the CPU for 2808ms burst [Q D G L M C O]
time 67877ms: Process H completed I/O; added to ready queue [Q D G L M C O H]
time 68068ms: Process K completed I/O; added to ready queue [Q D G L M C O H K]
time 68523ms: Process A completed I/O; added to ready queue [Q D G L M C O H K A]
time 69434ms: Process N completed I/O; added to ready queue [Q D G L M C O H K A N]
time 70295ms: Process P completed a CPU burst; 10 bursts to go [Q D G L M C O H K A N]
time 70295ms: Process P switching out of CPU; blocking on I/O until time 71185ms [Q D G L M C O H K A N]
time 70299ms: Process D started using the CPU for 119ms burst [Q G L M C O H K A N]
time 70418ms: Process D completed a CPU burst; 47 bursts to go [Q G L M C O H K A N]
time 70418ms: Process D switching out of CPU; blocking on I/O until time 75650ms [Q G L M C O H K A N]
time 70422ms: Process G started using the CPU for 2202ms burst [Q L M C O H K A N]
time 71185ms: Process P completed I/O; added to ready queue [Q L M C O H K A N P]
time 71420ms: Process B completed I/O; added to ready queue [Q L M C O H K A N P B]
time 72624ms: Process G completed a CPU burst; 14 bursts to go [Q L M C O H K A N P B]
time 72624ms: Process G switching out of CPU; blocking on I/O until time 89316ms [Q L M C O H K A N P B]
time 72628ms: Process L started using the CPU for 187ms burst [Q M C O H K A N P B]
time 72815ms: Process L completed a CPU burst; 25 bursts to go [Q M C O H K A N P B]
time 72815ms: Process L switching out of CPU; blocking on I/O until time 75617ms [Q M C O H K A N P B]
time 72819ms: Process M started using the CPU for 606ms burst [Q C O H K A N P B]
time 73235ms: Process E completed I/O; added to ready queue [Q C O H K A N P B E]
time 73425ms: Process M completed a CPU burst; 6 bursts to go [Q C O H K A N P B E]
time 73425ms: Process M switching out of CPU; blocking on I/O until time 83047ms [Q C O H K A N P B E]
time 73429ms: Process C started using the CPU for 1464ms burst [Q O H K A N P B E]
time 74309ms: Process I completed I/O; added to ready queue [Q O H K A N P B E I]
time 74513ms: Process J completed I/O; added to ready queue [Q O H K A N P B E I J]
time 74893ms: Process C completed a CPU burst; 42 bursts to go [Q O H K A N P B E I J]
time 74893ms: Process C switching out of CPU; blocking on I/O until time 82055ms [Q O H K A N P B E I J]
time 74897ms: Process O started using the CPU for 5624ms burst [Q H K A N P B E I J]
time 75617ms: Process L completed I/O; added to ready queue [Q H K A N P B E I J L]
time 75650ms: Process D completed I/O; added to ready queue [Q H K A N P B E I J L D]
time 80521ms: Process O completed a CPU burst; 53 bursts to go [Q H K A N P B E I J L D]
time 80521ms: Process O switching out of CPU; blocking on I/O until time 82921ms [Q H K A N P B E I J L D]
time 80525ms: Process H started using the CPU for 330ms burst [Q K A N P B E I J L D]
time 80855ms: Process H completed a CPU burst; 5 bursts to go [Q K A N P B E I J L D]
time 80855ms: Process H switching out of CPU; blocking on I/O until time 97107ms [Q K A N P B E I J L D]
time 80859ms: Process K started using the CPU for 770ms burst [Q A N P B E I J L D]
time 81629ms: Process K completed a CPU burst; 27 bursts to go [Q A N P B E I J L D]
time 81629ms: Process K switching out of CPU; blocking on I/O until time 82771ms [Q A N P B E I J L D]
time 81633ms: Process A started using the CPU for 266ms burst [Q N P B E I J L D]
time 81899ms: Process A completed a CPU burst; 5 bursts to go [Q N P B E I J L D]
time 81899ms: Process A switching out of CPU; blocking on I/O until time 99751ms [Q N P B E I J L D]
time 81903ms: Process N started using the CPU for 438ms burst [Q P B E I J L D]
time 82055ms: Process C completed I/O; added to ready queue [Q P B E I J L D C]
time 82341ms: Process N completed a CPU burst; 46 bursts to go [Q P B E I J L D C]
time 82341ms: Process N switching out of CPU; blocking on I/O until time 97593ms [Q P B E I J L D C]
time 82345ms: Process P started using the CPU for 3176ms burst [Q B E I J L D C]
time 82407ms: Process F completed I/O; added to ready queue [Q B E I J L D C F]
time 82771ms: Process K completed I/O; added to ready queue [Q B E I J L D C F K]
time 82921ms: Process O completed I/O; added to ready queue [Q B E I J L D C F K O]
time 83047ms: Process M completed I/O; added to ready queue [Q B E I J L D C F K O M]
time 85521ms: Process P completed a CPU burst; 9 bursts to go [Q B E I J L D C F K O M]
time 85521ms: Process P switching out of CPU; blocking on I/O until time 85839ms [Q B E I J L D C F K O M]
time 85525ms: Process B started using the CPU for 2564ms burst [Q E I J L D C F K O M]
time 85839ms: Process P completed I/O; added to ready queue [Q E I J L D C F K O M P]
time 88089ms: Process B completed a CPU burst; 4 bursts to go [Q E I J L D C F K O M P]
time 88089ms: Process B switching out of CPU; blocking on I/O until time 94191ms [Q E I J L D C F K O M P]
time 88093ms: Process E started using the CPU for 540ms burst [Q I J L D C F K O M P]
time 88633ms: Process E completed a CPU burst; 53 bursts to go [Q I J L D C F K O M P]
time 88633ms: Process E switching out of CPU; blocking on I/O until time 92355ms [Q I J L D C F K O M P]
time 88637ms: Process I started using the CPU for 53ms burst [Q J L D C F K O M P]
time 88690ms: Process I completed a CPU burst; 40 bursts to go [Q J L D C F K O M P]
time 88690ms: Process I switching out of CPU; blocking on I/O until time 102732ms [Q J L D C F K O M P]
time 88694ms: Process J started using the CPU for 441ms burst [Q L D C F K O M P]
time 89135ms: Process J completed a CPU burst; 9 bursts to go [Q L D C F K O M P]
time 89135ms: Process J switching out of CPU; blocking on I/O until time 91407ms [Q L D C F K O M P]
time 89139ms: Process L started using the CPU for 396ms burst [Q D C F K O M P]
time 89316ms: Process G completed I/O; added to ready queue [Q D C F K O M P G]
time 89535ms: Process L completed a CPU burst; 24 bursts to go [Q D C F K O M P G]
time 89535ms: Process L switching out of CPU; blocking on I/O until time 92447ms [Q D C F K O M P G]
time 89539ms: Process D started using the CPU for 914ms burst [Q C F K O M P G]
time 90453ms: Process D completed a CPU burst; 46 bursts to go [Q C F K O M P G]
time 90453ms: Process D switching out of CPU; blocking on I/O until time 103445ms [Q C F K O M P G]
time 90457ms: Process C started using the CPU for 1203ms burst [Q F K O M P G]
time 91407ms: Process J completed I/O; added to ready queue [Q F K O M P G J]
time 91660ms: Process C completed a CPU burst; 41 bursts to go [Q F K O M P G J]
time 91660ms: Process C switching out of CPU; blocking on I/O until time 100962ms [Q F K O M P G J]
time 91664ms: Process F started using the CPU for 2196ms burst [Q K O M P G J]
time 92355ms: Process E completed I/O; added to ready queue [Q K O M P G J E]
time 92447ms: Process L completed I/O; added to ready queue [Q K O M P G J E L]
time 93860ms: Process F completed a CPU burst; 44 bursts to go [Q K O M P G J E L]
time 93860ms: Process F switching out of CPU; blocking on I/O until time 108172ms [Q K O M P G J E L]
time 93864ms: Process K started using the CPU for 1224ms burst [Q O M P G J E L]
time 94191ms: Process B completed I/O; added to ready queue [Q O M P G J E L B]
time 95088ms: Process K completed a CPU burst; 26 bursts to go [Q O M P G J E L B]
time 95088ms: Process K switching out of CPU; blocking on I/O until time 100980ms [Q O M P G J E L B]
time 95092ms: Process O started using the CPU for 1424ms burst [Q M P G J E L B]
time 96516ms: Process O completed a CPU burst; 52 bursts to go [Q M P G J E L B]
time 96516ms: Process O switching out of CPU; blocking on I/O until time 96923ms [Q M P G J E L B]
time 96520ms: Process M started using the CPU for 1039ms burst [Q P G J E L B]
time 96923ms: Process O completed I/O; added to ready queue [Q P G J E L B O]
time 97107ms: Process H completed I/O; added to ready queue [Q P G J E L B O H]
time 97559ms: Process M completed a CPU burst; 5 bursts to go [Q P G J E L B O H]
time 97559ms: Process M switching out of CPU; blocking on I/O until time 113421ms [Q P G J E L B O H]
time 97563ms: Process P started using the CPU for 1364ms burst [Q G J E L B O H]
time 97593ms: Process N completed I/O; added to ready queue [Q G J E L B O H N]
time 98927ms: Process P completed a CPU burst; 8 bursts to go [Q G J E L B O H N]
time 98927ms: Process P switching out of CPU; blocking on I/O until time 99795ms [Q G J E L B O H N]
time 98931ms: Process G started using the CPU for 2ms burst [Q J E L B O H N]
time 98933ms: Process G completed a CPU burst; 13 bursts to go [Q J E L B O H N]
time 98933ms: Process G switching out of CPU; blocking on I/O until time 99185ms [Q J E L B O H N]
time 98937ms: Process J started using the CPU for 1195ms burst [Q E L B O H N]
time 99185ms: Process G completed I/O; added to ready queue [Q E L B O H N G]
time 99751ms: Process A completed I/O; added to ready queue [Q E L B O H N G A]
time 99795ms: Process P completed I/O; added to ready queue [Q E L B O H N G A P]
time 100132ms: Process J completed a CPU burst; 8 bursts to go [Q E L B O H N G A P]
time 100132ms: Process J switching out of CPU; blocking on I/O until time 103824ms [Q E L B O H N G A P]
time 100136ms: Process E started using the CPU for 684ms burst [Q L B O H N G A P]
time 100820ms: Process E completed a CPU burst; 52 bursts to go [Q L B O H N G A P]
time 100820ms: Process E switching out of CPU; blocking on I/O until time 112992ms [Q L B O H N G A P]
time 100824ms: Process L started using the CPU for 89ms burst [Q B O H N G A P]
time 100913ms: Process L completed a CPU burst; 23 bursts to go [Q B O H N G A P]
time 100913ms: Process L switching out of CPU; blocking on I/O until time 111955ms [Q B O H N G A P]
time 100917ms: Process B started using the CPU for 816ms burst [Q O H N G A P]
time 100962ms: Process C completed I/O; added to ready queue [Q O H N G A P C]
time 100980ms: Process K completed I/O; added to ready queue [Q O H N G A P C K]
time 101733ms: Process B completed a CPU burst; 3 bursts to go [Q O H N G A P C K]
time 101733ms: Process B switching out of CPU; blocking on I/O until time 109395ms [Q O H N G A P C K]
time 101737ms: Process O started using the CPU for 8868ms burst [Q H N G A P C K]
time 102732ms: Process I completed I/O; added to ready queue [Q H N G A P C K I]
time 103445ms: Process D completed I/O; added to ready queue [Q H N G A P C K I D]
time 103824ms: Process J completed I/O; added to ready queue [Q H N G A P C K I D J]
time 108172ms: Process F completed I/O; added to ready queue [Q H N G A P C K I D J F]
time 109395ms: Process B completed I/O; added to ready queue [Q H N G A P C K I D J F B]
time 110605ms: Process O completed a CPU burst; 51 bursts to go [Q H N G A P C K I D J F B]
time 110605ms: Process O switching out of CPU; blocking on I/O until time 111413ms [Q H N G A P C K I D J F B]
time 110609ms: Process H started using the CPU for 1956ms burst [Q N G A P C K I D J F B]
time 111413ms: Process O completed I/O; added to ready queue [Q N G A P C K I D J F B O]
time 111955ms: Process L completed I/O; added to ready queue [Q N G A P C K I D J F B O L]
time 112565ms: Process H completed a CPU burst; 4 bursts to go [Q N G A P C K I D J F B O L]
time 112565ms: Process H switching out of CPU; blocking on I/O until time 119807ms [Q N G A P C K I D J F B O L]
time 112569ms: Process N started using the CPU for 381ms burst [Q G A P C K I D J F B O L]
time 112950ms: Process N completed a CPU burst; 45 bursts to go [Q G A P C K I D J F B O L]
time 112950ms: Process N switching out of CPU; blocking on I/O until time 117232ms [Q G A P C K I D J F B O L]
time 112954ms: Process G started using the CPU for 555ms burst [Q A P C K I D J F B O L]
time 112992ms: Process E completed I/O; added to ready queue [Q A P C K I D J F B O L E]
time 113421ms: Process M completed I/O; added to ready queue [Q A P C K I D J F B O L E M]
time 113509ms: Process G completed a CPU burst; 12 bursts to go [Q A P C K I D J F B O L E M]
time 113509ms: Process G switching out of CPU; blocking on I/O until time 126451ms [Q A P C K I D J F B O L E M]
time 113513ms: Process A started using the CPU for 553ms burst [Q P C K I D J F B O L E M]
time 114066ms: Process A completed a CPU burst; 4 bursts to go [Q P C K I D J F B O L E M]
time 114066ms: Process A switching out of CPU; blocking on I/O until time 133638ms [Q P C K I D J F B O L E M]
time 114070ms: Process P started using the CPU for 9268ms burst [Q C K I D J F B O L E M]
time 117232ms: Process N completed I/O; added to ready queue [Q C K I D J F B O L E M N]
time 119807ms: Process H completed I/O; added to ready queue [Q C K I D J F B O L E M N H]
time 123338ms: Process P completed a CPU burst; 7 bursts to go [Q C K I D J F B O L E M N H]
time 123338ms: Process P switching out of CPU; blocking on I/O until time 123608ms [Q C K I D J F B O L E M N H]
time 123342ms: Process C started using the CPU for 445ms burst [Q K I D J F B O L E M N H]
time 123608ms: Process P completed I/O; added to ready queue [Q K I D J F B O L E M N H P]
time 123787ms: Process C completed a CPU burst; 40 bursts to go [Q K I D J F B O L E M N H P]
time 123787ms: Process C switching out of CPU; blocking on I/O until time 131879ms [Q K I D J F B O L E M N H P]
time 123791ms: Process K started using the CPU for 882ms burst [Q I D J F B O L E M N H P]
time 124673ms: Process K completed a CPU burst; 25 bursts to go [Q I D J F B O L E M N H P]
time 124673ms: Process K switching out of CPU; blocking on I/O until time 124735ms [Q I D J F B O L E M N H P]
time 124677ms: Process I started using the CPU for 1713ms burst [Q D J F B O L E M N H P]
time 124735ms: Process K completed I/O; added to ready queue [Q D J F B O L E M N H P K]
time 126390ms: Process I completed a CPU burst; 39 bursts to go [Q D J F B O L E M N H P K]
time 126390ms: Process I switching out of CPU; blocking on I/O until time 133322ms [Q D J F B O L E M N H P K]
time 126394ms: Process D started using the CPU for 14ms burst [Q J F B O L E M N H P K]
time 126408ms: Process D completed a CPU burst; 45 bursts to go [Q J F B O L E M N H P K]
time 126408ms: Process D switching out of CPU; blocking on I/O until time 139290ms [Q J F B O L E M N H P K]
time 126412ms: Process J started using the CPU for 326ms burst [Q F B O L E M N H P K]
time 126451ms: Process G completed I/O; added to ready queue [Q F B O L E M N H P K G]
time 126738ms: Process J completed a CPU burst; 7 bursts to go [Q F B O L E M N H P K G]
time 126738ms: Process J switching out of CPU; blocking on I/O until time 139430ms [Q F B O L E M N H P K G]
time 126742ms: Process F started using the CPU for 924ms burst [Q B O L E M N H P K G]
time 127666ms: Process F completed a CPU burst; 43 bursts to go [Q B O L E M N H P K G]
time 127666ms: Process F switching out of CPU; blocking on I/O until time 146178ms [Q B O L E M N H P K G]
time 127670ms: Process B started using the CPU for 1000ms burst [Q O L E M N H P K G]
time 128670ms: Process B completed a CPU burst; 2 bursts to go [Q O L E M N H P K G]
time 128670ms: Process B switching out of CPU; blocking on I/O until time 129592ms [Q O L E M N H P K G]
time 128674ms: Process O started using the CPU for 816ms burst [Q L E M N H P K G]
time 129490ms: Process O completed a CPU burst; 50 bursts to go [Q L E M N H P K G]
time 129490ms: Process O switching out of CPU; blocking on I/O until time 129587ms [Q L E M N H P K G]
time 129494ms: Process L started using the CPU for 1796ms burst [Q E M N H P K G]
time 129587ms: Process O completed I/O; added to ready queue [Q E M N H P K G O]
time 129592ms: Process B completed I/O; added to ready queue [Q E M N H P K G O B]
time 131290ms: Process L completed a CPU burst; 22 bursts to go [Q E M N H P K G O B]
time 131290ms: Process L switching out of CPU; blocking on I/O until time 133122ms [Q E M N H P K G O B]
time 131294ms: Process E started using the CPU for 1616ms burst [Q M N H P K G O B]
time 131879ms: Process C completed I/O; added to ready queue [Q M N H P K G O B C]
time 132910ms: Process E completed a CPU burst; 51 bursts to go [Q M N H P K G O B C]
time 132910ms: Process E switching out of CPU; blocking on I/O until time 139152ms [Q M N H P K G O B C]
time 132914ms: Process M started using the CPU for 738ms burst [Q N H P K G O B C]
time 133122ms: Process L completed I/O; added to ready queue [Q N H P K G O B C L]
time 133322ms: Process I completed I/O; added to ready queue [Q N H P K G O B C L I]
time 133638ms: Process A completed I/O; added to ready queue [Q N H P K G O B C L I A]
time 133652ms: Process M completed a CPU burst; 4 bursts to go [Q N H P K G O B C L I A]
time 133652ms: Process M switching out of CPU; blocking on I/O until time 136454ms [Q N H P K G O B C L I A]
time 133656ms: Process N started using the CPU for 1358ms burst [Q H P K G O B C L I A]
time 135014ms: Process N completed a CPU burst; 44 bursts to go [Q H P K G O B C L I A]
time 135014ms: Process N switching out of CPU; blocking on I/O until time 135786ms [Q H P K G O B C L I A]
time 135018ms: Process H started using the CPU for 592ms burst [Q P K G O B C L I A]
time 135610ms: Process H completed a CPU burst; 3 bursts to go [Q P K G O B C L I A]
time 135610ms: Process H switching out of CPU; blocking on I/O until time 154512ms [Q P K G O B C L I A]
time 135614ms: Process P started using the CPU for 800ms burst [Q K G O B C L I A]
time 135786ms: Process N completed I/O; added to ready queue [Q K G O B C L I A N]
time 136414ms: Process P completed a CPU burst; 6 bursts to go [Q K G O B C L I A N]
time 136414ms: Process P switching out of CPU; blocking on I/O until time 136419ms [Q K G O B C L I A N]
time 136418ms: Process K started using the CPU for 1016ms burst [Q G O B C L I A N]
time 136419ms: Process P completed I/O; added to ready queue [Q G O B C L I A N P]
time 136454ms: Process M completed I/O; added to ready queue [Q G O B C L I A N P M]
time 137434ms: Process K completed a CPU burst; 24 bursts to go [Q G O B C L I A N P M]
time 137434ms: Process K switching out of CPU; blocking on I/O until time 142976ms [Q G O B C L I A N P M]
time 137438ms: Process G started using the CPU for 443ms burst [Q O B C L I A N P M]
time 137881ms: Process G completed a CPU burst; 11 bursts to go [Q O B C L I A N P M]
time 137881ms: Process G switching out of CPU; blocking on I/O until time 152953ms [Q O B C L I A N P M]
time 137885ms: Process O started using the CPU for 208ms burst [Q B C L I A N P M]
time 138093ms: Process O completed a CPU burst; 49 bursts to go [Q B C L I A N P M]
time 138093ms: Process O switching out of CPU; blocking on I/O until time 140452ms [Q B C L I A N P M]
time 138097ms: Process B started using the CPU for 583ms burst [Q C L I A N P M]
time 138680ms: Process B completed a CPU burst; 1 burst to go [Q C L I A N P M]
time 138680ms: Process B switching out of CPU; blocking on I/O until time 162202ms [Q C L I A N P M]
time 138684ms: Process C started using the CPU for 2176ms burst [Q L I A N P M]
time 139152ms: Process E completed I/O; added to ready queue [Q L I A N P M E]
time 139290ms: Process D completed I/O; added to ready queue [Q L I A N P M E D]
time 139430ms: Process J completed I/O; added to ready queue [Q L I A N P M E D J]
time 140452ms: Process O completed I/O; added to ready queue [Q L I A N P M E D J O]
time 140860ms: Process C completed a CPU burst; 39 bursts to go [Q L I A N P M E D J O]
time 140860ms: Process C switching out of CPU; blocking on I/O until time 145822ms [Q L I A N P M E D J O]
time 140864ms: Process L started using the CPU for 1169ms burst [Q I A N P M E D J O]
time 142033ms: Process L completed a CPU burst; 21 bursts to go [Q I A N P M E D J O]
time 142033ms: Process L switching out of CPU; blocking on I/O until time 155275ms [Q I A N P M E D J O]
time 142037ms: Process I started using the CPU for 386ms burst [Q A N P M E D J O]
time 142423ms: Process I completed a CPU burst; 38 bursts to go [Q A N P M E D J O]
time 142423ms: Process I switching out of CPU; blocking on I/O until time 145215ms [Q A N P M E D J O]
time 142427ms: Process A started using the CPU for 2660ms burst [Q N P M E D J O]
time 142976ms: Process K completed I/O; added to ready queue [Q N P M E D J O K]
time 145087ms: Process A completed a CPU burst; 3 bursts to go [Q N P M E D J O K]
time 145087ms: Process A switching out of CPU; blocking on I/O until time 146449ms [Q N P M E D J O K]
time 145091ms: Process N started using the CPU for 2861ms burst [Q P M E D J O K]
time 145215ms: Process I completed I/O; added to ready queue [Q P M E D J O K I]
time 145822ms: Process C completed I/O; added to ready queue [Q P M E D J O K I C]
time 146178ms: Process F completed I/O; added to ready queue [Q P M E D J O K I C F]
time 146449ms: Process A completed I/O; added to ready queue [Q P M E D J O K I C F A]
time 147952ms: Process N completed a CPU burst; 43 bursts to go [Q P M E D J O K I C F A]
time 147952ms: Process N switching out of CPU; blocking on I/O until time 156474ms [Q P M E D J O K I C F A]
time 147956ms: Process P started using the CPU for 7648ms burst [Q M E D J O K I C F A]
time 152953ms: Process G completed I/O; added to ready queue [Q M E D J O K I C F A G]
time 154512ms: Process H completed I/O; added to ready queue [Q M E D J O K I C F A G H]
time 155275ms: Process L completed I/O; added to ready queue [Q M E D J O K I C F A G H L]
time 155604ms: Process P completed a CPU burst; 5 bursts to go [Q M E D J O K I C F A G H L]
time 155604ms: Process P switching out of CPU; blocking on I/O until time 155727ms [Q M E D J O K I C F A G H L]
time 155608ms: Process M started using the CPU for 1197ms burst [Q E D J O K I C F A G H L]
time 155727ms: Process P completed I/O; added to ready queue [Q E D J O K I C F A G H L P]
time 156474ms: Process N completed I/O; added to ready queue [Q E D J O K I C F A G H L P N]
time 156805ms: Process M completed a CPU burst; 3 bursts to go [Q E D J O K I C F A G H L P N]
time 156805ms: Process M switching out of CPU; blocking on I/O until time 173967ms [Q E D J O K I C F A G H L P N]
time 156809ms: Process E started using the CPU for 102ms burst [Q D J O K I C F A G H L P N]
time 156911ms: Process E completed a CPU burst; 50 bursts to go [Q D J O K I C F A G H L P N]
time 156911ms: Process E switching out of CPU; blocking on I/O until time 176403ms [Q D J O K I C F A G H L P N]
time 156915ms: Process D started using the CPU for 2343ms burst [Q J O K I C F A G H L P N]
time 159258ms: Process D completed a CPU burst; 44 bursts to go [Q J O K I C F A G H L P N]
time 159258ms: Process D switching out of CPU; blocking on I/O until time 165310ms [Q J O K I C F A G H L P N]
time 159262ms: Process J started using the CPU for 1103ms burst [Q O K I C F A G H L P N]
time 160365ms: Process J completed a CPU burst; 6 bursts to go [Q O K I C F A G H L P N]
time 160365ms: Process J switching out of CPU; blocking on I/O until time 162327ms [Q O K I C F A G H L P N]
time 160369ms: Process O started using the CPU for 616ms burst [Q K I C F A G H L P N]
time 160985ms: Process O completed a CPU burst; 48 bursts to go [Q K I C F A G H L P N]
time 160985ms: Process O switching out of CPU; blocking on I/O until time 162012ms [Q K I C F A G H L P N]
time 160989ms: Process K started using the CPU for 367ms burst [Q I C F A G H L P N]
time 161356ms: Process K completed a CPU burst; 23 bursts to go [Q I C F A G H L P N]
time 161356ms: Process K switching out of CPU; blocking on I/O until time 166858ms [Q I C F A G H L P N]
time 161360ms: Process I started using the CPU for 274ms burst [Q C F A G H L P N]
time 161634ms: Process I completed a CPU burst; 37 bursts to go [Q C F A G H L P N]
time 161634ms: Process I switching out of CPU; blocking on I/O until time 173236ms [Q C F A G H L P N]
time 161638ms: Process C started using the CPU for 516ms burst [Q F A G H L P N]
time 162012ms: Process O completed I/O; added to ready queue [Q F A G H L P N O]
time 162154ms: Process C completed a CPU burst; 38 bursts to go [Q F A G H L P N O]
time 162154ms: Process C switching out of CPU; blocking on I/O until time 170046ms [Q F A G H L P N O]
time 162158ms: Process F started using the CPU for 1459ms burst [Q A G H L P N O]
time 162202ms: Process B completed I/O; added to ready queue [Q A G H L P N O B]
time 162327ms: Process J completed I/O; added to ready queue [Q A G H L P N O B J]
time 163617ms: Process F completed a CPU burst; 42 bursts to go [Q A G H L P N O B J]
time 163617ms: Process F switching out of CPU; blocking on I/O until time 171759ms [Q A G H L P N O B J]
time 163621ms: Process A started using the CPU for 1470ms burst [Q G H L P N O B J]
time 165091ms: Process A completed a CPU burst; 2 bursts to go [Q G H L P N O B J]
time 165091ms: Process A switching out of CPU; blocking on I/O until time 181903ms [Q G H L P N O B J]
time 165095ms: Process G started using the CPU for 263ms burst [Q H L P N O B J]
time 165310ms: Process D completed I/O; added to ready queue [Q H L P N O B J D]
time 165358ms: Process G completed a CPU burst; 10 bursts to go [Q H L P N O B J D]
time 165358ms: Process G switching out of CPU; blocking on I/O until time 177890ms [Q H L P N O B J D]
time 165362ms: Process H started using the CPU for 2116ms burst [Q L P N O B J D]
time 166858ms: Process K completed I/O; added to ready queue [Q L P N O B J D K]
time 167478ms: Process H completed a CPU burst; 2 bursts to go [Q L P N O B J D K]
time 167478ms: Process H switching out of CPU; blocking on I/O until time 188130ms [Q L P N O B J D K]
time 167482ms: Process L started using the CPU for 1885ms burst [Q P N O B J D K]
time 169367ms: Process L completed a CPU burst; 20 bursts to go [Q P N O B J D K]
time 169367ms: Process L switching out of CPU; blocking on I/O until time 179239ms [Q P N O B J D K]
time 169371ms: Process P started using the CPU for 1916ms burst [Q N O B J D K]
time 170046ms: Process C completed I/O; added to ready queue [Q N O B J D K C]
time 171287ms: Process P completed a CPU burst; 4 bursts to go [Q N O B J D K C]
time 171287ms: Process P switching out of CPU; blocking on I/O until time 171311ms [Q N O B J D K C]
time 171291ms: Process N started using the CPU for 1ms burst [Q O B J D K C]
time 171292ms: Process N completed a CPU burst; 42 bursts to go [Q O B J D K C]
time 171292ms: Process N switching out of CPU; blocking on I/O until time 173594ms [Q O B J D K C]
time 171296ms: Process O started using the CPU for 1892ms burst [Q B J D K C]
time 171311ms: Process P completed I/O; added to ready queue [Q B J D K C P]
time 171759ms: Process F completed I/O; added to ready queue [Q B J D K C P F]
time 173188ms: Process O completed a CPU burst; 47 bursts to go [Q B J D K C P F]
time 173188ms: Process O switching out of CPU; blocking on I/O until time 175441ms [Q B J D K C P F]
time 173192ms: Process B started using the CPU for 1495ms burst [Q J D K C P F]
time 173236ms: Process I completed I/O; added to ready queue [Q J D K C P F I]
time 173594ms: Process N completed I/O; added to ready queue [Q J D K C P F I N]
time 173967ms: Process M completed I/O; added to ready queue [Q J D K C P F I N M]
time 174687ms: Process B terminated [Q J D K C P F I N M]
time 174691ms: Process J started using the CPU for 883ms burst [Q D K C P F I N M]
time 175441ms: Process O completed I/O; added to ready queue [Q D K C P F I N M O]
time 175574ms: Process J completed a CPU burst; 5 bursts to go [Q D K C P F I N M O]
time 175574ms: Process J switching out of CPU; blocking on I/O until time 178836ms [Q D K C P F I N M O]
time 175578ms: Process D started using the CPU for 953ms burst [Q K C P F I N M O]
time 176403ms: Process E completed I/O; added to ready queue [Q K C P F I N M O E]
time 176531ms: Process D completed a CPU burst; 43 bursts to go [Q K C P F I N M O E]
time 176531ms: Process D switching out of CPU; blocking on I/O until time 184293ms [Q K C P F I N M O E]
time 176535ms: Process K started using the CPU for 1069ms burst [Q C P F I N M O E]
time 177604ms: Process K completed a CPU burst; 22 bursts to go [Q C P F I N M O E]
time 177604ms: Process K switching out of CPU; blocking on I/O until time 192116ms [Q C P F I N M O E]
time 177608ms: Process C started using the CPU for 1476ms burst [Q P F I N M O E]
time 177890ms: Process G completed I/O; added to ready queue [Q P F I N M O E G]
time 178836ms: Process J completed I/O; added to ready queue [Q P F I N M O E G J]
time 179084ms: Process C completed a CPU burst; 37 bursts to go [Q P F I N M O E G J]
time 179084ms: Process C switching out of CPU; blocking on I/O until time 181686ms [Q P F I N M O E G J]
time 179088ms: Process P started using the CPU for 1364ms burst [Q F I N M O E G J]
time 179239ms: Process L completed I/O; added to ready queue [Q F I N M O E G J L]
time 180452ms: Process P completed a CPU burst; 3 bursts to go [Q F I N M O E G J L]
time 180452ms: Process P switching out of CPU; blocking on I/O until time 180954ms [Q F I N M O E G J L]
time 180456ms: Process F started using the CPU for 1587ms burst [Q I N M O E G J L]
time 180954ms: Process P completed I/O; added to ready queue [Q I N M O E G J L P]
time 181686ms: Process C completed I/O; added to ready queue [Q I N M O E G J L P C]
time 181903ms: Process A completed I/O; added to ready queue [Q I N M O E G J L P C A]
time 182043ms: Process F completed a CPU burst; 41 bursts to go [Q I N M O E G J L P C A]
time 182043ms: Process F switching out of CPU; blocking on I/O until time 185655ms [Q I N M O E G J L P C A]
time 182047ms: Process I started using the CPU for 533ms burst [Q N M O E G J L P C A]
time 182580ms: Process I completed a CPU burst; 36 bursts to go [Q N M O E G J L P C A]
time 182580ms: Process I switching out of CPU; blocking on I/O until time 206552ms [Q N M O E G J L P C A]
time 182584ms: Process N started using the CPU for 1382ms burst [Q M O E G J L P C A]
time 183966ms: Process N completed a CPU burst; 41 bursts to go [Q M O E G J L P C A]
time 183966ms: Process N switching out of CPU; blocking on I/O until time 206868ms [Q M O E G J L P C A]
time 183970ms: Process M started using the CPU for 1740ms burst [Q O E G J L P C A]
time 184293ms: Process D completed I/O; added to ready queue [Q O E G J L P C A D]
time 185655ms: Process F completed I/O; added to ready queue [Q O E G J L P C A D F]
time 185710ms: Process M completed a CPU burst; 2 bursts to go [Q O E G J L P C A D F]
time 185710ms: Process M switching out of CPU; blocking on I/O until time 211632ms [Q O E G J L P C A D F]
time 185714ms: Process O started using the CPU for 832ms burst [Q E G J L P C A D F]
time 186546ms: Process O completed a CPU burst; 46 bursts to go [Q E G J L P C A D F]
time 186546ms: Process O switching out of CPU; blocking on I/O until time 186878ms [Q E G J L P C A D F]
time 186550ms: Process E started using the CPU for 1321ms burst [Q G J L P C A D F]
time 186878ms: Process O completed I/O; added to ready queue [Q G J L P C A D F O]
time 187871ms: Process E completed a CPU burst; 49 bursts to go [Q G J L P C A D F O]
time 187871ms: Process E switching out of CPU; blocking on I/O until time 195363ms [Q G J L P C A D F O]
time 187875ms: Process G started using the CPU for 496ms burst [Q J L P C A D F O]
time 188130ms: Process H completed I/O; added to ready queue [Q J L P C A D F O H]
time 188371ms: Process G completed a CPU burst; 9 bursts to go [Q J L P C A D F O H]
time 188371ms: Process G switching out of CPU; blocking on I/O until time 200033ms [Q J L P C A D F O H]
time 188375ms: Process J started using the CPU for 899ms burst [Q L P C A D F O H]
time 189274ms: Process J completed a CPU burst; 4 bursts to go [Q L P C A D F O H]
time 189274ms: Process J switching out of CPU; blocking on I/O until time 209876ms [Q L P C A D F O H]
time 189278ms: Process L started using the CPU for 858ms burst [Q P C A D F O H]
time 190136ms: Process L completed a CPU burst; 19 bursts to go [Q P C A D F O H]
time 190136ms: Process L switching out of CPU; blocking on I/O until time 195698ms [Q P C A D F O H]
time 190140ms: Process P started using the CPU for 2132ms burst [Q C A D F O H]
time 192116ms: Process K completed I/O; added to ready queue [Q C A D F O H K]
time 192272ms: Process P completed a CPU burst; 2 bursts to go [Q C A D F O H K]
time 192272ms: Process P switching out of CPU; blocking on I/O until time 194565ms [Q C A D F O H K]
time 192276ms: Process C started using the CPU for 2016ms burst [Q A D F O H K]
time 194292ms: Process C completed a CPU burst; 36 bursts to go [Q A D F O H K]
time 194292ms: Process C switching out of CPU; blocking on I/O until time 201534ms [Q A D F O H K]
time 194296ms: Process A started using the CPU for 478ms burst [Q D F O H K]
time 194565ms: Process P completed I/O; added to ready queue [Q D F O H K P]
time 194774ms: Process A completed a CPU burst; 1 burst to go [Q D F O H K P]
time 194774ms: Process A switching out of CPU; blocking on I/O until time 197076ms [Q D F O H K P]
time 194778ms: Process D started using the CPU for 1566ms burst [Q F O H K P]
time 195363ms: Process E completed I/O; added to ready queue [Q F O H K P E]
time 195698ms: Process L completed I/O; added to ready queue [Q F O H K P E L]
time 196344ms: Process D completed a CPU burst; 42 bursts to go [Q F O H K P E L]
time 196344ms: Process D switching out of CPU; blocking on I/O until time 197416ms [Q F O H K P E L]
time 196348ms: Process F started using the CPU for 229ms burst [Q O H K P E L]
time 196577ms: Process F completed a CPU burst; 40 bursts to go [Q O H K P E L]
time 196577ms: Process F switching out of CPU; blocking on I/O until time 201839ms [Q O H K P E L]
time 196581ms: Process O started using the CPU for 8996ms burst [Q H K P E L]
time 197076ms: Process A completed I/O; added to ready queue [Q H K P E L A]
time 197416ms: Process D completed I/O; added to ready queue [Q H K P E L A D]
time 200033ms: Process G completed I/O; added to ready queue [Q H K P E L A D G]
time 201534ms: Process C completed I/O; added to ready queue [Q H K P E L A D G C]
time 201839ms: Process F completed I/O; added to ready queue [Q H K P E L A D G C F]
time 205577ms: Process O completed a CPU burst; 45 bursts to go [Q H K P E L A D G C F]
time 205577ms: Process O switching out of CPU; blocking on I/O until time 206192ms [Q H K P E L A D G C F]
time 205581ms: Process H started using the CPU for 944ms burst [Q K P E L A D G C F]
time 206192ms: Process O completed I/O; added to ready queue [Q K P E L A D G C F O]
time 206525ms: Process H completed a CPU burst; 1 burst to go [Q K P E L A D G C F O]
time 206525ms: Process H switching out of CPU; blocking on I/O until time 224357ms [Q K P E L A D G C F O]
time 206529ms: Process K started using the CPU for 714ms burst [Q P E L A D G C F O]
time 206552ms: Process I completed I/O; added to ready queue [Q P E L A D G C F O I]
time 206868ms: Process N completed I/O; added to ready queue [Q P E L A D G C F O I N]
time 207243ms: Process K completed a CPU burst; 21 bursts to go [Q P E L A D G C F O I N]
time 207243ms: Process K switching out of CPU; blocking on I/O until time 222215ms [Q P E L A D G C F O I N]
time 207247ms: Process P started using the CPU for 3100ms burst [Q E L A D G C F O I N]
time 209876ms: Process J completed I/O; added to ready queue [Q E L A D G C F O I N J]
time 210347ms: Process P completed a CPU burst; 1 burst to go [Q E L A D G C F O I N J]
time 210347ms: Process P switching out of CPU; blocking on I/O until time 212554ms [Q E L A D G C F O I N J]
time 210351ms: Process E started using the CPU for 1468ms burst [Q L A D G C F O I N J]
time 211632ms: Process M completed I/O; added to ready queue [Q L A D G C F O I N J M]
time 211819ms: Process E completed a CPU burst; 48 bursts to go [Q L A D G C F O I N J M]
time 211819ms: Process E switching out of CPU; blocking on I/O until time 213161ms [Q L A D G C F O I N J M]
time 211823ms: Process L started using the CPU for 421ms burst [Q A D G C F O I N J M]
time 212244ms: Process L completed a CPU burst; 18 bursts to go [Q A D G C F O I N J M]
time 212244ms: Process L switching out of CPU; blocking on I/O until time 223156ms [Q A D G C F O I N J M]
time 212248ms: Process A started using the CPU for 50ms burst [Q D G C F O I N J M]
time 212298ms: Process A terminated [Q D G C F O I N J M]
time 212302ms: Process D started using the CPU for 285ms burst [Q G C F O I N J M]
time 212554ms: Process P completed I/O; added to ready queue [Q G C F O I N J M P]
time 212587ms: Process D completed a CPU burst; 41 bursts to go [Q G C F O I N J M P]
time 212587ms: Process D switching out of CPU; blocking on I/O until time 219699ms [Q G C F O I N J M P]
time 212591ms: Process G started using the CPU for 71ms burst [Q C F O I N J M P]
time 212662ms: Process G completed a CPU burst; 8 bursts to go [Q C F O I N J M P]
time 212662ms: Process G switching out of CPU; blocking on I/O until time 225504ms [Q C F O I N J M P]
time 212666ms: Process C started using the CPU for 1586ms burst [Q F O I N J M P]
time 213161ms: Process E completed I/O; added to ready queue [Q F O I N J M P E]
time 214252ms: Process C completed a CPU burst; 35 bursts to go [Q F O I N J M P E]
time 214252ms: Process C switching out of CPU; blocking on I/O until time 234234ms [Q F O I N J M P E]
time 214256ms: Process F started using the CPU for 1386ms burst [Q O I N J M P E]
time 215642ms: Process F completed a CPU burst; 39 bursts to go [Q O I N J M P E]
time 215642ms: Process F switching out of CPU; blocking on I/O until time 227634ms [Q O I N J M P E]
time 215646ms: Process O started using the CPU for 1892ms burst [Q I N J M P E]
time 217538ms: Process O completed a CPU burst; 44 bursts to go [Q I N J M P E]
time 217538ms: Process O switching out of CPU; blocking on I/O until time 217952ms [Q I N J M P E]
time 217542ms: Process I started using the CPU for 593ms burst [Q N J M P E]
time 217952ms: Process O completed I/O; added to ready queue [Q N J M P E O]
time 218135ms: Process I completed a CPU burst; 35 bursts to go [Q N J M P E O]
time 218135ms: Process I switching out of CPU; blocking on I/O until time 219467ms [Q N J M P E O]
time 218139ms: Process N started using the CPU for 1164ms burst [Q J M P E O]
time 219303ms: Process N completed a CPU burst; 40 bursts to go [Q J M P E O]
time 219303ms: Process N switching out of CPU; blocking on I/O until time 229325ms [Q J M P E O]
time 219307ms: Process J started using the CPU for 228ms burst [Q M P E O]
time 219467ms: Process I completed I/O; added to ready queue [Q M P E O I]
time 219535ms: Process J completed a CPU burst; 3 bursts to go [Q M P E O I]
time 219535ms: Process J switching out of CPU; blocking on I/O until time 235077ms [Q M P E O I]
time 219539ms: Process M started using the CPU for 777ms burst [Q P E O I]
time 219699ms: Process D completed I/O; added to ready queue [Q P E O I D]
time 220316ms: Process M completed a CPU burst; 1 burst to go [Q P E O I D]
time 220316ms: Process M switching out of CPU; blocking on I/O until time 233778ms [Q P E O I D]
time 220320ms: Process P started using the CPU for 2604ms burst [Q E O I D]
time 222215ms: Process K completed I/O; added to ready queue [Q E O I D K]
time 222924ms: Process P terminated [Q E O I D K]
time 222928ms: Process E started using the CPU for 333ms burst [Q O I D K]
time 223156ms: Process L completed I/O; added to ready queue [Q O I D K L]
time 223261ms: Process E completed a CPU burst; 47 bursts to go [Q O I D K L]
time 223261ms: Process E switching out of CPU; blocking on I/O until time 224713ms [Q O I D K L]
time 223265ms: Process O started using the CPU for 1412ms burst [Q I D K L]
time 224357ms: Process H completed I/O; added to ready queue [Q I D K L H]
time 224677ms: Process O completed a CPU burst; 43 bursts to go [Q I D K L H]
time 224677ms: Process O switching out of CPU; blocking on I/O until time 225476ms [Q I D K L H]
time 224681ms: Process I started using the CPU for 761ms burst [Q D K L H]
time 224713ms: Process E completed I/O; added to ready queue [Q D K L H E]
time 225442ms: Process I completed a CPU burst; 34 bursts to go [Q D K L H E]
time 225442ms: Process I switching out of CPU; blocking on I/O until time 252174ms [Q D K L H E]
time 225446ms: Process D started using the CPU for 2967ms burst [Q K L H E]
time 225476ms: Process O completed I/O; added to ready queue [Q K L H E O]
time 225504ms: Process G completed I/O; added to ready queue [Q K L H E O G]
time 227634ms: Process F completed I/O; added to ready queue [Q K L H E O G F]
time 228413ms: Process D completed a CPU burst; 40 bursts to go [Q K L H E O G F]
time 228413ms: Process D switching out of CPU; blocking on I/O until time 243805ms [Q K L H E O G F]
time 228417ms: Process K started using the CPU for 1525ms burst [Q L H E O G F]
time 229325ms: Process N completed I/O; added to ready queue [Q L H E O G F N]
time 229942ms: Process K completed a CPU burst; 20 bursts to go [Q L H E O G F N]
time 229942ms: Process K switching out of CPU; blocking on I/O until time 245834ms [Q L H E O G F N]
time 229946ms: Process L started using the CPU for 238ms burst [Q H E O G F N]
time 230184ms: Process L completed a CPU burst; 17 bursts to go [Q H E O G F N]
time 230184ms: Process L switching out of CPU; blocking on I/O until time 237026ms [Q H E O G F N]
time 230188ms: Process H started using the CPU for 1090ms burst [Q E O G F N]
time 231278ms: Process H terminated [Q E O G F N]
time 231282ms: Process E started using the CPU for 417ms burst [Q O G F N]
time 231699ms: Process E completed a CPU burst; 46 bursts to go [Q O G F N]
time 231699ms: Process E switching out of CPU; blocking on I/O until time 237761ms [Q O G F N]
time 231703ms: Process O started using the CPU for 112ms burst [Q G F N]
time 231815ms: Process O completed a CPU burst; 42 bursts to go [Q G F N]
time 231815ms: Process O switching out of CPU; blocking on I/O until time 231970ms [Q G F N]
time 231819ms: Process G started using the CPU for 588ms burst [Q F N]
time 231970ms: Process O completed I/O; added to ready queue [Q F N O]
time 232407ms: Process G completed a CPU burst; 7 bursts to go [Q F N O]
time 232407ms: Process G switching out of CPU; blocking on I/O until time 248139ms [Q F N O]
time 232411ms: Process F started using the CPU for 39ms burst [Q N O]
time 232450ms: Process F completed a CPU burst; 38 bursts to go [Q N O]
time 232450ms: Process F switching out of CPU; blocking on I/O until time 239652ms [Q N O]
time 232454ms: Process N started using the CPU for 663ms burst [Q O]
time 233117ms: Process N completed a CPU burst; 39 bursts to go [Q O]
time 233117ms: Process N switching out of CPU; blocking on I/O until time 233159ms [Q O]
time 233121ms: Process O started using the CPU for 6212ms burst [Q <empty>]
time 233159ms: Process N completed I/O; added to ready queue [Q N]
time 233778ms: Process M completed I/O; added to ready queue [Q N M]
time 234234ms: Process C completed I/O; added to ready queue [Q N M C]
time 235077ms: Process J completed I/O; added to ready queue [Q N M C J]
time 237026ms: Process L completed I/O; added to ready queue [Q N M C J L]
time 237761ms: Process E completed I/O; added to ready queue [Q N M C J L E]
time 239333ms: Process O completed a CPU burst; 41 bursts to go [Q N M C J L E]
time 239333ms: Process O switching out of CPU; blocking on I/O until time 240067ms [Q N M C J L E]
time 239337ms: Process N started using the CPU for 1136ms burst [Q M C J L E]
time 239652ms: Process F completed I/O; added to ready queue [Q M C J L E F]
time 240067ms: Process O completed I/O; added to ready queue [Q M C J L E F O]
time 240473ms: Process N completed a CPU burst; 38 bursts to go [Q M C J L E F O]
time 240473ms: Process N switching out of CPU; blocking on I/O until time 241225ms [Q M C J L E F O]
time 240477ms: Process M started using the CPU for 552ms burst [Q C J L E F O]
time 241029ms: Process M terminated [Q C J L E F O]
time 241033ms: Process C started using the CPU for 527ms burst [Q J L E F O]
time 241225ms: Process N completed I/O; added to ready queue [Q J L E F O N]
time 241560ms: Process C completed a CPU burst; 34 bursts to go [Q J L E F O N]
time 241560ms: Process C switching out of CPU; blocking on I/O until time 246482ms [Q J L E F O N]
time 241564ms: Process J started using the CPU for 337ms burst [Q L E F O N]
time 241901ms: Process J completed a CPU burst; 2 bursts to go [Q L E F O N]
time 241901ms: Process J switching out of CPU; blocking on I/O until time 260033ms [Q L E F O N]
time 241905ms: Process L started using the CPU for 1709ms burst [Q E F O N]
time 243614ms: Process L completed a CPU burst; 16 bursts to go [Q E F O N]
time 243614ms: Process L switching out of CPU; blocking on I/O until time 248526ms [Q E F O N]
time 243618ms: Process E started using the CPU for 951ms burst [Q F O N]
time 243805ms: Process D completed I/O; added to ready queue [Q F O N D]
time 244569ms: Process E completed a CPU burst; 45 bursts to go [Q F O N D]
time 244569ms: Process E switching out of CPU; blocking on I/O until time 260511ms [Q F O N D]
time 244573ms: Process F started using the CPU for 848ms burst [Q O N D]
time 245421ms: Process F completed a CPU burst; 37 bursts to go [Q O N D]
time 245421ms: Process F switching out of CPU; blocking on I/O until time 247073ms [Q O N D]
time 245425ms: Process O started using the CPU for 6680ms burst [Q N D]
time 245834ms: Process K completed I/O; added to ready queue [Q N D K]
time 246482ms: Process C completed I/O; added to ready queue [Q N D K C]
time 247073ms: Process F completed I/O; added to ready queue [Q N D K C F]
time 248139ms: Process G completed I/O; added to ready queue [Q N D K C F G]
time 248526ms: Process L completed I/O; added to ready queue [Q N D K C F G L]
time 252105ms: Process O completed a CPU burst; 40 bursts to go [Q N D K C F G L]
time 252105ms: Process O switching out of CPU; blocking on I/O until time 253702ms [Q N D K C F G L]
time 252109ms: Process N started using the CPU for 1057ms burst [Q D K C F G L]
time 252174ms: Process I completed I/O; added to ready queue [Q D K C F G L I]
time 253166ms: Process N completed a CPU burst; 37 bursts to go [Q D K C F G L I]
time 253166ms: Process N switching out of CPU; blocking on I/O until time 257838ms [Q D K C F G L I]
time 253170ms: Process D started using the CPU for 382ms burst [Q K C F G L I]
time 253552ms: Process D completed a CPU burst; 39 bursts to go [Q K C F G L I]
time 253552ms: Process D switching out of CPU; blocking on I/O until time 255514ms [Q K C F G L I]
time 253556ms: Process K started using the CPU for 2066ms burst [Q C F G L I]
time 253702ms: Process O completed I/O; added to ready queue [Q C F G L I O]
time 255514ms: Process D completed I/O; added to ready queue [Q C F G L I O D]
time 255622ms: Process K completed a CPU burst; 19 bursts to go [Q C F G L I O D]
time 255622ms: Process K switching out of CPU; blocking on I/O until time 257884ms [Q C F G L I O D]
time 255626ms: Process C started using the CPU for 2851ms burst [Q F G L I O D]
time 257838ms: Process N completed I/O; added to ready queue [Q F G L I O D N]
time 257884ms: Process K completed I/O; added to ready queue [Q F G L I O D N K]
time 258477ms: Process C completed a CPU burst; 33 bursts to go [Q F G L I O D N K]
time 258477ms: Process C switching out of CPU; blocking on I/O until time 265639ms [Q F G L I O D N K]
time 258481ms: Process F started using the CPU for 325ms burst [Q G L I O D N K]
time 258806ms: Process F completed a CPU burst; 36 bursts to go [Q G L I O D N K]
time 258806ms: Process F switching out of CPU; blocking on I/O until time 268018ms [Q G L I O D N K]
time 258810ms: Process G started using the CPU for 980ms burst [Q L I O D N K]
time 259790ms: Process G completed a CPU burst; 6 bursts to go [Q L I O D N K]
time 259790ms: Process G switching out of CPU; blocking on I/O until time 262892ms [Q L I O D N K]
time 259794ms: Process L started using the CPU for 1553ms burst [Q I O D N K]
time 260033ms: Process J completed I/O; added to ready queue [Q I O D N K J]
time 260511ms: Process E completed I/O; added to ready queue [Q I O D N K J E]
time 261347ms: Process L completed a CPU burst; 15 bursts to go [Q I O D N K J E]
time 261347ms: Process L switching out of CPU; blocking on I/O until time 272479ms [Q I O D N K J E]
time 261351ms: Process I started using the CPU for 785ms burst [Q O D N K J E]
time 262136ms: Process I completed a CPU burst; 33 bursts to go [Q O D N K J E]
time 262136ms: Process I switching out of CPU; blocking on I/O until time 270828ms [Q O D N K J E]
time 262140ms: Process O started using the CPU for 2476ms burst [Q D N K J E]
time 262892ms: Process G completed I/O; added to ready queue [Q D N K J E G]
time 264616ms: Process O completed a CPU burst; 39 bursts to go [Q D N K J E G]
time 264616ms: Process O switching out of CPU; blocking on I/O until time 264950ms [Q D N K J E G]
time 264620ms: Process D started using the CPU for 1310ms burst [Q N K J E G]
time 264950ms: Process O completed I/O; added to ready queue [Q N K J E G O]
time 265639ms: Process C completed I/O; added to ready queue [Q N K J E G O C]
time 265930ms: Process D completed a CPU burst; 38 bursts to go [Q N K J E G O C]
time 265930ms: Process D switching out of CPU; blocking on I/O until time 277032ms [Q N K J E G O C]
time 265934ms: Process N started using the CPU for 413ms burst [Q K J E G O C]
time 266347ms: Process N completed a CPU burst; 36 bursts to go [Q K J E G O C]
time 266347ms: Process N switching out of CPU; blocking on I/O until time 271449ms [Q K J E G O C]
time 266351ms: Process K started using the CPU for 1404ms burst [Q J E G O C]
time 267755ms: Process K completed a CPU burst; 18 bursts to go [Q J E G O C]
time 267755ms: Process K switching out of CPU; blocking on I/O until time 271387ms [Q J E G O C]
time 267759ms: Process J started using the CPU for 1498ms burst [Q E G O C]
time 268018ms: Process F completed I/O; added to ready queue [Q E G O C F]
time 269257ms: Process J completed a CPU burst; 1 burst to go [Q E G O C F]
time 269257ms: Process J switching out of CPU; blocking on I/O until time 273419ms [Q E G O C F]
time 269261ms: Process E started using the CPU for 1612ms burst [Q G O C F]
time 270828ms: Process I completed I/O; added to ready queue [Q G O C F I]
time 270873ms: Process E completed a CPU burst; 44 bursts to go [Q G O C F I]
time 270873ms: Process E switching out of CPU; blocking on I/O until time 271435ms [Q G O C F I]
time 270877ms: Process G started using the CPU for 306ms burst [Q O C F I]
time 271183ms: Process G completed a CPU burst; 5 bursts to go [Q O C F I]
time 271183ms: Process G switching out of CPU; blocking on I/O until time 281295ms [Q O C F I]
time 271187ms: Process O started using the CPU for 1124ms burst [Q C F I]
time 271387ms: Process K completed I/O; added to ready queue [Q C F I K]
time 271435ms: Process E completed I/O; added to ready queue [Q C F I K E]
time 271449ms: Process N completed I/O; added to ready queue [Q C F I K E N]
time 272311ms: Process O completed a CPU burst; 38 bursts to go [Q C F I K E N]
time 272311ms: Process O switching out of CPU; blocking on I/O until time 273845ms [Q C F I K E N]
time 272315ms: Process C started using the CPU for 261ms burst [Q F I K E N]
time 272479ms: Process L completed I/O; added to ready queue [Q F I K E N L]
time 272576ms: Process C completed a CPU burst; 32 bursts to go [Q F I K E N L]
time 272576ms: Process C switching out of CPU; blocking on I/O until time 273858ms [Q F I K E N L]
time 272580ms: Process F started using the CPU for 857ms burst [Q I K E N L]
time 273419ms: Process J completed I/O; added to ready queue [Q I K E N L J]
time 273437ms: Process F completed a CPU burst; 35 bursts to go [Q I K E N L J]
time 273437ms: Process F switching out of CPU; blocking on I/O until time 288959ms [Q I K E N L J]
time 273441ms: Process I started using the CPU for 1603ms burst [Q K E N L J]
time 273845ms: Process O completed I/O; added to ready queue [Q K E N L J O]
time 273858ms: Process C completed I/O; added to ready queue [Q K E N L J O C]
time 275044ms: Process I completed a CPU burst; 32 bursts to go [Q K E N L J O C]
time 275044ms: Process I switching out of CPU; blocking on I/O until time 277376ms [Q K E N L J O C]
time 275048ms: Process K started using the CPU for 2715ms burst [Q E N L J O C]
time 277032ms: Process D completed I/O; added to ready queue [Q E N L J O C D]
time 277376ms: Process I completed I/O; added to ready queue [Q E N L J O C D I]
time 277763ms: Process K completed a CPU burst; 17 bursts to go [Q E N L J O C D I]
time 277763ms: Process K switching out of CPU; blocking on I/O until time 284225ms [Q E N L J O C D I]
time 277767ms: Process E started using the CPU for 659ms burst [Q N L J O C D I]
time 278426ms: Process E completed a CPU burst; 43 bursts to go [Q N L J O C D I]
time 278426ms: Process E switching out of CPU; blocking on I/O until time 281218ms [Q N L J O C D I]
time 278430ms: Process N started using the CPU for 69ms burst [Q L J O C D I]
time 278499ms: Process N completed a CPU burst; 35 bursts to go [Q L J O C D I]
time 278499ms: Process N switching out of CPU; blocking on I/O until time 289151ms [Q L J O C D I]
time 278503ms: Process L started using the CPU for 39ms burst [Q J O C D I]
time 278542ms: Process L completed a CPU burst; 14 bursts to go [Q J O C D I]
time 278542ms: Process L switching out of CPU; blocking on I/O until time 290054ms [Q J O C D I]
time 278546ms: Process J started using the CPU for 1478ms burst [Q O C D I]
time 280024ms: Process J terminated [Q O C D I]
time 280028ms: Process O started using the CPU for 11108ms burst [Q C D I]
time 281218ms: Process E completed I/O; added to ready queue [Q C D I E]
time 281295ms: Process G completed I/O; added to ready queue [Q C D I E G]
time 284225ms: Process K completed I/O; added to ready queue [Q C D I E G K]
time 288959ms: Process F completed I/O; added to ready queue [Q C D I E G K F]
time 289151ms: Process N completed I/O; added to ready queue [Q C D I E G K F N]
time 290054ms: Process L completed I/O; added to ready queue [Q C D I E G K F N L]
time 291136ms: Process O completed a CPU burst; 37 bursts to go [Q C D I E G K F N L]
time 291136ms: Process O switching out of CPU; blocking on I/O until time 293965ms [Q C D I E G K F N L]
time 291140ms: Process C started using the CPU for 1760ms burst [Q D I E G K F N L]
time 292900ms: Process C completed a CPU burst; 31 bursts to go [Q D I E G K F N L]
time 292900ms: Process C switching out of CPU; blocking on I/O until time 295162ms [Q D I E G K F N L]
time 292904ms: Process D started using the CPU for 2006ms burst [Q I E G K F N L]
time 293965ms: Process O completed I/O; added to ready queue [Q I E G K F N L O]
time 294910ms: Process D completed a CPU burst; 37 bursts to go [Q I E G K F N L O]
time 294910ms: Process D switching out of CPU; blocking on I/O until time 302412ms [Q I E G K F N L O]
time 294914ms: Process I started using the CPU for 507ms burst [Q E G K F N L O]
time 295162ms: Process C completed I/O; added to ready queue [Q E G K F N L O C]
time 295421ms: Process I completed a CPU burst; 31 bursts to go [Q E G K F N L O C]
time 295421ms: Process I switching out of CPU; blocking on I/O until time 299253ms [Q E G K F N L O C]
time 295425ms: Process E started using the CPU for 757ms burst [Q G K F N L O C]
time 296182ms: Process E completed a CPU burst; 42 bursts to go [Q G K F N L O C]
time 296182ms: Process E switching out of CPU; blocking on I/O until time 317614ms [Q G K F N L O C]
time 296186ms: Process G started using the CPU for 2272ms burst [Q K F N L O C]
time 298458ms: Process G completed a CPU burst; 4 bursts to go [Q K F N L O C]
time 298458ms: Process G switching out of CPU; blocking on I/O until time 310700ms [Q K F N L O C]
time 298462ms: Process K started using the CPU for 552ms burst [Q F N L O C]
time 299014ms: Process K completed a CPU burst; 16 bursts to go [Q F N L O C]
time 299014ms: Process K switching out of CPU; blocking on I/O until time 299256ms [Q F N L O C]
time 299018ms: Process F started using the CPU for 1107ms burst [Q N L O C]
time 299253ms: Process I completed I/O; added to ready queue [Q N L O C I]
time 299256ms: Process K completed I/O; added to ready queue [Q N L O C I K]
time 300125ms: Process F completed a CPU burst; 34 bursts to go [Q N L O C I K]
time 300125ms: Process F switching out of CPU; blocking on I/O until time 307747ms [Q N L O C I K]
time 300129ms: Process N started using the CPU for 2661ms burst [Q L O C I K]
time 302412ms: Process D completed I/O; added to ready queue [Q L O C I K D]
time 302790ms: Process N completed a CPU burst; 34 bursts to go [Q L O C I K D]
time 302790ms: Process N switching out of CPU; blocking on I/O until time 318922ms [Q L O C I K D]
time 302794ms: Process L started using the CPU for 279ms burst [Q O C I K D]
time 303073ms: Process L completed a CPU burst; 13 bursts to go [Q O C I K D]
time 303073ms: Process L switching out of CPU; blocking on I/O until time 303225ms [Q O C I K D]
time 303077ms: Process O started using the CPU for 940ms burst [Q C I K D]
time 303225ms: Process L completed I/O; added to ready queue [Q C I K D L]
time 304017ms: Process O completed a CPU burst; 36 bursts to go [Q C I K D L]
time 304017ms: Process O switching out of CPU; blocking on I/O until time 307031ms [Q C I K D L]
time 304021ms: Process C started using the CPU for 406ms burst [Q I K D L]
time 304427ms: Process C completed a CPU burst; 30 bursts to go [Q I K D L]
time 304427ms: Process C switching out of CPU; blocking on I/O until time 315679ms [Q I K D L]
time 304431ms: Process I started using the CPU for 600ms burst [Q K D L]
time 305031ms: Process I completed a CPU burst; 30 bursts to go [Q K D L]
time 305031ms: Process I switching out of CPU; blocking on I/O until time 311373ms [Q K D L]
time 305035ms: Process K started using the CPU for 2684ms burst [Q D L]
time 307031ms: Process O completed I/O; added to ready queue [Q D L O]
time 307719ms: Process K completed a CPU burst; 15 bursts to go [Q D L O]
time 307719ms: Process K switching out of CPU; blocking on I/O until time 333891ms [Q D L O]
time 307723ms: Process D started using the CPU for 16ms burst [Q L O]
time 307739ms: Process D completed a CPU burst; 36 bursts to go [Q L O]
time 307739ms: Process D switching out of CPU; blocking on I/O until time 314121ms [Q L O]
time 307743ms: Process L started using the CPU for 332ms burst [Q O]
time 307747ms: Process F completed I/O; added to ready queue [Q O F]
time 308075ms: Process L completed a CPU burst; 12 bursts to go [Q O F]
time 308075ms: Process L switching out of CPU; blocking on I/O until time 308457ms [Q O F]
time 308079ms: Process O started using the CPU for 1080ms burst [Q F]
time 308457ms: Process L completed I/O; added to ready queue [Q F L]
time 309159ms: Process O completed a CPU burst; 35 bursts to go [Q F L]
time 309159ms: Process O switching out of CPU; blocking on I/O until time 310067ms [Q F L]
time 309163ms: Process F started using the CPU for 444ms burst [Q L]
time 309607ms: Process F completed a CPU burst; 33 bursts to go [Q L]
time 309607ms: Process F switching out of CPU; blocking on I/O until time 313619ms [Q L]
time 309611ms: Process L started using the CPU for 551ms burst [Q <empty>]
time 310067ms: Process O completed I/O; added to ready queue [Q O]
time 310162ms: Process L completed a CPU burst; 11 bursts to go [Q O]
time 310162ms: Process L switching out of CPU; blocking on I/O until time 323594ms [Q O]
time 310166ms: Process O started using the CPU for 832ms burst [Q <empty>]
time 310700ms: Process G completed I/O; added to ready queue [Q G]
time 310998ms: Process O completed a CPU burst; 34 bursts to go [Q G]
time 310998ms: Process O switching out of CPU; blocking on I/O until time 312491ms [Q G]
time 311002ms: Process G started using the CPU for 1671ms burst [Q <empty>]
time 311373ms: Process I completed I/O; added to ready queue [Q I]
time 312491ms: Process O completed I/O; added to ready queue [Q I O]
time 312673ms: Process G completed a CPU burst; 3 bursts to go [Q I O]
time 312673ms: Process G switching out of CPU; blocking on I/O until time 333015ms [Q I O]
time 312677ms: Process I started using the CPU for 1407ms burst [Q O]
time 313619ms: Process F completed I/O; added to ready queue [Q O F]
time 314084ms: Process I completed a CPU burst; 29 bursts to go [Q O F]
time 314084ms: Process I switching out of CPU; blocking on I/O until time 314116ms [Q O F]
time 314088ms: Process O started using the CPU for 6160ms burst [Q F]
time 314116ms: Process I completed I/O; added to ready queue [Q F I]
time 314121ms: Process D completed I/O; added to ready queue [Q F I D]
time 315679ms: Process C completed I/O; added to ready queue [Q F I D C]
time 317614ms: Process E completed I/O; added to ready queue [Q F I D C E]
time 318922ms: Process N completed I/O; added to ready queue [Q F I D C E N]
time 320248ms: Process O completed a CPU burst; 33 bursts to go [Q F I D C E N]
time 320248ms: Process O switching out of CPU; blocking on I/O until time 320361ms [Q F I D C E N]
time 320252ms: Process F started using the CPU for 401ms burst [Q I D C E N]
time 320361ms: Process O completed I/O; added to ready queue [Q I D C E N O]
time 320653ms: Process F completed a CPU burst; 32 bursts to go [Q I D C E N O]
time 320653ms: Process F switching out of CPU; blocking on I/O until time 325475ms [Q I D C E N O]
time 320657ms: Process I started using the CPU for 751ms burst [Q D C E N O]
time 321408ms: Process I completed a CPU burst; 28 bursts to go [Q D C E N O]
time 321408ms: Process I switching out of CPU; blocking on I/O until time 332130ms [Q D C E N O]
time 321412ms: Process D started using the CPU for 567ms burst [Q C E N O]
time 321979ms: Process D completed a CPU burst; 35 bursts to go [Q C E N O]
time 321979ms: Process D switching out of CPU; blocking on I/O until time 331241ms [Q C E N O]
time 321983ms: Process C started using the CPU for 2859ms burst [Q E N O]
time 323594ms: Process L completed I/O; added to ready queue [Q E N O L]
time 324842ms: Process C completed a CPU burst; 29 bursts to go [Q E N O L]
time 324842ms: Process C switching out of CPU; blocking on I/O until time 328714ms [Q E N O L]
time 324846ms: Process E started using the CPU for 453ms burst [Q N O L]
time 325299ms: Process E completed a CPU burst; 41 bursts to go [Q N O L]
time 325299ms: Process E switching out of CPU; blocking on I/O until time 353571ms [Q N O L]
time 325303ms: Process N started using the CPU for 328ms burst [Q O L]
time 325475ms: Process F completed I/O; added to ready queue [Q O L F]
time 325631ms: Process N completed a CPU burst; 33 bursts to go [Q O L F]
time 325631ms: Process N switching out of CPU; blocking on I/O until time 342343ms [Q O L F]
time 325635ms: Process O started using the CPU for 4760ms burst [Q L F]
time 328714ms: Process C completed I/O; added to ready queue [Q L F C]
time 330395ms: Process O completed a CPU burst; 32 bursts to go [Q L F C]
time 330395ms: Process O switching out of CPU; blocking on I/O until time 332129ms [Q L F C]
time 330399ms: Process L started using the CPU for 418ms burst [Q F C]
time 330817ms: Process L completed a CPU burst; 10 bursts to go [Q F C]
time 330817ms: Process L switching out of CPU; blocking on I/O until time 354959ms [Q F C]
time 330821ms: Process F started using the CPU for 1110ms burst [Q C]
time 331241ms: Process D completed I/O; added to ready queue [Q C D]
time 331931ms: Process F completed a CPU burst; 31 bursts to go [Q C D]
time 331931ms: Process F switching out of CPU; blocking on I/O until time 343583ms [Q C D]
time 331935ms: Process C started using the CPU for 931ms burst [Q D]
time 332129ms: Process O completed I/O; added to ready queue [Q D O]
time 332130ms: Process I completed I/O; added to ready queue [Q D O I]
time 332866ms: Process C completed a CPU burst; 28 bursts to go [Q D O I]
time 332866ms: Process C switching out of CPU; blocking on I/O until time 338308ms [Q D O I]
time 332870ms: Process D started using the CPU for 1185ms burst [Q O I]
time 333015ms: Process G completed I/O; added to ready queue [Q O I G]
time 333891ms: Process K completed I/O; added to ready queue [Q O I G K]
time 334055ms: Process D completed a CPU burst; 34 bursts to go [Q O I G K]
time 334055ms: Process D switching out of CPU; blocking on I/O until time 335597ms [Q O I G K]
time 334059ms: Process O started using the CPU for 1980ms burst [Q I G K]
time 335597ms: Process D completed I/O; added to ready queue [Q I G K D]
time 336039ms: Process O completed a CPU burst; 31 bursts to go [Q I G K D]
time 336039ms: Process O switching out of CPU; blocking on I/O until time 336153ms [Q I G K D]
time 336043ms: Process I started using the CPU for 744ms burst [Q G K D]
time 336153ms: Process O completed I/O; added to ready queue [Q G K D O]
time 336787ms: Process I completed a CPU burst; 27 bursts to go [Q G K D O]
time 336787ms: Process I switching out of CPU; blocking on I/O until time 344739ms [Q G K D O]
time 336791ms: Process G started using the CPU for 216ms burst [Q K D O]
time 337007ms: Process G completed a CPU burst; 2 bursts to go [Q K D O]
time 337007ms: Process G switching out of CPU; blocking on I/O until time 340519ms [Q K D O]
time 337011ms: Process K started using the CPU for 1827ms burst [Q D O]
time 338308ms: Process C completed I/O; added to ready queue [Q D O C]
time 338838ms: Process K completed a CPU burst; 14 bursts to go [Q D O C]
time 338838ms: Process K switching out of CPU; blocking on I/O until time 339550ms [Q D O C]
time 338842ms: Process D started using the CPU for 703ms burst [Q O C]
time 339545ms: Process D completed a CPU burst; 33 bursts to go [Q O C]
time 339545ms: Process D switching out of CPU; blocking on I/O until time 346897ms [Q O C]
time 339549ms: Process O started using the CPU for 3980ms burst [Q C]
time 339550ms: Process K completed I/O; added to ready queue [Q C K]
time 340519ms: Process G completed I/O; added to ready queue [Q C K G]
time 342343ms: Process N completed I/O; added to ready queue [Q C K G N]
time 343529ms: Process O completed a CPU burst; 30 bursts to go [Q C K G N]
time 343529ms: Process O switching out of CPU; blocking on I/O until time 345308ms [Q C K G N]
time 343533ms: Process C started using the CPU for 687ms burst [Q K G N]
time 343583ms: Process F completed I/O; added to ready queue [Q K G N F]
time 344220ms: Process C completed a CPU burst; 27 bursts to go [Q K G N F]
time 344220ms: Process C switching out of CPU; blocking on I/O until time 356452ms [Q K G N F]
time 344224ms: Process K started using the CPU for 2065ms burst [Q G N F]
time 344739ms: Process I completed I/O; added to ready queue [Q G N F I]
time 345308ms: Process O completed I/O; added to ready queue [Q G N F I O]
time 346289ms: Process K completed a CPU burst; 13 bursts to go [Q G N F I O]
time 346289ms: Process K switching out of CPU; blocking on I/O until time 346361ms [Q G N F I O]
time 346293ms: Process G started using the CPU for 155ms burst [Q N F I O]
time 346361ms: Process K completed I/O; added to ready queue [Q N F I O K]
time 346448ms: Process G completed a CPU burst; 1 burst to go [Q N F I O K]
time 346448ms: Process G switching out of CPU; blocking on I/O until time 358090ms [Q N F I O K]
time 346452ms: Process N started using the CPU for 127ms burst [Q F I O K]
time 346579ms: Process N completed a CPU burst; 32 bursts to go [Q F I O K]
time 346579ms: Process N switching out of CPU; blocking on I/O until time 363971ms [Q F I O K]
time 346583ms: Process F started using the CPU for 809ms burst [Q I O K]
time 346897ms: Process D completed I/O; added to ready queue [Q I O K D]
time 347392ms: Process F completed a CPU burst; 30 bursts to go [Q I O K D]
time 347392ms: Process F switching out of CPU; blocking on I/O until time 349144ms [Q I O K D]
time 347396ms: Process I started using the CPU for 327ms burst [Q O K D]
time 347723ms: Process I completed a CPU burst; 26 bursts to go [Q O K D]
time 347723ms: Process I switching out of CPU; blocking on I/O until time 348555ms [Q O K D]
time 347727ms: Process O started using the CPU for 2780ms burst [Q K D]
time 348555ms: Process I completed I/O; added to ready queue [Q K D I]
time 349144ms: Process F completed I/O; added to ready queue [Q K D I F]
time 350507ms: Process O completed a CPU burst; 29 bursts to go [Q K D I F]
time 350507ms: Process O switching out of CPU; blocking on I/O until time 351997ms [Q K D I F]
time 350511ms: Process K started using the CPU for 1605ms burst [Q D I F]
time 351997ms: Process O completed I/O; added to ready queue [Q D I F O]
time 352116ms: Process K completed a CPU burst; 12 bursts to go [Q D I F O]
time 352116ms: Process K switching out of CPU; blocking on I/O until time 366658ms [Q D I F O]
time 352120ms: Process D started using the CPU for 801ms burst [Q I F O]
time 352921ms: Process D completed a CPU burst; 32 bursts to go [Q I F O]
time 352921ms: Process D switching out of CPU; blocking on I/O until time 359293ms [Q I F O]
time 352925ms: Process I started using the CPU for 46ms burst [Q F O]
time 352971ms: Process I completed a CPU burst; 25 bursts to go [Q F O]
time 352971ms: Process I switching out of CPU; blocking on I/O until time 359793ms [Q F O]
time 352975ms: Process F started using the CPU for 195ms burst [Q O]
time 353170ms: Process F completed a CPU burst; 29 bursts to go [Q O]
time 353170ms: Process F switching out of CPU; blocking on I/O until time 354132ms [Q O]
time 353174ms: Process O started using the CPU for 544ms burst [Q <empty>]
time 353571ms: Process E completed I/O; added to ready queue [Q E]
time 353718ms: Process O completed a CPU burst; 28 bursts to go [Q E]
time 353718ms: Process O switching out of CPU; blocking on I/O until time 356726ms [Q E]
time 353722ms: Process E started using the CPU for 36ms burst [Q <empty>]
time 353758ms: Process E completed a CPU burst; 40 bursts to go [Q <empty>]
time 353758ms: Process E switching out of CPU; blocking on I/O until time 355750ms [Q <empty>]
time 354132ms: Process F completed I/O; added to ready queue [Q F]
time 354134ms: Process F started using the CPU for 23ms burst [Q <empty>]
time 354157ms: Process F completed a CPU burst; 28 bursts to go [Q <empty>]
time 354157ms: Process F switching out of CPU; blocking on I/O until time 357059ms [Q <empty>]
time 354959ms: Process L completed I/O; added to ready queue [Q L]
time 354961ms: Process L started using the CPU for 2716ms burst [Q <empty>]
time 355750ms: Process E completed I/O; added to ready queue [Q E]
time 356452ms: Process C completed I/O; added to ready queue [Q E C]
time 356726ms: Process O completed I/O; added to ready queue [Q E C O]
time 357059ms: Process F completed I/O; added to ready queue [Q E C O F]
time 357677ms: Process L completed a CPU burst; 9 bursts to go [Q E C O F]
time 357677ms: Process L switching out of CPU; blocking on I/O until time 367319ms [Q E C O F]
time 357681ms: Process E started using the CPU for 383ms burst [Q C O F]
time 358064ms: Process E completed a CPU burst; 39 bursts to go [Q C O F]
time 358064ms: Process E switching out of CPU; blocking on I/O until time 358906ms [Q C O F]
time 358068ms: Process C started using the CPU for 1526ms burst [Q O F]
time 358090ms: Process G completed I/O; added to ready queue [Q O F G]
time 358906ms: Process E completed I/O; added to ready queue [Q O F G E]
time 359293ms: Process D completed I/O; added to ready queue [Q O F G E D]
time 359594ms: Process C completed a CPU burst; 26 bursts to go [Q O F G E D]
time 359594ms: Process C switching out of CPU; blocking on I/O until time 368776ms [Q O F G E D]
time 359598ms: Process O started using the CPU for 8740ms burst [Q F G E D]
time 359793ms: Process I completed I/O; added to ready queue [Q F G E D I]
time 363971ms: Process N completed I/O; added to ready queue [Q F G E D I N]
time 366658ms: Process K completed I/O; added to ready queue [Q F G E D I N K]
time 367319ms: Process L completed I/O; added to ready queue [Q F G E D I N K L]
time 368338ms: Process O completed a CPU burst; 27 bursts to go [Q F G E D I N K L]
time 368338ms: Process O switching out of CPU; blocking on I/O until time 368853ms [Q F G E D I N K L]
time 368342ms: Process F started using the CPU for 2381ms burst [Q G E D I N K L]
time 368776ms: Process C completed I/O; added to ready queue [Q G E D I N K L C]
time 368853ms: Process O completed I/O; added to ready queue [Q G E D I N K L C O]
time 370723ms: Process F completed a CPU burst; 27 bursts to go [Q G E D I N K L C O]
time 370723ms: Process F switching out of CPU; blocking on I/O until time 376915ms [Q G E D I N K L C O]
time 370727ms: Process G started using the CPU for 139ms burst [Q E D I N K L C O]
time 370866ms: Process G terminated [Q E D I N K L C O]
time 370870ms: Process E started using the CPU for 172ms burst [Q D I N K L C O]
time 371042ms: Process E completed a CPU burst; 38 bursts to go [Q D I N K L C O]
time 371042ms: Process E switching out of CPU; blocking on I/O until time 372204ms [Q D I N K L C O]
time 371046ms: Process D started using the CPU for 70ms burst [Q I N K L C O]
time 371116ms: Process D completed a CPU burst; 31 bursts to go [Q I N K L C O]
time 371116ms: Process D switching out of CPU; blocking on I/O until time 381998ms [Q I N K L C O]
time 371120ms: Process I started using the CPU for 1783ms burst [Q N K L C O]
time 372204ms: Process E completed I/O; added to ready queue [Q N K L C O E]
time 372903ms: Process I completed a CPU burst; 24 bursts to go [Q N K L C O E]
time 372903ms: Process I switching out of CPU; blocking on I/O until time 375425ms [Q N K L C O E]
time 372907ms: Process N started using the CPU for 343ms burst [Q K L C O E]
time 373250ms: Process N completed a CPU burst; 31 bursts to go [Q K L C O E]
time 373250ms: Process N switching out of CPU; blocking on I/O until time 382412ms [Q K L C O E]
time 373254ms: Process K started using the CPU for 2009ms burst [Q L C O E]
time 375263ms: Process K completed a CPU burst; 11 bursts to go [Q L C O E]
time 375263ms: Process K switching out of CPU; blocking on I/O until time 397285ms [Q L C O E]
time 375267ms: Process L started using the CPU for 1ms burst [Q C O E]
time 375268ms: Process L completed a CPU burst; 8 bursts to go [Q C O E]
time 375268ms: Process L switching out of CPU; blocking on I/O until time 384490ms [Q C O E]
time 375272ms: Process C started using the CPU for 710ms burst [Q O E]
time 375425ms: Process I completed I/O; added to ready queue [Q O E I]
time 375982ms: Process C completed a CPU burst; 25 bursts to go [Q O E I]
time 375982ms: Process C switching out of CPU; blocking on I/O until time 377634ms [Q O E I]
time 375986ms: Process O started using the CPU for 3908ms burst [Q E I]
time 376915ms: Process F completed I/O; added to ready queue [Q E I F]
time 377634ms: Process C completed I/O; added to ready queue [Q E I F C]
time 379894ms: Process O completed a CPU burst; 26 bursts to go [Q E I F C]
time 379894ms: Process O switching out of CPU; blocking on I/O until time 380224ms [Q E I F C]
time 379898ms: Process E started using the CPU for 2233ms burst [Q I F C]
time 380224ms: Process O completed I/O; added to ready queue [Q I F C O]
time 381998ms: Process D completed I/O; added to ready queue [Q I F C O D]
time 382131ms: Process E completed a CPU burst; 37 bursts to go [Q I F C O D]
time 382131ms: Process E switching out of CPU; blocking on I/O until time 382343ms [Q I F C O D]
time 382135ms: Process I started using the CPU for 1768ms burst [Q F C O D]
time 382343ms: Process E completed I/O; added to ready queue [Q F C O D E]
time 382412ms: Process N completed I/O; added to ready queue [Q F C O D E N]
time 383903ms: Process I completed a CPU burst; 23 bursts to go [Q F C O D E N]
time 383903ms: Process I switching out of CPU; blocking on I/O until time 384755ms [Q F C O D E N]
time 383907ms: Process F started using the CPU for 1176ms burst [Q C O D E N]
time 384490ms: Process L completed I/O; added to ready queue [Q C O D E N L]
time 384755ms: Process I completed I/O; added to ready queue [Q C O D E N L I]
time 385083ms: Process F completed a CPU burst; 26 bursts to go [Q C O D E N L I]
time 385083ms: Process F switching out of CPU; blocking on I/O until time 388245ms [Q C O D E N L I]
time 385087ms: Process C started using the CPU for 455ms burst [Q O D E N L I]
